package com.salvestrom.w2theJungle.worldGen.structures;
import java.util.Random;

import com.salvestrom.w2theJungle.w2theJungle;
import com.salvestrom.w2theJungle.blocks.mossySlab;
import com.salvestrom.w2theJungle.blocks.mossySlab.EnumType;
import com.salvestrom.w2theJungle.init.JungleBlocks;
import com.salvestrom.w2theJungle.mobs.entity.EntityLenny;

import net.minecraft.block.Block;
import net.minecraft.block.BlockPistonBase;
import net.minecraft.init.Blocks;
import net.minecraft.util.EnumFacing;
import net.minecraft.util.math.BlockPos;
import net.minecraft.world.World;
import net.minecraft.world.gen.feature.WorldGenerator;

public class LostWorldHeart extends WorldGenerator
{
	public blockPlacmentBridge bridge = new blockPlacmentBridge();
	
	public boolean dun;
	public fillWithBlocks fill = new fillWithBlocks();
	public jungleBeaconWG jB = new jungleBeaconWG();
	public String rota = "e"; //in actual use rota would be set on method call, not hard coded.
	
	public LostWorldHeart() {}

	public boolean generate(World world, Random rand, int i, int j, int k) {
		
		if(dun)
		{return false;}
		
		//-45 to 195 and -80 to 85
		
		//im not sure this has made any discernable speed difference to generation. still 8-9 secs
		/*
		if(partialBuild(world, rand, -45, 0, -80, -40)) {
			if(partialBuild(world, rand, -45, 0, -39, 0)) {
				
				if(partialBuild(world, rand, 1, 85, 1, 85)) {
					if(partialBuild(world, rand, 86, 195, 1, 85)) {
				
						if(partialBuild(world, rand, -45, 0, 1, 85)) {
						
							if(partialBuild(world, rand, 1, 85, -80, -40)) {
								if(partialBuild(world, rand, 86, 195, -80, -40)) {
								
									if(partialBuild(world, rand, 1, 85, -39, 0)) {
										this.partialBuild(world, rand, 86, 195, -39, 0);
									}
								}
							}
						}
					}
				}
			}
		}
		*/
		
		for(int fi = 0; fi <= 34; fi++)
			for(int fk = 0; fk <= 34; fk++) {
				bridge.setBlock(world, i + fi, j + 0, k + fk, JungleBlocks.ancientMossyBlock, 0, 2);
			}
		
		fill.fillWithRotationAndMeta(world, i, j, k, 0, 0, 1, 1, 0, 34, Blocks.STONEBRICK, 1, 2, rota);

		bridge.setBlock(world, i + 0, j + 2, k + 6, JungleBlocks.ancientMossyBlock);
		bridge.setBlock(world, i + 0, j + 2, k + 14, JungleBlocks.ancientMossyBlock);
		bridge.setBlock(world, i + 0, j + 2, k + 15, JungleBlocks.jungleBrazier);
		bridge.setBlock(world, i + 0, j + 2, k + 19, JungleBlocks.jungleBrazier);
		bridge.setBlock(world, i + 0, j + 2, k + 20, JungleBlocks.ancientMossyBlock);
		bridge.setBlock(world, i + 0, j + 2, k + 28, JungleBlocks.ancientMossyBlock);
		bridge.setBlock(world, i + 0, j + 3, k + 6, Blocks.COBBLESTONE_WALL, 1, 2);
		bridge.setBlock(world, i + 0, j + 3, k + 14, Blocks.COBBLESTONE_WALL, 1, 2);
		bridge.setBlock(world, i + 0, j + 3, k + 20, Blocks.COBBLESTONE_WALL, 1, 2);
		bridge.setBlock(world, i + 0, j + 3, k + 28, Blocks.COBBLESTONE_WALL, 1, 2);
		bridge.setBlock(world, i + 0, j + 4, k + 6, JungleBlocks.ancientMossyBlock);
		bridge.setBlock(world, i + 0, j + 4, k + 14, JungleBlocks.ancientMossyBlock);
		bridge.setBlock(world, i + 0, j + 4, k + 20, JungleBlocks.ancientMossyBlock);
		bridge.setBlock(world, i + 0, j + 4, k + 28, JungleBlocks.ancientMossyBlock);
		bridge.setBlock(world, i + 0, j + 5, k + 6, Blocks.COBBLESTONE_WALL, 1, 2);
		bridge.setBlock(world, i + 0, j + 5, k + 14, Blocks.COBBLESTONE_WALL, 1, 2);
		bridge.setBlock(world, i + 0, j + 5, k + 20, Blocks.COBBLESTONE_WALL, 1, 2);
		bridge.setBlock(world, i + 0, j + 5, k + 28, Blocks.COBBLESTONE_WALL, 1, 2);
		bridge.setBlock(world, i + 0, j + 6, k + 6, Blocks.COBBLESTONE_WALL, 1, 2);
		bridge.setBlock(world, i + 0, j + 6, k + 14, Blocks.COBBLESTONE_WALL, 1, 2);
		bridge.setBlock(world, i + 0, j + 6, k + 20, Blocks.COBBLESTONE_WALL, 1, 2);
		bridge.setBlock(world, i + 0, j + 6, k + 28, Blocks.COBBLESTONE_WALL, 1, 2);
		bridge.setBlock(world, i + 0, j + 7, k + 6, JungleBlocks.mossystairs);
		bridge.setBlock(world, i + 0, j + 7, k + 14, JungleBlocks.mossystairs);
		bridge.setBlock(world, i + 0, j + 7, k + 20, JungleBlocks.mossystairs);
		bridge.setBlock(world, i + 0, j + 7, k + 28, JungleBlocks.mossystairs);
		bridge.setBlock(world, i + 1, j + 1, k + 0, Blocks.STONEBRICK, 1, 2);
		
		fill.fillWithRotationAndMeta(world, i, j, k, 1, 1, 1, 1, 1, 33, Blocks.DIRT, 0, 2, rota);
		
//		for(int fk = 1; fk <= 33; ++fk) {bridge.setBlock(world, i + 1, j + 1, k + fk, Blocks.DIRT, 0, 2);}
		fill.placeBlockWithMetaAndRota(world, i, j, k, 1, 1, 34, Blocks.STONEBRICK, 1, 2, rota);
		
		fill.fillWithRotation(world, i, j, k, 1, 1, 2, 2, 1, 15, JungleBlocks.ancientMossyBlock, rota);
		fill.fillWithRotationAndMeta(world, i, j, k, 1, 1, 2, 2, 16, 18, JungleBlocks.mossystairs, 0, 2, rota);
		fill.fillWithRotation(world, i, j, k, 1, 1, 2, 2, 19, 33, JungleBlocks.ancientMossyBlock, rota);
		
		bridge.setBlock(world, i + 1, j + 3, k + 1, JungleBlocks.ancientMossyBlock);
		bridge.setBlock(world, i + 1, j + 3, k + 2, JungleBlocks.mossystairs);
		bridge.setBlock(world, i + 1, j + 3, k + 3, JungleBlocks.mossystairs);
		bridge.setBlock(world, i + 1, j + 3, k + 4, JungleBlocks.mossystairs);
		bridge.setBlock(world, i + 1, j + 3, k + 5, JungleBlocks.mossystairs);
		bridge.setBlock(world, i + 1, j + 3, k + 6, JungleBlocks.ancientMossyBlock);
		bridge.setBlock(world, i + 1, j + 3, k + 10, JungleBlocks.ancientMossyBlock);
		bridge.setBlock(world, i + 1, j + 3, k + 11, JungleBlocks.mossystairs);
		bridge.setBlock(world, i + 1, j + 3, k + 12, JungleBlocks.mossystairs);
		bridge.setBlock(world, i + 1, j + 3, k + 13, JungleBlocks.mossystairs);
		bridge.setBlock(world, i + 1, j + 3, k + 14, JungleBlocks.ancientMossyBlock);
		bridge.setBlock(world, i + 1, j + 3, k + 20, JungleBlocks.ancientMossyBlock);
		bridge.setBlock(world, i + 1, j + 3, k + 21, JungleBlocks.mossystairs);
		bridge.setBlock(world, i + 1, j + 3, k + 22, JungleBlocks.mossystairs);
		bridge.setBlock(world, i + 1, j + 3, k + 23, JungleBlocks.mossystairs);
		bridge.setBlock(world, i + 1, j + 3, k + 24, JungleBlocks.ancientMossyBlock);
		bridge.setBlock(world, i + 1, j + 3, k + 28, JungleBlocks.ancientMossyBlock);
		bridge.setBlock(world, i + 1, j + 3, k + 29, JungleBlocks.mossystairs);
		bridge.setBlock(world, i + 1, j + 3, k + 30, JungleBlocks.mossystairs);
		bridge.setBlock(world, i + 1, j + 3, k + 31, JungleBlocks.mossystairs);
		bridge.setBlock(world, i + 1, j + 3, k + 32, JungleBlocks.mossystairs);
		bridge.setBlock(world, i + 1, j + 3, k + 33, JungleBlocks.ancientMossyBlock);
		bridge.setBlock(world, i + 1, j + 7, k + 6, JungleBlocks.mossyslabSingle, 14, 2);
		bridge.setBlock(world, i + 1, j + 7, k + 14, JungleBlocks.mossyslabSingle, 14, 2);
		bridge.setBlock(world, i + 1, j + 7, k + 20, JungleBlocks.mossyslabSingle, 14, 2);
		bridge.setBlock(world, i + 1, j + 7, k + 28, JungleBlocks.mossyslabSingle, 14, 2);
		bridge.setBlock(world, i + 1, j + 8, k + 6, JungleBlocks.mossyslabSingle, 6, 2);
		bridge.setBlock(world, i + 1, j + 8, k + 14, JungleBlocks.mossyslabSingle, 6, 2);
		bridge.setBlock(world, i + 1, j + 8, k + 20, JungleBlocks.mossyslabSingle, 6, 2);
		bridge.setBlock(world, i + 1, j + 8, k + 28, JungleBlocks.mossyslabSingle, 6, 2);
		bridge.setBlock(world, i + 2, j + 1, k + 0, Blocks.STONEBRICK, 1, 2);
		
		fill.fillWithRotationAndMeta(world, i, j, k, 2, 2, 1, 1, 1, 33, Blocks.DIRT, 0, 2, rota);
		fill.placeBlockWithMetaAndRota(world, i, j, k, 2, 2, 34, Blocks.STONEBRICK, 1, 2, rota);
		fill.fillWithRotation(world, i, j, k, 2, 2, 2, 2, 1, 33, JungleBlocks.ancientMossyBlock, rota);
		fill.placeBlockWithMetaAndRota(world, i, j, k, 2, 3, 1, JungleBlocks.mossystairs, 2, 2, rota);
		fill.fillWithRotation(world, i, j, k, 2, 2, 3, 3, 2, 32, JungleBlocks.ancientMossyBlock, rota);
		
		bridge.setBlock(world, i + 2, j + 3, k + 33, JungleBlocks.mossystairs, 3, 2);
		bridge.setBlock(world, i + 2, j + 4, k + 2, JungleBlocks.ancientMossyBlock);
		bridge.setBlock(world, i + 2, j + 4, k + 3, JungleBlocks.mossystairs);
		bridge.setBlock(world, i + 2, j + 4, k + 4, JungleBlocks.mossystairs);
		bridge.setBlock(world, i + 2, j + 4, k + 5, JungleBlocks.mossystairs);
		bridge.setBlock(world, i + 2, j + 4, k + 6, JungleBlocks.ancientMossyBlock);
		bridge.setBlock(world, i + 2, j + 4, k + 10, JungleBlocks.ancientMossyBlock);
		bridge.setBlock(world, i + 2, j + 4, k + 11, JungleBlocks.mossystairs);
		bridge.setBlock(world, i + 2, j + 4, k + 12, JungleBlocks.mossystairs);
		bridge.setBlock(world, i + 2, j + 4, k + 13, JungleBlocks.mossystairs);
		bridge.setBlock(world, i + 2, j + 4, k + 14, JungleBlocks.ancientMossyBlock);
		bridge.setBlock(world, i + 2, j + 4, k + 20, JungleBlocks.ancientMossyBlock);
		bridge.setBlock(world, i + 2, j + 4, k + 21, JungleBlocks.mossystairs);
		bridge.setBlock(world, i + 2, j + 4, k + 22, JungleBlocks.mossystairs);
		bridge.setBlock(world, i + 2, j + 4, k + 23, JungleBlocks.mossystairs);
		bridge.setBlock(world, i + 2, j + 4, k + 24, JungleBlocks.ancientMossyBlock);
		bridge.setBlock(world, i + 2, j + 4, k + 28, JungleBlocks.ancientMossyBlock);
		bridge.setBlock(world, i + 2, j + 4, k + 29, JungleBlocks.mossystairs);
		bridge.setBlock(world, i + 2, j + 4, k + 30, JungleBlocks.mossystairs);
		bridge.setBlock(world, i + 2, j + 4, k + 31, JungleBlocks.mossystairs);
		bridge.setBlock(world, i + 2, j + 4, k + 32, JungleBlocks.ancientMossyBlock);
		bridge.setBlock(world, i + 2, j + 5, k + 6, Blocks.COBBLESTONE_WALL, 1, 2);
		bridge.setBlock(world, i + 2, j + 5, k + 14, Blocks.COBBLESTONE_WALL, 1, 2);
		bridge.setBlock(world, i + 2, j + 5, k + 20, Blocks.COBBLESTONE_WALL, 1, 2);
		bridge.setBlock(world, i + 2, j + 5, k + 28, Blocks.COBBLESTONE_WALL, 1, 2);
		bridge.setBlock(world, i + 2, j + 6, k + 6, Blocks.COBBLESTONE_WALL, 1, 2);
		bridge.setBlock(world, i + 2, j + 6, k + 14, Blocks.COBBLESTONE_WALL, 1, 2);
		bridge.setBlock(world, i + 2, j + 6, k + 20, Blocks.COBBLESTONE_WALL, 1, 2);
		bridge.setBlock(world, i + 2, j + 6, k + 28, Blocks.COBBLESTONE_WALL, 1, 2);
		bridge.setBlock(world, i + 2, j + 7, k + 6, JungleBlocks.mossystairs, 1, 2);
		bridge.setBlock(world, i + 2, j + 7, k + 14, JungleBlocks.mossystairs, 1, 2);
		bridge.setBlock(world, i + 2, j + 7, k + 20, JungleBlocks.mossystairs, 1, 2);
		bridge.setBlock(world, i + 2, j + 7, k + 28, JungleBlocks.mossystairs, 1, 2);
		bridge.setBlock(world, i + 3, j + 1, k + 0, Blocks.STONEBRICK, 1, 2);
		
		bridge.setBlock(world, i + 3, j + 1, k + 1, Blocks.DIRT, 0, 2);
		bridge.setBlock(world, i + 3, j + 1, k + 2, Blocks.DIRT, 0, 2);
		bridge.setBlock(world, i + 3, j + 1, k + 3, Blocks.DIRT, 0, 2);
		bridge.setBlock(world, i + 3, j + 1, k + 4, Blocks.DIRT, 0, 2);
		bridge.setBlock(world, i + 3, j + 1, k + 5, Blocks.DIRT, 0, 2);
		bridge.setBlock(world, i + 3, j + 1, k + 6, Blocks.DIRT, 0, 2);
		bridge.setBlock(world, i + 3, j + 1, k + 7, Blocks.DIRT, 0, 2);
		bridge.setBlock(world, i + 3, j + 1, k + 8, Blocks.DIRT, 0, 2);
		bridge.setBlock(world, i + 3, j + 1, k + 9, Blocks.DIRT, 0, 2);
		bridge.setBlock(world, i + 3, j + 1, k + 10, Blocks.DIRT, 0, 2);
		bridge.setBlock(world, i + 3, j + 1, k + 11, Blocks.DIRT, 0, 2);
		bridge.setBlock(world, i + 3, j + 1, k + 12, Blocks.DIRT, 0, 2);
		bridge.setBlock(world, i + 3, j + 1, k + 13, Blocks.DIRT, 0, 2);
		bridge.setBlock(world, i + 3, j + 1, k + 14, Blocks.DIRT, 0, 2);
		bridge.setBlock(world, i + 3, j + 1, k + 15, Blocks.DIRT, 0, 2);
		bridge.setBlock(world, i + 3, j + 1, k + 16, Blocks.DIRT, 0, 2);
		bridge.setBlock(world, i + 3, j + 1, k + 17, Blocks.DIRT, 0, 2);
		bridge.setBlock(world, i + 3, j + 1, k + 18, Blocks.DIRT, 0, 2);
		bridge.setBlock(world, i + 3, j + 1, k + 19, Blocks.DIRT, 0, 2);
		bridge.setBlock(world, i + 3, j + 1, k + 20, Blocks.DIRT, 0, 2);
		bridge.setBlock(world, i + 3, j + 1, k + 21, Blocks.DIRT, 0, 2);
		bridge.setBlock(world, i + 3, j + 1, k + 22, Blocks.DIRT, 0, 2);
		bridge.setBlock(world, i + 3, j + 1, k + 23, Blocks.DIRT, 0, 2);
		bridge.setBlock(world, i + 3, j + 1, k + 24, Blocks.DIRT, 0, 2);
		bridge.setBlock(world, i + 3, j + 1, k + 25, Blocks.DIRT, 0, 2);
		bridge.setBlock(world, i + 3, j + 1, k + 26, Blocks.DIRT, 0, 2);
		bridge.setBlock(world, i + 3, j + 1, k + 27, Blocks.DIRT, 0, 2);
		bridge.setBlock(world, i + 3, j + 1, k + 28, Blocks.DIRT, 0, 2);
		bridge.setBlock(world, i + 3, j + 1, k + 29, Blocks.DIRT, 0, 2);
		bridge.setBlock(world, i + 3, j + 1, k + 30, Blocks.DIRT, 0, 2);
		bridge.setBlock(world, i + 3, j + 1, k + 31, Blocks.DIRT, 0, 2);
		bridge.setBlock(world, i + 3, j + 1, k + 32, Blocks.DIRT, 0, 2);
		bridge.setBlock(world, i + 3, j + 1, k + 33, Blocks.DIRT, 0, 2);
		bridge.setBlock(world, i + 3, j + 1, k + 34, Blocks.STONEBRICK, 1, 2);
		bridge.setBlock(world, i + 3, j + 2, k + 1, JungleBlocks.ancientMossyBlock);
		bridge.setBlock(world, i + 3, j + 2, k + 2, JungleBlocks.ancientMossyBlock);
		bridge.setBlock(world, i + 3, j + 2, k + 3, JungleBlocks.ancientMossyBlock);
		bridge.setBlock(world, i + 3, j + 2, k + 4, JungleBlocks.ancientMossyBlock);
		bridge.setBlock(world, i + 3, j + 2, k + 5, JungleBlocks.ancientMossyBlock);
		bridge.setBlock(world, i + 3, j + 2, k + 6, JungleBlocks.ancientMossyBlock);
		bridge.setBlock(world, i + 3, j + 2, k + 7, JungleBlocks.ancientMossyBlock);
		bridge.setBlock(world, i + 3, j + 2, k + 8, JungleBlocks.ancientMossyBlock);
		bridge.setBlock(world, i + 3, j + 2, k + 9, JungleBlocks.ancientMossyBlock);
		bridge.setBlock(world, i + 3, j + 2, k + 10, JungleBlocks.ancientMossyBlock);
		bridge.setBlock(world, i + 3, j + 2, k + 11, JungleBlocks.ancientMossyBlock);
		bridge.setBlock(world, i + 3, j + 2, k + 12, JungleBlocks.ancientMossyBlock);
		bridge.setBlock(world, i + 3, j + 2, k + 13, JungleBlocks.ancientMossyBlock);
		bridge.setBlock(world, i + 3, j + 2, k + 14, JungleBlocks.ancientMossyBlock);
		bridge.setBlock(world, i + 3, j + 2, k + 15, JungleBlocks.ancientMossyBlock);
		bridge.setBlock(world, i + 3, j + 2, k + 16, JungleBlocks.ancientMossyBlock);
		bridge.setBlock(world, i + 3, j + 2, k + 17, JungleBlocks.ancientMossyBlock);
		bridge.setBlock(world, i + 3, j + 2, k + 18, JungleBlocks.ancientMossyBlock);
		bridge.setBlock(world, i + 3, j + 2, k + 19, JungleBlocks.ancientMossyBlock);
		bridge.setBlock(world, i + 3, j + 2, k + 20, JungleBlocks.ancientMossyBlock);
		bridge.setBlock(world, i + 3, j + 2, k + 21, JungleBlocks.ancientMossyBlock);
		bridge.setBlock(world, i + 3, j + 2, k + 22, JungleBlocks.ancientMossyBlock);
		bridge.setBlock(world, i + 3, j + 2, k + 23, JungleBlocks.ancientMossyBlock);
		bridge.setBlock(world, i + 3, j + 2, k + 24, JungleBlocks.ancientMossyBlock);
		bridge.setBlock(world, i + 3, j + 2, k + 25, JungleBlocks.ancientMossyBlock);
		bridge.setBlock(world, i + 3, j + 2, k + 26, JungleBlocks.ancientMossyBlock);
		bridge.setBlock(world, i + 3, j + 2, k + 27, JungleBlocks.ancientMossyBlock);
		bridge.setBlock(world, i + 3, j + 2, k + 28, JungleBlocks.ancientMossyBlock);
		bridge.setBlock(world, i + 3, j + 2, k + 29, JungleBlocks.ancientMossyBlock);
		bridge.setBlock(world, i + 3, j + 2, k + 30, JungleBlocks.ancientMossyBlock);
		bridge.setBlock(world, i + 3, j + 2, k + 31, JungleBlocks.ancientMossyBlock);
		bridge.setBlock(world, i + 3, j + 2, k + 32, JungleBlocks.ancientMossyBlock);
		bridge.setBlock(world, i + 3, j + 2, k + 33, JungleBlocks.ancientMossyBlock);
		bridge.setBlock(world, i + 3, j + 3, k + 1, JungleBlocks.mossystairs, 2, 2);
		bridge.setBlock(world, i + 3, j + 3, k + 2, JungleBlocks.ancientMossyBlock);
		bridge.setBlock(world, i + 3, j + 3, k + 3, JungleBlocks.ancientMossyBlock);
		bridge.setBlock(world, i + 3, j + 3, k + 4, JungleBlocks.ancientMossyBlock);
		bridge.setBlock(world, i + 3, j + 3, k + 5, JungleBlocks.ancientMossyBlock);
		bridge.setBlock(world, i + 3, j + 3, k + 6, JungleBlocks.ancientMossyBlock);
		bridge.setBlock(world, i + 3, j + 3, k + 7, JungleBlocks.ancientMossyBlock);
		bridge.setBlock(world, i + 3, j + 3, k + 8, JungleBlocks.ancientMossyBlock);
		bridge.setBlock(world, i + 3, j + 3, k + 9, JungleBlocks.ancientMossyBlock);
		bridge.setBlock(world, i + 3, j + 3, k + 10, JungleBlocks.ancientMossyBlock);
		bridge.setBlock(world, i + 3, j + 3, k + 11, JungleBlocks.ancientMossyBlock);
		bridge.setBlock(world, i + 3, j + 3, k + 12, JungleBlocks.ancientMossyBlock);
		bridge.setBlock(world, i + 3, j + 3, k + 13, JungleBlocks.ancientMossyBlock);
		bridge.setBlock(world, i + 3, j + 3, k + 14, JungleBlocks.ancientMossyBlock);
		bridge.setBlock(world, i + 3, j + 3, k + 15, JungleBlocks.ancientMossyBlock);
		bridge.setBlock(world, i + 3, j + 3, k + 16, JungleBlocks.ancientMossyBlock);
		bridge.setBlock(world, i + 3, j + 3, k + 17, JungleBlocks.ancientMossyBlock);
		bridge.setBlock(world, i + 3, j + 3, k + 18, JungleBlocks.ancientMossyBlock);
		bridge.setBlock(world, i + 3, j + 3, k + 19, JungleBlocks.ancientMossyBlock);
		bridge.setBlock(world, i + 3, j + 3, k + 20, JungleBlocks.ancientMossyBlock);
		bridge.setBlock(world, i + 3, j + 3, k + 21, JungleBlocks.ancientMossyBlock);
		bridge.setBlock(world, i + 3, j + 3, k + 22, JungleBlocks.ancientMossyBlock);
		bridge.setBlock(world, i + 3, j + 3, k + 23, JungleBlocks.ancientMossyBlock);
		bridge.setBlock(world, i + 3, j + 3, k + 24, JungleBlocks.ancientMossyBlock);
		bridge.setBlock(world, i + 3, j + 3, k + 25, JungleBlocks.ancientMossyBlock);
		bridge.setBlock(world, i + 3, j + 3, k + 26, JungleBlocks.ancientMossyBlock);
		bridge.setBlock(world, i + 3, j + 3, k + 27, JungleBlocks.ancientMossyBlock);
		bridge.setBlock(world, i + 3, j + 3, k + 28, JungleBlocks.ancientMossyBlock);
		bridge.setBlock(world, i + 3, j + 3, k + 29, JungleBlocks.ancientMossyBlock);
		bridge.setBlock(world, i + 3, j + 3, k + 30, JungleBlocks.ancientMossyBlock);
		bridge.setBlock(world, i + 3, j + 3, k + 31, JungleBlocks.ancientMossyBlock);
		bridge.setBlock(world, i + 3, j + 3, k + 32, JungleBlocks.ancientMossyBlock);
		bridge.setBlock(world, i + 3, j + 3, k + 33, JungleBlocks.mossystairs, 3, 2);
		bridge.setBlock(world, i + 3, j + 4, k + 2, JungleBlocks.mossystairs, 2, 2);
		bridge.setBlock(world, i + 3, j + 4, k + 3, JungleBlocks.ancientMossyBlock);
		bridge.setBlock(world, i + 3, j + 4, k + 4, JungleBlocks.ancientMossyBlock);
		bridge.setBlock(world, i + 3, j + 4, k + 5, JungleBlocks.ancientMossyBlock);
		bridge.setBlock(world, i + 3, j + 4, k + 6, JungleBlocks.ancientMossyBlock);
		bridge.setBlock(world, i + 3, j + 4, k + 7, JungleBlocks.ancientMossyBlock);
		bridge.setBlock(world, i + 3, j + 4, k + 8, JungleBlocks.ancientMossyBlock);
		bridge.setBlock(world, i + 3, j + 4, k + 9, JungleBlocks.ancientMossyBlock);
		bridge.setBlock(world, i + 3, j + 4, k + 10, JungleBlocks.ancientMossyBlock);
		bridge.setBlock(world, i + 3, j + 4, k + 11, JungleBlocks.ancientMossyBlock);
		bridge.setBlock(world, i + 3, j + 4, k + 12, JungleBlocks.ancientMossyBlock);
		bridge.setBlock(world, i + 3, j + 4, k + 13, JungleBlocks.ancientMossyBlock);
		bridge.setBlock(world, i + 3, j + 4, k + 14, JungleBlocks.ancientMossyBlock);
		bridge.setBlock(world, i + 3, j + 4, k + 15, JungleBlocks.ancientMossyBlock);
		bridge.setBlock(world, i + 3, j + 4, k + 16, JungleBlocks.mossystairs);
		bridge.setBlock(world, i + 3, j + 4, k + 17, JungleBlocks.mossystairs);
		bridge.setBlock(world, i + 3, j + 4, k + 18, JungleBlocks.mossystairs);
		bridge.setBlock(world, i + 3, j + 4, k + 19, JungleBlocks.ancientMossyBlock);
		bridge.setBlock(world, i + 3, j + 4, k + 20, JungleBlocks.ancientMossyBlock);
		bridge.setBlock(world, i + 3, j + 4, k + 21, JungleBlocks.ancientMossyBlock);
		bridge.setBlock(world, i + 3, j + 4, k + 22, JungleBlocks.ancientMossyBlock);
		bridge.setBlock(world, i + 3, j + 4, k + 23, JungleBlocks.ancientMossyBlock);
		bridge.setBlock(world, i + 3, j + 4, k + 24, JungleBlocks.ancientMossyBlock);
		bridge.setBlock(world, i + 3, j + 4, k + 25, JungleBlocks.ancientMossyBlock);
		bridge.setBlock(world, i + 3, j + 4, k + 26, JungleBlocks.ancientMossyBlock);
		bridge.setBlock(world, i + 3, j + 4, k + 27, JungleBlocks.ancientMossyBlock);
		bridge.setBlock(world, i + 3, j + 4, k + 28, JungleBlocks.ancientMossyBlock);
		bridge.setBlock(world, i + 3, j + 4, k + 29, JungleBlocks.ancientMossyBlock);
		bridge.setBlock(world, i + 3, j + 4, k + 30, JungleBlocks.ancientMossyBlock);
		bridge.setBlock(world, i + 3, j + 4, k + 31, JungleBlocks.ancientMossyBlock);
		bridge.setBlock(world, i + 3, j + 4, k + 32, JungleBlocks.mossystairs, 3, 2);
		bridge.setBlock(world, i + 3, j + 5, k + 3, JungleBlocks.ancientMossyBlock);
		bridge.setBlock(world, i + 3, j + 5, k + 4, JungleBlocks.mossystairs);
		bridge.setBlock(world, i + 3, j + 5, k + 5, JungleBlocks.mossystairs);
		bridge.setBlock(world, i + 3, j + 5, k + 6, JungleBlocks.ancientMossyBlock);
		bridge.setBlock(world, i + 3, j + 5, k + 10, JungleBlocks.ancientMossyBlock);
		bridge.setBlock(world, i + 3, j + 5, k + 11, JungleBlocks.mossystairs);
		bridge.setBlock(world, i + 3, j + 5, k + 12, JungleBlocks.mossystairs);
		bridge.setBlock(world, i + 3, j + 5, k + 13, JungleBlocks.mossystairs);
		bridge.setBlock(world, i + 3, j + 5, k + 14, JungleBlocks.ancientMossyBlock);
		bridge.setBlock(world, i + 3, j + 5, k + 20, JungleBlocks.ancientMossyBlock);
		bridge.setBlock(world, i + 3, j + 5, k + 21, JungleBlocks.mossystairs);
		bridge.setBlock(world, i + 3, j + 5, k + 22, JungleBlocks.mossystairs);
		bridge.setBlock(world, i + 3, j + 5, k + 23, JungleBlocks.mossystairs);
		bridge.setBlock(world, i + 3, j + 5, k + 24, JungleBlocks.ancientMossyBlock);
		bridge.setBlock(world, i + 3, j + 5, k + 28, JungleBlocks.ancientMossyBlock);
		bridge.setBlock(world, i + 3, j + 5, k + 29, JungleBlocks.mossystairs);
		bridge.setBlock(world, i + 3, j + 5, k + 30, JungleBlocks.mossystairs);
		bridge.setBlock(world, i + 3, j + 5, k + 31, JungleBlocks.ancientMossyBlock);
		bridge.setBlock(world, i + 4, j + 1, k + 0, Blocks.STONEBRICK, 1, 2);
		bridge.setBlock(world, i + 4, j + 1, k + 1, Blocks.DIRT, 0, 2);
		bridge.setBlock(world, i + 4, j + 1, k + 2, Blocks.DIRT, 0, 2);
		bridge.setBlock(world, i + 4, j + 1, k + 3, Blocks.DIRT, 0, 2);
		bridge.setBlock(world, i + 4, j + 1, k + 4, Blocks.DIRT, 0, 2);
		bridge.setBlock(world, i + 4, j + 1, k + 5, Blocks.DIRT, 0, 2);
		bridge.setBlock(world, i + 4, j + 1, k + 6, Blocks.DIRT, 0, 2);
		bridge.setBlock(world, i + 4, j + 1, k + 7, Blocks.DIRT, 0, 2);
		bridge.setBlock(world, i + 4, j + 1, k + 8, Blocks.DIRT, 0, 2);
		bridge.setBlock(world, i + 4, j + 1, k + 9, Blocks.DIRT, 0, 2);
		bridge.setBlock(world, i + 4, j + 1, k + 10, Blocks.DIRT, 0, 2);
		bridge.setBlock(world, i + 4, j + 1, k + 11, Blocks.DIRT, 0, 2);
		bridge.setBlock(world, i + 4, j + 1, k + 12, Blocks.DIRT, 0, 2);
		bridge.setBlock(world, i + 4, j + 1, k + 13, Blocks.DIRT, 0, 2);
		bridge.setBlock(world, i + 4, j + 1, k + 14, Blocks.DIRT, 0, 2);
		bridge.setBlock(world, i + 4, j + 1, k + 15, Blocks.DIRT, 0, 2);
		bridge.setBlock(world, i + 4, j + 1, k + 16, Blocks.DIRT, 0, 2);
		bridge.setBlock(world, i + 4, j + 1, k + 17, Blocks.DIRT, 0, 2);
		bridge.setBlock(world, i + 4, j + 1, k + 18, Blocks.DIRT, 0, 2);
		bridge.setBlock(world, i + 4, j + 1, k + 19, Blocks.DIRT, 0, 2);
		bridge.setBlock(world, i + 4, j + 1, k + 20, Blocks.DIRT, 0, 2);
		bridge.setBlock(world, i + 4, j + 1, k + 21, Blocks.DIRT, 0, 2);
		bridge.setBlock(world, i + 4, j + 1, k + 22, Blocks.DIRT, 0, 2);
		bridge.setBlock(world, i + 4, j + 1, k + 23, Blocks.DIRT, 0, 2);
		bridge.setBlock(world, i + 4, j + 1, k + 24, Blocks.DIRT, 0, 2);
		bridge.setBlock(world, i + 4, j + 1, k + 25, Blocks.DIRT, 0, 2);
		bridge.setBlock(world, i + 4, j + 1, k + 26, Blocks.DIRT, 0, 2);
		bridge.setBlock(world, i + 4, j + 1, k + 27, JungleBlocks.ancientMossyBlock);
		bridge.setBlock(world, i + 4, j + 1, k + 28, Blocks.DIRT, 0, 2);
		bridge.setBlock(world, i + 4, j + 1, k + 29, Blocks.DIRT, 0, 2);
		bridge.setBlock(world, i + 4, j + 1, k + 30, Blocks.DIRT, 0, 2);
		bridge.setBlock(world, i + 4, j + 1, k + 31, Blocks.DIRT, 0, 2);
		bridge.setBlock(world, i + 4, j + 1, k + 32, Blocks.DIRT, 0, 2);
		bridge.setBlock(world, i + 4, j + 1, k + 33, Blocks.DIRT, 0, 2);
		bridge.setBlock(world, i + 4, j + 1, k + 34, Blocks.STONEBRICK, 1, 2);
		bridge.setBlock(world, i + 4, j + 2, k + 1, JungleBlocks.ancientMossyBlock);
		bridge.setBlock(world, i + 4, j + 2, k + 2, JungleBlocks.ancientMossyBlock);
		bridge.setBlock(world, i + 4, j + 2, k + 3, JungleBlocks.ancientMossyBlock);
		bridge.setBlock(world, i + 4, j + 2, k + 4, JungleBlocks.ancientMossyBlock);
		bridge.setBlock(world, i + 4, j + 2, k + 5, JungleBlocks.ancientMossyBlock);
		bridge.setBlock(world, i + 4, j + 2, k + 6, JungleBlocks.ancientMossyBlock);
		bridge.setBlock(world, i + 4, j + 2, k + 7, JungleBlocks.ancientMossyBlock);
		bridge.setBlock(world, i + 4, j + 2, k + 8, JungleBlocks.ancientMossyBlock);
		bridge.setBlock(world, i + 4, j + 2, k + 9, JungleBlocks.ancientMossyBlock);
		bridge.setBlock(world, i + 4, j + 2, k + 10, JungleBlocks.ancientMossyBlock);
		bridge.setBlock(world, i + 4, j + 2, k + 11, JungleBlocks.ancientMossyBlock);
		bridge.setBlock(world, i + 4, j + 2, k + 12, JungleBlocks.ancientMossyBlock);
		bridge.setBlock(world, i + 4, j + 2, k + 13, JungleBlocks.ancientMossyBlock);
		bridge.setBlock(world, i + 4, j + 2, k + 14, JungleBlocks.ancientMossyBlock);
		bridge.setBlock(world, i + 4, j + 2, k + 15, JungleBlocks.ancientMossyBlock);
		bridge.setBlock(world, i + 4, j + 2, k + 16, JungleBlocks.ancientMossyBlock);
		bridge.setBlock(world, i + 4, j + 2, k + 17, JungleBlocks.ancientMossyBlock);
		bridge.setBlock(world, i + 4, j + 2, k + 18, JungleBlocks.ancientMossyBlock);
		bridge.setBlock(world, i + 4, j + 2, k + 19, JungleBlocks.ancientMossyBlock);
		bridge.setBlock(world, i + 4, j + 2, k + 20, JungleBlocks.ancientMossyBlock);
		bridge.setBlock(world, i + 4, j + 2, k + 21, JungleBlocks.ancientMossyBlock);
		bridge.setBlock(world, i + 4, j + 2, k + 22, JungleBlocks.ancientMossyBlock);
		bridge.setBlock(world, i + 4, j + 2, k + 23, JungleBlocks.ancientMossyBlock);
		bridge.setBlock(world, i + 4, j + 2, k + 24, JungleBlocks.ancientMossyBlock);
		bridge.setBlock(world, i + 4, j + 2, k + 25, JungleBlocks.ancientMossyBlock);
		bridge.setBlock(world, i + 4, j + 2, k + 26, JungleBlocks.ancientMossyBlock);
		bridge.setBlock(world, i + 4, j + 2, k + 27, JungleBlocks.ancientMossyBlock);
		bridge.setBlock(world, i + 4, j + 2, k + 28, JungleBlocks.ancientMossyBlock);
		bridge.setBlock(world, i + 4, j + 2, k + 29, JungleBlocks.ancientMossyBlock);
		bridge.setBlock(world, i + 4, j + 2, k + 30, JungleBlocks.ancientMossyBlock);
		bridge.setBlock(world, i + 4, j + 2, k + 31, JungleBlocks.ancientMossyBlock);
		bridge.setBlock(world, i + 4, j + 2, k + 32, JungleBlocks.ancientMossyBlock);
		bridge.setBlock(world, i + 4, j + 2, k + 33, JungleBlocks.ancientMossyBlock);
		bridge.setBlock(world, i + 4, j + 3, k + 1, JungleBlocks.mossystairs, 2, 2);
		bridge.setBlock(world, i + 4, j + 3, k + 2, JungleBlocks.ancientMossyBlock);
		bridge.setBlock(world, i + 4, j + 3, k + 3, JungleBlocks.ancientMossyBlock);
		bridge.setBlock(world, i + 4, j + 3, k + 4, JungleBlocks.ancientMossyBlock);
		bridge.setBlock(world, i + 4, j + 3, k + 5, JungleBlocks.ancientMossyBlock);
		bridge.setBlock(world, i + 4, j + 3, k + 6, JungleBlocks.ancientMossyBlock);
		bridge.setBlock(world, i + 4, j + 3, k + 7, JungleBlocks.ancientMossyBlock);
		bridge.setBlock(world, i + 4, j + 3, k + 8, JungleBlocks.ancientMossyBlock);
		bridge.setBlock(world, i + 4, j + 3, k + 9, JungleBlocks.ancientMossyBlock);
		bridge.setBlock(world, i + 4, j + 3, k + 10, JungleBlocks.ancientMossyBlock);
		bridge.setBlock(world, i + 4, j + 3, k + 11, JungleBlocks.ancientMossyBlock);
		bridge.setBlock(world, i + 4, j + 3, k + 12, JungleBlocks.ancientMossyBlock);
		bridge.setBlock(world, i + 4, j + 3, k + 13, JungleBlocks.ancientMossyBlock);
		bridge.setBlock(world, i + 4, j + 3, k + 14, JungleBlocks.ancientMossyBlock);
		bridge.setBlock(world, i + 4, j + 3, k + 15, JungleBlocks.ancientMossyBlock);
		bridge.setBlock(world, i + 4, j + 3, k + 16, JungleBlocks.ancientMossyBlock);
		bridge.setBlock(world, i + 4, j + 3, k + 17, JungleBlocks.ancientMossyBlock);
		bridge.setBlock(world, i + 4, j + 3, k + 18, JungleBlocks.ancientMossyBlock);
		bridge.setBlock(world, i + 4, j + 3, k + 19, JungleBlocks.ancientMossyBlock);
		bridge.setBlock(world, i + 4, j + 3, k + 20, JungleBlocks.ancientMossyBlock);
		bridge.setBlock(world, i + 4, j + 3, k + 21, JungleBlocks.ancientMossyBlock);
		bridge.setBlock(world, i + 4, j + 3, k + 22, JungleBlocks.ancientMossyBlock);
		bridge.setBlock(world, i + 4, j + 3, k + 24, JungleBlocks.ancientMossyBlock);
		bridge.setBlock(world, i + 4, j + 3, k + 26, JungleBlocks.ancientMossyBlock);
		bridge.setBlock(world, i + 4, j + 3, k + 28, JungleBlocks.ancientMossyBlock);
		bridge.setBlock(world, i + 4, j + 3, k + 29, JungleBlocks.ancientMossyBlock);
		bridge.setBlock(world, i + 4, j + 3, k + 30, JungleBlocks.ancientMossyBlock);
		bridge.setBlock(world, i + 4, j + 3, k + 31, JungleBlocks.ancientMossyBlock);
		bridge.setBlock(world, i + 4, j + 3, k + 32, JungleBlocks.ancientMossyBlock);
		bridge.setBlock(world, i + 4, j + 3, k + 33, JungleBlocks.mossystairs, 3, 2);
		bridge.setBlock(world, i + 4, j + 4, k + 2, JungleBlocks.mossystairs, 2, 2);
		bridge.setBlock(world, i + 4, j + 4, k + 3, JungleBlocks.ancientMossyBlock);
		bridge.setBlock(world, i + 4, j + 4, k + 4, JungleBlocks.ancientMossyBlock);
		bridge.setBlock(world, i + 4, j + 4, k + 5, JungleBlocks.ancientMossyBlock);
		bridge.setBlock(world, i + 4, j + 4, k + 6, JungleBlocks.ancientMossyBlock);
		bridge.setBlock(world, i + 4, j + 4, k + 7, JungleBlocks.ancientMossyBlock);
		bridge.setBlock(world, i + 4, j + 4, k + 8, JungleBlocks.ancientMossyBlock);
		bridge.setBlock(world, i + 4, j + 4, k + 9, JungleBlocks.ancientMossyBlock);
		bridge.setBlock(world, i + 4, j + 4, k + 10, JungleBlocks.ancientMossyBlock);
		bridge.setBlock(world, i + 4, j + 4, k + 11, JungleBlocks.ancientMossyBlock);
		bridge.setBlock(world, i + 4, j + 4, k + 12, JungleBlocks.ancientMossyBlock);
		bridge.setBlock(world, i + 4, j + 4, k + 13, JungleBlocks.ancientMossyBlock);
		bridge.setBlock(world, i + 4, j + 4, k + 14, JungleBlocks.ancientMossyBlock);
		bridge.setBlock(world, i + 4, j + 4, k + 15, JungleBlocks.ancientMossyBlock);
		bridge.setBlock(world, i + 4, j + 4, k + 16, JungleBlocks.ancientMossyBlock);
		bridge.setBlock(world, i + 4, j + 4, k + 17, JungleBlocks.ancientMossyBlock);
		bridge.setBlock(world, i + 4, j + 4, k + 18, JungleBlocks.ancientMossyBlock);
		bridge.setBlock(world, i + 4, j + 4, k + 19, JungleBlocks.ancientMossyBlock);
		bridge.setBlock(world, i + 4, j + 4, k + 20, JungleBlocks.ancientMossyBlock);
		bridge.setBlock(world, i + 4, j + 4, k + 21, JungleBlocks.ancientMossyBlock);
		bridge.setBlock(world, i + 4, j + 4, k + 22, JungleBlocks.ancientMossyBlock);
		bridge.setBlock(world, i + 4, j + 4, k + 23, JungleBlocks.ancientMossyBlock);
		bridge.setBlock(world, i + 4, j + 4, k + 24, JungleBlocks.ancientMossyBlock);
		bridge.setBlock(world, i + 4, j + 4, k + 25, JungleBlocks.ancientMossyBlock);
		bridge.setBlock(world, i + 4, j + 4, k + 26, JungleBlocks.ancientMossyBlock);
		bridge.setBlock(world, i + 4, j + 4, k + 27, JungleBlocks.ancientMossyBlock);
		bridge.setBlock(world, i + 4, j + 4, k + 28, JungleBlocks.ancientMossyBlock);
		bridge.setBlock(world, i + 4, j + 4, k + 29, JungleBlocks.ancientMossyBlock);
		bridge.setBlock(world, i + 4, j + 4, k + 30, JungleBlocks.ancientMossyBlock);
		bridge.setBlock(world, i + 4, j + 4, k + 31, JungleBlocks.ancientMossyBlock);
		bridge.setBlock(world, i + 4, j + 4, k + 32, JungleBlocks.mossystairs, 3, 2);
		bridge.setBlock(world, i + 4, j + 5, k + 3, JungleBlocks.mossystairs, 2, 2);
		bridge.setBlock(world, i + 4, j + 5, k + 4, JungleBlocks.ancientMossyBlock);
		bridge.setBlock(world, i + 4, j + 5, k + 5, JungleBlocks.ancientMossyBlock);
		bridge.setBlock(world, i + 4, j + 5, k + 6, JungleBlocks.ancientMossyBlock);
		bridge.setBlock(world, i + 4, j + 5, k + 7, JungleBlocks.ancientMossyBlock);
		bridge.setBlock(world, i + 4, j + 5, k + 8, JungleBlocks.ancientMossyBlock);
		bridge.setBlock(world, i + 4, j + 5, k + 9, JungleBlocks.ancientMossyBlock);
		bridge.setBlock(world, i + 4, j + 5, k + 10, JungleBlocks.ancientMossyBlock);
		bridge.setBlock(world, i + 4, j + 5, k + 11, JungleBlocks.ancientMossyBlock);
		bridge.setBlock(world, i + 4, j + 5, k + 12, JungleBlocks.ancientMossyBlock);
		bridge.setBlock(world, i + 4, j + 5, k + 13, JungleBlocks.ancientMossyBlock);
		bridge.setBlock(world, i + 4, j + 5, k + 14, JungleBlocks.ancientMossyBlock);
		bridge.setBlock(world, i + 4, j + 5, k + 15, JungleBlocks.ancientMossyBlock);
		bridge.setBlock(world, i + 4, j + 5, k + 16, JungleBlocks.mossystairs);
		bridge.setBlock(world, i + 4, j + 5, k + 17, JungleBlocks.mossystairs);
		bridge.setBlock(world, i + 4, j + 5, k + 18, JungleBlocks.mossystairs);
		bridge.setBlock(world, i + 4, j + 5, k + 19, JungleBlocks.ancientMossyBlock);
		bridge.setBlock(world, i + 4, j + 5, k + 20, JungleBlocks.ancientMossyBlock);
		bridge.setBlock(world, i + 4, j + 5, k + 21, JungleBlocks.ancientMossyBlock);
		bridge.setBlock(world, i + 4, j + 5, k + 22, JungleBlocks.ancientMossyBlock);
		bridge.setBlock(world, i + 4, j + 5, k + 23, JungleBlocks.ancientMossyBlock);
		bridge.setBlock(world, i + 4, j + 5, k + 24, JungleBlocks.ancientMossyBlock);
		bridge.setBlock(world, i + 4, j + 5, k + 25, JungleBlocks.ancientMossyBlock);
		bridge.setBlock(world, i + 4, j + 5, k + 26, JungleBlocks.ancientMossyBlock);
		bridge.setBlock(world, i + 4, j + 5, k + 27, JungleBlocks.ancientMossyBlock);
		bridge.setBlock(world, i + 4, j + 5, k + 28, JungleBlocks.ancientMossyBlock);
		bridge.setBlock(world, i + 4, j + 5, k + 29, JungleBlocks.ancientMossyBlock);
		bridge.setBlock(world, i + 4, j + 5, k + 30, JungleBlocks.ancientMossyBlock);
		bridge.setBlock(world, i + 4, j + 5, k + 31, JungleBlocks.mossystairs, 3, 2);
		bridge.setBlock(world, i + 4, j + 6, k + 4, JungleBlocks.ancientMossyBlock);
		bridge.setBlock(world, i + 4, j + 6, k + 5, JungleBlocks.mossystairs);
		bridge.setBlock(world, i + 4, j + 6, k + 6, JungleBlocks.ancientMossyBlock);
		bridge.setBlock(world, i + 4, j + 6, k + 10, JungleBlocks.ancientMossyBlock);
		bridge.setBlock(world, i + 4, j + 6, k + 11, JungleBlocks.mossystairs);
		bridge.setBlock(world, i + 4, j + 6, k + 12, JungleBlocks.mossystairs);
		bridge.setBlock(world, i + 4, j + 6, k + 13, JungleBlocks.mossystairs);
		bridge.setBlock(world, i + 4, j + 6, k + 14, JungleBlocks.ancientMossyBlock);
		bridge.setBlock(world, i + 4, j + 6, k + 20, JungleBlocks.ancientMossyBlock);
		bridge.setBlock(world, i + 4, j + 6, k + 21, JungleBlocks.mossystairs);
		bridge.setBlock(world, i + 4, j + 6, k + 22, JungleBlocks.mossystairs);
		bridge.setBlock(world, i + 4, j + 6, k + 23, JungleBlocks.mossystairs);
		bridge.setBlock(world, i + 4, j + 6, k + 24, JungleBlocks.ancientMossyBlock);
		bridge.setBlock(world, i + 4, j + 6, k + 28, JungleBlocks.ancientMossyBlock);
		bridge.setBlock(world, i + 4, j + 6, k + 29, JungleBlocks.mossystairs);
		bridge.setBlock(world, i + 4, j + 6, k + 30, JungleBlocks.ancientMossyBlock);
		bridge.setBlock(world, i + 4, j + 7, k + 6, Blocks.COBBLESTONE_WALL, 1, 2);
		bridge.setBlock(world, i + 4, j + 7, k + 14, Blocks.COBBLESTONE_WALL, 1, 2);
		bridge.setBlock(world, i + 4, j + 7, k + 20, Blocks.COBBLESTONE_WALL, 1, 2);
		bridge.setBlock(world, i + 4, j + 7, k + 28, Blocks.COBBLESTONE_WALL, 1, 2);
		bridge.setBlock(world, i + 4, j + 8, k + 6, Blocks.COBBLESTONE_WALL, 1, 2);
		bridge.setBlock(world, i + 4, j + 8, k + 14, JungleBlocks.ancientMossyBlock);
		bridge.setBlock(world, i + 4, j + 8, k + 20, JungleBlocks.ancientMossyBlock);
		bridge.setBlock(world, i + 4, j + 8, k + 28, Blocks.COBBLESTONE_WALL, 1, 2);
		bridge.setBlock(world, i + 4, j + 9, k + 14, Blocks.COBBLESTONE_WALL, 1, 2);
		bridge.setBlock(world, i + 4, j + 9, k + 20, Blocks.COBBLESTONE_WALL, 1, 2);
		bridge.setBlock(world, i + 4, j + 10, k + 14, JungleBlocks.mossystairs);
		bridge.setBlock(world, i + 4, j + 10, k + 20, JungleBlocks.mossystairs);
		bridge.setBlock(world, i + 5, j + 0, k + 27, JungleBlocks.ancientMossyBlock);
		bridge.setBlock(world, i + 5, j + 1, k + 0, Blocks.STONEBRICK, 1, 2);
		bridge.setBlock(world, i + 5, j + 1, k + 1, Blocks.DIRT, 0, 2);
		bridge.setBlock(world, i + 5, j + 1, k + 2, Blocks.DIRT, 0, 2);
		bridge.setBlock(world, i + 5, j + 1, k + 3, Blocks.DIRT, 0, 2);
		bridge.setBlock(world, i + 5, j + 1, k + 4, Blocks.DIRT, 0, 2);
		bridge.setBlock(world, i + 5, j + 1, k + 5, Blocks.DIRT, 0, 2);
		bridge.setBlock(world, i + 5, j + 1, k + 6, Blocks.DIRT, 0, 2);
		bridge.setBlock(world, i + 5, j + 1, k + 7, Blocks.DIRT, 0, 2);
		bridge.setBlock(world, i + 5, j + 1, k + 8, Blocks.DIRT, 0, 2);
		bridge.setBlock(world, i + 5, j + 1, k + 9, Blocks.DIRT, 0, 2);
		bridge.setBlock(world, i + 5, j + 1, k + 10, Blocks.DIRT, 0, 2);
		bridge.setBlock(world, i + 5, j + 1, k + 11, Blocks.DIRT, 0, 2);
		bridge.setBlock(world, i + 5, j + 1, k + 12, Blocks.DIRT, 0, 2);
		bridge.setBlock(world, i + 5, j + 1, k + 13, Blocks.DIRT, 0, 2);
		bridge.setBlock(world, i + 5, j + 1, k + 14, Blocks.DIRT, 0, 2);
		bridge.setBlock(world, i + 5, j + 1, k + 15, Blocks.DIRT, 0, 2);
		bridge.setBlock(world, i + 5, j + 1, k + 16, Blocks.DIRT, 0, 2);
		bridge.setBlock(world, i + 5, j + 1, k + 17, Blocks.DIRT, 0, 2);
		bridge.setBlock(world, i + 5, j + 1, k + 18, Blocks.DIRT, 0, 2);
		bridge.setBlock(world, i + 5, j + 1, k + 19, Blocks.DIRT, 0, 2);
		bridge.setBlock(world, i + 5, j + 1, k + 20, Blocks.DIRT, 0, 2);
		bridge.setBlock(world, i + 5, j + 1, k + 21, Blocks.DIRT, 0, 2);
		bridge.setBlock(world, i + 5, j + 1, k + 22, Blocks.DIRT, 0, 2);
		bridge.setBlock(world, i + 5, j + 1, k + 23, JungleBlocks.ancientMossyBlock);
		bridge.setBlock(world, i + 5, j + 1, k + 24, Blocks.DIRT, 0, 2);
		bridge.setBlock(world, i + 5, j + 1, k + 25, JungleBlocks.ancientMossyBlock);
		bridge.setBlock(world, i + 5, j + 1, k + 26, JungleBlocks.ancientMossyBlock);
		bridge.setBlock(world, i + 5, j + 1, k + 27, JungleBlocks.ancientMossyBlock);
		bridge.setBlock(world, i + 5, j + 1, k + 28, JungleBlocks.ancientMossyBlock);
		bridge.setBlock(world, i + 5, j + 1, k + 29, JungleBlocks.ancientMossyBlock);
		bridge.setBlock(world, i + 5, j + 1, k + 30, Blocks.DIRT, 0, 2);
		bridge.setBlock(world, i + 5, j + 1, k + 31, Blocks.DIRT, 0, 2);
		bridge.setBlock(world, i + 5, j + 1, k + 32, Blocks.DIRT, 0, 2);
		bridge.setBlock(world, i + 5, j + 1, k + 33, Blocks.DIRT, 0, 2);
		bridge.setBlock(world, i + 5, j + 1, k + 34, Blocks.STONEBRICK, 1, 2);
		bridge.setBlock(world, i + 5, j + 2, k + 1, JungleBlocks.ancientMossyBlock);
		bridge.setBlock(world, i + 5, j + 2, k + 2, JungleBlocks.ancientMossyBlock);
		bridge.setBlock(world, i + 5, j + 2, k + 3, JungleBlocks.ancientMossyBlock);
		bridge.setBlock(world, i + 5, j + 2, k + 4, JungleBlocks.ancientMossyBlock);
		bridge.setBlock(world, i + 5, j + 2, k + 5, JungleBlocks.ancientMossyBlock);
		bridge.setBlock(world, i + 5, j + 2, k + 6, JungleBlocks.ancientMossyBlock);
		bridge.setBlock(world, i + 5, j + 2, k + 7, JungleBlocks.ancientMossyBlock);
		bridge.setBlock(world, i + 5, j + 2, k + 8, JungleBlocks.ancientMossyBlock);
		bridge.setBlock(world, i + 5, j + 2, k + 9, JungleBlocks.ancientMossyBlock);
		bridge.setBlock(world, i + 5, j + 2, k + 10, JungleBlocks.ancientMossyBlock);
		bridge.setBlock(world, i + 5, j + 2, k + 11, JungleBlocks.ancientMossyBlock);
		bridge.setBlock(world, i + 5, j + 2, k + 12, JungleBlocks.ancientMossyBlock);
		bridge.setBlock(world, i + 5, j + 2, k + 13, JungleBlocks.ancientMossyBlock);
		bridge.setBlock(world, i + 5, j + 2, k + 14, JungleBlocks.ancientMossyBlock);
		bridge.setBlock(world, i + 5, j + 2, k + 15, JungleBlocks.ancientMossyBlock);
		bridge.setBlock(world, i + 5, j + 2, k + 16, JungleBlocks.ancientMossyBlock);
		bridge.setBlock(world, i + 5, j + 2, k + 17, JungleBlocks.ancientMossyBlock);
		bridge.setBlock(world, i + 5, j + 2, k + 18, JungleBlocks.ancientMossyBlock);
		bridge.setBlock(world, i + 5, j + 2, k + 19, JungleBlocks.ancientMossyBlock);
		bridge.setBlock(world, i + 5, j + 2, k + 20, JungleBlocks.ancientMossyBlock);
		bridge.setBlock(world, i + 5, j + 2, k + 21, JungleBlocks.ancientMossyBlock);
		bridge.setBlock(world, i + 5, j + 2, k + 22, JungleBlocks.ancientMossyBlock);
		bridge.setBlock(world, i + 5, j + 2, k + 24, JungleBlocks.ancientMossyBlock);
		//bridge.setBlock(world, i + 5, j + 2, k + 25, Blocks.lit_pumpkin, 3, 2);
		bridge.setBlock(world, i + 5, j + 2, k + 26, JungleBlocks.ancientMossyBlock);
		//bridge.setBlock(world, i + 5, j + 2, k + 27, Blocks.chest, 5, 2);
		bridge.setBlock(world, i + 5, j + 2, k + 28, JungleBlocks.ancientMossyBlock);
		bridge.setBlock(world, i + 5, j + 2, k + 29, JungleBlocks.ancientMossyBlock);
		bridge.setBlock(world, i + 5, j + 2, k + 30, JungleBlocks.ancientMossyBlock);
		bridge.setBlock(world, i + 5, j + 2, k + 31, JungleBlocks.ancientMossyBlock);
		bridge.setBlock(world, i + 5, j + 2, k + 32, JungleBlocks.ancientMossyBlock);
		bridge.setBlock(world, i + 5, j + 2, k + 33, JungleBlocks.ancientMossyBlock);
		bridge.setBlock(world, i + 5, j + 3, k + 1, JungleBlocks.mossystairs, 2, 2);
		bridge.setBlock(world, i + 5, j + 3, k + 2, JungleBlocks.ancientMossyBlock);
		bridge.setBlock(world, i + 5, j + 3, k + 3, JungleBlocks.ancientMossyBlock);
		bridge.setBlock(world, i + 5, j + 3, k + 4, JungleBlocks.ancientMossyBlock);
		bridge.setBlock(world, i + 5, j + 3, k + 5, JungleBlocks.ancientMossyBlock);
		bridge.setBlock(world, i + 5, j + 3, k + 6, JungleBlocks.ancientMossyBlock);
		bridge.setBlock(world, i + 5, j + 3, k + 7, JungleBlocks.ancientMossyBlock);
		bridge.setBlock(world, i + 5, j + 3, k + 8, JungleBlocks.ancientMossyBlock);
		bridge.setBlock(world, i + 5, j + 3, k + 9, JungleBlocks.ancientMossyBlock);
		bridge.setBlock(world, i + 5, j + 3, k + 10, JungleBlocks.ancientMossyBlock);
		bridge.setBlock(world, i + 5, j + 3, k + 11, JungleBlocks.ancientMossyBlock);
		bridge.setBlock(world, i + 5, j + 3, k + 12, JungleBlocks.ancientMossyBlock);
		bridge.setBlock(world, i + 5, j + 3, k + 13, JungleBlocks.ancientMossyBlock);
		bridge.setBlock(world, i + 5, j + 3, k + 14, JungleBlocks.ancientMossyBlock);
		bridge.setBlock(world, i + 5, j + 3, k + 15, JungleBlocks.ancientMossyBlock);
		bridge.setBlock(world, i + 5, j + 3, k + 16, JungleBlocks.ancientMossyBlock);
		bridge.setBlock(world, i + 5, j + 3, k + 17, JungleBlocks.ancientMossyBlock);
		bridge.setBlock(world, i + 5, j + 3, k + 18, JungleBlocks.ancientMossyBlock);
		bridge.setBlock(world, i + 5, j + 3, k + 19, JungleBlocks.ancientMossyBlock);
		bridge.setBlock(world, i + 5, j + 3, k + 20, JungleBlocks.ancientMossyBlock);
		bridge.setBlock(world, i + 5, j + 3, k + 21, JungleBlocks.ancientMossyBlock);
		bridge.setBlock(world, i + 5, j + 3, k + 22, JungleBlocks.ancientMossyBlock);
		bridge.setBlock(world, i + 5, j + 3, k + 24, JungleBlocks.ancientMossyBlock);
		bridge.setBlock(world, i + 5, j + 3, k + 26, JungleBlocks.ancientMossyBlock);
		bridge.setBlock(world, i + 5, j + 3, k + 28, JungleBlocks.ancientMossyBlock);
		bridge.setBlock(world, i + 5, j + 3, k + 29, JungleBlocks.ancientMossyBlock);
		bridge.setBlock(world, i + 5, j + 3, k + 30, JungleBlocks.ancientMossyBlock);
		bridge.setBlock(world, i + 5, j + 3, k + 31, JungleBlocks.ancientMossyBlock);
		bridge.setBlock(world, i + 5, j + 3, k + 32, JungleBlocks.ancientMossyBlock);
		bridge.setBlock(world, i + 5, j + 3, k + 33, JungleBlocks.mossystairs, 3, 2);
		bridge.setBlock(world, i + 5, j + 4, k + 2, JungleBlocks.mossystairs, 2, 2);
		bridge.setBlock(world, i + 5, j + 4, k + 3, JungleBlocks.ancientMossyBlock);
		bridge.setBlock(world, i + 5, j + 4, k + 4, JungleBlocks.ancientMossyBlock);
		bridge.setBlock(world, i + 5, j + 4, k + 5, JungleBlocks.ancientMossyBlock);
		bridge.setBlock(world, i + 5, j + 4, k + 6, JungleBlocks.ancientMossyBlock);
		bridge.setBlock(world, i + 5, j + 4, k + 7, JungleBlocks.ancientMossyBlock);
		bridge.setBlock(world, i + 5, j + 4, k + 8, JungleBlocks.ancientMossyBlock);
		bridge.setBlock(world, i + 5, j + 4, k + 9, JungleBlocks.ancientMossyBlock);
		bridge.setBlock(world, i + 5, j + 4, k + 10, JungleBlocks.ancientMossyBlock);
		bridge.setBlock(world, i + 5, j + 4, k + 11, JungleBlocks.ancientMossyBlock);
		bridge.setBlock(world, i + 5, j + 4, k + 12, JungleBlocks.ancientMossyBlock);
		bridge.setBlock(world, i + 5, j + 4, k + 13, JungleBlocks.ancientMossyBlock);
		bridge.setBlock(world, i + 5, j + 4, k + 14, JungleBlocks.ancientMossyBlock);
		bridge.setBlock(world, i + 5, j + 4, k + 15, JungleBlocks.ancientMossyBlock);
		bridge.setBlock(world, i + 5, j + 4, k + 16, JungleBlocks.ancientMossyBlock);
		bridge.setBlock(world, i + 5, j + 4, k + 17, JungleBlocks.ancientMossyBlock);
		bridge.setBlock(world, i + 5, j + 4, k + 18, JungleBlocks.ancientMossyBlock);
		bridge.setBlock(world, i + 5, j + 4, k + 19, JungleBlocks.ancientMossyBlock);
		bridge.setBlock(world, i + 5, j + 4, k + 20, JungleBlocks.ancientMossyBlock);
		bridge.setBlock(world, i + 5, j + 4, k + 21, JungleBlocks.ancientMossyBlock);
		bridge.setBlock(world, i + 5, j + 4, k + 22, JungleBlocks.ancientMossyBlock);
		bridge.setBlock(world, i + 5, j + 4, k + 24, JungleBlocks.ancientMossyBlock);
		bridge.setBlock(world, i + 5, j + 4, k + 26, JungleBlocks.ancientMossyBlock);
		bridge.setBlock(world, i + 5, j + 4, k + 28, JungleBlocks.ancientMossyBlock);
		bridge.setBlock(world, i + 5, j + 4, k + 29, JungleBlocks.ancientMossyBlock);
		bridge.setBlock(world, i + 5, j + 4, k + 30, JungleBlocks.ancientMossyBlock);
		bridge.setBlock(world, i + 5, j + 4, k + 31, JungleBlocks.ancientMossyBlock);
		bridge.setBlock(world, i + 5, j + 4, k + 32, JungleBlocks.mossystairs, 3, 2);
		bridge.setBlock(world, i + 5, j + 5, k + 3, JungleBlocks.mossystairs, 2, 2);
		bridge.setBlock(world, i + 5, j + 5, k + 4, JungleBlocks.ancientMossyBlock);
		bridge.setBlock(world, i + 5, j + 5, k + 5, JungleBlocks.ancientMossyBlock);
		bridge.setBlock(world, i + 5, j + 5, k + 6, JungleBlocks.ancientMossyBlock);
		bridge.setBlock(world, i + 5, j + 5, k + 7, JungleBlocks.ancientMossyBlock);
		bridge.setBlock(world, i + 5, j + 5, k + 8, JungleBlocks.ancientMossyBlock);
		bridge.setBlock(world, i + 5, j + 5, k + 9, JungleBlocks.ancientMossyBlock);
		bridge.setBlock(world, i + 5, j + 5, k + 10, JungleBlocks.ancientMossyBlock);
		bridge.setBlock(world, i + 5, j + 5, k + 11, JungleBlocks.ancientMossyBlock);
		bridge.setBlock(world, i + 5, j + 5, k + 12, JungleBlocks.ancientMossyBlock);
		bridge.setBlock(world, i + 5, j + 5, k + 13, JungleBlocks.ancientMossyBlock);
		bridge.setBlock(world, i + 5, j + 5, k + 14, JungleBlocks.ancientMossyBlock);
		bridge.setBlock(world, i + 5, j + 5, k + 15, JungleBlocks.ancientMossyBlock);
		bridge.setBlock(world, i + 5, j + 5, k + 16, JungleBlocks.ancientMossyBlock);
		bridge.setBlock(world, i + 5, j + 5, k + 17, JungleBlocks.ancientMossyBlock);
		bridge.setBlock(world, i + 5, j + 5, k + 18, JungleBlocks.ancientMossyBlock);
		bridge.setBlock(world, i + 5, j + 5, k + 19, JungleBlocks.ancientMossyBlock);
		bridge.setBlock(world, i + 5, j + 5, k + 20, JungleBlocks.ancientMossyBlock);
		bridge.setBlock(world, i + 5, j + 5, k + 21, JungleBlocks.ancientMossyBlock);
		bridge.setBlock(world, i + 5, j + 5, k + 22, JungleBlocks.ancientMossyBlock);
		bridge.setBlock(world, i + 5, j + 5, k + 23, JungleBlocks.ancientMossyBlock);
		bridge.setBlock(world, i + 5, j + 5, k + 24, JungleBlocks.ancientMossyBlock);
		bridge.setBlock(world, i + 5, j + 5, k + 25, JungleBlocks.ancientMossyBlock);
		bridge.setBlock(world, i + 5, j + 5, k + 26, JungleBlocks.ancientMossyBlock);
		bridge.setBlock(world, i + 5, j + 5, k + 27, JungleBlocks.ancientMossyBlock);
		bridge.setBlock(world, i + 5, j + 5, k + 28, JungleBlocks.ancientMossyBlock);
		bridge.setBlock(world, i + 5, j + 5, k + 29, JungleBlocks.ancientMossyBlock);
		bridge.setBlock(world, i + 5, j + 5, k + 30, JungleBlocks.ancientMossyBlock);
		bridge.setBlock(world, i + 5, j + 5, k + 31, JungleBlocks.mossystairs, 3, 2);
		bridge.setBlock(world, i + 5, j + 6, k + 4, JungleBlocks.mossystairs, 2, 2);
		bridge.setBlock(world, i + 5, j + 6, k + 5, JungleBlocks.ancientMossyBlock);
		bridge.setBlock(world, i + 5, j + 6, k + 6, JungleBlocks.ancientMossyBlock);
		bridge.setBlock(world, i + 5, j + 6, k + 7, JungleBlocks.ancientMossyBlock);
		bridge.setBlock(world, i + 5, j + 6, k + 8, JungleBlocks.ancientMossyBlock);
		bridge.setBlock(world, i + 5, j + 6, k + 9, JungleBlocks.ancientMossyBlock);
		bridge.setBlock(world, i + 5, j + 6, k + 10, JungleBlocks.ancientMossyBlock);
		bridge.setBlock(world, i + 5, j + 6, k + 11, JungleBlocks.ancientMossyBlock);
		bridge.setBlock(world, i + 5, j + 6, k + 12, JungleBlocks.ancientMossyBlock);
		bridge.setBlock(world, i + 5, j + 6, k + 13, JungleBlocks.ancientMossyBlock);
		bridge.setBlock(world, i + 5, j + 6, k + 14, JungleBlocks.ancientMossyBlock);
		bridge.setBlock(world, i + 5, j + 6, k + 15, JungleBlocks.ancientMossyBlock);
		bridge.setBlock(world, i + 5, j + 6, k + 16, JungleBlocks.mossystairs);
		bridge.setBlock(world, i + 5, j + 6, k + 17, JungleBlocks.mossystairs);
		bridge.setBlock(world, i + 5, j + 6, k + 18, JungleBlocks.mossystairs);
		bridge.setBlock(world, i + 5, j + 6, k + 19, JungleBlocks.ancientMossyBlock);
		bridge.setBlock(world, i + 5, j + 6, k + 20, JungleBlocks.ancientMossyBlock);
		bridge.setBlock(world, i + 5, j + 6, k + 21, JungleBlocks.ancientMossyBlock);
		bridge.setBlock(world, i + 5, j + 6, k + 22, JungleBlocks.ancientMossyBlock);
		bridge.setBlock(world, i + 5, j + 6, k + 23, JungleBlocks.ancientMossyBlock);
		bridge.setBlock(world, i + 5, j + 6, k + 24, JungleBlocks.ancientMossyBlock);
		bridge.setBlock(world, i + 5, j + 6, k + 25, JungleBlocks.ancientMossyBlock);
		bridge.setBlock(world, i + 5, j + 6, k + 26, JungleBlocks.ancientMossyBlock);
		bridge.setBlock(world, i + 5, j + 6, k + 27, JungleBlocks.ancientMossyBlock);
		bridge.setBlock(world, i + 5, j + 6, k + 28, JungleBlocks.ancientMossyBlock);
		bridge.setBlock(world, i + 5, j + 6, k + 29, JungleBlocks.ancientMossyBlock);
		bridge.setBlock(world, i + 5, j + 6, k + 30, JungleBlocks.mossystairs, 3, 2);
		bridge.setBlock(world, i + 5, j + 7, k + 5, JungleBlocks.jungleBrazier);
		bridge.setBlock(world, i + 5, j + 7, k + 6, JungleBlocks.ancientMossyBlock);
		bridge.setBlock(world, i + 5, j + 7, k + 10, JungleBlocks.ancientMossyBlock);
		bridge.setBlock(world, i + 5, j + 7, k + 11, JungleBlocks.mossystairs);
		bridge.setBlock(world, i + 5, j + 7, k + 12, JungleBlocks.mossystairs);
		bridge.setBlock(world, i + 5, j + 7, k + 13, JungleBlocks.mossystairs);
		bridge.setBlock(world, i + 5, j + 7, k + 14, JungleBlocks.ancientMossyBlock);
		bridge.setBlock(world, i + 5, j + 7, k + 20, JungleBlocks.ancientMossyBlock);
		bridge.setBlock(world, i + 5, j + 7, k + 21, JungleBlocks.mossystairs);
		bridge.setBlock(world, i + 5, j + 7, k + 22, JungleBlocks.mossystairs);
		bridge.setBlock(world, i + 5, j + 7, k + 23, JungleBlocks.mossystairs);
		bridge.setBlock(world, i + 5, j + 7, k + 24, JungleBlocks.ancientMossyBlock);
		bridge.setBlock(world, i + 5, j + 7, k + 28, JungleBlocks.ancientMossyBlock);
		bridge.setBlock(world, i + 5, j + 7, k + 29, JungleBlocks.jungleBrazier);
		bridge.setBlock(world, i + 5, j + 10, k + 14, JungleBlocks.mossyslabSingle, 14, 2);
		bridge.setBlock(world, i + 5, j + 10, k + 20, JungleBlocks.mossyslabSingle, 14, 2);
		bridge.setBlock(world, i + 5, j + 11, k + 14, JungleBlocks.mossyslabSingle, 6, 2);
		bridge.setBlock(world, i + 5, j + 11, k + 20, JungleBlocks.mossyslabSingle, 6, 2);
		bridge.setBlock(world, i + 6, j + 0, k + 27, JungleBlocks.ancientMossyBlock);
		bridge.setBlock(world, i + 6, j + 1, k + 0, Blocks.STONEBRICK, 1, 2);
		bridge.setBlock(world, i + 6, j + 1, k + 1, Blocks.DIRT, 0, 2);
		bridge.setBlock(world, i + 6, j + 1, k + 2, Blocks.DIRT, 0, 2);
		bridge.setBlock(world, i + 6, j + 1, k + 3, Blocks.DIRT, 0, 2);
		bridge.setBlock(world, i + 6, j + 1, k + 4, Blocks.DIRT, 0, 2);
		bridge.setBlock(world, i + 6, j + 1, k + 5, Blocks.DIRT, 0, 2);
		bridge.setBlock(world, i + 6, j + 1, k + 6, Blocks.DIRT, 0, 2);
		bridge.setBlock(world, i + 6, j + 1, k + 7, Blocks.DIRT, 0, 2);
		bridge.setBlock(world, i + 6, j + 1, k + 8, Blocks.DIRT, 0, 2);
		bridge.setBlock(world, i + 6, j + 1, k + 9, Blocks.DIRT, 0, 2);
		bridge.setBlock(world, i + 6, j + 1, k + 10, Blocks.DIRT, 0, 2);
		bridge.setBlock(world, i + 6, j + 1, k + 11, Blocks.DIRT, 0, 2);
		bridge.setBlock(world, i + 6, j + 1, k + 12, Blocks.DIRT, 0, 2);
		bridge.setBlock(world, i + 6, j + 1, k + 13, Blocks.DIRT, 0, 2);
		bridge.setBlock(world, i + 6, j + 1, k + 14, Blocks.DIRT, 0, 2);
		bridge.setBlock(world, i + 6, j + 1, k + 15, Blocks.DIRT, 0, 2);
		bridge.setBlock(world, i + 6, j + 1, k + 16, Blocks.DIRT, 0, 2);
		bridge.setBlock(world, i + 6, j + 1, k + 17, Blocks.DIRT, 0, 2);
		bridge.setBlock(world, i + 6, j + 1, k + 18, Blocks.DIRT, 0, 2);
		bridge.setBlock(world, i + 6, j + 1, k + 19, Blocks.DIRT, 0, 2);
		bridge.setBlock(world, i + 6, j + 1, k + 20, Blocks.DIRT, 0, 2);
		bridge.setBlock(world, i + 6, j + 1, k + 21, Blocks.DIRT, 0, 2);
		bridge.setBlock(world, i + 6, j + 1, k + 22, JungleBlocks.ancientMossyBlock);
		bridge.setBlock(world, i + 6, j + 1, k + 23, JungleBlocks.ancientMossyBlock);
		bridge.setBlock(world, i + 6, j + 1, k + 24, JungleBlocks.ancientMossyBlock);
		bridge.setBlock(world, i + 6, j + 1, k + 25, JungleBlocks.ancientMossyBlock);
		bridge.setBlock(world, i + 6, j + 1, k + 26, JungleBlocks.ancientMossyBlock);
		bridge.setBlock(world, i + 6, j + 1, k + 27, JungleBlocks.ancientMossyBlock);
		bridge.setBlock(world, i + 6, j + 1, k + 28, JungleBlocks.ancientMossyBlock);
		bridge.setBlock(world, i + 6, j + 1, k + 29, JungleBlocks.ancientMossyBlock);
		bridge.setBlock(world, i + 6, j + 1, k + 30, Blocks.DIRT, 0, 2);
		bridge.setBlock(world, i + 6, j + 1, k + 31, Blocks.DIRT, 0, 2);
		bridge.setBlock(world, i + 6, j + 1, k + 32, Blocks.DIRT, 0, 2);
		bridge.setBlock(world, i + 6, j + 1, k + 33, Blocks.DIRT, 0, 2);
		bridge.setBlock(world, i + 6, j + 1, k + 34, Blocks.STONEBRICK, 1, 2);
		bridge.setBlock(world, i + 6, j + 2, k + 0, JungleBlocks.ancientMossyBlock);
		bridge.setBlock(world, i + 6, j + 2, k + 1, JungleBlocks.ancientMossyBlock);
		bridge.setBlock(world, i + 6, j + 2, k + 2, JungleBlocks.ancientMossyBlock);
		bridge.setBlock(world, i + 6, j + 2, k + 3, JungleBlocks.ancientMossyBlock);
		bridge.setBlock(world, i + 6, j + 2, k + 4, JungleBlocks.ancientMossyBlock);
		bridge.setBlock(world, i + 6, j + 2, k + 5, JungleBlocks.ancientMossyBlock);
		bridge.setBlock(world, i + 6, j + 2, k + 6, JungleBlocks.ancientMossyBlock);
		bridge.setBlock(world, i + 6, j + 2, k + 7, JungleBlocks.ancientMossyBlock);
		bridge.setBlock(world, i + 6, j + 2, k + 8, JungleBlocks.ancientMossyBlock);
		bridge.setBlock(world, i + 6, j + 2, k + 9, JungleBlocks.ancientMossyBlock);
		bridge.setBlock(world, i + 6, j + 2, k + 10, JungleBlocks.ancientMossyBlock);
		bridge.setBlock(world, i + 6, j + 2, k + 11, JungleBlocks.ancientMossyBlock);
		bridge.setBlock(world, i + 6, j + 2, k + 12, JungleBlocks.ancientMossyBlock);
		bridge.setBlock(world, i + 6, j + 2, k + 13, JungleBlocks.ancientMossyBlock);
		bridge.setBlock(world, i + 6, j + 2, k + 14, JungleBlocks.ancientMossyBlock);
		bridge.setBlock(world, i + 6, j + 2, k + 15, JungleBlocks.ancientMossyBlock);
		bridge.setBlock(world, i + 6, j + 2, k + 16, JungleBlocks.ancientMossyBlock);
		bridge.setBlock(world, i + 6, j + 2, k + 17, JungleBlocks.ancientMossyBlock);
		bridge.setBlock(world, i + 6, j + 2, k + 18, JungleBlocks.ancientMossyBlock);
		bridge.setBlock(world, i + 6, j + 2, k + 19, JungleBlocks.ancientMossyBlock);
		bridge.setBlock(world, i + 6, j + 2, k + 20, JungleBlocks.ancientMossyBlock);
		bridge.setBlock(world, i + 6, j + 2, k + 21, JungleBlocks.ancientMossyBlock);
		bridge.setBlock(world, i + 6, j + 2, k + 29, JungleBlocks.ancientMossyBlock);
		bridge.setBlock(world, i + 6, j + 2, k + 30, JungleBlocks.ancientMossyBlock);
		bridge.setBlock(world, i + 6, j + 2, k + 31, JungleBlocks.ancientMossyBlock);
		bridge.setBlock(world, i + 6, j + 2, k + 32, JungleBlocks.ancientMossyBlock);
		bridge.setBlock(world, i + 6, j + 2, k + 33, JungleBlocks.ancientMossyBlock);
		bridge.setBlock(world, i + 6, j + 2, k + 34, JungleBlocks.ancientMossyBlock);
		bridge.setBlock(world, i + 6, j + 3, k + 0, Blocks.COBBLESTONE_WALL, 1, 2);
		bridge.setBlock(world, i + 6, j + 3, k + 1, JungleBlocks.ancientMossyBlock);
		bridge.setBlock(world, i + 6, j + 3, k + 2, JungleBlocks.ancientMossyBlock);
		bridge.setBlock(world, i + 6, j + 3, k + 3, JungleBlocks.ancientMossyBlock);
		bridge.setBlock(world, i + 6, j + 3, k + 4, JungleBlocks.ancientMossyBlock);
		bridge.setBlock(world, i + 6, j + 3, k + 5, JungleBlocks.ancientMossyBlock);
		bridge.setBlock(world, i + 6, j + 3, k + 6, JungleBlocks.ancientMossyBlock);
		bridge.setBlock(world, i + 6, j + 3, k + 7, JungleBlocks.ancientMossyBlock);
		bridge.setBlock(world, i + 6, j + 3, k + 8, JungleBlocks.ancientMossyBlock);
		bridge.setBlock(world, i + 6, j + 3, k + 9, JungleBlocks.ancientMossyBlock);
		bridge.setBlock(world, i + 6, j + 3, k + 10, JungleBlocks.ancientMossyBlock);
		bridge.setBlock(world, i + 6, j + 3, k + 11, JungleBlocks.ancientMossyBlock);
		bridge.setBlock(world, i + 6, j + 3, k + 12, JungleBlocks.ancientMossyBlock);
		bridge.setBlock(world, i + 6, j + 3, k + 13, JungleBlocks.ancientMossyBlock);
		bridge.setBlock(world, i + 6, j + 3, k + 14, JungleBlocks.ancientMossyBlock);
		bridge.setBlock(world, i + 6, j + 3, k + 15, JungleBlocks.ancientMossyBlock);
		bridge.setBlock(world, i + 6, j + 3, k + 16, JungleBlocks.ancientMossyBlock);
		bridge.setBlock(world, i + 6, j + 3, k + 17, JungleBlocks.ancientMossyBlock);
		bridge.setBlock(world, i + 6, j + 3, k + 18, JungleBlocks.ancientMossyBlock);
		bridge.setBlock(world, i + 6, j + 3, k + 19, JungleBlocks.ancientMossyBlock);
		bridge.setBlock(world, i + 6, j + 3, k + 20, JungleBlocks.ancientMossyBlock);
		bridge.setBlock(world, i + 6, j + 3, k + 21, Blocks.STONEBRICK, 1, 2);
		bridge.setBlock(world, i + 6, j + 3, k + 29, JungleBlocks.ancientMossyBlock);
		bridge.setBlock(world, i + 6, j + 3, k + 30, JungleBlocks.ancientMossyBlock);
		bridge.setBlock(world, i + 6, j + 3, k + 31, JungleBlocks.ancientMossyBlock);
		bridge.setBlock(world, i + 6, j + 3, k + 32, JungleBlocks.ancientMossyBlock);
		bridge.setBlock(world, i + 6, j + 3, k + 33, JungleBlocks.ancientMossyBlock);
		bridge.setBlock(world, i + 6, j + 3, k + 34, Blocks.COBBLESTONE_WALL, 1, 2);
		bridge.setBlock(world, i + 6, j + 4, k + 0, JungleBlocks.ancientMossyBlock);
		bridge.setBlock(world, i + 6, j + 4, k + 2, JungleBlocks.ancientMossyBlock);
		bridge.setBlock(world, i + 6, j + 4, k + 3, JungleBlocks.ancientMossyBlock);
		bridge.setBlock(world, i + 6, j + 4, k + 4, JungleBlocks.ancientMossyBlock);
		bridge.setBlock(world, i + 6, j + 4, k + 5, JungleBlocks.ancientMossyBlock);
		bridge.setBlock(world, i + 6, j + 4, k + 6, JungleBlocks.ancientMossyBlock);
		bridge.setBlock(world, i + 6, j + 4, k + 7, JungleBlocks.ancientMossyBlock);
		bridge.setBlock(world, i + 6, j + 4, k + 8, JungleBlocks.ancientMossyBlock);
		bridge.setBlock(world, i + 6, j + 4, k + 9, JungleBlocks.ancientMossyBlock);
		bridge.setBlock(world, i + 6, j + 4, k + 10, JungleBlocks.ancientMossyBlock);
		bridge.setBlock(world, i + 6, j + 4, k + 11, JungleBlocks.ancientMossyBlock);
		bridge.setBlock(world, i + 6, j + 4, k + 12, JungleBlocks.ancientMossyBlock);
		bridge.setBlock(world, i + 6, j + 4, k + 13, JungleBlocks.ancientMossyBlock);
		bridge.setBlock(world, i + 6, j + 4, k + 14, JungleBlocks.ancientMossyBlock);
		bridge.setBlock(world, i + 6, j + 4, k + 15, JungleBlocks.ancientMossyBlock);
		bridge.setBlock(world, i + 6, j + 4, k + 16, JungleBlocks.ancientMossyBlock);
		bridge.setBlock(world, i + 6, j + 4, k + 17, JungleBlocks.ancientMossyBlock);
		bridge.setBlock(world, i + 6, j + 4, k + 18, JungleBlocks.ancientMossyBlock);
		bridge.setBlock(world, i + 6, j + 4, k + 19, JungleBlocks.ancientMossyBlock);
		bridge.setBlock(world, i + 6, j + 4, k + 20, JungleBlocks.ancientMossyBlock);
		bridge.setBlock(world, i + 6, j + 4, k + 21, Blocks.STONEBRICK, 1, 2);
		bridge.setBlock(world, i + 6, j + 4, k + 29, JungleBlocks.ancientMossyBlock);
		bridge.setBlock(world, i + 6, j + 4, k + 30, JungleBlocks.ancientMossyBlock);
		bridge.setBlock(world, i + 6, j + 4, k + 31, JungleBlocks.ancientMossyBlock);
		bridge.setBlock(world, i + 6, j + 4, k + 32, JungleBlocks.ancientMossyBlock);
		bridge.setBlock(world, i + 6, j + 4, k + 34, JungleBlocks.ancientMossyBlock);
		bridge.setBlock(world, i + 6, j + 5, k + 0, Blocks.COBBLESTONE_WALL, 1, 2);
		bridge.setBlock(world, i + 6, j + 5, k + 2, Blocks.COBBLESTONE_WALL, 1, 2);
		bridge.setBlock(world, i + 6, j + 5, k + 3, JungleBlocks.ancientMossyBlock);
		bridge.setBlock(world, i + 6, j + 5, k + 4, JungleBlocks.ancientMossyBlock);
		bridge.setBlock(world, i + 6, j + 5, k + 5, JungleBlocks.ancientMossyBlock);
		bridge.setBlock(world, i + 6, j + 5, k + 6, JungleBlocks.ancientMossyBlock);
		bridge.setBlock(world, i + 6, j + 5, k + 7, JungleBlocks.ancientMossyBlock);
		bridge.setBlock(world, i + 6, j + 5, k + 8, JungleBlocks.ancientMossyBlock);
		bridge.setBlock(world, i + 6, j + 5, k + 9, JungleBlocks.ancientMossyBlock);
		bridge.setBlock(world, i + 6, j + 5, k + 10, JungleBlocks.ancientMossyBlock);
		bridge.setBlock(world, i + 6, j + 5, k + 11, JungleBlocks.ancientMossyBlock);
		bridge.setBlock(world, i + 6, j + 5, k + 12, JungleBlocks.ancientMossyBlock);
		bridge.setBlock(world, i + 6, j + 5, k + 13, JungleBlocks.ancientMossyBlock);
		bridge.setBlock(world, i + 6, j + 5, k + 14, JungleBlocks.ancientMossyBlock);
		bridge.setBlock(world, i + 6, j + 5, k + 15, JungleBlocks.ancientMossyBlock);
		bridge.setBlock(world, i + 6, j + 5, k + 16, JungleBlocks.ancientMossyBlock);
		bridge.setBlock(world, i + 6, j + 5, k + 17, JungleBlocks.ancientMossyBlock);
		bridge.setBlock(world, i + 6, j + 5, k + 18, JungleBlocks.ancientMossyBlock);
		bridge.setBlock(world, i + 6, j + 5, k + 19, JungleBlocks.ancientMossyBlock);
		bridge.setBlock(world, i + 6, j + 5, k + 20, JungleBlocks.ancientMossyBlock);
		bridge.setBlock(world, i + 6, j + 5, k + 21, JungleBlocks.ancientMossyBlock);
		bridge.setBlock(world, i + 6, j + 5, k + 29, JungleBlocks.ancientMossyBlock);
		bridge.setBlock(world, i + 6, j + 5, k + 30, JungleBlocks.ancientMossyBlock);
		bridge.setBlock(world, i + 6, j + 5, k + 31, JungleBlocks.ancientMossyBlock);
		bridge.setBlock(world, i + 6, j + 5, k + 32, Blocks.COBBLESTONE_WALL, 1, 2);
		bridge.setBlock(world, i + 6, j + 5, k + 34, Blocks.COBBLESTONE_WALL, 1, 2);
		bridge.setBlock(world, i + 6, j + 6, k + 0, Blocks.COBBLESTONE_WALL, 1, 2);
		bridge.setBlock(world, i + 6, j + 6, k + 2, Blocks.COBBLESTONE_WALL, 1, 2);
		bridge.setBlock(world, i + 6, j + 6, k + 4, JungleBlocks.ancientMossyBlock);
		bridge.setBlock(world, i + 6, j + 6, k + 5, JungleBlocks.ancientMossyBlock);
		bridge.setBlock(world, i + 6, j + 6, k + 6, JungleBlocks.ancientMossyBlock);
		bridge.setBlock(world, i + 6, j + 6, k + 7, JungleBlocks.ancientMossyBlock);
		bridge.setBlock(world, i + 6, j + 6, k + 8, JungleBlocks.ancientMossyBlock);
		bridge.setBlock(world, i + 6, j + 6, k + 9, JungleBlocks.ancientMossyBlock);
		bridge.setBlock(world, i + 6, j + 6, k + 10, JungleBlocks.ancientMossyBlock);
		bridge.setBlock(world, i + 6, j + 6, k + 11, JungleBlocks.ancientMossyBlock);
		bridge.setBlock(world, i + 6, j + 6, k + 12, JungleBlocks.ancientMossyBlock);
		bridge.setBlock(world, i + 6, j + 6, k + 13, JungleBlocks.ancientMossyBlock);
		bridge.setBlock(world, i + 6, j + 6, k + 14, JungleBlocks.ancientMossyBlock);
		bridge.setBlock(world, i + 6, j + 6, k + 15, JungleBlocks.ancientMossyBlock);
		bridge.setBlock(world, i + 6, j + 6, k + 16, JungleBlocks.ancientMossyBlock);
		bridge.setBlock(world, i + 6, j + 6, k + 17, JungleBlocks.ancientMossyBlock);
		bridge.setBlock(world, i + 6, j + 6, k + 18, JungleBlocks.ancientMossyBlock);
		bridge.setBlock(world, i + 6, j + 6, k + 19, JungleBlocks.ancientMossyBlock);
		bridge.setBlock(world, i + 6, j + 6, k + 20, JungleBlocks.ancientMossyBlock);
		bridge.setBlock(world, i + 6, j + 6, k + 21, JungleBlocks.ancientMossyBlock);
		bridge.setBlock(world, i + 6, j + 6, k + 22, JungleBlocks.ancientMossyBlock);
		bridge.setBlock(world, i + 6, j + 6, k + 23, JungleBlocks.ancientMossyBlock);
		bridge.setBlock(world, i + 6, j + 6, k + 24, JungleBlocks.ancientMossyBlock);
		bridge.setBlock(world, i + 6, j + 6, k + 25, JungleBlocks.ancientMossyBlock);
		bridge.setBlock(world, i + 6, j + 6, k + 26, JungleBlocks.ancientMossyBlock);
		bridge.setBlock(world, i + 6, j + 6, k + 27, JungleBlocks.ancientMossyBlock);
		bridge.setBlock(world, i + 6, j + 6, k + 28, JungleBlocks.ancientMossyBlock);
		bridge.setBlock(world, i + 6, j + 6, k + 29, JungleBlocks.ancientMossyBlock);
		bridge.setBlock(world, i + 6, j + 6, k + 30, JungleBlocks.ancientMossyBlock);
		bridge.setBlock(world, i + 6, j + 6, k + 32, Blocks.COBBLESTONE_WALL, 1, 2);
		bridge.setBlock(world, i + 6, j + 6, k + 34, Blocks.COBBLESTONE_WALL, 1, 2);
		bridge.setBlock(world, i + 6, j + 7, k + 0, JungleBlocks.mossystairs, 2, 2);
		bridge.setBlock(world, i + 6, j + 7, k + 1, JungleBlocks.mossyslabSingle, 14, 2);
		bridge.setBlock(world, i + 6, j + 7, k + 2, JungleBlocks.mossystairs, 3, 2);
		bridge.setBlock(world, i + 6, j + 7, k + 4, Blocks.COBBLESTONE_WALL, 1, 2);
		bridge.setBlock(world, i + 6, j + 7, k + 5, JungleBlocks.ancientMossyBlock);
		bridge.setBlock(world, i + 6, j + 7, k + 6, JungleBlocks.ancientMossyBlock);
		bridge.setBlock(world, i + 6, j + 7, k + 9, JungleBlocks.ancientMossyBlock);
		bridge.setBlock(world, i + 6, j + 7, k + 10, JungleBlocks.ancientMossyBlock);
		bridge.setBlock(world, i + 6, j + 7, k + 11, JungleBlocks.ancientMossyBlock);
		bridge.setBlock(world, i + 6, j + 7, k + 12, JungleBlocks.ancientMossyBlock);
		bridge.setBlock(world, i + 6, j + 7, k + 13, JungleBlocks.ancientMossyBlock);
		bridge.setBlock(world, i + 6, j + 7, k + 14, JungleBlocks.ancientMossyBlock);
		bridge.setBlock(world, i + 6, j + 7, k + 15, JungleBlocks.ancientMossyBlock);
		bridge.setBlock(world, i + 6, j + 7, k + 16, JungleBlocks.mossystairs);
		bridge.setBlock(world, i + 6, j + 7, k + 17, JungleBlocks.mossystairs);
		bridge.setBlock(world, i + 6, j + 7, k + 18, JungleBlocks.mossystairs);
		bridge.setBlock(world, i + 6, j + 7, k + 19, JungleBlocks.ancientMossyBlock);
		bridge.setBlock(world, i + 6, j + 7, k + 20, JungleBlocks.ancientMossyBlock);
		bridge.setBlock(world, i + 6, j + 7, k + 21, JungleBlocks.ancientMossyBlock);
		bridge.setBlock(world, i + 6, j + 7, k + 22, JungleBlocks.ancientMossyBlock);
		bridge.setBlock(world, i + 6, j + 7, k + 23, JungleBlocks.ancientMossyBlock);
		bridge.setBlock(world, i + 6, j + 7, k + 24, JungleBlocks.ancientMossyBlock);
		bridge.setBlock(world, i + 6, j + 7, k + 25, JungleBlocks.ancientMossyBlock);
		bridge.setBlock(world, i + 6, j + 7, k + 28, JungleBlocks.ancientMossyBlock);
		bridge.setBlock(world, i + 6, j + 7, k + 29, JungleBlocks.ancientMossyBlock);
		bridge.setBlock(world, i + 6, j + 7, k + 30, Blocks.COBBLESTONE_WALL, 1, 2);
		bridge.setBlock(world, i + 6, j + 7, k + 32, JungleBlocks.mossystairs, 2, 2);
		bridge.setBlock(world, i + 6, j + 7, k + 33, JungleBlocks.mossyslabSingle, 14, 2);
		bridge.setBlock(world, i + 6, j + 7, k + 34, JungleBlocks.mossystairs, 3, 2);
		bridge.setBlock(world, i + 6, j + 8, k + 1, JungleBlocks.mossyslabSingle, 6, 2);
		bridge.setBlock(world, i + 6, j + 8, k + 4, Blocks.COBBLESTONE_WALL, 1, 2);
		bridge.setBlock(world, i + 6, j + 8, k + 10, JungleBlocks.ancientMossyBlock);
		bridge.setBlock(world, i + 6, j + 8, k + 11, JungleBlocks.mossystairs);
		bridge.setBlock(world, i + 6, j + 8, k + 12, JungleBlocks.mossystairs);
		bridge.setBlock(world, i + 6, j + 8, k + 13, JungleBlocks.mossystairs);
		bridge.setBlock(world, i + 6, j + 8, k + 14, JungleBlocks.ancientMossyBlock);
		bridge.setBlock(world, i + 6, j + 8, k + 20, JungleBlocks.ancientMossyBlock);
		bridge.setBlock(world, i + 6, j + 8, k + 21, JungleBlocks.mossystairs);
		bridge.setBlock(world, i + 6, j + 8, k + 22, JungleBlocks.mossystairs);
		bridge.setBlock(world, i + 6, j + 8, k + 23, JungleBlocks.mossystairs);
		bridge.setBlock(world, i + 6, j + 8, k + 24, JungleBlocks.ancientMossyBlock);
		bridge.setBlock(world, i + 6, j + 8, k + 30, Blocks.COBBLESTONE_WALL, 1, 2);
		bridge.setBlock(world, i + 6, j + 8, k + 33, JungleBlocks.mossyslabSingle, 6, 2);
		bridge.setBlock(world, i + 6, j + 9, k + 14, Blocks.COBBLESTONE_WALL, 1, 2);
		bridge.setBlock(world, i + 6, j + 9, k + 20, Blocks.COBBLESTONE_WALL, 1, 2);
		bridge.setBlock(world, i + 6, j + 10, k + 14, JungleBlocks.ancientMossyBlock);
		bridge.setBlock(world, i + 6, j + 10, k + 20, JungleBlocks.ancientMossyBlock);
		bridge.setBlock(world, i + 6, j + 11, k + 14, JungleBlocks.ancientMossyBlock);
		bridge.setBlock(world, i + 6, j + 11, k + 20, JungleBlocks.ancientMossyBlock);
		bridge.setBlock(world, i + 7, j + 0, k + 25, JungleBlocks.ancientMossyBlock);
		bridge.setBlock(world, i + 7, j + 1, k + 0, Blocks.STONEBRICK, 1, 2);
		bridge.setBlock(world, i + 7, j + 1, k + 1, Blocks.DIRT, 0, 2);
		bridge.setBlock(world, i + 7, j + 1, k + 2, Blocks.DIRT, 0, 2);
		bridge.setBlock(world, i + 7, j + 1, k + 3, Blocks.DIRT, 0, 2);
		bridge.setBlock(world, i + 7, j + 1, k + 4, Blocks.DIRT, 0, 2);
		bridge.setBlock(world, i + 7, j + 1, k + 5, Blocks.DIRT, 0, 2);
		bridge.setBlock(world, i + 7, j + 1, k + 6, Blocks.DIRT, 0, 2);
		bridge.setBlock(world, i + 7, j + 1, k + 7, Blocks.DIRT, 0, 2);
		bridge.setBlock(world, i + 7, j + 1, k + 8, Blocks.DIRT, 0, 2);
		bridge.setBlock(world, i + 7, j + 1, k + 9, Blocks.DIRT, 0, 2);
		bridge.setBlock(world, i + 7, j + 1, k + 10, Blocks.DIRT, 0, 2);
		bridge.setBlock(world, i + 7, j + 1, k + 11, Blocks.DIRT, 0, 2);
		bridge.setBlock(world, i + 7, j + 1, k + 12, Blocks.DIRT, 0, 2);
		bridge.setBlock(world, i + 7, j + 1, k + 13, Blocks.DIRT, 0, 2);
		bridge.setBlock(world, i + 7, j + 1, k + 14, Blocks.DIRT, 0, 2);
		bridge.setBlock(world, i + 7, j + 1, k + 15, Blocks.DIRT, 0, 2);
		bridge.setBlock(world, i + 7, j + 1, k + 16, Blocks.DIRT, 0, 2);
		bridge.setBlock(world, i + 7, j + 1, k + 17, Blocks.DIRT, 0, 2);
		bridge.setBlock(world, i + 7, j + 1, k + 18, Blocks.DIRT, 0, 2);
		bridge.setBlock(world, i + 7, j + 1, k + 19, Blocks.DIRT, 0, 2);
		bridge.setBlock(world, i + 7, j + 1, k + 20, Blocks.DIRT, 0, 2);
		bridge.setBlock(world, i + 7, j + 1, k + 21, Blocks.DIRT, 0, 2);
		bridge.setBlock(world, i + 7, j + 1, k + 22, JungleBlocks.ancientMossyBlock);
		bridge.setBlock(world, i + 7, j + 1, k + 23, JungleBlocks.ancientMossyBlock);
		bridge.setBlock(world, i + 7, j + 1, k + 24, JungleBlocks.ancientMossyBlock);
		bridge.setBlock(world, i + 7, j + 1, k + 25, JungleBlocks.ancientMossyBlock);
		bridge.setBlock(world, i + 7, j + 1, k + 26, JungleBlocks.ancientMossyBlock);
		bridge.setBlock(world, i + 7, j + 1, k + 27, JungleBlocks.ancientMossyBlock);
		bridge.setBlock(world, i + 7, j + 1, k + 28, JungleBlocks.ancientMossyBlock);
		bridge.setBlock(world, i + 7, j + 1, k + 29, JungleBlocks.ancientMossyBlock);
		bridge.setBlock(world, i + 7, j + 1, k + 30, Blocks.DIRT, 0, 2);
		bridge.setBlock(world, i + 7, j + 1, k + 31, Blocks.DIRT, 0, 2);
		bridge.setBlock(world, i + 7, j + 1, k + 32, Blocks.DIRT, 0, 2);
		bridge.setBlock(world, i + 7, j + 1, k + 33, Blocks.DIRT, 0, 2);
		bridge.setBlock(world, i + 7, j + 1, k + 34, Blocks.STONEBRICK, 1, 2);
		bridge.setBlock(world, i + 7, j + 2, k + 1, JungleBlocks.ancientMossyBlock);
		bridge.setBlock(world, i + 7, j + 2, k + 2, JungleBlocks.ancientMossyBlock);
		bridge.setBlock(world, i + 7, j + 2, k + 3, JungleBlocks.ancientMossyBlock);
		bridge.setBlock(world, i + 7, j + 2, k + 4, JungleBlocks.ancientMossyBlock);
		bridge.setBlock(world, i + 7, j + 2, k + 5, JungleBlocks.ancientMossyBlock);
		bridge.setBlock(world, i + 7, j + 2, k + 6, JungleBlocks.ancientMossyBlock);
		bridge.setBlock(world, i + 7, j + 2, k + 7, JungleBlocks.ancientMossyBlock);
		bridge.setBlock(world, i + 7, j + 2, k + 8, JungleBlocks.ancientMossyBlock);
		bridge.setBlock(world, i + 7, j + 2, k + 9, JungleBlocks.ancientMossyBlock);
		bridge.setBlock(world, i + 7, j + 2, k + 10, JungleBlocks.ancientMossyBlock);
		bridge.setBlock(world, i + 7, j + 2, k + 11, JungleBlocks.ancientMossyBlock);
		bridge.setBlock(world, i + 7, j + 2, k + 12, JungleBlocks.ancientMossyBlock);
		bridge.setBlock(world, i + 7, j + 2, k + 13, JungleBlocks.ancientMossyBlock);
		bridge.setBlock(world, i + 7, j + 2, k + 14, JungleBlocks.ancientMossyBlock);
		bridge.setBlock(world, i + 7, j + 2, k + 15, JungleBlocks.ancientMossyBlock);
		bridge.setBlock(world, i + 7, j + 2, k + 16, JungleBlocks.ancientMossyBlock);
		bridge.setBlock(world, i + 7, j + 2, k + 17, JungleBlocks.ancientMossyBlock);
		bridge.setBlock(world, i + 7, j + 2, k + 18, JungleBlocks.ancientMossyBlock);
		bridge.setBlock(world, i + 7, j + 2, k + 19, JungleBlocks.ancientMossyBlock);
		bridge.setBlock(world, i + 7, j + 2, k + 20, JungleBlocks.ancientMossyBlock);
		bridge.setBlock(world, i + 7, j + 2, k + 21, JungleBlocks.ancientMossyBlock);
		bridge.setBlock(world, i + 7, j + 2, k + 22, JungleBlocks.jungleBrazier);
		bridge.setBlock(world, i + 7, j + 2, k + 29, JungleBlocks.ancientMossyBlock);
		bridge.setBlock(world, i + 7, j + 2, k + 30, JungleBlocks.ancientMossyBlock);
		bridge.setBlock(world, i + 7, j + 2, k + 31, JungleBlocks.ancientMossyBlock);
		bridge.setBlock(world, i + 7, j + 2, k + 32, JungleBlocks.ancientMossyBlock);
		bridge.setBlock(world, i + 7, j + 2, k + 33, JungleBlocks.ancientMossyBlock);
		bridge.setBlock(world, i + 7, j + 3, k + 2, JungleBlocks.ancientMossyBlock);
		bridge.setBlock(world, i + 7, j + 3, k + 3, JungleBlocks.ancientMossyBlock);
		bridge.setBlock(world, i + 7, j + 3, k + 4, JungleBlocks.ancientMossyBlock);
		bridge.setBlock(world, i + 7, j + 3, k + 5, JungleBlocks.ancientMossyBlock);
		bridge.setBlock(world, i + 7, j + 3, k + 6, JungleBlocks.ancientMossyBlock);
		bridge.setBlock(world, i + 7, j + 3, k + 7, JungleBlocks.ancientMossyBlock);
		bridge.setBlock(world, i + 7, j + 3, k + 8, JungleBlocks.ancientMossyBlock);
		bridge.setBlock(world, i + 7, j + 3, k + 9, JungleBlocks.ancientMossyBlock);
		bridge.setBlock(world, i + 7, j + 3, k + 10, JungleBlocks.ancientMossyBlock);
		bridge.setBlock(world, i + 7, j + 3, k + 11, JungleBlocks.ancientMossyBlock);
		bridge.setBlock(world, i + 7, j + 3, k + 12, JungleBlocks.ancientMossyBlock);
		bridge.setBlock(world, i + 7, j + 3, k + 13, JungleBlocks.ancientMossyBlock);
		bridge.setBlock(world, i + 7, j + 3, k + 14, JungleBlocks.ancientMossyBlock);
		bridge.setBlock(world, i + 7, j + 3, k + 15, JungleBlocks.ancientMossyBlock);
		bridge.setBlock(world, i + 7, j + 3, k + 16, JungleBlocks.ancientMossyBlock);
		bridge.setBlock(world, i + 7, j + 3, k + 17, JungleBlocks.ancientMossyBlock);
		bridge.setBlock(world, i + 7, j + 3, k + 18, JungleBlocks.ancientMossyBlock);
		bridge.setBlock(world, i + 7, j + 3, k + 19, JungleBlocks.ancientMossyBlock);
		bridge.setBlock(world, i + 7, j + 3, k + 20, JungleBlocks.ancientMossyBlock);
		bridge.setBlock(world, i + 7, j + 3, k + 21, Blocks.STONEBRICK, 1, 2);
		bridge.setBlock(world, i + 7, j + 3, k + 29, JungleBlocks.ancientMossyBlock);
		bridge.setBlock(world, i + 7, j + 3, k + 30, JungleBlocks.ancientMossyBlock);
		bridge.setBlock(world, i + 7, j + 3, k + 31, JungleBlocks.ancientMossyBlock);
		bridge.setBlock(world, i + 7, j + 3, k + 32, JungleBlocks.ancientMossyBlock);
		bridge.setBlock(world, i + 7, j + 4, k + 3, JungleBlocks.ancientMossyBlock);
		bridge.setBlock(world, i + 7, j + 4, k + 4, JungleBlocks.ancientMossyBlock);
		bridge.setBlock(world, i + 7, j + 4, k + 5, JungleBlocks.ancientMossyBlock);
		bridge.setBlock(world, i + 7, j + 4, k + 6, JungleBlocks.ancientMossyBlock);
		bridge.setBlock(world, i + 7, j + 4, k + 7, JungleBlocks.ancientMossyBlock);
		bridge.setBlock(world, i + 7, j + 4, k + 8, JungleBlocks.ancientMossyBlock);
		bridge.setBlock(world, i + 7, j + 4, k + 9, JungleBlocks.ancientMossyBlock);
		bridge.setBlock(world, i + 7, j + 4, k + 10, JungleBlocks.ancientMossyBlock);
		bridge.setBlock(world, i + 7, j + 4, k + 11, JungleBlocks.ancientMossyBlock);
		bridge.setBlock(world, i + 7, j + 4, k + 12, JungleBlocks.ancientMossyBlock);
		bridge.setBlock(world, i + 7, j + 4, k + 13, JungleBlocks.ancientMossyBlock);
		bridge.setBlock(world, i + 7, j + 4, k + 14, JungleBlocks.ancientMossyBlock);
		bridge.setBlock(world, i + 7, j + 4, k + 15, JungleBlocks.ancientMossyBlock);
		bridge.setBlock(world, i + 7, j + 4, k + 16, JungleBlocks.ancientMossyBlock);
		bridge.setBlock(world, i + 7, j + 4, k + 17, JungleBlocks.ancientMossyBlock);
		bridge.setBlock(world, i + 7, j + 4, k + 18, JungleBlocks.ancientMossyBlock);
		bridge.setBlock(world, i + 7, j + 4, k + 19, JungleBlocks.ancientMossyBlock);
		bridge.setBlock(world, i + 7, j + 4, k + 20, JungleBlocks.ancientMossyBlock);
		bridge.setBlock(world, i + 7, j + 4, k + 21, Blocks.STONEBRICK, 1, 2);
		bridge.setBlock(world, i + 7, j + 4, k + 29, JungleBlocks.ancientMossyBlock);
		bridge.setBlock(world, i + 7, j + 4, k + 30, JungleBlocks.ancientMossyBlock);
		bridge.setBlock(world, i + 7, j + 4, k + 31, JungleBlocks.ancientMossyBlock);
		bridge.setBlock(world, i + 7, j + 5, k + 4, JungleBlocks.ancientMossyBlock);
		bridge.setBlock(world, i + 7, j + 5, k + 5, JungleBlocks.ancientMossyBlock);
		bridge.setBlock(world, i + 7, j + 5, k + 6, JungleBlocks.ancientMossyBlock);
		bridge.setBlock(world, i + 7, j + 5, k + 7, JungleBlocks.ancientMossyBlock);
		bridge.setBlock(world, i + 7, j + 5, k + 8, JungleBlocks.ancientMossyBlock);
		bridge.setBlock(world, i + 7, j + 5, k + 9, JungleBlocks.ancientMossyBlock);
		bridge.setBlock(world, i + 7, j + 5, k + 10, JungleBlocks.ancientMossyBlock);
		bridge.setBlock(world, i + 7, j + 5, k + 11, JungleBlocks.ancientMossyBlock);
		bridge.setBlock(world, i + 7, j + 5, k + 12, JungleBlocks.ancientMossyBlock);
		bridge.setBlock(world, i + 7, j + 5, k + 13, JungleBlocks.ancientMossyBlock);
		bridge.setBlock(world, i + 7, j + 5, k + 14, JungleBlocks.ancientMossyBlock);
		bridge.setBlock(world, i + 7, j + 5, k + 15, JungleBlocks.ancientMossyBlock);
		bridge.setBlock(world, i + 7, j + 5, k + 16, JungleBlocks.ancientMossyBlock);
		bridge.setBlock(world, i + 7, j + 5, k + 17, JungleBlocks.ancientMossyBlock);
		bridge.setBlock(world, i + 7, j + 5, k + 18, JungleBlocks.ancientMossyBlock);
		bridge.setBlock(world, i + 7, j + 5, k + 19, JungleBlocks.ancientMossyBlock);
		bridge.setBlock(world, i + 7, j + 5, k + 20, JungleBlocks.ancientMossyBlock);
		bridge.setBlock(world, i + 7, j + 5, k + 21, JungleBlocks.ancientMossyBlock);
		bridge.setBlock(world, i + 7, j + 5, k + 29, JungleBlocks.ancientMossyBlock);
		bridge.setBlock(world, i + 7, j + 5, k + 30, JungleBlocks.ancientMossyBlock);
		bridge.setBlock(world, i + 7, j + 6, k + 5, JungleBlocks.ancientMossyBlock);
		bridge.setBlock(world, i + 7, j + 6, k + 6, JungleBlocks.ancientMossyBlock);
		bridge.setBlock(world, i + 7, j + 6, k + 7, JungleBlocks.ancientMossyBlock);
		bridge.setBlock(world, i + 7, j + 6, k + 8, JungleBlocks.ancientMossyBlock);
		bridge.setBlock(world, i + 7, j + 6, k + 9, JungleBlocks.ancientMossyBlock);
		bridge.setBlock(world, i + 7, j + 6, k + 10, JungleBlocks.ancientMossyBlock);
		bridge.setBlock(world, i + 7, j + 6, k + 11, JungleBlocks.ancientMossyBlock);
		bridge.setBlock(world, i + 7, j + 6, k + 12, JungleBlocks.ancientMossyBlock);
		bridge.setBlock(world, i + 7, j + 6, k + 13, JungleBlocks.ancientMossyBlock);
		bridge.setBlock(world, i + 7, j + 6, k + 14, JungleBlocks.ancientMossyBlock);
		bridge.setBlock(world, i + 7, j + 6, k + 15, JungleBlocks.ancientMossyBlock);
		bridge.setBlock(world, i + 7, j + 6, k + 16, JungleBlocks.ancientMossyBlock);
		bridge.setBlock(world, i + 7, j + 6, k + 17, JungleBlocks.ancientMossyBlock);
		bridge.setBlock(world, i + 7, j + 6, k + 18, JungleBlocks.ancientMossyBlock);
		bridge.setBlock(world, i + 7, j + 6, k + 19, JungleBlocks.ancientMossyBlock);
		bridge.setBlock(world, i + 7, j + 6, k + 20, JungleBlocks.ancientMossyBlock);
		bridge.setBlock(world, i + 7, j + 6, k + 21, JungleBlocks.ancientMossyBlock);
		bridge.setBlock(world, i + 7, j + 6, k + 22, Blocks.STONEBRICK, 1, 2);
		bridge.setBlock(world, i + 7, j + 6, k + 23, JungleBlocks.ancientMossyBlock);
		bridge.setBlock(world, i + 7, j + 6, k + 24, JungleBlocks.ancientMossyBlock);
		bridge.setBlock(world, i + 7, j + 6, k + 25, JungleBlocks.ancientMossyBlock);
		bridge.setBlock(world, i + 7, j + 6, k + 26, JungleBlocks.ancientMossyBlock);
		bridge.setBlock(world, i + 7, j + 6, k + 27, JungleBlocks.ancientMossyBlock);
		bridge.setBlock(world, i + 7, j + 6, k + 28, JungleBlocks.ancientMossyBlock);
		bridge.setBlock(world, i + 7, j + 6, k + 29, JungleBlocks.ancientMossyBlock);
		bridge.setBlock(world, i + 7, j + 7, k + 7, JungleBlocks.ancientMossyBlock);
		bridge.setBlock(world, i + 7, j + 7, k + 8, JungleBlocks.ancientMossyBlock);
		bridge.setBlock(world, i + 7, j + 7, k + 9, JungleBlocks.ancientMossyBlock);
		bridge.setBlock(world, i + 7, j + 7, k + 10, JungleBlocks.ancientMossyBlock);
		bridge.setBlock(world, i + 7, j + 7, k + 11, JungleBlocks.ancientMossyBlock);
		bridge.setBlock(world, i + 7, j + 7, k + 12, JungleBlocks.ancientMossyBlock);
		bridge.setBlock(world, i + 7, j + 7, k + 13, JungleBlocks.ancientMossyBlock);
		bridge.setBlock(world, i + 7, j + 7, k + 14, JungleBlocks.ancientMossyBlock);
		bridge.setBlock(world, i + 7, j + 7, k + 15, JungleBlocks.ancientMossyBlock);
		bridge.setBlock(world, i + 7, j + 7, k + 16, JungleBlocks.ancientMossyBlock);
		bridge.setBlock(world, i + 7, j + 7, k + 17, JungleBlocks.ancientMossyBlock);
		bridge.setBlock(world, i + 7, j + 7, k + 18, JungleBlocks.ancientMossyBlock);
		bridge.setBlock(world, i + 7, j + 7, k + 19, JungleBlocks.ancientMossyBlock);
		bridge.setBlock(world, i + 7, j + 7, k + 20, JungleBlocks.ancientMossyBlock);
		bridge.setBlock(world, i + 7, j + 7, k + 21, JungleBlocks.ancientMossyBlock);
		bridge.setBlock(world, i + 7, j + 7, k + 22, JungleBlocks.ancientMossyBlock);
		bridge.setBlock(world, i + 7, j + 7, k + 23, JungleBlocks.ancientMossyBlock);

		generate2(world, rand, i, j, k);
		return true;
	}

	public boolean generate2(World world, Random rand, int i, int j, int k) {
		bridge.setBlock(world, i + 7, j + 7, k + 24, JungleBlocks.ancientMossyBlock);
		bridge.setBlock(world, i + 7, j + 7, k + 25, JungleBlocks.ancientMossyBlock);
		bridge.setBlock(world, i + 7, j + 7, k + 26, JungleBlocks.ancientMossyBlock);
		bridge.setBlock(world, i + 7, j + 7, k + 27, JungleBlocks.ancientMossyBlock);
		bridge.setBlock(world, i + 7, j + 8, k + 7, JungleBlocks.ancientMossyBlock);
		bridge.setBlock(world, i + 7, j + 8, k + 8, JungleBlocks.ancientMossyBlock);
		bridge.setBlock(world, i + 7, j + 8, k + 9, JungleBlocks.ancientMossyBlock);
		bridge.setBlock(world, i + 7, j + 8, k + 10, JungleBlocks.ancientMossyBlock);
		bridge.setBlock(world, i + 7, j + 8, k + 11, JungleBlocks.ancientMossyBlock);
		bridge.setBlock(world, i + 7, j + 8, k + 12, JungleBlocks.ancientMossyBlock);
		bridge.setBlock(world, i + 7, j + 8, k + 13, JungleBlocks.ancientMossyBlock);
		bridge.setBlock(world, i + 7, j + 8, k + 14, JungleBlocks.ancientMossyBlock);
		bridge.setBlock(world, i + 7, j + 8, k + 15, JungleBlocks.ancientMossyBlock);
		bridge.setBlock(world, i + 7, j + 8, k + 16, JungleBlocks.mossystairs);
		bridge.setBlock(world, i + 7, j + 8, k + 17, JungleBlocks.mossystairs);
		bridge.setBlock(world, i + 7, j + 8, k + 18, JungleBlocks.mossystairs);
		bridge.setBlock(world, i + 7, j + 8, k + 19, JungleBlocks.ancientMossyBlock);
		bridge.setBlock(world, i + 7, j + 8, k + 20, JungleBlocks.ancientMossyBlock);
		bridge.setBlock(world, i + 7, j + 8, k + 21, JungleBlocks.ancientMossyBlock);
		bridge.setBlock(world, i + 7, j + 8, k + 22, JungleBlocks.ancientMossyBlock);
		bridge.setBlock(world, i + 7, j + 8, k + 23, JungleBlocks.ancientMossyBlock);
		bridge.setBlock(world, i + 7, j + 8, k + 24, JungleBlocks.ancientMossyBlock);
		bridge.setBlock(world, i + 7, j + 8, k + 25, JungleBlocks.ancientMossyBlock);
		bridge.setBlock(world, i + 7, j + 8, k + 26, JungleBlocks.ancientMossyBlock);
		bridge.setBlock(world, i + 7, j + 8, k + 27, JungleBlocks.ancientMossyBlock);
		bridge.setBlock(world, i + 7, j + 9, k + 10, JungleBlocks.ancientMossyBlock);
		bridge.setBlock(world, i + 7, j + 9, k + 11, JungleBlocks.mossystairs);
		bridge.setBlock(world, i + 7, j + 9, k + 12, JungleBlocks.mossystairs);
		bridge.setBlock(world, i + 7, j + 9, k + 13, JungleBlocks.mossystairs);
		bridge.setBlock(world, i + 7, j + 9, k + 14, JungleBlocks.ancientMossyBlock);
		bridge.setBlock(world, i + 7, j + 9, k + 20, JungleBlocks.ancientMossyBlock);
		bridge.setBlock(world, i + 7, j + 9, k + 21, JungleBlocks.mossystairs);
		bridge.setBlock(world, i + 7, j + 9, k + 22, JungleBlocks.mossystairs);
		bridge.setBlock(world, i + 7, j + 9, k + 23, JungleBlocks.mossystairs);
		bridge.setBlock(world, i + 7, j + 9, k + 24, JungleBlocks.ancientMossyBlock);
		bridge.setBlock(world, i + 7, j + 11, k + 14, JungleBlocks.ancientMossyBlock);
		bridge.setBlock(world, i + 7, j + 11, k + 20, JungleBlocks.ancientMossyBlock);
		bridge.setBlock(world, i + 8, j + 1, k + 0, Blocks.STONEBRICK, 1, 2);
		bridge.setBlock(world, i + 8, j + 1, k + 1, Blocks.DIRT, 0, 2);
		bridge.setBlock(world, i + 8, j + 1, k + 2, Blocks.DIRT, 0, 2);
		bridge.setBlock(world, i + 8, j + 1, k + 3, Blocks.DIRT, 0, 2);
		bridge.setBlock(world, i + 8, j + 1, k + 4, Blocks.DIRT, 0, 2);
		bridge.setBlock(world, i + 8, j + 1, k + 5, Blocks.DIRT, 0, 2);
		bridge.setBlock(world, i + 8, j + 1, k + 6, Blocks.DIRT, 0, 2);
		bridge.setBlock(world, i + 8, j + 1, k + 7, Blocks.DIRT, 0, 2);
		bridge.setBlock(world, i + 8, j + 1, k + 8, Blocks.DIRT, 0, 2);
		bridge.setBlock(world, i + 8, j + 1, k + 9, Blocks.DIRT, 0, 2);
		bridge.setBlock(world, i + 8, j + 1, k + 10, Blocks.DIRT, 0, 2);
		bridge.setBlock(world, i + 8, j + 1, k + 11, Blocks.DIRT, 0, 2);
		bridge.setBlock(world, i + 8, j + 1, k + 12, Blocks.DIRT, 0, 2);
		bridge.setBlock(world, i + 8, j + 1, k + 13, Blocks.DIRT, 0, 2);
		bridge.setBlock(world, i + 8, j + 1, k + 14, Blocks.DIRT, 0, 2);
		bridge.setBlock(world, i + 8, j + 1, k + 15, Blocks.DIRT, 0, 2);
		bridge.setBlock(world, i + 8, j + 1, k + 16, Blocks.DIRT, 0, 2);
		bridge.setBlock(world, i + 8, j + 1, k + 17, Blocks.DIRT, 0, 2);
		bridge.setBlock(world, i + 8, j + 1, k + 18, Blocks.DIRT, 0, 2);
		bridge.setBlock(world, i + 8, j + 1, k + 19, Blocks.DIRT, 0, 2);
		bridge.setBlock(world, i + 8, j + 1, k + 20, Blocks.DIRT, 0, 2);
		bridge.setBlock(world, i + 8, j + 1, k + 21, Blocks.DIRT, 0, 2);
		bridge.setBlock(world, i + 8, j + 1, k + 22, JungleBlocks.ancientMossyBlock);
		bridge.setBlock(world, i + 8, j + 1, k + 23, JungleBlocks.ancientMossyBlock);
		bridge.setBlock(world, i + 8, j + 1, k + 24, JungleBlocks.ancientMossyBlock);
		bridge.setBlock(world, i + 8, j + 1, k + 25, JungleBlocks.ancientMossyBlock);
		bridge.setBlock(world, i + 8, j + 1, k + 26, JungleBlocks.ancientMossyBlock);
		bridge.setBlock(world, i + 8, j + 1, k + 27, JungleBlocks.ancientMossyBlock);
		bridge.setBlock(world, i + 8, j + 1, k + 28, JungleBlocks.ancientMossyBlock);
		bridge.setBlock(world, i + 8, j + 1, k + 29, JungleBlocks.ancientMossyBlock);
		bridge.setBlock(world, i + 8, j + 1, k + 30, Blocks.DIRT, 0, 2);
		bridge.setBlock(world, i + 8, j + 1, k + 31, Blocks.DIRT, 0, 2);
		bridge.setBlock(world, i + 8, j + 1, k + 32, Blocks.DIRT, 0, 2);
		bridge.setBlock(world, i + 8, j + 1, k + 33, Blocks.DIRT, 0, 2);
		bridge.setBlock(world, i + 8, j + 1, k + 34, Blocks.STONEBRICK, 1, 2);
		bridge.setBlock(world, i + 8, j + 2, k + 1, JungleBlocks.ancientMossyBlock);
		bridge.setBlock(world, i + 8, j + 2, k + 2, JungleBlocks.ancientMossyBlock);
		bridge.setBlock(world, i + 8, j + 2, k + 3, JungleBlocks.ancientMossyBlock);
		bridge.setBlock(world, i + 8, j + 2, k + 4, JungleBlocks.ancientMossyBlock);
		bridge.setBlock(world, i + 8, j + 2, k + 5, JungleBlocks.ancientMossyBlock);
		bridge.setBlock(world, i + 8, j + 2, k + 6, JungleBlocks.ancientMossyBlock);
		bridge.setBlock(world, i + 8, j + 2, k + 7, JungleBlocks.ancientMossyBlock);
		bridge.setBlock(world, i + 8, j + 2, k + 8, JungleBlocks.ancientMossyBlock);
		bridge.setBlock(world, i + 8, j + 2, k + 9, JungleBlocks.ancientMossyBlock);
		bridge.setBlock(world, i + 8, j + 2, k + 10, JungleBlocks.ancientMossyBlock);
		bridge.setBlock(world, i + 8, j + 2, k + 11, JungleBlocks.ancientMossyBlock);
		bridge.setBlock(world, i + 8, j + 2, k + 12, JungleBlocks.ancientMossyBlock);
		bridge.setBlock(world, i + 8, j + 2, k + 13, JungleBlocks.ancientMossyBlock);
		bridge.setBlock(world, i + 8, j + 2, k + 14, JungleBlocks.ancientMossyBlock);
		bridge.setBlock(world, i + 8, j + 2, k + 15, JungleBlocks.ancientMossyBlock);
		bridge.setBlock(world, i + 8, j + 2, k + 16, JungleBlocks.ancientMossyBlock);
		bridge.setBlock(world, i + 8, j + 2, k + 17, JungleBlocks.ancientMossyBlock);
		bridge.setBlock(world, i + 8, j + 2, k + 18, JungleBlocks.ancientMossyBlock);
		bridge.setBlock(world, i + 8, j + 2, k + 19, JungleBlocks.ancientMossyBlock);
		bridge.setBlock(world, i + 8, j + 2, k + 20, JungleBlocks.ancientMossyBlock);
		bridge.setBlock(world, i + 8, j + 2, k + 21, JungleBlocks.ancientMossyBlock);
		bridge.setBlock(world, i + 8, j + 2, k + 29, JungleBlocks.ancientMossyBlock);
		bridge.setBlock(world, i + 8, j + 2, k + 30, JungleBlocks.ancientMossyBlock);
		bridge.setBlock(world, i + 8, j + 2, k + 31, JungleBlocks.ancientMossyBlock);
		bridge.setBlock(world, i + 8, j + 2, k + 32, JungleBlocks.ancientMossyBlock);
		bridge.setBlock(world, i + 8, j + 2, k + 33, JungleBlocks.ancientMossyBlock);
		bridge.setBlock(world, i + 8, j + 3, k + 2, JungleBlocks.ancientMossyBlock);
		bridge.setBlock(world, i + 8, j + 3, k + 3, JungleBlocks.ancientMossyBlock);
		bridge.setBlock(world, i + 8, j + 3, k + 4, JungleBlocks.ancientMossyBlock);
		bridge.setBlock(world, i + 8, j + 3, k + 5, JungleBlocks.ancientMossyBlock);
		bridge.setBlock(world, i + 8, j + 3, k + 6, JungleBlocks.ancientMossyBlock);
		bridge.setBlock(world, i + 8, j + 3, k + 7, JungleBlocks.ancientMossyBlock);
		bridge.setBlock(world, i + 8, j + 3, k + 8, JungleBlocks.ancientMossyBlock);
		bridge.setBlock(world, i + 8, j + 3, k + 9, JungleBlocks.ancientMossyBlock);
		bridge.setBlock(world, i + 8, j + 3, k + 10, JungleBlocks.ancientMossyBlock);
		bridge.setBlock(world, i + 8, j + 3, k + 11, JungleBlocks.ancientMossyBlock);
		bridge.setBlock(world, i + 8, j + 3, k + 12, JungleBlocks.ancientMossyBlock);
		bridge.setBlock(world, i + 8, j + 3, k + 13, JungleBlocks.ancientMossyBlock);
		bridge.setBlock(world, i + 8, j + 3, k + 14, JungleBlocks.ancientMossyBlock);
		bridge.setBlock(world, i + 8, j + 3, k + 15, JungleBlocks.ancientMossyBlock);
		bridge.setBlock(world, i + 8, j + 3, k + 16, JungleBlocks.ancientMossyBlock);
		bridge.setBlock(world, i + 8, j + 3, k + 17, JungleBlocks.ancientMossyBlock);
		bridge.setBlock(world, i + 8, j + 3, k + 18, JungleBlocks.ancientMossyBlock);
		bridge.setBlock(world, i + 8, j + 3, k + 19, JungleBlocks.ancientMossyBlock);
		bridge.setBlock(world, i + 8, j + 3, k + 20, JungleBlocks.ancientMossyBlock);
		bridge.setBlock(world, i + 8, j + 3, k + 21, Blocks.STONEBRICK, 1, 2);
		bridge.setBlock(world, i + 8, j + 3, k + 29, JungleBlocks.ancientMossyBlock);
		bridge.setBlock(world, i + 8, j + 3, k + 30, JungleBlocks.ancientMossyBlock);
		bridge.setBlock(world, i + 8, j + 3, k + 31, JungleBlocks.ancientMossyBlock);
		bridge.setBlock(world, i + 8, j + 3, k + 32, JungleBlocks.ancientMossyBlock);
		bridge.setBlock(world, i + 8, j + 4, k + 3, JungleBlocks.ancientMossyBlock);
		bridge.setBlock(world, i + 8, j + 4, k + 4, JungleBlocks.ancientMossyBlock);
		bridge.setBlock(world, i + 8, j + 4, k + 5, JungleBlocks.ancientMossyBlock);
		bridge.setBlock(world, i + 8, j + 4, k + 6, JungleBlocks.ancientMossyBlock);
		bridge.setBlock(world, i + 8, j + 4, k + 7, JungleBlocks.ancientMossyBlock);
		bridge.setBlock(world, i + 8, j + 4, k + 8, JungleBlocks.ancientMossyBlock);
		bridge.setBlock(world, i + 8, j + 4, k + 9, JungleBlocks.ancientMossyBlock);
		bridge.setBlock(world, i + 8, j + 4, k + 10, JungleBlocks.ancientMossyBlock);
		bridge.setBlock(world, i + 8, j + 4, k + 11, JungleBlocks.ancientMossyBlock);
		bridge.setBlock(world, i + 8, j + 4, k + 12, JungleBlocks.ancientMossyBlock);
		bridge.setBlock(world, i + 8, j + 4, k + 13, Blocks.STONEBRICK, 1, 2);
		bridge.setBlock(world, i + 8, j + 4, k + 14, Blocks.STONEBRICK, 1, 2);
		bridge.setBlock(world, i + 8, j + 4, k + 15, Blocks.STONEBRICK, 1, 2);
		bridge.setBlock(world, i + 8, j + 4, k + 16, Blocks.STONEBRICK, 1, 2);
		bridge.setBlock(world, i + 8, j + 4, k + 17, JungleBlocks.ancientMossyBlock);
		bridge.setBlock(world, i + 8, j + 4, k + 18, Blocks.STONEBRICK, 1, 2);
		bridge.setBlock(world, i + 8, j + 4, k + 19, Blocks.STONEBRICK, 1, 2);
		bridge.setBlock(world, i + 8, j + 4, k + 20, Blocks.STONEBRICK, 1, 2);
		bridge.setBlock(world, i + 8, j + 4, k + 21, Blocks.STONEBRICK, 1, 2);
		bridge.setBlock(world, i + 8, j + 4, k + 29, JungleBlocks.ancientMossyBlock);
		bridge.setBlock(world, i + 8, j + 4, k + 30, JungleBlocks.ancientMossyBlock);
		bridge.setBlock(world, i + 8, j + 4, k + 31, JungleBlocks.ancientMossyBlock);
		bridge.setBlock(world, i + 8, j + 5, k + 4, JungleBlocks.ancientMossyBlock);
		bridge.setBlock(world, i + 8, j + 5, k + 5, JungleBlocks.ancientMossyBlock);
		bridge.setBlock(world, i + 8, j + 5, k + 6, JungleBlocks.ancientMossyBlock);
		bridge.setBlock(world, i + 8, j + 5, k + 7, JungleBlocks.ancientMossyBlock);
		bridge.setBlock(world, i + 8, j + 5, k + 8, JungleBlocks.ancientMossyBlock);
		bridge.setBlock(world, i + 8, j + 5, k + 9, JungleBlocks.ancientMossyBlock);
		bridge.setBlock(world, i + 8, j + 5, k + 10, JungleBlocks.ancientMossyBlock);
		bridge.setBlock(world, i + 8, j + 5, k + 11, JungleBlocks.ancientMossyBlock);
		bridge.setBlock(world, i + 8, j + 5, k + 12, JungleBlocks.ancientMossyBlock);
		bridge.setBlock(world, i + 8, j + 5, k + 13, Blocks.STONEBRICK, 1, 2);
		bridge.setBlock(world, i + 8, j + 5, k + 14, Blocks.STONEBRICK, 1, 2);
		bridge.setBlock(world, i + 8, j + 5, k + 15, Blocks.STONEBRICK, 1, 2);
		bridge.setBlock(world, i + 8, j + 5, k + 16, Blocks.STONEBRICK, 1, 2);
		bridge.setBlock(world, i + 8, j + 5, k + 17, JungleBlocks.ancientMossyBlock);
		bridge.setBlock(world, i + 8, j + 5, k + 18, Blocks.STONEBRICK, 1, 2);
		bridge.setBlock(world, i + 8, j + 5, k + 19, Blocks.STONEBRICK, 1, 2);
		bridge.setBlock(world, i + 8, j + 5, k + 20, Blocks.STONEBRICK, 1, 2);
		bridge.setBlock(world, i + 8, j + 5, k + 21, JungleBlocks.ancientMossyBlock);
		bridge.setBlock(world, i + 8, j + 5, k + 29, JungleBlocks.ancientMossyBlock);
		bridge.setBlock(world, i + 8, j + 5, k + 30, JungleBlocks.ancientMossyBlock);
		bridge.setBlock(world, i + 8, j + 6, k + 5, JungleBlocks.ancientMossyBlock);
		bridge.setBlock(world, i + 8, j + 6, k + 6, JungleBlocks.ancientMossyBlock);
		bridge.setBlock(world, i + 8, j + 6, k + 7, JungleBlocks.ancientMossyBlock);
		bridge.setBlock(world, i + 8, j + 6, k + 8, JungleBlocks.ancientMossyBlock);
		bridge.setBlock(world, i + 8, j + 6, k + 9, JungleBlocks.ancientMossyBlock);
		bridge.setBlock(world, i + 8, j + 6, k + 10, JungleBlocks.ancientMossyBlock);
		bridge.setBlock(world, i + 8, j + 6, k + 11, JungleBlocks.ancientMossyBlock);
		bridge.setBlock(world, i + 8, j + 6, k + 12, JungleBlocks.ancientMossyBlock);
		bridge.setBlock(world, i + 8, j + 6, k + 13, JungleBlocks.ancientMossyBlock);
		bridge.setBlock(world, i + 8, j + 6, k + 14, JungleBlocks.ancientMossyBlock);
		bridge.setBlock(world, i + 8, j + 6, k + 15, JungleBlocks.ancientMossyBlock);
		bridge.setBlock(world, i + 8, j + 6, k + 16, JungleBlocks.ancientMossyBlock);
		bridge.setBlock(world, i + 8, j + 6, k + 17, JungleBlocks.ancientMossyBlock);
		bridge.setBlock(world, i + 8, j + 6, k + 18, JungleBlocks.ancientMossyBlock);
		bridge.setBlock(world, i + 8, j + 6, k + 19, JungleBlocks.ancientMossyBlock);
		bridge.setBlock(world, i + 8, j + 6, k + 20, JungleBlocks.ancientMossyBlock);
		bridge.setBlock(world, i + 8, j + 6, k + 21, JungleBlocks.ancientMossyBlock);
		bridge.setBlock(world, i + 8, j + 6, k + 22, Blocks.STONEBRICK, 1, 2);
		bridge.setBlock(world, i + 8, j + 6, k + 23, JungleBlocks.ancientMossyBlock);
		bridge.setBlock(world, i + 8, j + 6, k + 24, JungleBlocks.ancientMossyBlock);
		bridge.setBlock(world, i + 8, j + 6, k + 25, JungleBlocks.ancientMossyBlock);
		bridge.setBlock(world, i + 8, j + 6, k + 26, JungleBlocks.ancientMossyBlock);
		bridge.setBlock(world, i + 8, j + 6, k + 27, JungleBlocks.ancientMossyBlock);
		bridge.setBlock(world, i + 8, j + 6, k + 28, JungleBlocks.ancientMossyBlock);
		bridge.setBlock(world, i + 8, j + 6, k + 29, JungleBlocks.ancientMossyBlock);
		bridge.setBlock(world, i + 8, j + 7, k + 7, JungleBlocks.ancientMossyBlock);
		bridge.setBlock(world, i + 8, j + 7, k + 8, JungleBlocks.ancientMossyBlock);
		bridge.setBlock(world, i + 8, j + 7, k + 9, JungleBlocks.ancientMossyBlock);
		bridge.setBlock(world, i + 8, j + 7, k + 10, JungleBlocks.ancientMossyBlock);
		bridge.setBlock(world, i + 8, j + 7, k + 11, JungleBlocks.ancientMossyBlock);
		bridge.setBlock(world, i + 8, j + 7, k + 12, JungleBlocks.ancientMossyBlock);
		bridge.setBlock(world, i + 8, j + 7, k + 13, Blocks.STONEBRICK, 1, 2);
		bridge.setBlock(world, i + 8, j + 7, k + 14, Blocks.STONEBRICK, 1, 2);
		bridge.setBlock(world, i + 8, j + 7, k + 15, Blocks.STONEBRICK, 1, 2);
		bridge.setBlock(world, i + 8, j + 7, k + 16, Blocks.STONEBRICK, 1, 2);
		bridge.setBlock(world, i + 8, j + 7, k + 17, JungleBlocks.ancientMossyBlock);
		bridge.setBlock(world, i + 8, j + 7, k + 18, Blocks.STONEBRICK, 1, 2);
		bridge.setBlock(world, i + 8, j + 7, k + 19, Blocks.STONEBRICK, 1, 2);
		bridge.setBlock(world, i + 8, j + 7, k + 20, Blocks.STONEBRICK, 1, 2);
		bridge.setBlock(world, i + 8, j + 7, k + 21, Blocks.STONEBRICK, 1, 2);
		bridge.setBlock(world, i + 8, j + 7, k + 22, JungleBlocks.ancientMossyBlock);
		bridge.setBlock(world, i + 8, j + 7, k + 23, JungleBlocks.ancientMossyBlock);
		bridge.setBlock(world, i + 8, j + 7, k + 24, JungleBlocks.ancientMossyBlock);
		bridge.setBlock(world, i + 8, j + 7, k + 25, JungleBlocks.ancientMossyBlock);
		bridge.setBlock(world, i + 8, j + 7, k + 26, JungleBlocks.ancientMossyBlock);
		bridge.setBlock(world, i + 8, j + 7, k + 27, JungleBlocks.ancientMossyBlock);
		bridge.setBlock(world, i + 8, j + 8, k + 7, JungleBlocks.ancientMossyBlock);
		bridge.setBlock(world, i + 8, j + 8, k + 8, JungleBlocks.ancientMossyBlock);
		bridge.setBlock(world, i + 8, j + 8, k + 9, JungleBlocks.ancientMossyBlock);
		bridge.setBlock(world, i + 8, j + 8, k + 10, JungleBlocks.ancientMossyBlock);
		bridge.setBlock(world, i + 8, j + 8, k + 11, JungleBlocks.ancientMossyBlock);
		bridge.setBlock(world, i + 8, j + 8, k + 12, JungleBlocks.ancientMossyBlock);
		bridge.setBlock(world, i + 8, j + 8, k + 13, JungleBlocks.ancientMossyBlock);
		bridge.setBlock(world, i + 8, j + 8, k + 14, JungleBlocks.ancientMossyBlock);
		bridge.setBlock(world, i + 8, j + 8, k + 15, JungleBlocks.ancientMossyBlock);
		bridge.setBlock(world, i + 8, j + 8, k + 16, JungleBlocks.ancientMossyBlock);
		bridge.setBlock(world, i + 8, j + 8, k + 17, JungleBlocks.ancientMossyBlock);
		bridge.setBlock(world, i + 8, j + 8, k + 18, JungleBlocks.ancientMossyBlock);
		bridge.setBlock(world, i + 8, j + 8, k + 19, JungleBlocks.ancientMossyBlock);
		bridge.setBlock(world, i + 8, j + 8, k + 20, JungleBlocks.ancientMossyBlock);
		bridge.setBlock(world, i + 8, j + 8, k + 21, JungleBlocks.ancientMossyBlock);
		bridge.setBlock(world, i + 8, j + 8, k + 22, JungleBlocks.ancientMossyBlock);
		bridge.setBlock(world, i + 8, j + 8, k + 23, JungleBlocks.ancientMossyBlock);
