package com.salvestrom.w2theJungle.worldGen.structures;

import java.util.Random;

import com.salvestrom.w2theJungle.blocks.mossySlab;
import com.salvestrom.w2theJungle.blocks.mossySlab.EnumType;
import com.salvestrom.w2theJungle.init.JungleBlocks;

import net.minecraft.block.Block;
import net.minecraft.block.BlockStoneSlab;
import net.minecraft.init.Blocks;
import net.minecraft.util.math.BlockPos;
import net.minecraft.world.World;
import net.minecraft.world.gen.feature.WorldGenerator;

public class lostTempleWG2 extends WorldGenerator
{
	public fillWithBlocks fill = new fillWithBlocks();
	public blockPlacmentBridge bridge = new blockPlacmentBridge();
	public String rota = "e";
	public World world;
	
	@Override
	public boolean generate(World wrld, Random rnd, BlockPos pos)
	{
		return false;
	}
	
	public Block stone()
	{
		Random rnd = new Random();
		return rnd.nextInt(5) < 2 ? Blocks.STONE : JungleBlocks.mossyStone; 
	}

	public Block blockRandom(String s) {
		
		Random rnd = new Random();

		Block block;
		Block block2;
		
		if(s == "mossSmoothSlab") {
			block = JungleBlocks.mossyslabSingle.getDefaultState().withProperty(mossySlab.VARIANT, EnumType.MOSSY_SMOOTH_SLAB).getBlock();  //smooth
			block2 = Blocks.STONE_SLAB.getDefaultState().withProperty(BlockStoneSlab.VARIANT, BlockStoneSlab.EnumType.SMOOTHBRICK).getBlock();
			} else if(s == "mossCobbSlab") {
				block = JungleBlocks.mossyslabSingle.getDefaultState().withProperty(mossySlab.VARIANT, EnumType.MOSSY_SLAB).getBlock();  //cobbled
				block2 = Blocks.STONE_SLAB.getDefaultState().withProperty(BlockStoneSlab.VARIANT, BlockStoneSlab.EnumType.COBBLESTONE).getBlock();
				} else if(s == "mossSmoothStairs") {
					block = JungleBlocks.mossyStoneSteps;
					block2 = Blocks.STONE_BRICK_STAIRS;
					} else {
						block = JungleBlocks.mossystairs;
						block2 = Blocks.STONE_STAIRS;
		
					}
					
		return rnd.nextInt(7) == 0 ? block2 : block;
			}
	
	public boolean generate9(World world, Random rand, int i, int j, int k) {
	bridge.setBlock(world, i + 33, j + 6, k + 23, stone());
	bridge.setBlock(world, i + 33, j + 6, k + 24, stone());
	bridge.setBlock(world, i + 33, j + 6, k + 25, stone());
	bridge.setBlock(world, i + 33, j + 6, k + 26, stone());
	bridge.setBlock(world, i + 33, j + 6, k + 27, stone());
	bridge.setBlock(world, i + 33, j + 7, k + 6, stone());
	bridge.setBlock(world, i + 33, j + 7, k + 13, Blocks.AIR);
	bridge.setBlock(world, i + 33, j + 7, k + 14, stone());
	bridge.setBlock(world, i + 33, j + 7, k + 15, stone());
	bridge.setBlock(world, i + 33, j + 7, k + 16, stone());
	bridge.setBlock(world, i + 33, j + 7, k + 17, stone());
	bridge.setBlock(world, i + 33, j + 7, k + 23, stone());
	bridge.setBlock(world, i + 33, j + 7, k + 24, stone());
	bridge.setBlock(world, i + 33, j + 7, k + 25, stone());
	bridge.setBlock(world, i + 33, j + 7, k + 26, stone());
	bridge.setBlock(world, i + 33, j + 7, k + 27, stone());
	bridge.setBlock(world, i + 33, j + 8, k + 6, stone());
	bridge.setBlock(world, i + 33, j + 8, k + 13, Blocks.AIR);
	bridge.setBlock(world, i + 33, j + 8, k + 14, stone());
	bridge.setBlock(world, i + 33, j + 8, k + 15, stone());
	bridge.setBlock(world, i + 33, j + 8, k + 16, stone());
	bridge.setBlock(world, i + 33, j + 8, k + 17, stone());
	bridge.setBlock(world, i + 33, j + 8, k + 24, stone());
	bridge.setBlock(world, i + 33, j + 8, k + 25, stone());
	bridge.setBlock(world, i + 33, j + 8, k + 26, JungleBlocks.ancientMossyBlock);
	bridge.setBlock(world, i + 33, j + 8, k + 27, stone());
	bridge.setBlock(world, i + 33, j + 9, k + 7, stone());
	bridge.setBlock(world, i + 33, j + 9, k + 12, Blocks.AIR);
	bridge.setBlock(world, i + 33, j + 9, k + 13, Blocks.AIR);
	bridge.setBlock(world, i + 33, j + 9, k + 14, stone());
	bridge.setBlock(world, i + 33, j + 9, k + 15, stone());
	bridge.setBlock(world, i + 33, j + 9, k + 16, stone());
	bridge.setBlock(world, i + 33, j + 9, k + 17, stone());
	bridge.setBlock(world, i + 33, j + 9, k + 24, stone());
	bridge.setBlock(world, i + 33, j + 9, k + 25, JungleBlocks.ancientMossyBlock);
	bridge.setBlock(world, i + 33, j + 9, k + 26, stone());
	bridge.setBlock(world, i + 33, j + 10, k + 7, stone());
	bridge.setBlock(world, i + 33, j + 10, k + 8, stone());
	bridge.setBlock(world, i + 33, j + 10, k + 9, Blocks.AIR);
	bridge.setBlock(world, i + 33, j + 10, k + 10, Blocks.AIR);
	bridge.setBlock(world, i + 33, j + 10, k + 11, Blocks.AIR);
	bridge.setBlock(world, i + 33, j + 10, k + 12, Blocks.AIR);
	bridge.setBlock(world, i + 33, j + 10, k + 13, stone());
	bridge.setBlock(world, i + 33, j + 10, k + 14, stone());
	bridge.setBlock(world, i + 33, j + 10, k + 15, stone());
	bridge.setBlock(world, i + 33, j + 10, k + 16, stone());
	bridge.setBlock(world, i + 33, j + 10, k + 17, stone());
	bridge.setBlock(world, i + 33, j + 10, k + 23, stone());
	bridge.setBlock(world, i + 33, j + 10, k + 24, JungleBlocks.ancientMossyBlock);
	bridge.setBlock(world, i + 33, j + 10, k + 25, stone());
	bridge.setBlock(world, i + 33, j + 10, k + 26, stone());
	bridge.setBlock(world, i + 33, j + 11, k + 7, stone());
	bridge.setBlock(world, i + 33, j + 11, k + 8, stone());
	bridge.setBlock(world, i + 33, j + 11, k + 9, stone());
	bridge.setBlock(world, i + 33, j + 11, k + 10, stone());
	bridge.setBlock(world, i + 33, j + 11, k + 11, stone());
	bridge.setBlock(world, i + 33, j + 11, k + 12, stone());
	bridge.setBlock(world, i + 33, j + 11, k + 13, stone());
	bridge.setBlock(world, i + 33, j + 11, k + 14, stone());
	bridge.setBlock(world, i + 33, j + 11, k + 15, stone());
	bridge.setBlock(world, i + 33, j + 11, k + 16, stone());
	bridge.setBlock(world, i + 33, j + 11, k + 17, stone());
	bridge.setBlock(world, i + 33, j + 11, k + 18, stone());
	bridge.setBlock(world, i + 33, j + 11, k + 19, stone());
	bridge.setBlock(world, i + 33, j + 11, k + 22, stone());
	bridge.setBlock(world, i + 33, j + 11, k + 23, JungleBlocks.ancientMossyBlock);
	bridge.setBlock(world, i + 33, j + 11, k + 24, stone());
	bridge.setBlock(world, i + 33, j + 12, k + 7, stone());
	bridge.setBlock(world, i + 33, j + 12, k + 8, stone());
	bridge.setBlock(world, i + 33, j + 12, k + 9, stone());
	bridge.setBlock(world, i + 33, j + 12, k + 10, stone());
	bridge.setBlock(world, i + 33, j + 12, k + 11, stone());
	bridge.setBlock(world, i + 33, j + 12, k + 12, stone());
	bridge.setBlock(world, i + 33, j + 12, k + 13, stone());
	bridge.setBlock(world, i + 33, j + 12, k + 14, stone());
	bridge.setBlock(world, i + 33, j + 12, k + 15, stone());
	bridge.setBlock(world, i + 33, j + 12, k + 16, stone());
	bridge.setBlock(world, i + 33, j + 12, k + 17, stone());
	bridge.setBlock(world, i + 33, j + 12, k + 18, stone());
	bridge.setBlock(world, i + 33, j + 12, k + 19, stone());
	bridge.setBlock(world, i + 33, j + 12, k + 20, stone());
	bridge.setBlock(world, i + 33, j + 12, k + 21, stone());
	bridge.setBlock(world, i + 33, j + 12, k + 22, JungleBlocks.ancientMossyBlock);
	bridge.setBlock(world, i + 33, j + 12, k + 23, stone());
	bridge.setBlock(world, i + 33, j + 13, k + 8, JungleBlocks.ancientMossyBlock);
	bridge.setBlock(world, i + 33, j + 13, k + 9, JungleBlocks.ancientMossyBlock);
	bridge.setBlock(world, i + 33, j + 13, k + 10, JungleBlocks.ancientMossyBlock);
	bridge.setBlock(world, i + 33, j + 13, k + 11, JungleBlocks.ancientMossyBlock);
	bridge.setBlock(world, i + 33, j + 13, k + 12, JungleBlocks.ancientMossyBlock);
	bridge.setBlock(world, i + 33, j + 13, k + 13, JungleBlocks.ancientMossyBlock);
	bridge.setBlock(world, i + 33, j + 13, k + 14, JungleBlocks.ancientMossyBlock);
	bridge.setBlock(world, i + 33, j + 13, k + 15, JungleBlocks.ancientMossyBlock);
	bridge.setBlock(world, i + 33, j + 13, k + 16, JungleBlocks.ancientMossyBlock);
	bridge.setBlock(world, i + 33, j + 13, k + 17, JungleBlocks.ancientMossyBlock);
	bridge.setBlock(world, i + 33, j + 13, k + 18, JungleBlocks.ancientMossyBlock);
	bridge.setBlock(world, i + 33, j + 13, k + 19, JungleBlocks.ancientMossyBlock);
	bridge.setBlock(world, i + 33, j + 13, k + 20, JungleBlocks.ancientMossyBlock);
	bridge.setBlock(world, i + 33, j + 13, k + 21, JungleBlocks.ancientMossyBlock);
	bridge.setBlock(world, i + 33, j + 14, k + 8, JungleBlocks.ancientMossyBlock);
	bridge.setBlock(world, i + 33, j + 14, k + 9, JungleBlocks.mossystairs, 1, 2);
	bridge.setBlock(world, i + 33, j + 14, k + 10, JungleBlocks.mossystairs, 1, 2);
	bridge.setBlock(world, i + 33, j + 14, k + 11, this.blockRandom(null), 1, 2);
	bridge.setBlock(world, i + 33, j + 14, k + 12, JungleBlocks.ancientMossyBlock);
	bridge.setBlock(world, i + 33, j + 14, k + 13, this.blockRandom(null), 1, 2);
	bridge.setBlock(world, i + 33, j + 14, k + 14, this.blockRandom(null), 1, 2);
	bridge.setBlock(world, i + 33, j + 14, k + 15, JungleBlocks.mossystairs, 1, 2);
	bridge.setBlock(world, i + 33, j + 14, k + 16, JungleBlocks.mossystairs, 1, 2);
	bridge.setBlock(world, i + 33, j + 14, k + 17, JungleBlocks.mossystairs, 1, 2);
	bridge.setBlock(world, i + 33, j + 14, k + 18, JungleBlocks.ancientMossyBlock);
	bridge.setBlock(world, i + 33, j + 14, k + 19, JungleBlocks.mossystairs, 1, 2);
	bridge.setBlock(world, i + 33, j + 14, k + 20, JungleBlocks.mossystairs, 1, 2);
	bridge.setBlock(world, i + 33, j + 14, k + 21, JungleBlocks.mossystairs, 1, 2);
	bridge.setBlock(world, i + 33, j + 15, k + 12, JungleBlocks.ancientMossyBlock);
	bridge.setBlock(world, i + 33, j + 15, k + 18, JungleBlocks.ancientMossyBlock);
	bridge.setBlock(world, i + 33, j + 16, k + 12, Blocks.COBBLESTONE_WALL, 1, 2);
	bridge.setBlock(world, i + 33, j + 16, k + 18, Blocks.COBBLESTONE_WALL, 1, 2);
	bridge.setBlock(world, i + 33, j + 17, k + 12, JungleBlocks.ancientMossyBlock);
	bridge.setBlock(world, i + 33, j + 17, k + 18, JungleBlocks.ancientMossyBlock);
	bridge.setBlock(world, i + 33, j + 18, k + 12, Blocks.COBBLESTONE_WALL, 1, 2);
	bridge.setBlock(world, i + 33, j + 18, k + 18, Blocks.COBBLESTONE_WALL, 1, 2);
	bridge.setBlock(world, i + 33, j + 19, k + 12, Blocks.COBBLESTONE_WALL, 1, 2);
	bridge.setBlock(world, i + 33, j + 19, k + 18, Blocks.COBBLESTONE_WALL, 1, 2);
	bridge.setBlock(world, i + 33, j + 20, k + 12, JungleBlocks.mossystairs, 1, 2);
	bridge.setBlock(world, i + 33, j + 20, k + 18, JungleBlocks.mossystairs, 1, 2);
	bridge.setBlock(world, i + 34, j + 0, k + 3, stone());
	bridge.setBlock(world, i + 34, j + 0, k + 4, stone());
	bridge.setBlock(world, i + 34, j + 0, k + 5, stone());
	bridge.setBlock(world, i + 34, j + 0, k + 6, stone());
	bridge.setBlock(world, i + 34, j + 0, k + 7, stone());
	bridge.setBlock(world, i + 34, j + 0, k + 8, stone());
	bridge.setBlock(world, i + 34, j + 0, k + 9, stone());
	bridge.setBlock(world, i + 34, j + 0, k + 10, stone());
	bridge.setBlock(world, i + 34, j + 0, k + 11, stone());
	bridge.setBlock(world, i + 34, j + 0, k + 12, stone());
	bridge.setBlock(world, i + 34, j + 0, k + 13, stone());
	bridge.setBlock(world, i + 34, j + 0, k + 14, stone());
	bridge.setBlock(world, i + 34, j + 0, k + 15, stone());
	bridge.setBlock(world, i + 34, j + 0, k + 16, stone());
	bridge.setBlock(world, i + 34, j + 0, k + 17, stone());
	bridge.setBlock(world, i + 34, j + 0, k + 18, stone());
	bridge.setBlock(world, i + 34, j + 0, k + 19, stone());
	bridge.setBlock(world, i + 34, j + 0, k + 20, stone());
	bridge.setBlock(world, i + 34, j + 0, k + 21, stone());
	bridge.setBlock(world, i + 34, j + 0, k + 22, stone());
	bridge.setBlock(world, i + 34, j + 0, k + 23, stone());
	bridge.setBlock(world, i + 34, j + 0, k + 24, stone());
	bridge.setBlock(world, i + 34, j + 0, k + 25, stone());
	bridge.setBlock(world, i + 34, j + 0, k + 26, stone());
	bridge.setBlock(world, i + 34, j + 0, k + 27, stone());
	bridge.setBlock(world, i + 34, j + 0, k + 28, stone());
	bridge.setBlock(world, i + 34, j + 1, k + 3, stone());
	bridge.setBlock(world, i + 34, j + 1, k + 4, stone());
	bridge.setBlock(world, i + 34, j + 1, k + 5, stone());
	bridge.setBlock(world, i + 34, j + 1, k + 6, stone());
	bridge.setBlock(world, i + 34, j + 1, k + 7, stone());
	bridge.setBlock(world, i + 34, j + 1, k + 8, stone());
	bridge.setBlock(world, i + 34, j + 1, k + 9, stone());
	bridge.setBlock(world, i + 34, j + 1, k + 10, stone());
	bridge.setBlock(world, i + 34, j + 1, k + 11, stone());
	bridge.setBlock(world, i + 34, j + 1, k + 12, stone());
	bridge.setBlock(world, i + 34, j + 1, k + 13, stone());
	bridge.setBlock(world, i + 34, j + 1, k + 14, stone());
	bridge.setBlock(world, i + 34, j + 1, k + 15, stone());
	bridge.setBlock(world, i + 34, j + 1, k + 16, stone());
	bridge.setBlock(world, i + 34, j + 1, k + 17, stone());
	bridge.setBlock(world, i + 34, j + 1, k + 18, stone());
	bridge.setBlock(world, i + 34, j + 1, k + 19, stone());
	bridge.setBlock(world, i + 34, j + 1, k + 20, stone());
	bridge.setBlock(world, i + 34, j + 1, k + 21, stone());
	bridge.setBlock(world, i + 34, j + 1, k + 22, stone());
	bridge.setBlock(world, i + 34, j + 1, k + 23, stone());
	bridge.setBlock(world, i + 34, j + 1, k + 24, stone());
	bridge.setBlock(world, i + 34, j + 1, k + 25, stone());
	bridge.setBlock(world, i + 34, j + 1, k + 26, stone());
	bridge.setBlock(world, i + 34, j + 1, k + 27, stone());
	bridge.setBlock(world, i + 34, j + 1, k + 28, stone());
	bridge.setBlock(world, i + 34, j + 2, k + 3, stone());
	bridge.setBlock(world, i + 34, j + 2, k + 4, stone());
	bridge.setBlock(world, i + 34, j + 2, k + 5, stone());
	bridge.setBlock(world, i + 34, j + 2, k + 6, stone());
	bridge.setBlock(world, i + 34, j + 2, k + 7, stone());
	bridge.setBlock(world, i + 34, j + 2, k + 8, stone());
	bridge.setBlock(world, i + 34, j + 2, k + 9, stone());
	bridge.setBlock(world, i + 34, j + 2, k + 14, stone());
	bridge.setBlock(world, i + 34, j + 2, k + 15, stone());
	bridge.setBlock(world, i + 34, j + 2, k + 16, stone());
	bridge.setBlock(world, i + 34, j + 2, k + 17, stone());
	bridge.setBlock(world, i + 34, j + 2, k + 18, Blocks.AIR);
	bridge.setBlock(world, i + 34, j + 2, k + 19, Blocks.AIR);
	bridge.setBlock(world, i + 34, j + 2, k + 20, Blocks.AIR);
	bridge.setBlock(world, i + 34, j + 2, k + 21, Blocks.AIR);
	bridge.setBlock(world, i + 34, j + 2, k + 22, stone());
	bridge.setBlock(world, i + 34, j + 2, k + 23, stone());
	bridge.setBlock(world, i + 34, j + 2, k + 24, stone());
	bridge.setBlock(world, i + 34, j + 2, k + 25, stone());
	bridge.setBlock(world, i + 34, j + 2, k + 26, stone());
	bridge.setBlock(world, i + 34, j + 2, k + 27, stone());
	bridge.setBlock(world, i + 34, j + 2, k + 28, stone());
	bridge.setBlock(world, i + 34, j + 3, k + 3, stone());
	bridge.setBlock(world, i + 34, j + 3, k + 4, stone());
	bridge.setBlock(world, i + 34, j + 3, k + 8, Blocks.AIR);
	bridge.setBlock(world, i + 34, j + 3, k + 9, Blocks.AIR);
	bridge.setBlock(world, i + 34, j + 3, k + 10, Blocks.AIR);
	bridge.setBlock(world, i + 34, j + 3, k + 11, Blocks.AIR);
	bridge.setBlock(world, i + 34, j + 3, k + 12, Blocks.AIR);
	bridge.setBlock(world, i + 34, j + 3, k + 13, Blocks.AIR);
	bridge.setBlock(world, i + 34, j + 3, k + 14, stone());
	bridge.setBlock(world, i + 34, j + 3, k + 15, stone());
	bridge.setBlock(world, i + 34, j + 3, k + 16, stone());
	bridge.setBlock(world, i + 34, j + 3, k + 22, stone());
	bridge.setBlock(world, i + 34, j + 3, k + 23, stone());
	bridge.setBlock(world, i + 34, j + 3, k + 24, stone());
	bridge.setBlock(world, i + 34, j + 3, k + 25, stone());
	bridge.setBlock(world, i + 34, j + 3, k + 26, stone());
	bridge.setBlock(world, i + 34, j + 3, k + 27, stone());
	bridge.setBlock(world, i + 34, j + 3, k + 28, stone());
	bridge.setBlock(world, i + 34, j + 4, k + 3, stone());
	bridge.setBlock(world, i + 34, j + 4, k + 4, stone());
	bridge.setBlock(world, i + 34, j + 4, k + 8, Blocks.AIR);
	bridge.setBlock(world, i + 34, j + 4, k + 9, Blocks.AIR);
	bridge.setBlock(world, i + 34, j + 4, k + 13, Blocks.AIR);
	bridge.setBlock(world, i + 34, j + 4, k + 14, stone());
	bridge.setBlock(world, i + 34, j + 4, k + 15, stone());
	bridge.setBlock(world, i + 34, j + 4, k + 23, stone());
	bridge.setBlock(world, i + 34, j + 4, k + 24, stone());
	bridge.setBlock(world, i + 34, j + 4, k + 25, stone());
	bridge.setBlock(world, i + 34, j + 4, k + 26, stone());
	bridge.setBlock(world, i + 34, j + 4, k + 27, stone());
	bridge.setBlock(world, i + 34, j + 4, k + 28, stone());
	bridge.setBlock(world, i + 34, j + 5, k + 3, stone());
	bridge.setBlock(world, i + 34, j + 5, k + 4, stone());
	bridge.setBlock(world, i + 34, j + 5, k + 13, Blocks.AIR);
	bridge.setBlock(world, i + 34, j + 5, k + 14, stone());
	bridge.setBlock(world, i + 34, j + 5, k + 15, stone());
	bridge.setBlock(world, i + 34, j + 5, k + 23, stone());
	bridge.setBlock(world, i + 34, j + 5, k + 24, stone());
	bridge.setBlock(world, i + 34, j + 5, k + 25, stone());
	bridge.setBlock(world, i + 34, j + 5, k + 26, stone());
	bridge.setBlock(world, i + 34, j + 5, k + 27, stone());
	bridge.setBlock(world, i + 34, j + 5, k + 28, stone());
	bridge.setBlock(world, i + 34, j + 6, k + 4, stone());
	bridge.setBlock(world, i + 34, j + 6, k + 5, stone());
	bridge.setBlock(world, i + 34, j + 6, k + 13, Blocks.AIR);
	bridge.setBlock(world, i + 34, j + 6, k + 14, stone());
	bridge.setBlock(world, i + 34, j + 6, k + 15, stone());
	bridge.setBlock(world, i + 34, j + 6, k + 23, stone());
	bridge.setBlock(world, i + 34, j + 6, k + 24, stone());
	bridge.setBlock(world, i + 34, j + 6, k + 25, stone());
	bridge.setBlock(world, i + 34, j + 6, k + 26, stone());
	bridge.setBlock(world, i + 34, j + 6, k + 27, stone());
	bridge.setBlock(world, i + 34, j + 6, k + 28, stone());
	bridge.setBlock(world, i + 34, j + 7, k + 5, stone());
	bridge.setBlock(world, i + 34, j + 7, k + 6, stone());
	bridge.setBlock(world, i + 34, j + 7, k + 13, Blocks.AIR);
	bridge.setBlock(world, i + 34, j + 7, k + 14, stone());
	bridge.setBlock(world, i + 34, j + 7, k + 15, stone());
	bridge.setBlock(world, i + 34, j + 7, k + 16, stone());
	bridge.setBlock(world, i + 34, j + 7, k + 24, stone());
	bridge.setBlock(world, i + 34, j + 7, k + 25, stone());
	bridge.setBlock(world, i + 34, j + 7, k + 26, stone());
	bridge.setBlock(world, i + 34, j + 7, k + 27, JungleBlocks.ancientMossyBlock);
	bridge.setBlock(world, i + 34, j + 7, k + 28, stone());
	bridge.setBlock(world, i + 34, j + 8, k + 5, stone());
	bridge.setBlock(world, i + 34, j + 8, k + 6, stone());
	bridge.setBlock(world, i + 34, j + 8, k + 7, Blocks.AIR);
	bridge.setBlock(world, i + 34, j + 8, k + 13, Blocks.AIR);
	bridge.setBlock(world, i + 34, j + 8, k + 14, stone());
	bridge.setBlock(world, i + 34, j + 8, k + 15, stone());
	bridge.setBlock(world, i + 34, j + 8, k + 16, stone());
	bridge.setBlock(world, i + 34, j + 8, k + 24, stone());
	bridge.setBlock(world, i + 34, j + 8, k + 25, stone());
	bridge.setBlock(world, i + 34, j + 8, k + 26, JungleBlocks.ancientMossyBlock);
	bridge.setBlock(world, i + 34, j + 8, k + 27, stone());
	bridge.setBlock(world, i + 34, j + 8, k + 28, stone());
	bridge.setBlock(world, i + 34, j + 9, k + 6, stone());
	bridge.setBlock(world, i + 34, j + 9, k + 7, stone());
	bridge.setBlock(world, i + 34, j + 9, k + 12, Blocks.AIR);
	bridge.setBlock(world, i + 34, j + 9, k + 13, stone());
	bridge.setBlock(world, i + 34, j + 9, k + 14, stone());
	bridge.setBlock(world, i + 34, j + 9, k + 15, stone());
	bridge.setBlock(world, i + 34, j + 9, k + 16, stone());
	bridge.setBlock(world, i + 34, j + 9, k + 17, stone());
	bridge.setBlock(world, i + 34, j + 9, k + 24, stone());
	bridge.setBlock(world, i + 34, j + 9, k + 25, JungleBlocks.ancientMossyBlock);
	bridge.setBlock(world, i + 34, j + 9, k + 26, stone());
	bridge.setBlock(world, i + 34, j + 9, k + 27, stone());
	bridge.setBlock(world, i + 34, j + 10, k + 6, stone());
	bridge.setBlock(world, i + 34, j + 10, k + 7, stone());
	bridge.setBlock(world, i + 34, j + 10, k + 8, stone());
	bridge.setBlock(world, i + 34, j + 10, k + 9, stone());
	bridge.setBlock(world, i + 34, j + 10, k + 10, Blocks.AIR);
	bridge.setBlock(world, i + 34, j + 10, k + 11, stone());
	bridge.setBlock(world, i + 34, j + 10, k + 12, stone());
	bridge.setBlock(world, i + 34, j + 10, k + 13, stone());
	bridge.setBlock(world, i + 34, j + 10, k + 14, stone());
	bridge.setBlock(world, i + 34, j + 10, k + 15, stone());
	bridge.setBlock(world, i + 34, j + 10, k + 16, stone());
	bridge.setBlock(world, i + 34, j + 10, k + 17, stone());
	bridge.setBlock(world, i + 34, j + 10, k + 18, stone());
	bridge.setBlock(world, i + 34, j + 10, k + 23, stone());
	bridge.setBlock(world, i + 34, j + 10, k + 24, JungleBlocks.ancientMossyBlock);
	bridge.setBlock(world, i + 34, j + 10, k + 25, JungleBlocks.mossystairs, 3, 2);
	bridge.setBlock(world, i + 34, j + 11, k + 6, stone());
	bridge.setBlock(world, i + 34, j + 11, k + 7, stone());
	bridge.setBlock(world, i + 34, j + 11, k + 8, stone());
	bridge.setBlock(world, i + 34, j + 11, k + 9, stone());
	bridge.setBlock(world, i + 34, j + 11, k + 10, stone());
	bridge.setBlock(world, i + 34, j + 11, k + 11, stone());
	bridge.setBlock(world, i + 34, j + 11, k + 12, stone());
	bridge.setBlock(world, i + 34, j + 11, k + 13, stone());
	bridge.setBlock(world, i + 34, j + 11, k + 14, stone());
	bridge.setBlock(world, i + 34, j + 11, k + 15, stone());
	bridge.setBlock(world, i + 34, j + 11, k + 16, stone());
	bridge.setBlock(world, i + 34, j + 11, k + 17, stone());
	bridge.setBlock(world, i + 34, j + 11, k + 18, stone());
	bridge.setBlock(world, i + 34, j + 11, k + 19, stone());
	bridge.setBlock(world, i + 34, j + 11, k + 20, stone());
	bridge.setBlock(world, i + 34, j + 11, k + 21, stone());
	bridge.setBlock(world, i + 34, j + 11, k + 22, stone());
	bridge.setBlock(world, i + 34, j + 11, k + 23, JungleBlocks.ancientMossyBlock);
	bridge.setBlock(world, i + 34, j + 11, k + 24, JungleBlocks.mossystairs, 3, 2);
	bridge.setBlock(world, i + 34, j + 12, k + 7, this.blockRandom(null), 2, 2);
	bridge.setBlock(world, i + 34, j + 12, k + 8, JungleBlocks.ancientMossyBlock);
	bridge.setBlock(world, i + 34, j + 12, k + 9, JungleBlocks.ancientMossyBlock);
	bridge.setBlock(world, i + 34, j + 12, k + 10, JungleBlocks.ancientMossyBlock);
	bridge.setBlock(world, i + 34, j + 12, k + 11, JungleBlocks.ancientMossyBlock);
	bridge.setBlock(world, i + 34, j + 12, k + 12, JungleBlocks.ancientMossyBlock);
	bridge.setBlock(world, i + 34, j + 12, k + 13, JungleBlocks.ancientMossyBlock);
	bridge.setBlock(world, i + 34, j + 12, k + 14, JungleBlocks.ancientMossyBlock);
	bridge.setBlock(world, i + 34, j + 12, k + 15, JungleBlocks.ancientMossyBlock);
	bridge.setBlock(world, i + 34, j + 12, k + 16, JungleBlocks.ancientMossyBlock);
	bridge.setBlock(world, i + 34, j + 12, k + 17, JungleBlocks.ancientMossyBlock);
	bridge.setBlock(world, i + 34, j + 12, k + 18, JungleBlocks.ancientMossyBlock);
	bridge.setBlock(world, i + 34, j + 12, k + 19, JungleBlocks.ancientMossyBlock);
	bridge.setBlock(world, i + 34, j + 12, k + 20, JungleBlocks.ancientMossyBlock);
	bridge.setBlock(world, i + 34, j + 12, k + 21, JungleBlocks.ancientMossyBlock);
	bridge.setBlock(world, i + 34, j + 12, k + 23, JungleBlocks.mossystairs, 3, 2);
	bridge.setBlock(world, i + 34, j + 13, k + 8, JungleBlocks.ancientMossyBlock);
	bridge.setBlock(world, i + 34, j + 13, k + 9, this.blockRandom(null), 1, 2);
	bridge.setBlock(world, i + 34, j + 13, k + 10, JungleBlocks.mossystairs, 1, 2);
	bridge.setBlock(world, i + 34, j + 13, k + 11, JungleBlocks.mossystairs, 1, 2);
	bridge.setBlock(world, i + 34, j + 13, k + 12, JungleBlocks.mossystairs, 1, 2);
	bridge.setBlock(world, i + 34, j + 13, k + 13, this.blockRandom(null), 1, 2);
	bridge.setBlock(world, i + 34, j + 13, k + 14, this.blockRandom(null), 1, 2);
	bridge.setBlock(world, i + 34, j + 13, k + 15, this.blockRandom(null), 1, 2);
	bridge.setBlock(world, i + 34, j + 13, k + 16, JungleBlocks.mossystairs, 1, 2);
	bridge.setBlock(world, i + 34, j + 13, k + 17, this.blockRandom(null), 1, 2);
	bridge.setBlock(world, i + 34, j + 13, k + 18, JungleBlocks.mossystairs, 1, 2);
	bridge.setBlock(world, i + 34, j + 13, k + 19, JungleBlocks.mossystairs, 1, 2);
	bridge.setBlock(world, i + 34, j + 13, k + 20, this.blockRandom(null), 1, 2);
	bridge.setBlock(world, i + 34, j + 13, k + 21, JungleBlocks.mossystairs, 1, 2);
	bridge.setBlock(world, i + 35, j + 0, k + 3, stone());
	bridge.setBlock(world, i + 35, j + 0, k + 4, stone());
	bridge.setBlock(world, i + 35, j + 0, k + 5, stone());
	bridge.setBlock(world, i + 35, j + 0, k + 6, stone());
	bridge.setBlock(world, i + 35, j + 0, k + 7, stone());
	bridge.setBlock(world, i + 35, j + 0, k + 8, stone());
	bridge.setBlock(world, i + 35, j + 0, k + 9, stone());
	bridge.setBlock(world, i + 35, j + 0, k + 10, stone());
	bridge.setBlock(world, i + 35, j + 0, k + 11, stone());
	bridge.setBlock(world, i + 35, j + 0, k + 12, stone());
	bridge.setBlock(world, i + 35, j + 0, k + 13, stone());
	bridge.setBlock(world, i + 35, j + 0, k + 14, stone());
	bridge.setBlock(world, i + 35, j + 0, k + 15, stone());
	bridge.setBlock(world, i + 35, j + 0, k + 16, stone());
	bridge.setBlock(world, i + 35, j + 0, k + 17, stone());
	bridge.setBlock(world, i + 35, j + 0, k + 18, stone());
	bridge.setBlock(world, i + 35, j + 0, k + 19, stone());
	bridge.setBlock(world, i + 35, j + 0, k + 20, stone());
	bridge.setBlock(world, i + 35, j + 0, k + 21, stone());
	bridge.setBlock(world, i + 35, j + 0, k + 22, stone());
	bridge.setBlock(world, i + 35, j + 0, k + 23, stone());
	bridge.setBlock(world, i + 35, j + 0, k + 24, stone());
	bridge.setBlock(world, i + 35, j + 0, k + 25, stone());
	bridge.setBlock(world, i + 35, j + 0, k + 26, stone());
	bridge.setBlock(world, i + 35, j + 0, k + 27, stone());
	bridge.setBlock(world, i + 35, j + 0, k + 28, stone());
	bridge.setBlock(world, i + 35, j + 1, k + 3, stone());
	bridge.setBlock(world, i + 35, j + 1, k + 4, stone());
	bridge.setBlock(world, i + 35, j + 1, k + 5, stone());
	bridge.setBlock(world, i + 35, j + 1, k + 6, stone());
	bridge.setBlock(world, i + 35, j + 1, k + 7, stone());
	bridge.setBlock(world, i + 35, j + 1, k + 8, stone());
	bridge.setBlock(world, i + 35, j + 1, k + 9, stone());
	bridge.setBlock(world, i + 35, j + 1, k + 10, stone());
	bridge.setBlock(world, i + 35, j + 1, k + 11, stone());
	bridge.setBlock(world, i + 35, j + 1, k + 12, stone());
	bridge.setBlock(world, i + 35, j + 1, k + 13, stone());
	bridge.setBlock(world, i + 35, j + 1, k + 14, stone());
	bridge.setBlock(world, i + 35, j + 1, k + 15, stone());
	bridge.setBlock(world, i + 35, j + 1, k + 16, stone());
	bridge.setBlock(world, i + 35, j + 1, k + 17, stone());
	bridge.setBlock(world, i + 35, j + 1, k + 18, stone());
	bridge.setBlock(world, i + 35, j + 1, k + 19, stone());
	bridge.setBlock(world, i + 35, j + 1, k + 20, stone());
	bridge.setBlock(world, i + 35, j + 1, k + 21, stone());
	bridge.setBlock(world, i + 35, j + 1, k + 22, stone());
	bridge.setBlock(world, i + 35, j + 1, k + 23, stone());
	bridge.setBlock(world, i + 35, j + 1, k + 24, stone());
	bridge.setBlock(world, i + 35, j + 1, k + 25, stone());
	bridge.setBlock(world, i + 35, j + 1, k + 26, stone());
	bridge.setBlock(world, i + 35, j + 1, k + 27, stone());
	bridge.setBlock(world, i + 35, j + 1, k + 28, stone());
	bridge.setBlock(world, i + 35, j + 1, k + 29, stone());
	bridge.setBlock(world, i + 35, j + 2, k + 3, stone());
	bridge.setBlock(world, i + 35, j + 2, k + 4, stone());
	bridge.setBlock(world, i + 35, j + 2, k + 5, stone());
	bridge.setBlock(world, i + 35, j + 2, k + 6, stone());
	bridge.setBlock(world, i + 35, j + 2, k + 7, stone());
	bridge.setBlock(world, i + 35, j + 2, k + 8, stone());
	bridge.setBlock(world, i + 35, j + 2, k + 9, stone());
	bridge.setBlock(world, i + 35, j + 2, k + 10, stone());
	bridge.setBlock(world, i + 35, j + 2, k + 11, stone());
	bridge.setBlock(world, i + 35, j + 2, k + 12, stone());
	bridge.setBlock(world, i + 35, j + 2, k + 13, stone());
	bridge.setBlock(world, i + 35, j + 2, k + 14, stone());
	bridge.setBlock(world, i + 35, j + 2, k + 15, stone());
	bridge.setBlock(world, i + 35, j + 2, k + 16, stone());
	bridge.setBlock(world, i + 35, j + 2, k + 17, stone());
	bridge.setBlock(world, i + 35, j + 2, k + 18, Blocks.AIR);
	bridge.setBlock(world, i + 35, j + 2, k + 19, Blocks.AIR);
	bridge.setBlock(world, i + 35, j + 2, k + 20, Blocks.AIR);
	bridge.setBlock(world, i + 35, j + 2, k + 21, Blocks.AIR);
	bridge.setBlock(world, i + 35, j + 2, k + 22, Blocks.AIR);
	bridge.setBlock(world, i + 35, j + 2, k + 23, stone());
	bridge.setBlock(world, i + 35, j + 2, k + 24, stone());
	bridge.setBlock(world, i + 35, j + 2, k + 25, stone());
	bridge.setBlock(world, i + 35, j + 2, k + 26, stone());
	bridge.setBlock(world, i + 35, j + 2, k + 27, stone());
	bridge.setBlock(world, i + 35, j + 2, k + 28, stone());
	bridge.setBlock(world, i + 35, j + 2, k + 29, stone());
	bridge.setBlock(world, i + 35, j + 3, k + 3, stone());
	bridge.setBlock(world, i + 35, j + 3, k + 4, stone());
	bridge.setBlock(world, i + 35, j + 3, k + 9, Blocks.AIR);
	bridge.setBlock(world, i + 35, j + 3, k + 10, Blocks.AIR);
	bridge.setBlock(world, i + 35, j + 3, k + 11, Blocks.AIR);
	bridge.setBlock(world, i + 35, j + 3, k + 12, Blocks.AIR);
	bridge.setBlock(world, i + 35, j + 3, k + 13, Blocks.AIR);
	bridge.setBlock(world, i + 35, j + 3, k + 14, Blocks.AIR);
	bridge.setBlock(world, i + 35, j + 3, k + 15, stone());
	bridge.setBlock(world, i + 35, j + 3, k + 23, stone());
	bridge.setBlock(world, i + 35, j + 3, k + 24, stone());
	bridge.setBlock(world, i + 35, j + 3, k + 25, stone());
	bridge.setBlock(world, i + 35, j + 3, k + 26, stone());
	bridge.setBlock(world, i + 35, j + 3, k + 27, stone());
	bridge.setBlock(world, i + 35, j + 3, k + 28, stone());
	bridge.setBlock(world, i + 35, j + 3, k + 29, stone());
	bridge.setBlock(world, i + 35, j + 4, k + 3, stone());
	bridge.setBlock(world, i + 35, j + 4, k + 4, stone());
	bridge.setBlock(world, i + 35, j + 4, k + 13, Blocks.AIR);
	bridge.setBlock(world, i + 35, j + 4, k + 14, Blocks.AIR);
	bridge.setBlock(world, i + 35, j + 4, k + 24, stone());
	bridge.setBlock(world, i + 35, j + 4, k + 25, stone());
	bridge.setBlock(world, i + 35, j + 4, k + 26, stone());
	bridge.setBlock(world, i + 35, j + 4, k + 27, stone());
	bridge.setBlock(world, i + 35, j + 4, k + 28, stone());
	bridge.setBlock(world, i + 35, j + 4, k + 29, stone());
	bridge.setBlock(world, i + 35, j + 5, k + 3, stone());
	bridge.setBlock(world, i + 35, j + 5, k + 4, stone());
	bridge.setBlock(world, i + 35, j + 5, k + 13, Blocks.AIR);
	bridge.setBlock(world, i + 35, j + 5, k + 14, Blocks.AIR);
	bridge.setBlock(world, i + 35, j + 5, k + 15, stone());
	bridge.setBlock(world, i + 35, j + 5, k + 24, stone());
	bridge.setBlock(world, i + 35, j + 5, k + 25, stone());
	bridge.setBlock(world, i + 35, j + 5, k + 26, stone());
	bridge.setBlock(world, i + 35, j + 5, k + 27, stone());
	bridge.setBlock(world, i + 35, j + 5, k + 28, stone());
	bridge.setBlock(world, i + 35, j + 5, k + 29, stone());
	bridge.setBlock(world, i + 35, j + 6, k + 3, stone());
	bridge.setBlock(world, i + 35, j + 6, k + 4, stone());
	bridge.setBlock(world, i + 35, j + 6, k + 5, stone());
	bridge.setBlock(world, i + 35, j + 6, k + 13, Blocks.AIR);
	bridge.setBlock(world, i + 35, j + 6, k + 14, stone());
	bridge.setBlock(world, i + 35, j + 6, k + 15, stone());
	bridge.setBlock(world, i + 35, j + 6, k + 24, stone());
	bridge.setBlock(world, i + 35, j + 6, k + 25, stone());
	bridge.setBlock(world, i + 35, j + 6, k + 26, stone());
	bridge.setBlock(world, i + 35, j + 6, k + 27, stone());
	bridge.setBlock(world, i + 35, j + 6, k + 28, stone());
	bridge.setBlock(world, i + 35, j + 7, k + 4, stone());
	bridge.setBlock(world, i + 35, j + 7, k + 5, stone());
	bridge.setBlock(world, i + 35, j + 7, k + 6, stone());
	bridge.setBlock(world, i + 35, j + 7, k + 13, Blocks.AIR);
	bridge.setBlock(world, i + 35, j + 7, k + 14, stone());
	bridge.setBlock(world, i + 35, j + 7, k + 15, stone());
	bridge.setBlock(world, i + 35, j + 7, k + 16, stone());
	bridge.setBlock(world, i + 35, j + 7, k + 24, stone());
	bridge.setBlock(world, i + 35, j + 7, k + 25, stone());
	bridge.setBlock(world, i + 35, j + 7, k + 26, stone());
	bridge.setBlock(world, i + 35, j + 7, k + 27, JungleBlocks.ancientMossyBlock);
	bridge.setBlock(world, i + 35, j + 7, k + 28, stone());
	bridge.setBlock(world, i + 35, j + 8, k + 4, stone());
	bridge.setBlock(world, i + 35, j + 8, k + 5, stone());
	bridge.setBlock(world, i + 35, j + 8, k + 6, stone());
	bridge.setBlock(world, i + 35, j + 8, k + 7, stone());
	bridge.setBlock(world, i + 35, j + 8, k + 12, Blocks.AIR);
	bridge.setBlock(world, i + 35, j + 8, k + 13, stone());
	bridge.setBlock(world, i + 35, j + 8, k + 14, stone());
	bridge.setBlock(world, i + 35, j + 8, k + 15, stone());
	bridge.setBlock(world, i + 35, j + 8, k + 16, stone());
	bridge.setBlock(world, i + 35, j + 8, k + 17, stone());
	bridge.setBlock(world, i + 35, j + 8, k + 24, stone());
	bridge.setBlock(world, i + 35, j + 8, k + 25, stone());
	bridge.setBlock(world, i + 35, j + 8, k + 26, JungleBlocks.ancientMossyBlock);
	bridge.setBlock(world, i + 35, j + 8, k + 27, stone());
	bridge.setBlock(world, i + 35, j + 8, k + 28, stone());
	bridge.setBlock(world, i + 35, j + 9, k + 5, stone());
	bridge.setBlock(world, i + 35, j + 9, k + 6, stone());
	bridge.setBlock(world, i + 35, j + 9, k + 7, stone());
	bridge.setBlock(world, i + 35, j + 9, k + 8, stone());
	bridge.setBlock(world, i + 35, j + 9, k + 10, Blocks.AIR);
	bridge.setBlock(world, i + 35, j + 9, k + 11, Blocks.AIR);
	bridge.setBlock(world, i + 35, j + 9, k + 12, stone());
	bridge.setBlock(world, i + 35, j + 9, k + 13, stone());
	bridge.setBlock(world, i + 35, j + 9, k + 14, stone());
	bridge.setBlock(world, i + 35, j + 9, k + 15, stone());
	bridge.setBlock(world, i + 35, j + 9, k + 16, stone());
	bridge.setBlock(world, i + 35, j + 9, k + 17, stone());
	bridge.setBlock(world, i + 35, j + 9, k + 18, stone());
	bridge.setBlock(world, i + 35, j + 9, k + 23, stone());
	bridge.setBlock(world, i + 35, j + 9, k + 24, stone());
	bridge.setBlock(world, i + 35, j + 9, k + 25, JungleBlocks.ancientMossyBlock);
	bridge.setBlock(world, i + 35, j + 9, k + 26, JungleBlocks.mossystairs, 3, 2);
	bridge.setBlock(world, i + 35, j + 10, k + 5, stone());
	bridge.setBlock(world, i + 35, j + 10, k + 6, JungleBlocks.ancientMossyBlock);
	bridge.setBlock(world, i + 35, j + 10, k + 7, stone());
	bridge.setBlock(world, i + 35, j + 10, k + 8, stone());
	bridge.setBlock(world, i + 35, j + 10, k + 9, stone());
	bridge.setBlock(world, i + 35, j + 10, k + 10, stone());
	bridge.setBlock(world, i + 35, j + 10, k + 11, stone());
	bridge.setBlock(world, i + 35, j + 10, k + 12, stone());
	bridge.setBlock(world, i + 35, j + 10, k + 13, stone());
	bridge.setBlock(world, i + 35, j + 10, k + 14, stone());
	bridge.setBlock(world, i + 35, j + 10, k + 15, stone());
	bridge.setBlock(world, i + 35, j + 10, k + 16, stone());
	bridge.setBlock(world, i + 35, j + 10, k + 17, stone());
	bridge.setBlock(world, i + 35, j + 10, k + 18, JungleBlocks.ancientMossyBlock);
	bridge.setBlock(world, i + 35, j + 10, k + 19, stone());
	bridge.setBlock(world, i + 35, j + 10, k + 20, stone());
	bridge.setBlock(world, i + 35, j + 10, k + 21, stone());
	bridge.setBlock(world, i + 35, j + 10, k + 22, stone());
	bridge.setBlock(world, i + 35, j + 10, k + 23, stone());
	bridge.setBlock(world, i + 35, j + 10, k + 25, JungleBlocks.mossystairs, 3, 2);
	bridge.setBlock(world, i + 35, j + 11, k + 6, this.blockRandom(null), 2, 2);
	bridge.setBlock(world, i + 35, j + 11, k + 7, JungleBlocks.ancientMossyBlock);
	bridge.setBlock(world, i + 35, j + 11, k + 8, JungleBlocks.ancientMossyBlock);
	bridge.setBlock(world, i + 35, j + 11, k + 9, JungleBlocks.ancientMossyBlock);
	bridge.setBlock(world, i + 35, j + 11, k + 10, JungleBlocks.ancientMossyBlock);
	bridge.setBlock(world, i + 35, j + 11, k + 11, JungleBlocks.ancientMossyBlock);
	bridge.setBlock(world, i + 35, j + 11, k + 12, JungleBlocks.ancientMossyBlock);
	bridge.setBlock(world, i + 35, j + 11, k + 13, JungleBlocks.ancientMossyBlock);
	bridge.setBlock(world, i + 35, j + 11, k + 14, JungleBlocks.ancientMossyBlock);
	bridge.setBlock(world, i + 35, j + 11, k + 15, JungleBlocks.ancientMossyBlock);
	bridge.setBlock(world, i + 35, j + 11, k + 16, JungleBlocks.ancientMossyBlock);
	bridge.setBlock(world, i + 35, j + 11, k + 17, JungleBlocks.ancientMossyBlock);
	bridge.setBlock(world, i + 35, j + 11, k + 18, JungleBlocks.ancientMossyBlock);
	bridge.setBlock(world, i + 35, j + 11, k + 19, JungleBlocks.ancientMossyBlock);
	bridge.setBlock(world, i + 35, j + 11, k + 20, JungleBlocks.ancientMossyBlock);
	bridge.setBlock(world, i + 35, j + 11, k + 21, JungleBlocks.ancientMossyBlock);
	bridge.setBlock(world, i + 35, j + 11, k + 22, JungleBlocks.ancientMossyBlock);
	bridge.setBlock(world, i + 35, j + 12, k + 7, this.blockRandom(null), 1, 2);
	bridge.setBlock(world, i + 35, j + 12, k + 8, JungleBlocks.mossystairs, 1, 2);
	bridge.setBlock(world, i + 35, j + 12, k + 9, JungleBlocks.mossystairs, 1, 2);
	bridge.setBlock(world, i + 35, j + 12, k + 10, JungleBlocks.mossystairs, 1, 2);
	bridge.setBlock(world, i + 35, j + 12, k + 11, this.blockRandom(null), 1, 2);
	bridge.setBlock(world, i + 35, j + 12, k + 12, JungleBlocks.ancientMossyBlock);
	bridge.setBlock(world, i + 35, j + 12, k + 13, this.blockRandom(null), 1, 2);
	bridge.setBlock(world, i + 35, j + 12, k + 14, this.blockRandom(null), 1, 2);
	bridge.setBlock(world, i + 35, j + 12, k + 15, JungleBlocks.mossystairs, 1, 2);
	bridge.setBlock(world, i + 35, j + 12, k + 16, JungleBlocks.mossystairs, 1, 2);
	bridge.setBlock(world, i + 35, j + 12, k + 17, this.blockRandom(null), 1, 2);
	bridge.setBlock(world, i + 35, j + 12, k + 18, JungleBlocks.ancientMossyBlock);
	bridge.setBlock(world, i + 35, j + 12, k + 19, this.blockRandom(null), 1, 2);
	bridge.setBlock(world, i + 35, j + 12, k + 20, this.blockRandom(null), 1, 2);
	bridge.setBlock(world, i + 35, j + 12, k + 21, JungleBlocks.mossystairs, 1, 2);
	bridge.setBlock(world, i + 35, j + 13, k + 12, JungleBlocks.ancientMossyBlock);
	bridge.setBlock(world, i + 35, j + 13, k + 18, Blocks.COBBLESTONE_WALL, 1, 2);
	bridge.setBlock(world, i + 35, j + 14, k + 12, Blocks.COBBLESTONE_WALL, 1, 2);
	bridge.setBlock(world, i + 35, j + 14, k + 18, Blocks.COBBLESTONE_WALL, 1, 2);
	bridge.setBlock(world, i + 35, j + 15, k + 12, Blocks.COBBLESTONE_WALL, 1, 2);
	bridge.setBlock(world, i + 35, j + 15, k + 18, this.blockRandom(null));
	bridge.setBlock(world, i + 35, j + 16, k + 12, this.blockRandom(null));
	bridge.setBlock(world, i + 36, j + 0, k + 1, stone());
	bridge.setBlock(world, i + 36, j + 0, k + 2, stone());
	bridge.setBlock(world, i + 36, j + 0, k + 3, stone());
	bridge.setBlock(world, i + 36, j + 0, k + 4, stone());
	bridge.setBlock(world, i + 36, j + 0, k + 5, stone());
	bridge.setBlock(world, i + 36, j + 0, k + 6, stone());
	bridge.setBlock(world, i + 36, j + 0, k + 7, stone());
	bridge.setBlock(world, i + 36, j + 0, k + 8, stone());
	bridge.setBlock(world, i + 36, j + 0, k + 9, stone());
	bridge.setBlock(world, i + 36, j + 0, k + 10, stone());
	bridge.setBlock(world, i + 36, j + 0, k + 11, stone());
	bridge.setBlock(world, i + 36, j + 0, k + 12, stone());
	bridge.setBlock(world, i + 36, j + 0, k + 13, stone());
	bridge.setBlock(world, i + 36, j + 0, k + 14, stone());
	bridge.setBlock(world, i + 36, j + 0, k + 15, stone());
	bridge.setBlock(world, i + 36, j + 0, k + 16, stone());
	bridge.setBlock(world, i + 36, j + 0, k + 17, stone());
	bridge.setBlock(world, i + 36, j + 0, k + 18, stone());
	bridge.setBlock(world, i + 36, j + 0, k + 19, stone());
	bridge.setBlock(world, i + 36, j + 0, k + 20, stone());
	bridge.setBlock(world, i + 36, j + 0, k + 21, stone());
	bridge.setBlock(world, i + 36, j + 0, k + 22, stone());
	bridge.setBlock(world, i + 36, j + 0, k + 23, stone());
	bridge.setBlock(world, i + 36, j + 0, k + 24, stone());
	bridge.setBlock(world, i + 36, j + 0, k + 25, stone());
	bridge.setBlock(world, i + 36, j + 0, k + 26, stone());
	bridge.setBlock(world, i + 36, j + 0, k + 27, stone());
	bridge.setBlock(world, i + 36, j + 0, k + 28, stone());
	bridge.setBlock(world, i + 36, j + 0, k + 29, stone());
	bridge.setBlock(world, i + 36, j + 1, k + 1, stone());
	bridge.setBlock(world, i + 36, j + 1, k + 2, stone());
	bridge.setBlock(world, i + 36, j + 1, k + 3, stone());
	bridge.setBlock(world, i + 36, j + 1, k + 4, stone());
	bridge.setBlock(world, i + 36, j + 1, k + 5, stone());
	bridge.setBlock(world, i + 36, j + 1, k + 6, stone());
	bridge.setBlock(world, i + 36, j + 1, k + 7, stone());
	bridge.setBlock(world, i + 36, j + 1, k + 8, stone());
	bridge.setBlock(world, i + 36, j + 1, k + 9, stone());
	bridge.setBlock(world, i + 36, j + 1, k + 10, stone());
	bridge.setBlock(world, i + 36, j + 1, k + 11, stone());
	bridge.setBlock(world, i + 36, j + 1, k + 12, stone());
	bridge.setBlock(world, i + 36, j + 1, k + 13, stone());
	bridge.setBlock(world, i + 36, j + 1, k + 14, stone());
	bridge.setBlock(world, i + 36, j + 1, k + 15, stone());
	bridge.setBlock(world, i + 36, j + 1, k + 16, stone());
	bridge.setBlock(world, i + 36, j + 1, k + 17, stone());
	bridge.setBlock(world, i + 36, j + 1, k + 18, stone());
	bridge.setBlock(world, i + 36, j + 1, k + 22, stone());
	bridge.setBlock(world, i + 36, j + 1, k + 23, stone());
	bridge.setBlock(world, i + 36, j + 1, k + 24, stone());
	bridge.setBlock(world, i + 36, j + 1, k + 25, stone());
	bridge.setBlock(world, i + 36, j + 1, k + 26, stone());
	bridge.setBlock(world, i + 36, j + 1, k + 27, stone());
	bridge.setBlock(world, i + 36, j + 1, k + 28, stone());
	bridge.setBlock(world, i + 36, j + 1, k + 29, stone());
	bridge.setBlock(world, i + 36, j + 2, k + 1, stone());
	bridge.setBlock(world, i + 36, j + 2, k + 2, stone());
	bridge.setBlock(world, i + 36, j + 2, k + 3, stone());
	bridge.setBlock(world, i + 36, j + 2, k + 4, stone());
	bridge.setBlock(world, i + 36, j + 2, k + 5, stone());
	bridge.setBlock(world, i + 36, j + 2, k + 6, stone());
	bridge.setBlock(world, i + 36, j + 2, k + 7, stone());
	bridge.setBlock(world, i + 36, j + 2, k + 8, stone());
	bridge.setBlock(world, i + 36, j + 2, k + 9, stone());
	bridge.setBlock(world, i + 36, j + 2, k + 10, stone());
	bridge.setBlock(world, i + 36, j + 2, k + 11, stone());
	bridge.setBlock(world, i + 36, j + 2, k + 12, stone());
	bridge.setBlock(world, i + 36, j + 2, k + 13, stone());
	bridge.setBlock(world, i + 36, j + 2, k + 14, stone());
	bridge.setBlock(world, i + 36, j + 2, k + 15, stone());
	bridge.setBlock(world, i + 36, j + 2, k + 16, stone());
	bridge.setBlock(world, i + 36, j + 2, k + 17, stone());
	bridge.setBlock(world, i + 36, j + 2, k + 18, Blocks.AIR);
	bridge.setBlock(world, i + 36, j + 2, k + 19, Blocks.AIR);
	bridge.setBlock(world, i + 36, j + 2, k + 20, Blocks.AIR);
	bridge.setBlock(world, i + 36, j + 2, k + 21, Blocks.AIR);
	bridge.setBlock(world, i + 36, j + 2, k + 22, Blocks.AIR);
	bridge.setBlock(world, i + 36, j + 2, k + 23, Blocks.AIR);
	bridge.setBlock(world, i + 36, j + 2, k + 24, Blocks.AIR);
	bridge.setBlock(world, i + 36, j + 2, k + 25, stone());
	bridge.setBlock(world, i + 36, j + 2, k + 26, stone());
	bridge.setBlock(world, i + 36, j + 2, k + 27, stone());
	bridge.setBlock(world, i + 36, j + 2, k + 28, stone());
	bridge.setBlock(world, i + 36, j + 2, k + 29, stone());
	bridge.setBlock(world, i + 36, j + 3, k + 1, stone());
	bridge.setBlock(world, i + 36, j + 3, k + 2, stone());
	bridge.setBlock(world, i + 36, j + 3, k + 3, stone());
	bridge.setBlock(world, i + 36, j + 3, k + 4, stone());
	bridge.setBlock(world, i + 36, j + 3, k + 5, stone());
	bridge.setBlock(world, i + 36, j + 3, k + 25, stone());
	bridge.setBlock(world, i + 36, j + 3, k + 26, stone());
	bridge.setBlock(world, i + 36, j + 3, k + 27, stone());
	bridge.setBlock(world, i + 36, j + 3, k + 28, stone());
	bridge.setBlock(world, i + 36, j + 3, k + 29, stone());
	bridge.setBlock(world, i + 36, j + 4, k + 1, stone());
	bridge.setBlock(world, i + 36, j + 4, k + 2, stone());
	bridge.setBlock(world, i + 36, j + 4, k + 3, stone());
	bridge.setBlock(world, i + 36, j + 4, k + 4, stone());
	bridge.setBlock(world, i + 36, j + 4, k + 25, stone());
	bridge.setBlock(world, i + 36, j + 4, k + 26, stone());
	bridge.setBlock(world, i + 36, j + 4, k + 27, stone());
	bridge.setBlock(world, i + 36, j + 4, k + 28, stone());
	bridge.setBlock(world, i + 36, j + 4, k + 29, stone());
	bridge.setBlock(world, i + 36, j + 5, k + 1, stone());
	bridge.setBlock(world, i + 36, j + 5, k + 2, stone());
	bridge.setBlock(world, i + 36, j + 5, k + 3, stone());
	bridge.setBlock(world, i + 36, j + 5, k + 4, stone());
	bridge.setBlock(world, i + 36, j + 5, k + 5, stone());
	bridge.setBlock(world, i + 36, j + 5, k + 25, stone());
	bridge.setBlock(world, i + 36, j + 5, k + 26, stone());
	bridge.setBlock(world, i + 36, j + 5, k + 27, stone());
	bridge.setBlock(world, i + 36, j + 5, k + 28, stone());
	bridge.setBlock(world, i + 36, j + 5, k + 29, stone());
	bridge.setBlock(world, i + 36, j + 6, k + 1, stone());
	bridge.setBlock(world, i + 36, j + 6, k + 2, stone());
	bridge.setBlock(world, i + 36, j + 6, k + 3, stone());
	bridge.setBlock(world, i + 36, j + 6, k + 4, stone());
	bridge.setBlock(world, i + 36, j + 6, k + 5, stone());
	bridge.setBlock(world, i + 36, j + 6, k + 13, Blocks.AIR);
	bridge.setBlock(world, i + 36, j + 6, k + 14, Blocks.AIR);
	bridge.setBlock(world, i + 36, j + 6, k + 15, stone());
	bridge.setBlock(world, i + 36, j + 6, k + 24, stone());
	bridge.setBlock(world, i + 36, j + 6, k + 25, stone());
	bridge.setBlock(world, i + 36, j + 6, k + 26, stone());
	bridge.setBlock(world, i + 36, j + 6, k + 27, stone());
	bridge.setBlock(world, i + 36, j + 6, k + 28, stone());
	bridge.setBlock(world, i + 36, j + 7, k + 3, stone());
	bridge.setBlock(world, i + 36, j + 7, k + 4, stone());
	bridge.setBlock(world, i + 36, j + 7, k + 5, stone());
	bridge.setBlock(world, i + 36, j + 7, k + 6, stone());
	bridge.setBlock(world, i + 36, j + 7, k + 11, Blocks.AIR);
	bridge.setBlock(world, i + 36, j + 7, k + 12, Blocks.AIR);
	bridge.setBlock(world, i + 36, j + 7, k + 13, stone());
	bridge.setBlock(world, i + 36, j + 7, k + 14, stone());
	bridge.setBlock(world, i + 36, j + 7, k + 15, stone());
	bridge.setBlock(world, i + 36, j + 7, k + 16, stone());
	bridge.setBlock(world, i + 36, j + 7, k + 24, stone());
	bridge.setBlock(world, i + 36, j + 7, k + 25, stone());
	bridge.setBlock(world, i + 36, j + 7, k + 26, stone());
	bridge.setBlock(world, i + 36, j + 7, k + 27, JungleBlocks.ancientMossyBlock);
	bridge.setBlock(world, i + 36, j + 7, k + 28, stone());
	bridge.setBlock(world, i + 36, j + 8, k + 3, stone());
	bridge.setBlock(world, i + 36, j + 8, k + 4, stone());
	bridge.setBlock(world, i + 36, j + 8, k + 5, stone());
	bridge.setBlock(world, i + 36, j + 8, k + 6, stone());
	bridge.setBlock(world, i + 36, j + 8, k + 7, stone());
	bridge.setBlock(world, i + 36, j + 8, k + 8, stone());
	bridge.setBlock(world, i + 36, j + 8, k + 11, Blocks.AIR);
	bridge.setBlock(world, i + 36, j + 8, k + 12, stone());
	bridge.setBlock(world, i + 36, j + 8, k + 13, stone());
	bridge.setBlock(world, i + 36, j + 8, k + 14, stone());
	bridge.setBlock(world, i + 36, j + 8, k + 15, stone());
	bridge.setBlock(world, i + 36, j + 8, k + 16, stone());
	bridge.setBlock(world, i + 36, j + 8, k + 17, stone());
	bridge.setBlock(world, i + 36, j + 8, k + 23, stone());
	bridge.setBlock(world, i + 36, j + 8, k + 24, stone());
	bridge.setBlock(world, i + 36, j + 8, k + 25, stone());
	bridge.setBlock(world, i + 36, j + 8, k + 26, JungleBlocks.ancientMossyBlock);
	bridge.setBlock(world, i + 36, j + 8, k + 27, JungleBlocks.mossystairs, 3, 2);
	bridge.setBlock(world, i + 36, j + 9, k + 4, stone());
	bridge.setBlock(world, i + 36, j + 9, k + 5, JungleBlocks.ancientMossyBlock);
	bridge.setBlock(world, i + 36, j + 9, k + 6, stone());
	bridge.setBlock(world, i + 36, j + 9, k + 7, stone());
	bridge.setBlock(world, i + 36, j + 9, k + 8, stone());
	bridge.setBlock(world, i + 36, j + 9, k + 9, stone());
	bridge.setBlock(world, i + 36, j + 9, k + 10, stone());
	bridge.setBlock(world, i + 36, j + 9, k + 11, stone());
	bridge.setBlock(world, i + 36, j + 9, k + 12, stone());
	bridge.setBlock(world, i + 36, j + 9, k + 13, stone());
	bridge.setBlock(world, i + 36, j + 9, k + 14, stone());
	bridge.setBlock(world, i + 36, j + 9, k + 15, stone());
	bridge.setBlock(world, i + 36, j + 9, k + 16, stone());
	bridge.setBlock(world, i + 36, j + 9, k + 17, stone());
	bridge.setBlock(world, i + 36, j + 9, k + 18, stone());
	bridge.setBlock(world, i + 36, j + 9, k + 19, stone());
	bridge.setBlock(world, i + 36, j + 9, k + 20, stone());
	bridge.setBlock(world, i + 36, j + 9, k + 21, stone());
	bridge.setBlock(world, i + 36, j + 9, k + 22, stone());
	bridge.setBlock(world, i + 36, j + 9, k + 23, stone());
	bridge.setBlock(world, i + 36, j + 9, k + 24, stone());
	bridge.setBlock(world, i + 36, j + 9, k + 26, JungleBlocks.mossystairs, 3, 2);
	bridge.setBlock(world, i + 36, j + 10, k + 5, this.blockRandom(null), 2, 2);
	bridge.setBlock(world, i + 36, j + 10, k + 6, JungleBlocks.ancientMossyBlock);
	bridge.setBlock(world, i + 36, j + 10, k + 7, JungleBlocks.ancientMossyBlock);
	bridge.setBlock(world, i + 36, j + 10, k + 8, JungleBlocks.ancientMossyBlock);
	bridge.setBlock(world, i + 36, j + 10, k + 9, JungleBlocks.ancientMossyBlock);
	bridge.setBlock(world, i + 36, j + 10, k + 10, JungleBlocks.ancientMossyBlock);
	bridge.setBlock(world, i + 36, j + 10, k + 11, JungleBlocks.ancientMossyBlock);
	bridge.setBlock(world, i + 36, j + 10, k + 12, JungleBlocks.ancientMossyBlock);
	bridge.setBlock(world, i + 36, j + 10, k + 13, JungleBlocks.ancientMossyBlock);
	bridge.setBlock(world, i + 36, j + 10, k + 14, JungleBlocks.ancientMossyBlock);
	bridge.setBlock(world, i + 36, j + 10, k + 15, JungleBlocks.ancientMossyBlock);
	bridge.setBlock(world, i + 36, j + 10, k + 16, JungleBlocks.ancientMossyBlock);
	bridge.setBlock(world, i + 36, j + 10, k + 17, JungleBlocks.ancientMossyBlock);
	bridge.setBlock(world, i + 36, j + 10, k + 18, JungleBlocks.ancientMossyBlock);
	bridge.setBlock(world, i + 36, j + 10, k + 19, JungleBlocks.ancientMossyBlock);
	bridge.setBlock(world, i + 36, j + 10, k + 20, JungleBlocks.ancientMossyBlock);
	bridge.setBlock(world, i + 36, j + 10, k + 21, JungleBlocks.ancientMossyBlock);
	bridge.setBlock(world, i + 36, j + 10, k + 22, JungleBlocks.ancientMossyBlock);
	bridge.setBlock(world, i + 36, j + 10, k + 23, JungleBlocks.ancientMossyBlock);
	bridge.setBlock(world, i + 36, j + 11, k + 6, JungleBlocks.ancientMossyBlock);
	bridge.setBlock(world, i + 36, j + 11, k + 7, JungleBlocks.mossystairs, 1, 2);
	bridge.setBlock(world, i + 36, j + 11, k + 8, JungleBlocks.ancientMossyBlock);
	bridge.setBlock(world, i + 36, j + 11, k + 9, JungleBlocks.mossystairs, 1, 2);
	bridge.setBlock(world, i + 36, j + 11, k + 10, JungleBlocks.mossystairs, 1, 2);
	bridge.setBlock(world, i + 36, j + 11, k + 11, this.blockRandom(null), 1, 2);
	bridge.setBlock(world, i + 36, j + 11, k + 12, this.blockRandom(null), 1, 2);
	bridge.setBlock(world, i + 36, j + 11, k + 13, this.blockRandom(null), 1, 2);
	bridge.setBlock(world, i + 36, j + 11, k + 14, JungleBlocks.mossystairs, 1, 2);
	bridge.setBlock(world, i + 36, j + 11, k + 15, JungleBlocks.mossystairs, 1, 2);
	bridge.setBlock(world, i + 36, j + 11, k + 16, this.blockRandom(null), 1, 2);
	bridge.setBlock(world, i + 36, j + 11, k + 17, this.blockRandom(null), 1, 2);
	bridge.setBlock(world, i + 36, j + 11, k + 18, this.blockRandom(null), 1, 2);
	bridge.setBlock(world, i + 36, j + 11, k + 19, JungleBlocks.mossystairs, 1, 2);
	bridge.setBlock(world, i + 36, j + 11, k + 20, JungleBlocks.mossystairs, 1, 2);
	bridge.setBlock(world, i + 36, j + 11, k + 21, JungleBlocks.mossystairs, 1, 2);
	bridge.setBlock(world, i + 36, j + 11, k + 23, this.blockRandom(null), 1, 2);
	bridge.setBlock(world, i + 36, j + 14, k + 18, this.blockRandom("mossCobbSlab"), 11, 2);
	bridge.setBlock(world, i + 36, j + 15, k + 12, this.blockRandom("mossCobbSlab"), 11, 2);
	bridge.setBlock(world, i + 36, j + 15, k + 18, Blocks.COBBLESTONE_WALL, 1, 2);
	bridge.setBlock(world, i + 36, j + 16, k + 12, Blocks.COBBLESTONE_WALL, 1, 2);
	bridge.setBlock(world, i + 36, j + 16, k + 18, this.blockRandom("mossCobbSlab"), 3, 2);
	bridge.setBlock(world, i + 36, j + 17, k + 12, this.blockRandom("mossCobbSlab"), 3, 2);
	bridge.setBlock(world, i + 37, j + 0, k + 0, stone());
	bridge.setBlock(world, i + 37, j + 0, k + 1, stone());
	bridge.setBlock(world, i + 37, j + 0, k + 2, stone());
	bridge.setBlock(world, i + 37, j + 0, k + 3, stone());
	bridge.setBlock(world, i + 37, j + 0, k + 4, stone());
	bridge.setBlock(world, i + 37, j + 0, k + 5, stone());
	bridge.setBlock(world, i + 37, j + 0, k + 6, stone());
	bridge.setBlock(world, i + 37, j + 0, k + 7, stone());
	bridge.setBlock(world, i + 37, j + 0, k + 8, stone());
	bridge.setBlock(world, i + 37, j + 0, k + 9, stone());
	bridge.setBlock(world, i + 37, j + 0, k + 10, stone());
	bridge.setBlock(world, i + 37, j + 0, k + 11, stone());
	bridge.setBlock(world, i + 37, j + 0, k + 12, stone());
	bridge.setBlock(world, i + 37, j + 0, k + 13, stone());
	bridge.setBlock(world, i + 37, j + 0, k + 14, stone());
	bridge.setBlock(world, i + 37, j + 0, k + 15, stone());
	bridge.setBlock(world, i + 37, j + 0, k + 16, stone());
	bridge.setBlock(world, i + 37, j + 0, k + 17, stone());
	bridge.setBlock(world, i + 37, j + 0, k + 18, stone());
	bridge.setBlock(world, i + 37, j + 0, k + 19, stone());
	bridge.setBlock(world, i + 37, j + 0, k + 20, stone());
	bridge.setBlock(world, i + 37, j + 0, k + 21, stone());
	bridge.setBlock(world, i + 37, j + 0, k + 22, stone());
	bridge.setBlock(world, i + 37, j + 0, k + 23, stone());
	bridge.setBlock(world, i + 37, j + 0, k + 24, stone());
	bridge.setBlock(world, i + 37, j + 0, k + 25, stone());
	bridge.setBlock(world, i + 37, j + 0, k + 26, stone());
	bridge.setBlock(world, i + 37, j + 0, k + 27, stone());
	bridge.setBlock(world, i + 37, j + 0, k + 28, stone());
	bridge.setBlock(world, i + 37, j + 0, k + 29, stone());
	
	for(int fillk = 0; fillk <= 18; fillk++)
	{
	bridge.setBlock(world, i + 37, j + 1, k + fillk, stone());
	}

	bridge.setBlock(world, i + 37, j + 1, k + 24, stone());
	bridge.setBlock(world, i + 37, j + 1, k + 25, stone());
	bridge.setBlock(world, i + 37, j + 1, k + 26, stone());
	bridge.setBlock(world, i + 37, j + 1, k + 27, stone());
	bridge.setBlock(world, i + 37, j + 1, k + 28, stone());
	bridge.setBlock(world, i + 37, j + 1, k + 29, stone());
	bridge.setBlock(world, i + 37, j + 1, k + 30, stone());
	
	for(int fillk = 0; fillk <= 18; fillk++) {
		bridge.setBlock(world, i + 37, j + 2, k + fillk, stone());
		}
	
	for(int fillk = 26; fillk <= 30; fillk++) {
		bridge.setBlock(world, i + 37, j + 2, k + fillk, stone());
		}

	for(int fillk = 0; fillk <= 6; fillk++)	{
		bridge.setBlock(world, i + 37, j + 3, k + fillk, stone());
		}
	
	bridge.setBlock(world, i + 37, j + 3, k + 14, stone());
	bridge.setBlock(world, i + 37, j + 3, k + 15, stone());

	for(int fillk = 26; fillk <= 30; fillk++)	{
		bridge.setBlock(world, i + 37, j + 3, k + fillk, stone());
		bridge.setBlock(world, i + 37, j + 4, k + fillk, stone());
		}
	
	for(int fillk = 0; fillk <= 5; fillk++)	{
		bridge.setBlock(world, i + 37, j + 4, k + fillk, stone());
	}
	
	bridge.setBlock(world, i + 37, j + 4, k + 15, stone());

	bridge.setBlock(world, i + 37, j + 5, k + 0, stone());
	bridge.setBlock(world, i + 37, j + 5, k + 1, JungleBlocks.ancientMossyBlock);
	bridge.setBlock(world, i + 37, j + 5, k + 2, stone());
	bridge.setBlock(world, i + 37, j + 5, k + 3, stone());
	bridge.setBlock(world, i + 37, j + 5, k + 4, stone());
	bridge.setBlock(world, i + 37, j + 5, k + 5, stone());
	bridge.setBlock(world, i + 37, j + 5, k + 14, stone());
	bridge.setBlock(world, i + 37, j + 5, k + 15, stone());
	bridge.setBlock(world, i + 37, j + 5, k + 25, stone());
	bridge.setBlock(world, i + 37, j + 5, k + 26, stone());
	bridge.setBlock(world, i + 37, j + 5, k + 27, stone());
	bridge.setBlock(world, i + 37, j + 5, k + 28, stone());
	bridge.setBlock(world, i + 37, j + 5, k + 29, JungleBlocks.ancientMossyBlock);
	bridge.setBlock(world, i + 37, j + 5, k + 30, stone());
	bridge.setBlock(world, i + 37, j + 6, k + 1, stone());
	bridge.setBlock(world, i + 37, j + 6, k + 2, JungleBlocks.ancientMossyBlock);
	bridge.setBlock(world, i + 37, j + 6, k + 3, stone());
	bridge.setBlock(world, i + 37, j + 6, k + 4, stone());
	bridge.setBlock(world, i + 37, j + 6, k + 5, stone());
	bridge.setBlock(world, i + 37, j + 6, k + 13, stone());
	bridge.setBlock(world, i + 37, j + 6, k + 14, stone());
	bridge.setBlock(world, i + 37, j + 6, k + 15, stone());
	bridge.setBlock(world, i + 37, j + 6, k + 16, stone());
	bridge.setBlock(world, i + 37, j + 6, k + 24, stone());
	bridge.setBlock(world, i + 37, j + 6, k + 25, stone());
	bridge.setBlock(world, i + 37, j + 6, k + 26, stone());
	bridge.setBlock(world, i + 37, j + 6, k + 27, stone());
	bridge.setBlock(world, i + 37, j + 6, k + 28, JungleBlocks.ancientMossyBlock);
	bridge.setBlock(world, i + 37, j + 6, k + 29, stone());
	bridge.setBlock(world, i + 37, j + 7, k + 2, stone());
	bridge.setBlock(world, i + 37, j + 7, k + 3, JungleBlocks.ancientMossyBlock);
	bridge.setBlock(world, i + 37, j + 7, k + 4, stone());
	bridge.setBlock(world, i + 37, j + 7, k + 5, stone());
	bridge.setBlock(world, i + 37, j + 7, k + 6, stone());
	bridge.setBlock(world, i + 37, j + 7, k + 11, stone());
	bridge.setBlock(world, i + 37, j + 7, k + 12, stone());
	bridge.setBlock(world, i + 37, j + 7, k + 13, stone());
	bridge.setBlock(world, i + 37, j + 7, k + 14, stone());
	bridge.setBlock(world, i + 37, j + 7, k + 15, stone());
	bridge.setBlock(world, i + 37, j + 7, k + 16, stone());
	bridge.setBlock(world, i + 37, j + 7, k + 17, stone());
	bridge.setBlock(world, i + 37, j + 7, k + 22, stone());
	bridge.setBlock(world, i + 37, j + 7, k + 23, stone());
	bridge.setBlock(world, i + 37, j + 7, k + 24, stone());
	bridge.setBlock(world, i + 37, j + 7, k + 25, stone());
	bridge.setBlock(world, i + 37, j + 7, k + 26, stone());
	bridge.setBlock(world, i + 37, j + 7, k + 27, JungleBlocks.ancientMossyBlock);
	bridge.setBlock(world, i + 37, j + 7, k + 28, stone());
	bridge.setBlock(world, i + 37, j + 8, k + 3, stone());
	bridge.setBlock(world, i + 37, j + 8, k + 4, JungleBlocks.ancientMossyBlock);
	bridge.setBlock(world, i + 37, j + 8, k + 5, stone());
	bridge.setBlock(world, i + 37, j + 8, k + 6, stone());
	bridge.setBlock(world, i + 37, j + 8, k + 7, stone());
	bridge.setBlock(world, i + 37, j + 8, k + 8, stone());
	bridge.setBlock(world, i + 37, j + 8, k + 9, stone());
	bridge.setBlock(world, i + 37, j + 8, k + 10, stone());
	bridge.setBlock(world, i + 37, j + 8, k + 11, stone());
	bridge.setBlock(world, i + 37, j + 8, k + 12, stone());
	bridge.setBlock(world, i + 37, j + 8, k + 13, stone());
	bridge.setBlock(world, i + 37, j + 8, k + 14, stone());
	bridge.setBlock(world, i + 37, j + 8, k + 15, stone());
	bridge.setBlock(world, i + 37, j + 8, k + 16, stone());
	bridge.setBlock(world, i + 37, j + 8, k + 17, stone());
	bridge.setBlock(world, i + 37, j + 8, k + 18, stone());
	bridge.setBlock(world, i + 37, j + 8, k + 19, stone());
	bridge.setBlock(world, i + 37, j + 8, k + 20, stone());
	bridge.setBlock(world, i + 37, j + 8, k + 21, stone());
	bridge.setBlock(world, i + 37, j + 8, k + 22, stone());
	bridge.setBlock(world, i + 37, j + 8, k + 23, stone());
	bridge.setBlock(world, i + 37, j + 8, k + 24, stone());
	bridge.setBlock(world, i + 37, j + 8, k + 25, stone());
	bridge.setBlock(world, i + 37, j + 8, k + 26, JungleBlocks.ancientMossyBlock);
	bridge.setBlock(world, i + 37, j + 9, k + 4, this.blockRandom(null), 2, 2);
	bridge.setBlock(world, i + 37, j + 9, k + 5, JungleBlocks.ancientMossyBlock);
	bridge.setBlock(world, i + 37, j + 9, k + 6, JungleBlocks.ancientMossyBlock);
	bridge.setBlock(world, i + 37, j + 9, k + 7, JungleBlocks.ancientMossyBlock);
	bridge.setBlock(world, i + 37, j + 9, k + 8, JungleBlocks.ancientMossyBlock);
	bridge.setBlock(world, i + 37, j + 9, k + 9, JungleBlocks.ancientMossyBlock);
	bridge.setBlock(world, i + 37, j + 9, k + 10, JungleBlocks.ancientMossyBlock);
	bridge.setBlock(world, i + 37, j + 9, k + 11, JungleBlocks.ancientMossyBlock);
	bridge.setBlock(world, i + 37, j + 9, k + 12, JungleBlocks.ancientMossyBlock);
	bridge.setBlock(world, i + 37, j + 9, k + 13, JungleBlocks.ancientMossyBlock);
	bridge.setBlock(world, i + 37, j + 9, k + 14, JungleBlocks.ancientMossyBlock);
	bridge.setBlock(world, i + 37, j + 9, k + 15, JungleBlocks.ancientMossyBlock);
	bridge.setBlock(world, i + 37, j + 9, k + 16, JungleBlocks.ancientMossyBlock);
	bridge.setBlock(world, i + 37, j + 9, k + 17, JungleBlocks.ancientMossyBlock);
	bridge.setBlock(world, i + 37, j + 9, k + 18, JungleBlocks.ancientMossyBlock);
	bridge.setBlock(world, i + 37, j + 9, k + 19, JungleBlocks.ancientMossyBlock);
	bridge.setBlock(world, i + 37, j + 9, k + 20, JungleBlocks.ancientMossyBlock);
	bridge.setBlock(world, i + 37, j + 9, k + 22, JungleBlocks.ancientMossyBlock);
	bridge.setBlock(world, i + 37, j + 9, k + 23, JungleBlocks.ancientMossyBlock);
	bridge.setBlock(world, i + 37, j + 9, k + 24, JungleBlocks.ancientMossyBlock);
	bridge.setBlock(world, i + 37, j + 10, k + 5, this.blockRandom(null), 2, 2);
	bridge.setBlock(world, i + 37, j + 10, k + 6, JungleBlocks.mossystairs, 1, 2);
	bridge.setBlock(world, i + 37, j + 10, k + 7, JungleBlocks.mossystairs, 1, 2);
	bridge.setBlock(world, i + 37, j + 10, k + 8, JungleBlocks.mossystairs, 1, 2);
	bridge.setBlock(world, i + 37, j + 10, k + 9, JungleBlocks.mossystairs, 1, 2);
	bridge.setBlock(world, i + 37, j + 10, k + 10, JungleBlocks.mossystairs, 1, 2);
	bridge.setBlock(world, i + 37, j + 10, k + 11, this.blockRandom(null), 1, 2);
	bridge.setBlock(world, i + 37, j + 10, k + 12, JungleBlocks.ancientMossyBlock);
	bridge.setBlock(world, i + 37, j + 10, k + 13, this.blockRandom(null), 1, 2);
	bridge.setBlock(world, i + 37, j + 10, k + 14, JungleBlocks.mossystairs, 1, 2);
	bridge.setBlock(world, i + 37, j + 10, k + 15, JungleBlocks.mossystairs, 1, 2);
	bridge.setBlock(world, i + 37, j + 10, k + 16, JungleBlocks.mossystairs, 1, 2);
	bridge.setBlock(world, i + 37, j + 10, k + 17, this.blockRandom(null), 1, 2);
	bridge.setBlock(world, i + 37, j + 10, k + 18, JungleBlocks.ancientMossyBlock);
	bridge.setBlock(world, i + 37, j + 10, k + 19, JungleBlocks.mossystairs, 1, 2);
	bridge.setBlock(world, i + 37, j + 10, k + 20, JungleBlocks.mossystairs, 1, 2);
	bridge.setBlock(world, i + 37, j + 10, k + 23, this.blockRandom(null), 1, 2);
	bridge.setBlock(world, i + 37, j + 10, k + 24, this.blockRandom(null), 1, 2);
	bridge.setBlock(world, i + 37, j + 11, k + 12, JungleBlocks.ancientMossyBlock);
	bridge.setBlock(world, i + 37, j + 11, k + 18, Blocks.COBBLESTONE_WALL, 1, 2);
	bridge.setBlock(world, i + 37, j + 12, k + 12, Blocks.COBBLESTONE_WALL, 1, 2);
	bridge.setBlock(world, i + 37, j + 12, k + 18, JungleBlocks.ancientMossyBlock);
	bridge.setBlock(world, i + 37, j + 13, k + 12, JungleBlocks.ancientMossyBlock);
	bridge.setBlock(world, i + 37, j + 13, k + 18, Blocks.COBBLESTONE_WALL, 1, 2);
	bridge.setBlock(world, i + 37, j + 14, k + 12, Blocks.COBBLESTONE_WALL, 1, 2);
	bridge.setBlock(world, i + 37, j + 14, k + 18, Blocks.COBBLESTONE_WALL, 1, 2);
	bridge.setBlock(world, i + 37, j + 15, k + 12, Blocks.COBBLESTONE_WALL, 1, 2);
	bridge.setBlock(world, i + 37, j + 15, k + 18, JungleBlocks.mossystairs, 1, 2);
	bridge.setBlock(world, i + 37, j + 16, k + 12, JungleBlocks.mossystairs, 1, 2);

	for(int fill = 0; fill<30; ++fill)
	{bridge.setBlock(world, i + 38, j + 0, k + fill, stone());}
	
	bridge.setBlock(world, i + 38, j + 1, k + 0, stone());
	bridge.setBlock(world, i + 38, j + 1, k + 1, stone());
	bridge.setBlock(world, i + 38, j + 1, k + 2, stone());
	bridge.setBlock(world, i + 38, j + 1, k + 3, stone());
	bridge.setBlock(world, i + 38, j + 1, k + 4, stone());
	bridge.setBlock(world, i + 38, j + 1, k + 5, stone());
	bridge.setBlock(world, i + 38, j + 1, k + 6, stone());
	bridge.setBlock(world, i + 38, j + 1, k + 7, stone());
	bridge.setBlock(world, i + 38, j + 1, k + 8, stone());
	bridge.setBlock(world, i + 38, j + 1, k + 9, stone());
	bridge.setBlock(world, i + 38, j + 1, k + 10, stone());
	bridge.setBlock(world, i + 38, j + 1, k + 11, stone());
	bridge.setBlock(world, i + 38, j + 1, k + 12, stone());
	bridge.setBlock(world, i + 38, j + 1, k + 13, stone());
	bridge.setBlock(world, i + 38, j + 1, k + 14, stone());
	bridge.setBlock(world, i + 38, j + 1, k + 15, stone());
	bridge.setBlock(world, i + 38, j + 1, k + 16, stone());
	bridge.setBlock(world, i + 38, j + 1, k + 17, stone());
	bridge.setBlock(world, i + 38, j + 1, k + 18, stone());
	bridge.setBlock(world, i + 38, j + 1, k + 25, stone());
	bridge.setBlock(world, i + 38, j + 1, k + 26, stone());
	bridge.setBlock(world, i + 38, j + 1, k + 27, stone());
	bridge.setBlock(world, i + 38, j + 1, k + 28, stone());
	bridge.setBlock(world, i + 38, j + 1, k + 29, stone());
	bridge.setBlock(world, i + 38, j + 1, k + 30, stone());
	bridge.setBlock(world, i + 38, j + 2, k + 0, stone());
	bridge.setBlock(world, i + 38, j + 2, k + 1, stone());
	bridge.setBlock(world, i + 38, j + 2, k + 2, stone());
	bridge.setBlock(world, i + 38, j + 2, k + 3, stone());
	bridge.setBlock(world, i + 38, j + 2, k + 4, stone());
	bridge.setBlock(world, i + 38, j + 2, k + 5, stone());
	bridge.setBlock(world, i + 38, j + 2, k + 6, stone());
	bridge.setBlock(world, i + 38, j + 2, k + 7, stone());
	bridge.setBlock(world, i + 38, j + 2, k + 8, stone());
	bridge.setBlock(world, i + 38, j + 2, k + 9, stone());
	bridge.setBlock(world, i + 38, j + 2, k + 10, stone());
	bridge.setBlock(world, i + 38, j + 2, k + 11, stone());
	bridge.setBlock(world, i + 38, j + 2, k + 12, stone());
	bridge.setBlock(world, i + 38, j + 2, k + 13, stone());
	bridge.setBlock(world, i + 38, j + 2, k + 14, stone());
	bridge.setBlock(world, i + 38, j + 2, k + 15, stone());
	bridge.setBlock(world, i + 38, j + 2, k + 16, stone());
	bridge.setBlock(world, i + 38, j + 2, k + 17, stone());
	bridge.setBlock(world, i + 38, j + 2, k + 18, stone());
	bridge.setBlock(world, i + 38, j + 2, k + 19, Blocks.AIR);
	bridge.setBlock(world, i + 38, j + 2, k + 20, Blocks.AIR);
	bridge.setBlock(world, i + 38, j + 2, k + 21, Blocks.AIR);
	bridge.setBlock(world, i + 38, j + 2, k + 22, Blocks.AIR);
	bridge.setBlock(world, i + 38, j + 2, k + 23, Blocks.AIR);
	bridge.setBlock(world, i + 38, j + 2, k + 24, Blocks.AIR);
	bridge.setBlock(world, i + 38, j + 2, k + 25, Blocks.AIR);
	bridge.setBlock(world, i + 38, j + 2, k + 26, stone());
	bridge.setBlock(world, i + 38, j + 2, k + 27, stone());
	bridge.setBlock(world, i + 38, j + 2, k + 28, stone());
	bridge.setBlock(world, i + 38, j + 2, k + 29, stone());
	bridge.setBlock(world, i + 38, j + 2, k + 30, stone());
	bridge.setBlock(world, i + 38, j + 3, k + 0, stone());
	bridge.setBlock(world, i + 38, j + 3, k + 1, stone());
	bridge.setBlock(world, i + 38, j + 3, k + 2, stone());
	bridge.setBlock(world, i + 38, j + 3, k + 3, stone());
	bridge.setBlock(world, i + 38, j + 3, k + 4, stone());
	bridge.setBlock(world, i + 38, j + 3, k + 5, stone());
	bridge.setBlock(world, i + 38, j + 3, k + 6, stone());
	bridge.setBlock(world, i + 38, j + 3, k + 7, stone());
	bridge.setBlock(world, i + 38, j + 3, k + 8, Blocks.COBBLESTONE);
	bridge.setBlock(world, i + 38, j + 3, k + 10, Blocks.COBBLESTONE);
	bridge.setBlock(world, i + 38, j + 3, k + 12, stone());
	bridge.setBlock(world, i + 38, j + 3, k + 13, stone());
	bridge.setBlock(world, i + 38, j + 3, k + 14, stone());
	bridge.setBlock(world, i + 38, j + 3, k + 15, stone());
	bridge.setBlock(world, i + 38, j + 3, k + 16, stone());
	bridge.setBlock(world, i + 38, j + 3, k + 27, stone());
	bridge.setBlock(world, i + 38, j + 3, k + 28, stone());
	bridge.setBlock(world, i + 38, j + 3, k + 29, stone());
	bridge.setBlock(world, i + 38, j + 3, k + 30, stone());
	bridge.setBlock(world, i + 38, j + 4, k + 0, stone());
	bridge.setBlock(world, i + 38, j + 4, k + 1, stone());
	bridge.setBlock(world, i + 38, j + 4, k + 2, stone());
	bridge.setBlock(world, i + 38, j + 4, k + 3, stone());
	bridge.setBlock(world, i + 38, j + 4, k + 4, stone());
	bridge.setBlock(world, i + 38, j + 4, k + 5, stone());
	bridge.setBlock(world, i + 38, j + 4, k + 6, stone());
	bridge.setBlock(world, i + 38, j + 4, k + 12, stone());
	bridge.setBlock(world, i + 38, j + 4, k + 13, stone());
	bridge.setBlock(world, i + 38, j + 4, k + 14, stone());
	bridge.setBlock(world, i + 38, j + 4, k + 15, stone());
	bridge.setBlock(world, i + 38, j + 4, k + 16, stone());
	bridge.setBlock(world, i + 38, j + 4, k + 27, stone());
	bridge.setBlock(world, i + 38, j + 4, k + 28, stone());
	bridge.setBlock(world, i + 38, j + 4, k + 29, stone());
	bridge.setBlock(world, i + 38, j + 4, k + 30, stone());
	bridge.setBlock(world, i + 38, j + 5, k + 0, JungleBlocks.mossystairs, 2, 2);
	bridge.setBlock(world, i + 38, j + 5, k + 1, JungleBlocks.ancientMossyBlock);
	bridge.setBlock(world, i + 38, j + 5, k + 2, stone());
	bridge.setBlock(world, i + 38, j + 5, k + 3, stone());
	bridge.setBlock(world, i + 38, j + 5, k + 4, stone());
	bridge.setBlock(world, i + 38, j + 5, k + 5, stone());
	bridge.setBlock(world, i + 38, j + 5, k + 6, stone());
	bridge.setBlock(world, i + 38, j + 5, k + 12, stone());
	bridge.setBlock(world, i + 38, j + 5, k + 13, stone());
	bridge.setBlock(world, i + 38, j + 5, k + 14, stone());
	bridge.setBlock(world, i + 38, j + 5, k + 15, stone());
	bridge.setBlock(world, i + 38, j + 5, k + 16, stone());
	bridge.setBlock(world, i + 38, j + 5, k + 26, stone());
	bridge.setBlock(world, i + 38, j + 5, k + 27, stone());
	bridge.setBlock(world, i + 38, j + 5, k + 28, stone());
	bridge.setBlock(world, i + 38, j + 5, k + 29, JungleBlocks.ancientMossyBlock);
	bridge.setBlock(world, i + 38, j + 5, k + 30, this.blockRandom(null), 3, 2);
	bridge.setBlock(world, i + 38, j + 6, k + 1, JungleBlocks.mossystairs, 2, 2);
	bridge.setBlock(world, i + 38, j + 6, k + 2, JungleBlocks.ancientMossyBlock);
	bridge.setBlock(world, i + 38, j + 6, k + 3, stone());
	bridge.setBlock(world, i + 38, j + 6, k + 4, stone());
	bridge.setBlock(world, i + 38, j + 6, k + 5, stone());
	bridge.setBlock(world, i + 38, j + 6, k + 6, stone());
	bridge.setBlock(world, i + 38, j + 6, k + 7, stone());
	bridge.setBlock(world, i + 38, j + 6, k + 11, stone());
	bridge.setBlock(world, i + 38, j + 6, k + 12, stone());
	bridge.setBlock(world, i + 38, j + 6, k + 13, stone());
	bridge.setBlock(world, i + 38, j + 6, k + 14, stone());
	bridge.setBlock(world, i + 38, j + 6, k + 15, stone());
	bridge.setBlock(world, i + 38, j + 6, k + 16, stone());
	bridge.setBlock(world, i + 38, j + 6, k + 17, stone());
	bridge.setBlock(world, i + 38, j + 6, k + 21, stone());
	bridge.setBlock(world, i + 38, j + 6, k + 22, stone());
	bridge.setBlock(world, i + 38, j + 6, k + 23, stone());
	bridge.setBlock(world, i + 38, j + 6, k + 24, stone());
	bridge.setBlock(world, i + 38, j + 6, k + 25, stone());
	bridge.setBlock(world, i + 38, j + 6, k + 26, stone());
	bridge.setBlock(world, i + 38, j + 6, k + 27, stone());
	bridge.setBlock(world, i + 38, j + 6, k + 28, JungleBlocks.ancientMossyBlock);
	bridge.setBlock(world, i + 38, j + 6, k + 29, this.blockRandom(null), 3, 2);
	bridge.setBlock(world, i + 38, j + 7, k + 2, JungleBlocks.mossystairs, 2, 2);
	bridge.setBlock(world, i + 38, j + 7, k + 3, JungleBlocks.ancientMossyBlock);
	bridge.setBlock(world, i + 38, j + 7, k + 4, stone());
	bridge.setBlock(world, i + 38, j + 7, k + 5, stone());
	bridge.setBlock(world, i + 38, j + 7, k + 6, stone());
	bridge.setBlock(world, i + 38, j + 7, k + 7, stone());
	bridge.setBlock(world, i + 38, j + 7, k + 8, stone());
	bridge.setBlock(world, i + 38, j + 7, k + 9, stone());
	bridge.setBlock(world, i + 38, j + 7, k + 10, stone());
	bridge.setBlock(world, i + 38, j + 7, k + 11, stone());
	bridge.setBlock(world, i + 38, j + 7, k + 12, stone());
	bridge.setBlock(world, i + 38, j + 7, k + 13, stone());
	bridge.setBlock(world, i + 38, j + 7, k + 14, stone());
	bridge.setBlock(world, i + 38, j + 7, k + 15, stone());
	bridge.setBlock(world, i + 38, j + 7, k + 16, stone());
	bridge.setBlock(world, i + 38, j + 7, k + 17, stone());
	bridge.setBlock(world, i + 38, j + 7, k + 18, stone());
	bridge.setBlock(world, i + 38, j + 7, k + 19, stone());
	bridge.setBlock(world, i + 38, j + 7, k + 20, stone());
	bridge.setBlock(world, i + 38, j + 7, k + 21, stone());
	bridge.setBlock(world, i + 38, j + 7, k + 22, stone());
	bridge.setBlock(world, i + 38, j + 7, k + 23, stone());
	bridge.setBlock(world, i + 38, j + 7, k + 24, stone());
	bridge.setBlock(world, i + 38, j + 7, k + 25, stone());
	bridge.setBlock(world, i + 38, j + 7, k + 26, stone());
	bridge.setBlock(world, i + 38, j + 8, k + 3, this.blockRandom(null), 2, 2);
	bridge.setBlock(world, i + 38, j + 8, k + 4, JungleBlocks.ancientMossyBlock);
	bridge.setBlock(world, i + 38, j + 8, k + 5, JungleBlocks.ancientMossyBlock);
	bridge.setBlock(world, i + 38, j + 8, k + 6, JungleBlocks.ancientMossyBlock);
	bridge.setBlock(world, i + 38, j + 8, k + 7, JungleBlocks.ancientMossyBlock);
	bridge.setBlock(world, i + 38, j + 8, k + 8, JungleBlocks.ancientMossyBlock);
	bridge.setBlock(world, i + 38, j + 8, k + 9, JungleBlocks.ancientMossyBlock);
	bridge.setBlock(world, i + 38, j + 8, k + 10, JungleBlocks.ancientMossyBlock);
	bridge.setBlock(world, i + 38, j + 8, k + 11, JungleBlocks.ancientMossyBlock);
	bridge.setBlock(world, i + 38, j + 8, k + 12, JungleBlocks.ancientMossyBlock);
	bridge.setBlock(world, i + 38, j + 8, k + 13, JungleBlocks.ancientMossyBlock);
	bridge.setBlock(world, i + 38, j + 8, k + 14, JungleBlocks.ancientMossyBlock);
	bridge.setBlock(world, i + 38, j + 8, k + 15, JungleBlocks.ancientMossyBlock);
	bridge.setBlock(world, i + 38, j + 8, k + 16, JungleBlocks.ancientMossyBlock);
	bridge.setBlock(world, i + 38, j + 8, k + 17, JungleBlocks.ancientMossyBlock);
	bridge.setBlock(world, i + 38, j + 8, k + 18, JungleBlocks.ancientMossyBlock);
	bridge.setBlock(world, i + 38, j + 8, k + 19, JungleBlocks.ancientMossyBlock);
	bridge.setBlock(world, i + 38, j + 8, k + 20, JungleBlocks.ancientMossyBlock);
	bridge.setBlock(world, i + 38, j + 8, k + 21, JungleBlocks.ancientMossyBlock);
	bridge.setBlock(world, i + 38, j + 8, k + 24, JungleBlocks.ancientMossyBlock);
	bridge.setBlock(world, i + 38, j + 8, k + 25, JungleBlocks.ancientMossyBlock);
	bridge.setBlock(world, i + 38, j + 8, k + 26, JungleBlocks.ancientMossyBlock);
	bridge.setBlock(world, i + 38, j + 9, k + 4, JungleBlocks.ancientMossyBlock);
	bridge.setBlock(world, i + 38, j + 9, k + 5, this.blockRandom(null), 1, 2);
	bridge.setBlock(world, i + 38, j + 9, k + 6, JungleBlocks.mossystairs, 1, 2);
	bridge.setBlock(world, i + 38, j + 9, k + 7, JungleBlocks.mossystairs, 1, 2);
	bridge.setBlock(world, i + 38, j + 9, k + 8, JungleBlocks.ancientMossyBlock);
	bridge.setBlock(world, i + 38, j + 9, k + 9, this.blockRandom(null), 1, 2);
	bridge.setBlock(world, i + 38, j + 9, k + 10, JungleBlocks.mossystairs, 1, 2);
	bridge.setBlock(world, i + 38, j + 9, k + 11, JungleBlocks.mossystairs, 1, 2);
	bridge.setBlock(world, i + 38, j + 9, k + 12, JungleBlocks.mossystairs, 1, 2);
	bridge.setBlock(world, i + 38, j + 9, k + 13, JungleBlocks.mossystairs, 1, 2);
	bridge.setBlock(world, i + 38, j + 9, k + 14, JungleBlocks.mossystairs, 1, 2);
	bridge.setBlock(world, i + 38, j + 9, k + 15, JungleBlocks.mossystairs, 1, 2);
	bridge.setBlock(world, i + 38, j + 9, k + 16, JungleBlocks.mossystairs, 1, 2);
	bridge.setBlock(world, i + 38, j + 9, k + 17, JungleBlocks.mossystairs, 1, 2);
	bridge.setBlock(world, i + 38, j + 9, k + 18, JungleBlocks.mossystairs, 1, 2);
	bridge.setBlock(world, i + 38, j + 9, k + 19, JungleBlocks.mossystairs, 1, 2);
	bridge.setBlock(world, i + 38, j + 9, k + 20, JungleBlocks.mossystairs, 1, 2);
	bridge.setBlock(world, i + 38, j + 9, k + 24, JungleBlocks.mossystairs, 1, 2);
	bridge.setBlock(world, i + 38, j + 9, k + 26, JungleBlocks.ancientMossyBlock);
	
	for(int fill = 0; fill < 31; ++fill)
	{bridge.setBlock(world, i + 39, j + 0, k + fill, stone());}
	
	bridge.setBlock(world, i + 39, j + 1, k + 0, stone());
	bridge.setBlock(world, i + 39, j + 1, k + 1, stone());
	bridge.setBlock(world, i + 39, j + 1, k + 2, stone());
	bridge.setBlock(world, i + 39, j + 1, k + 3, stone());
	bridge.setBlock(world, i + 39, j + 1, k + 4, stone());
	bridge.setBlock(world, i + 39, j + 1, k + 5, stone());
	bridge.setBlock(world, i + 39, j + 1, k + 6, stone());
	bridge.setBlock(world, i + 39, j + 1, k + 7, stone());
	bridge.setBlock(world, i + 39, j + 1, k + 8, stone());
	bridge.setBlock(world, i + 39, j + 1, k + 9, stone());
	bridge.setBlock(world, i + 39, j + 1, k + 10, stone());
	bridge.setBlock(world, i + 39, j + 1, k + 11, stone());
	bridge.setBlock(world, i + 39, j + 1, k + 12, stone());
	bridge.setBlock(world, i + 39, j + 1, k + 13, stone());
	bridge.setBlock(world, i + 39, j + 1, k + 14, stone());
	bridge.setBlock(world, i + 39, j + 1, k + 15, stone());
	bridge.setBlock(world, i + 39, j + 1, k + 16, stone());
	bridge.setBlock(world, i + 39, j + 1, k + 17, stone());
	bridge.setBlock(world, i + 39, j + 1, k + 18, stone());
	bridge.setBlock(world, i + 39, j + 1, k + 19, stone());
	bridge.setBlock(world, i + 39, j + 1, k + 20, stone());
	bridge.setBlock(world, i + 39, j + 1, k + 25, stone());
	bridge.setBlock(world, i + 39, j + 1, k + 26, stone());
	bridge.setBlock(world, i + 39, j + 1, k + 27, stone());
	bridge.setBlock(world, i + 39, j + 1, k + 28, stone());
	bridge.setBlock(world, i + 39, j + 1, k + 29, stone());
	bridge.setBlock(world, i + 39, j + 1, k + 30, stone());
	bridge.setBlock(world, i + 39, j + 2, k + 0, stone());
	bridge.setBlock(world, i + 39, j + 2, k + 1, stone());
	bridge.setBlock(world, i + 39, j + 2, k + 2, stone());
	bridge.setBlock(world, i + 39, j + 2, k + 3, stone());
	bridge.setBlock(world, i + 39, j + 2, k + 4, stone());
	bridge.setBlock(world, i + 39, j + 2, k + 5, stone());
	bridge.setBlock(world, i + 39, j + 2, k + 6, stone());
	bridge.setBlock(world, i + 39, j + 2, k + 7, stone());
	bridge.setBlock(world, i + 39, j + 2, k + 8, stone());
	bridge.setBlock(world, i + 39, j + 2, k + 9, stone());
	bridge.setBlock(world, i + 39, j + 2, k + 10, stone());
	bridge.setBlock(world, i + 39, j + 2, k + 11, stone());
	bridge.setBlock(world, i + 39, j + 2, k + 12, stone());
	bridge.setBlock(world, i + 39, j + 2, k + 13, stone());
	bridge.setBlock(world, i + 39, j + 2, k + 14, stone());
	bridge.setBlock(world, i + 39, j + 2, k + 15, stone());
	bridge.setBlock(world, i + 39, j + 2, k + 16, stone());
	bridge.setBlock(world, i + 39, j + 2, k + 17, stone());
	bridge.setBlock(world, i + 39, j + 2, k + 18, stone());
	bridge.setBlock(world, i + 39, j + 2, k + 19, stone());
	bridge.setBlock(world, i + 39, j + 2, k + 20, Blocks.AIR);
	bridge.setBlock(world, i + 39, j + 2, k + 21, Blocks.AIR);
	bridge.setBlock(world, i + 39, j + 2, k + 22, Blocks.AIR);
	bridge.setBlock(world, i + 39, j + 2, k + 23, Blocks.AIR);
	bridge.setBlock(world, i + 39, j + 2, k + 24, Blocks.AIR);
	bridge.setBlock(world, i + 39, j + 2, k + 25, stone());
	bridge.setBlock(world, i + 39, j + 2, k + 26, stone());
	bridge.setBlock(world, i + 39, j + 2, k + 27, stone());
	bridge.setBlock(world, i + 39, j + 2, k + 28, stone());
	bridge.setBlock(world, i + 39, j + 2, k + 29, stone());
	bridge.setBlock(world, i + 39, j + 2, k + 30, stone());
	bridge.setBlock(world, i + 39, j + 3, k + 0, stone());
	bridge.setBlock(world, i + 39, j + 3, k + 1, stone());
	bridge.setBlock(world, i + 39, j + 3, k + 2, stone());
	bridge.setBlock(world, i + 39, j + 3, k + 3, stone());
	bridge.setBlock(world, i + 39, j + 3, k + 4, stone());
	bridge.setBlock(world, i + 39, j + 3, k + 5, stone());
	bridge.setBlock(world, i + 39, j + 3, k + 6, stone());
	bridge.setBlock(world, i + 39, j + 3, k + 7, stone());
	bridge.setBlock(world, i + 39, j + 3, k + 8, Blocks.COBBLESTONE);
	bridge.setBlock(world, i + 39, j + 3, k + 9, Blocks.COBBLESTONE);
	bridge.setBlock(world, i + 39, j + 3, k + 10, Blocks.COBBLESTONE);
	bridge.setBlock(world, i + 39, j + 3, k + 11, stone());
	bridge.setBlock(world, i + 39, j + 3, k + 12, stone());
	bridge.setBlock(world, i + 39, j + 3, k + 13, stone());
	bridge.setBlock(world, i + 39, j + 3, k + 14, stone());
	bridge.setBlock(world, i + 39, j + 3, k + 15, stone());
	bridge.setBlock(world, i + 39, j + 3, k + 16, stone());
	//this should be air. but its also not stone()...
	bridge.setBlock(world, i + 39, j + 3, k + 17, stone());
	bridge.setBlock(world, i + 39, j + 3, k + 18, stone());
	bridge.setBlock(world, i + 39, j + 3, k + 19, stone());
	bridge.setBlock(world, i + 39, j + 3, k + 26, stone());
	bridge.setBlock(world, i + 39, j + 3, k + 27, stone());
	bridge.setBlock(world, i + 39, j + 3, k + 28, stone());
	bridge.setBlock(world, i + 39, j + 3, k + 29, stone());
	bridge.setBlock(world, i + 39, j + 3, k + 30, stone());
	bridge.setBlock(world, i + 39, j + 4, k + 0, stone());
	bridge.setBlock(world, i + 39, j + 4, k + 1, stone());
	bridge.setBlock(world, i + 39, j + 4, k + 2, stone());
	bridge.setBlock(world, i + 39, j + 4, k + 3, stone());
	bridge.setBlock(world, i + 39, j + 4, k + 4, stone());
	bridge.setBlock(world, i + 39, j + 4, k + 5, stone());
	bridge.setBlock(world, i + 39, j + 4, k + 6, stone());
	bridge.setBlock(world, i + 39, j + 4, k + 7, stone());
	bridge.setBlock(world, i + 39, j + 4, k + 8, Blocks.COBBLESTONE);
	bridge.setBlock(world, i + 39, j + 4, k + 9, Blocks.COBBLESTONE);
	bridge.setBlock(world, i + 39, j + 4, k + 10, Blocks.COBBLESTONE);
	bridge.setBlock(world, i + 39, j + 4, k + 11, stone());
	bridge.setBlock(world, i + 39, j + 4, k + 12, stone());
	bridge.setBlock(world, i + 39, j + 4, k + 13, stone());
	bridge.setBlock(world, i + 39, j + 4, k + 14, stone());
	bridge.setBlock(world, i + 39, j + 4, k + 15, stone());
	bridge.setBlock(world, i + 39, j + 4, k + 16, stone());
	//next 4 should be air... bu t arent sstone() either...
	bridge.setBlock(world, i + 39, j + 4, k + 17, stone());
	bridge.setBlock(world, i + 39, j + 4, k + 18, stone());
	bridge.setBlock(world, i + 39, j + 4, k + 19, stone());
	bridge.setBlock(world, i + 39, j + 4, k + 20, stone());
	bridge.setBlock(world, i + 39, j + 4, k + 26, stone());
	bridge.setBlock(world, i + 39, j + 4, k + 27, stone());
	bridge.setBlock(world, i + 39, j + 4, k + 28, stone());
	bridge.setBlock(world, i + 39, j + 4, k + 29, stone());
	bridge.setBlock(world, i + 39, j + 4, k + 30, stone());
	bridge.setBlock(world, i + 39, j + 5, k + 0, JungleBlocks.mossystairs, 2, 2);
	bridge.setBlock(world, i + 39, j + 5, k + 1, JungleBlocks.ancientMossyBlock);
	bridge.setBlock(world, i + 39, j + 5, k + 2, stone());
	bridge.setBlock(world, i + 39, j + 5, k + 3, stone());
	bridge.setBlock(world, i + 39, j + 5, k + 4, stone());
	bridge.setBlock(world, i + 39, j + 5, k + 5, stone());
	bridge.setBlock(world, i + 39, j + 5, k + 6, stone());
	bridge.setBlock(world, i + 39, j + 5, k + 7, stone());
	bridge.setBlock(world, i + 39, j + 5, k + 9, Blocks.COBBLESTONE);
	bridge.setBlock(world, i + 39, j + 5, k + 11, stone());
	bridge.setBlock(world, i + 39, j + 5, k + 12, stone());
	bridge.setBlock(world, i + 39, j + 5, k + 13, stone());
	bridge.setBlock(world, i + 39, j + 5, k + 14, stone());
	bridge.setBlock(world, i + 39, j + 5, k + 15, stone());
	bridge.setBlock(world, i + 39, j + 5, k + 16, stone());
	bridge.setBlock(world, i + 39, j + 5, k + 17, stone());
	bridge.setBlock(world, i + 39, j + 5, k + 18, stone());
	bridge.setBlock(world, i + 39, j + 5, k + 19, stone());
	bridge.setBlock(world, i + 39, j + 5, k + 20, stone());
	bridge.setBlock(world, i + 39, j + 5, k + 21, stone());
	bridge.setBlock(world, i + 39, j + 5, k + 24, stone());
	bridge.setBlock(world, i + 39, j + 5, k + 25, stone());
	bridge.setBlock(world, i + 39, j + 5, k + 26, stone());
	bridge.setBlock(world, i + 39, j + 5, k + 27, stone());
	bridge.setBlock(world, i + 39, j + 5, k + 28, stone());
	bridge.setBlock(world, i + 39, j + 5, k + 29, JungleBlocks.ancientMossyBlock);
	bridge.setBlock(world, i + 39, j + 5, k + 30, this.blockRandom(null), 3, 2);
	bridge.setBlock(world, i + 39, j + 6, k + 1, JungleBlocks.mossystairs, 2, 2);
	bridge.setBlock(world, i + 39, j + 6, k + 2, JungleBlocks.ancientMossyBlock);
	bridge.setBlock(world, i + 39, j + 6, k + 3, stone());
	bridge.setBlock(world, i + 39, j + 6, k + 4, stone());
	bridge.setBlock(world, i + 39, j + 6, k + 5, stone());
	bridge.setBlock(world, i + 39, j + 6, k + 6, stone());
	bridge.setBlock(world, i + 39, j + 6, k + 7, stone());
	bridge.setBlock(world, i + 39, j + 6, k + 8, stone());
	bridge.setBlock(world, i + 39, j + 6, k + 9, stone());
	bridge.setBlock(world, i + 39, j + 6, k + 10, stone());
	bridge.setBlock(world, i + 39, j + 6, k + 11, stone());
	bridge.setBlock(world, i + 39, j + 6, k + 12, JungleBlocks.ancientMossyBlock);
	bridge.setBlock(world, i + 39, j + 6, k + 13, stone());
	bridge.setBlock(world, i + 39, j + 6, k + 14, stone());
	bridge.setBlock(world, i + 39, j + 6, k + 15, stone());
	bridge.setBlock(world, i + 39, j + 6, k + 16, stone());
	bridge.setBlock(world, i + 39, j + 6, k + 17, stone());
	bridge.setBlock(world, i + 39, j + 6, k + 18, stone());
	bridge.setBlock(world, i + 39, j + 6, k + 19, stone());
	bridge.setBlock(world, i + 39, j + 6, k + 20, stone());
	bridge.setBlock(world, i + 39, j + 6, k + 21, stone());
	bridge.setBlock(world, i + 39, j + 6, k + 22, stone());
	bridge.setBlock(world, i + 39, j + 6, k + 23, stone());
	bridge.setBlock(world, i + 39, j + 6, k + 24, stone());
	bridge.setBlock(world, i + 39, j + 6, k + 25, stone());
	bridge.setBlock(world, i + 39, j + 6, k + 26, stone());
	bridge.setBlock(world, i + 39, j + 6, k + 27, stone());
	bridge.setBlock(world, i + 39, j + 6, k + 29, JungleBlocks.mossystairs, 3, 2);
	bridge.setBlock(world, i + 39, j + 7, k + 2, this.blockRandom(null), 2, 2);
	bridge.setBlock(world, i + 39, j + 7, k + 3, JungleBlocks.ancientMossyBlock);
	bridge.setBlock(world, i + 39, j + 7, k + 4, JungleBlocks.ancientMossyBlock);
	bridge.setBlock(world, i + 39, j + 7, k + 5, JungleBlocks.ancientMossyBlock);
	bridge.setBlock(world, i + 39, j + 7, k + 6, JungleBlocks.ancientMossyBlock);
	bridge.setBlock(world, i + 39, j + 7, k + 7, JungleBlocks.ancientMossyBlock);
	bridge.setBlock(world, i + 39, j + 7, k + 8, JungleBlocks.ancientMossyBlock);
	bridge.setBlock(world, i + 39, j + 7, k + 9, JungleBlocks.ancientMossyBlock);
	bridge.setBlock(world, i + 39, j + 7, k + 10, JungleBlocks.ancientMossyBlock);
	bridge.setBlock(world, i + 39, j + 7, k + 11, JungleBlocks.ancientMossyBlock);
	bridge.setBlock(world, i + 39, j + 7, k + 12, JungleBlocks.ancientMossyBlock);
	bridge.setBlock(world, i + 39, j + 7, k + 13, JungleBlocks.ancientMossyBlock);
	bridge.setBlock(world, i + 39, j + 7, k + 14, JungleBlocks.ancientMossyBlock);
	bridge.setBlock(world, i + 39, j + 7, k + 15, JungleBlocks.ancientMossyBlock);
	bridge.setBlock(world, i + 39, j + 7, k + 16, JungleBlocks.ancientMossyBlock);
	bridge.setBlock(world, i + 39, j + 7, k + 17, JungleBlocks.ancientMossyBlock);
	bridge.setBlock(world, i + 39, j + 7, k + 18, JungleBlocks.ancientMossyBlock);
	bridge.setBlock(world, i + 39, j + 7, k + 19, JungleBlocks.ancientMossyBlock);
	bridge.setBlock(world, i + 39, j + 7, k + 20, JungleBlocks.ancientMossyBlock);
	bridge.setBlock(world, i + 39, j + 7, k + 21, JungleBlocks.ancientMossyBlock);
	bridge.setBlock(world, i + 39, j + 7, k + 22, JungleBlocks.ancientMossyBlock);
	bridge.setBlock(world, i + 39, j + 7, k + 23, JungleBlocks.ancientMossyBlock);
	bridge.setBlock(world, i + 39, j + 7, k + 24, JungleBlocks.ancientMossyBlock);
	bridge.setBlock(world, i + 39, j + 7, k + 25, JungleBlocks.ancientMossyBlock);
	bridge.setBlock(world, i + 39, j + 7, k + 26, JungleBlocks.ancientMossyBlock);
	bridge.setBlock(world, i + 39, j + 7, k + 27, JungleBlocks.ancientMossyBlock);
	bridge.setBlock(world, i + 39, j + 8, k + 3, this.blockRandom(null), 1, 2);
	bridge.setBlock(world, i + 39, j + 8, k + 4, this.blockRandom(null), 1, 2);
	bridge.setBlock(world, i + 39, j + 8, k + 5, JungleBlocks.mossystairs, 1, 2);
	bridge.setBlock(world, i + 39, j + 8, k + 6, JungleBlocks.mossystairs, 1, 2);
	bridge.setBlock(world, i + 39, j + 8, k + 7, JungleBlocks.mossystairs, 1, 2);
	bridge.setBlock(world, i + 39, j + 8, k + 8, this.blockRandom(null), 1, 2);
	bridge.setBlock(world, i + 39, j + 8, k + 9, JungleBlocks.mossystairs, 1, 2);
	bridge.setBlock(world, i + 39, j + 8, k + 10, JungleBlocks.mossystairs, 1, 2);
	bridge.setBlock(world, i + 39, j + 8, k + 11, JungleBlocks.mossystairs, 1, 2);

	generate10(world, rand, i, j, k);
	return true;
}

public boolean generate10(World world, Random rand, int i, int j, int k) {
	bridge.setBlock(world, i + 39, j + 8, k + 12, JungleBlocks.ancientMossyBlock);
	bridge.setBlock(world, i + 39, j + 8, k + 13, JungleBlocks.mossystairs, 1, 2);
	bridge.setBlock(world, i + 39, j + 8, k + 14, JungleBlocks.mossystairs, 1, 2);
	bridge.setBlock(world, i + 39, j + 8, k + 15, JungleBlocks.mossystairs, 1, 2);
	bridge.setBlock(world, i + 39, j + 8, k + 16, this.blockRandom(null), 1, 2);
	bridge.setBlock(world, i + 39, j + 8, k + 17, this.blockRandom(null), 1, 2);
	bridge.setBlock(world, i + 39, j + 8, k + 18, JungleBlocks.ancientMossyBlock);
	bridge.setBlock(world, i + 39, j + 8, k + 19, JungleBlocks.mossystairs, 1, 2);
	bridge.setBlock(world, i + 39, j + 8, k + 20, this.blockRandom(null), 1, 2);
	bridge.setBlock(world, i + 39, j + 8, k + 22, JungleBlocks.mossystairs, 1, 2);
	bridge.setBlock(world, i + 39, j + 8, k + 24, JungleBlocks.mossystairs, 1, 2);
	bridge.setBlock(world, i + 39, j + 8, k + 26, JungleBlocks.mossystairs, 1, 2);
	bridge.setBlock(world, i + 39, j + 8, k + 27, JungleBlocks.mossystairs, 3, 2);
	bridge.setBlock(world, i + 39, j + 9, k + 12, JungleBlocks.ancientMossyBlock);
	bridge.setBlock(world, i + 39, j + 9, k + 18, JungleBlocks.ancientMossyBlock);
	bridge.setBlock(world, i + 39, j + 10, k + 12, Blocks.COBBLESTONE_WALL, 1, 2);
	bridge.setBlock(world, i + 39, j + 10, k + 18, Blocks.COBBLESTONE_WALL, 1, 2);
	bridge.setBlock(world, i + 39, j + 11, k + 12, Blocks.COBBLESTONE_WALL, 1, 2);
	bridge.setBlock(world, i + 39, j + 11, k + 18, Blocks.COBBLESTONE_WALL, 1, 2);
	bridge.setBlock(world, i + 39, j + 12, k + 12, JungleBlocks.mossystairs);
	bridge.setBlock(world, i + 39, j + 12, k + 18, JungleBlocks.mossystairs);
	bridge.setBlock(world, i + 40, j + 0, k + 0, stone());
	bridge.setBlock(world, i + 40, j + 0, k + 1, stone());
	bridge.setBlock(world, i + 40, j + 0, k + 2, stone());
	bridge.setBlock(world, i + 40, j + 0, k + 3, stone());
	bridge.setBlock(world, i + 40, j + 0, k + 4, stone());
	bridge.setBlock(world, i + 40, j + 0, k + 5, stone());
	bridge.setBlock(world, i + 40, j + 0, k + 6, stone());
	bridge.setBlock(world, i + 40, j + 0, k + 7, stone());
	bridge.setBlock(world, i + 40, j + 0, k + 8, stone());
	bridge.setBlock(world, i + 40, j + 0, k + 9, stone());
	bridge.setBlock(world, i + 40, j + 0, k + 10, stone());
	bridge.setBlock(world, i + 40, j + 0, k + 11, stone());
	bridge.setBlock(world, i + 40, j + 0, k + 12, stone());
	bridge.setBlock(world, i + 40, j + 0, k + 13, stone());
	bridge.setBlock(world, i + 40, j + 0, k + 14, stone());
	bridge.setBlock(world, i + 40, j + 0, k + 15, stone());
	bridge.setBlock(world, i + 40, j + 0, k + 16, stone());
	bridge.setBlock(world, i + 40, j + 0, k + 17, stone());
	bridge.setBlock(world, i + 40, j + 0, k + 18, stone());
	bridge.setBlock(world, i + 40, j + 0, k + 19, stone());
	bridge.setBlock(world, i + 40, j + 0, k + 20, stone());
	bridge.setBlock(world, i + 40, j + 0, k + 21, stone());
	bridge.setBlock(world, i + 40, j + 0, k + 22, stone());
	bridge.setBlock(world, i + 40, j + 0, k + 23, stone());
	bridge.setBlock(world, i + 40, j + 0, k + 24, stone());
	bridge.setBlock(world, i + 40, j + 0, k + 25, stone());
	bridge.setBlock(world, i + 40, j + 0, k + 26, stone());
	bridge.setBlock(world, i + 40, j + 0, k + 27, stone());
	bridge.setBlock(world, i + 40, j + 0, k + 28, stone());
	bridge.setBlock(world, i + 40, j + 0, k + 29, stone());
	bridge.setBlock(world, i + 40, j + 0, k + 30, stone());
	bridge.setBlock(world, i + 40, j + 1, k + 0, stone());
	bridge.setBlock(world, i + 40, j + 1, k + 1, stone());
	bridge.setBlock(world, i + 40, j + 1, k + 2, stone());
	bridge.setBlock(world, i + 40, j + 1, k + 3, stone());
	bridge.setBlock(world, i + 40, j + 1, k + 4, stone());
	bridge.setBlock(world, i + 40, j + 1, k + 5, stone());
	bridge.setBlock(world, i + 40, j + 1, k + 6, stone());
	bridge.setBlock(world, i + 40, j + 1, k + 7, stone());
	bridge.setBlock(world, i + 40, j + 1, k + 8, stone());
	bridge.setBlock(world, i + 40, j + 1, k + 9, stone());
	bridge.setBlock(world, i + 40, j + 1, k + 10, stone());
	bridge.setBlock(world, i + 40, j + 1, k + 11, stone());
	bridge.setBlock(world, i + 40, j + 1, k + 12, stone());
	bridge.setBlock(world, i + 40, j + 1, k + 13, stone());
	bridge.setBlock(world, i + 40, j + 1, k + 14, stone());
	bridge.setBlock(world, i + 40, j + 1, k + 15, stone());
	bridge.setBlock(world, i + 40, j + 1, k + 16, stone());
	bridge.setBlock(world, i + 40, j + 1, k + 17, stone());
	bridge.setBlock(world, i + 40, j + 1, k + 18, stone());
	bridge.setBlock(world, i + 40, j + 1, k + 19, stone());
	bridge.setBlock(world, i + 40, j + 1, k + 20, stone());
	bridge.setBlock(world, i + 40, j + 1, k + 21, stone());
	bridge.setBlock(world, i + 40, j + 1, k + 25, stone());
	bridge.setBlock(world, i + 40, j + 1, k + 26, stone());
	bridge.setBlock(world, i + 40, j + 1, k + 27, stone());
	bridge.setBlock(world, i + 40, j + 1, k + 28, stone());
	bridge.setBlock(world, i + 40, j + 1, k + 29, stone());
	bridge.setBlock(world, i + 40, j + 1, k + 30, stone());
	bridge.setBlock(world, i + 40, j + 2, k + 0, stone());
	bridge.setBlock(world, i + 40, j + 2, k + 1, stone());
	bridge.setBlock(world, i + 40, j + 2, k + 2, stone());
	bridge.setBlock(world, i + 40, j + 2, k + 3, stone());
	bridge.setBlock(world, i + 40, j + 2, k + 4, stone());
	bridge.setBlock(world, i + 40, j + 2, k + 5, stone());
	bridge.setBlock(world, i + 40, j + 2, k + 6, stone());
	bridge.setBlock(world, i + 40, j + 2, k + 7, stone());
	bridge.setBlock(world, i + 40, j + 2, k + 8, stone());
	bridge.setBlock(world, i + 40, j + 2, k + 9, stone());
	bridge.setBlock(world, i + 40, j + 2, k + 10, stone());
	bridge.setBlock(world, i + 40, j + 2, k + 11, stone());
	bridge.setBlock(world, i + 40, j + 2, k + 12, stone());
	bridge.setBlock(world, i + 40, j + 2, k + 13, stone());
	bridge.setBlock(world, i + 40, j + 2, k + 14, stone());
	bridge.setBlock(world, i + 40, j + 2, k + 15, stone());
	bridge.setBlock(world, i + 40, j + 2, k + 16, stone());
	bridge.setBlock(world, i + 40, j + 2, k + 17, stone());
	bridge.setBlock(world, i + 40, j + 2, k + 18, stone());
	bridge.setBlock(world, i + 40, j + 2, k + 19, stone());
	bridge.setBlock(world, i + 40, j + 2, k + 20, stone());
	bridge.setBlock(world, i + 40, j + 2, k + 21, Blocks.AIR);
	bridge.setBlock(world, i + 40, j + 2, k + 22, Blocks.AIR);
	bridge.setBlock(world, i + 40, j + 2, k + 23, Blocks.AIR);
	bridge.setBlock(world, i + 40, j + 2, k + 24, Blocks.AIR);
	bridge.setBlock(world, i + 40, j + 2, k + 25, stone());
	bridge.setBlock(world, i + 40, j + 2, k + 26, stone());
	bridge.setBlock(world, i + 40, j + 2, k + 27, stone());
	bridge.setBlock(world, i + 40, j + 2, k + 28, stone());
	bridge.setBlock(world, i + 40, j + 2, k + 29, stone());
	bridge.setBlock(world, i + 40, j + 2, k + 30, stone());
	bridge.setBlock(world, i + 40, j + 3, k + 0, stone());
	bridge.setBlock(world, i + 40, j + 3, k + 1, stone());
	bridge.setBlock(world, i + 40, j + 3, k + 2, stone());
	bridge.setBlock(world, i + 40, j + 3, k + 3, stone());
	bridge.setBlock(world, i + 40, j + 3, k + 4, stone());
	bridge.setBlock(world, i + 40, j + 3, k + 5, stone());
	bridge.setBlock(world, i + 40, j + 3, k + 6, stone());
	bridge.setBlock(world, i + 40, j + 3, k + 7, stone());
	bridge.setBlock(world, i + 40, j + 3, k + 8, stone());
	bridge.setBlock(world, i + 40, j + 3, k + 9, stone());
	bridge.setBlock(world, i + 40, j + 3, k + 10, stone());
	bridge.setBlock(world, i + 40, j + 3, k + 11, stone());
	bridge.setBlock(world, i + 40, j + 3, k + 12, stone());
	bridge.setBlock(world, i + 40, j + 3, k + 13, stone());
	bridge.setBlock(world, i + 40, j + 3, k + 14, stone());
	bridge.setBlock(world, i + 40, j + 3, k + 15, stone());
	bridge.setBlock(world, i + 40, j + 3, k + 16, stone());
	bridge.setBlock(world, i + 40, j + 3, k + 17, stone());
	bridge.setBlock(world, i + 40, j + 3, k + 18, stone());
	bridge.setBlock(world, i + 40, j + 3, k + 19, stone());
	bridge.setBlock(world, i + 40, j + 3, k + 20, stone());
	bridge.setBlock(world, i + 40, j + 3, k + 25, stone());
	bridge.setBlock(world, i + 40, j + 3, k + 26, stone());
	bridge.setBlock(world, i + 40, j + 3, k + 27, stone());
	bridge.setBlock(world, i + 40, j + 3, k + 28, stone());
	bridge.setBlock(world, i + 40, j + 3, k + 29, stone());
	bridge.setBlock(world, i + 40, j + 3, k + 30, stone());
	bridge.setBlock(world, i + 40, j + 4, k + 0, stone());
	bridge.setBlock(world, i + 40, j + 4, k + 1, stone());
	bridge.setBlock(world, i + 40, j + 4, k + 2, stone());
	bridge.setBlock(world, i + 40, j + 4, k + 3, stone());
	bridge.setBlock(world, i + 40, j + 4, k + 4, stone());
	bridge.setBlock(world, i + 40, j + 4, k + 5, stone());
	bridge.setBlock(world, i + 40, j + 4, k + 6, stone());
	bridge.setBlock(world, i + 40, j + 4, k + 7, stone());
	bridge.setBlock(world, i + 40, j + 4, k + 8, stone());
	bridge.setBlock(world, i + 40, j + 4, k + 9, stone());
	bridge.setBlock(world, i + 40, j + 4, k + 10, stone());
	bridge.setBlock(world, i + 40, j + 4, k + 11, stone());
	bridge.setBlock(world, i + 40, j + 4, k + 12, stone());
	bridge.setBlock(world, i + 40, j + 4, k + 13, stone());
	bridge.setBlock(world, i + 40, j + 4, k + 14, stone());
	bridge.setBlock(world, i + 40, j + 4, k + 15, stone());
	bridge.setBlock(world, i + 40, j + 4, k + 16, stone());
	bridge.setBlock(world, i + 40, j + 4, k + 17, stone());
	bridge.setBlock(world, i + 40, j + 4, k + 18, stone());
	bridge.setBlock(world, i + 40, j + 4, k + 19, stone());
	bridge.setBlock(world, i + 40, j + 4, k + 20, stone());
	bridge.setBlock(world, i + 40, j + 4, k + 21, stone());
	bridge.setBlock(world, i + 40, j + 4, k + 22, stone());
	bridge.setBlock(world, i + 40, j + 4, k + 24, stone());
	bridge.setBlock(world, i + 40, j + 4, k + 25, stone());
	bridge.setBlock(world, i + 40, j + 4, k + 26, stone());
	bridge.setBlock(world, i + 40, j + 4, k + 27, stone());
	bridge.setBlock(world, i + 40, j + 4, k + 28, stone());
	bridge.setBlock(world, i + 40, j + 4, k + 29, stone());
	bridge.setBlock(world, i + 40, j + 4, k + 30, stone());
	bridge.setBlock(world, i + 40, j + 5, k + 0, JungleBlocks.mossystairs, 2, 2);
	bridge.setBlock(world, i + 40, j + 5, k + 1, JungleBlocks.ancientMossyBlock);
	bridge.setBlock(world, i + 40, j + 5, k + 2, stone());
	bridge.setBlock(world, i + 40, j + 5, k + 3, stone());
	bridge.setBlock(world, i + 40, j + 5, k + 4, stone());
	bridge.setBlock(world, i + 40, j + 5, k + 5, stone());
	bridge.setBlock(world, i + 40, j + 5, k + 6, stone());
	bridge.setBlock(world, i + 40, j + 5, k + 7, stone());
	bridge.setBlock(world, i + 40, j + 5, k + 8, stone());
	bridge.setBlock(world, i + 40, j + 5, k + 9, Blocks.COBBLESTONE);
	bridge.setBlock(world, i + 40, j + 5, k + 10, stone());
	bridge.setBlock(world, i + 40, j + 5, k + 11, stone());
	bridge.setBlock(world, i + 40, j + 5, k + 12, stone());
	bridge.setBlock(world, i + 40, j + 5, k + 13, stone());
	bridge.setBlock(world, i + 40, j + 5, k + 14, stone());
	bridge.setBlock(world, i + 40, j + 5, k + 15, stone());
	bridge.setBlock(world, i + 40, j + 5, k + 16, stone());
	bridge.setBlock(world, i + 40, j + 5, k + 17, stone());
	bridge.setBlock(world, i + 40, j + 5, k + 18, stone());
	bridge.setBlock(world, i + 40, j + 5, k + 19, stone());
	bridge.setBlock(world, i + 40, j + 5, k + 20, stone());
	bridge.setBlock(world, i + 40, j + 5, k + 21, stone());
	bridge.setBlock(world, i + 40, j + 5, k + 22, stone());
	bridge.setBlock(world, i + 40, j + 5, k + 23, stone());
	bridge.setBlock(world, i + 40, j + 5, k + 24, JungleBlocks.ancientMossyBlock);
