// MADE BY MITHION'S .SCHEMATIC TO JAVA CONVERTING TOOL v1.6 ***
//with corrections!
//pumpkin filling for spawners, glass filling for brazier

package com.salvestrom.w2theJungle.worldGen.structures;

import java.util.Random;

import com.salvestrom.w2theJungle.blocks.mossySlab;
import com.salvestrom.w2theJungle.blocks.mossySlab.EnumType;
import com.salvestrom.w2theJungle.init.JungleBlocks;

import net.minecraft.block.Block;
import net.minecraft.block.BlockStoneSlab;
import net.minecraft.init.Blocks;
import net.minecraft.util.math.BlockPos;
import net.minecraft.world.World;
import net.minecraft.world.gen.feature.WorldGenerator;

// one is at i30 j3 k9-13. air. second is at i38 j2 k19-24... dditional null blocks have appeared at:
// i39 j3-4 k17-24ish. find out why..
//careful with the new fill method. some existing for loops are < NOT <=
//j17 is main floor level.


public class lostTempleWG extends WorldGenerator
{

	public fillWithBlocks fill = new fillWithBlocks();
	public blockPlacmentBridge bridge = new blockPlacmentBridge();
	public String rota = "e";
	public World world;
	
	@Override
	public boolean generate(World wrld, Random rnd, BlockPos pos) {

		int x = pos.getX();
		int y = pos.getY();
		int z = pos.getZ();
		
		return this.generate(wrld, rnd, x, y, z);
	}
	
	public void theBuck(World world, Random rnd, int x, int y, int z) {
		
		this.world = world;

		this.generate(world, rnd, x, 0, z); //south
		this.generate(world, rnd, -x, 0, -z); //north
		this.generate(world, rnd, -z, 0, -x); //west
		this.generate(world, rnd, z, 0, x); //east
	}
	
	public Block[] GetValidSpawnBlocks()
	{
		return new Block[] {	
				Blocks.STONE,
				Blocks.GRASS,
				Blocks.DIRT
				};
	}

	public boolean LocationIsValidSpawn(World world, int i, int j, int k){
		int distanceToAir = 0;
		
		BlockPos pos = new BlockPos(i, j, k);
		Block checkID = world.getBlockState(pos).getBlock();

		if (checkID != Blocks.AIR)
		{
			distanceToAir++;
			checkID = world.getBlockState(pos.add(0, distanceToAir, 0)).getBlock();
		}

		if (distanceToAir > 15){
			return false;
		}
		j += distanceToAir-1;
		pos = new BlockPos(i, j, k);

		//adjusting these will raise/lower the building
		Block blockID = world.getBlockState(pos).getBlock();
		Block blockIDAbove = world.getBlockState(pos.add(0, 1, 0)).getBlock();
		Block blockIDBelow = world.getBlockState(pos.add(0, -1, 0)).getBlock();
		
		for (Block x : GetValidSpawnBlocks()){
			if (blockIDAbove != Blocks.AIR){
				return false;
			}
			if (blockID == x){
				return true;
			}else if (blockID == Blocks.SNOW && blockIDBelow == x){
				return true;
			}
		}
		return false;
	}
	
	public Block stone()
	{
		Random rnd = new Random();

		return rnd.nextInt(5) < 2 ? Blocks.STONE : JungleBlocks.mossyStone; 
	}

	public Block blockRandom(String s) {
		
		Random rnd = new Random();

		Block block;
		Block block2;
		
		if(s == "mossSmoothSlab") {
			block = JungleBlocks.mossyslabSingle.getDefaultState().withProperty(mossySlab.VARIANT, EnumType.MOSSY_SMOOTH_SLAB).getBlock();  //smooth
			block2 = Blocks.STONE_SLAB.getDefaultState().withProperty(BlockStoneSlab.VARIANT, BlockStoneSlab.EnumType.SMOOTHBRICK).getBlock();
			} else if(s == "mossCobbSlab") {
				block = JungleBlocks.mossyslabSingle.getDefaultState().withProperty(mossySlab.VARIANT, EnumType.MOSSY_SLAB).getBlock();  //cobbled
				block2 = Blocks.STONE_SLAB.getDefaultState().withProperty(BlockStoneSlab.VARIANT, BlockStoneSlab.EnumType.COBBLESTONE).getBlock();
				} else if(s == "mossSmoothStairs") {
					block = JungleBlocks.mossyStoneSteps;
					block2 = Blocks.STONE_BRICK_STAIRS;
					} else {
						block = JungleBlocks.mossystairs;
						block2 = Blocks.STONE_STAIRS;
		
					}
					
		return rnd.nextInt(7) == 0 ? block2 : block;
			}
	
	public lostTempleWG() {}
	
	public void setBlock(int x, int y, int z, Block block)
	{
		BlockPos pos = new BlockPos(x, y, z);
		
		this.world.setBlockState(pos, block.getDefaultState());
	}
	
	public void setBlock(int x, int y, int z, Block block, int i1, int i2)
	{
		BlockPos pos = new BlockPos(x, y, z);
		//TODO
		if(i1 == 0)
		{
			this.world.setBlockState(pos, block.getDefaultState(), i1);
		}
	}


	public boolean generate(World world, Random rand, int x, int y, int z) {
		
		//x*=16;
		//z*=16;
		this.world = world;
		y=world.getTopSolidOrLiquidBlock(new BlockPos(x+20, 0, z+15)).getY();
			
		int i = x;
		int j = y;
		int k = z;
		
		//if(!LocationIsValidSpawn(world, i, j, k) || !LocationIsValidSpawn(world, i + 58, j, k) || !LocationIsValidSpawn(world, i + 58, j, k + 30) || !LocationIsValidSpawn(world, i, j, k + 30))
		//if(!LocationIsValidSpawn(world, i + 30, j, k+9) || !LocationIsValidSpawn(world, i + 30, j, k + 21))	{return false;}
	
		j -= 5;

		fill.fillWithRotation(world, i, j, k, 0, 0, 0, 4, 4, 6, stone(), rota);
		fill.fillWithRotation(world, i, j, k, 0, 0, 0, 4, 16, 21, stone(), rota);
		fill.fillWithRotationAndMeta(world, i, j, k, 6, 24, 0, 29, 8, 22, Blocks.AIR, 0, 1, rota);
		fill.fillWithRotation(world, i, j, k, 0, 0, 5, 10, 4, 6, stone(), rota);
		fill.fillWithRotation(world, i, j, k, 0, 0, 5, 6, 16, 19, stone(), rota);
		fill.fillWithRotation(world, i, j, k, 0, 0, 7, 7, 16, 18, stone(), rota);

		bridge.setBlock(world, i + 0, j + 7, k + 24, stone());
		bridge.setBlock(world, i + 0, j + 8, k + 16, stone());
		bridge.setBlock(world, i + 0, j + 8, k + 17, stone());
		bridge.setBlock(world, i + 0, j + 8, k + 24, stone());
		bridge.setBlock(world, i + 0, j + 9, k + 16, stone());
		bridge.setBlock(world, i + 0, j + 9, k + 24, stone());
		bridge.setBlock(world, i + 0, j + 10, k + 23, stone());
		bridge.setBlock(world, i + 0, j + 10, k + 24, stone());
		bridge.setBlock(world, i + 0, j + 11, k + 4, stone());
		bridge.setBlock(world, i + 0, j + 11, k + 5, stone());
		bridge.setBlock(world, i + 0, j + 11, k + 23, stone());
		bridge.setBlock(world, i + 0, j + 11, k + 24, stone());
		bridge.setBlock(world, i + 0, j + 12, k + 5, stone());
		bridge.setBlock(world, i + 0, j + 12, k + 23, stone());
		bridge.setBlock(world, i + 0, j + 12, k + 24, stone());
		bridge.setBlock(world, i + 0, j + 13, k + 23, stone());
		bridge.setBlock(world, i + 0, j + 13, k + 24, stone());
		bridge.setBlock(world, i + 0, j + 14, k + 23, stone());
		bridge.setBlock(world, i + 0, j + 14, k + 24, stone());
		bridge.setBlock(world, i + 0, j + 15, k + 22, stone());
		bridge.setBlock(world, i + 0, j + 15, k + 23, stone());
		bridge.setBlock(world, i + 0, j + 15, k + 24, stone());
		bridge.setBlock(world, i + 0, j + 16, k + 23, stone());
		bridge.setBlock(world, i + 0, j + 16, k + 24, stone());
		bridge.setBlock(world, i + 0, j + 17, k + 23, stone());
		bridge.setBlock(world, i + 0, j + 17, k + 24, stone());
		bridge.setBlock(world, i + 0, j + 18, k + 24, stone());
		
		for (int fill = 3; fill < 11; ++fill) {
			for(int fillj = 0; fillj <= 5; fillj++) {
				bridge.setBlock(world, i + 1, j + fillj, k + fill, stone());
				}
			}

		for (int fill = 15; fill < 24; ++fill)
			{
			bridge.setBlock(world, i + 1, j + 0, k + fill, stone());
			bridge.setBlock(world, i + 1, j + 1, k + fill, stone());
			
			bridge.setBlock(world, i + 1, j + 4, k + fill, stone());
			bridge.setBlock(world, i + 1, j + 5, k + fill, stone());
			}

		for (int fill = 16; fill < 24; ++fill) {
			bridge.setBlock(world, i + 1, j + 2, k + fill, stone());
			bridge.setBlock(world, i + 1, j + 3, k + fill, stone());
			}

		for (int fill = 3; fill < 11; ++fill) {
			for(int fillj = 6; fillj <= 10; fillj++) {
				bridge.setBlock(world, i + 1, j + fillj, k + fill, stone());
			}
		}
		
		{int iplus = 1;
		for(int jplus = 6; jplus <= 8; jplus++) {
			for(int kplus = 15; kplus <= 19; kplus++) {
				bridge.setBlock(world, i + iplus, j + jplus, k + kplus, stone());
			}
		}
		for(int jplus = 9; jplus <= 10; jplus++) {
			for(int kplus = 15; kplus <= 18; kplus++) {
				bridge.setBlock(world, i + iplus, j + jplus, k + kplus, stone());				
			}
		}
		}
		
		bridge.setBlock(world, i + 1, j + 6, k + 20, stone());
		bridge.setBlock(world, i + 1, j + 6, k + 23, stone());
		
		bridge.setBlock(world, i + 1, j + 7, k + 23, stone());
		bridge.setBlock(world, i + 1, j + 7, k + 24, stone());
		
		bridge.setBlock(world, i + 1, j + 8, k + 23, stone());
		bridge.setBlock(world, i + 1, j + 8, k + 24, stone());
		bridge.setBlock(world, i + 1, j + 8, k + 25, stone());

		bridge.setBlock(world, i + 1, j + 9, k + 22, stone());
		bridge.setBlock(world, i + 1, j + 9, k + 23, stone());
		bridge.setBlock(world, i + 1, j + 9, k + 24, stone());
		bridge.setBlock(world, i + 1, j + 9, k + 25, stone());
		
		bridge.setBlock(world, i + 1, j + 10, k + 22, stone());
		bridge.setBlock(world, i + 1, j + 10, k + 23, stone());
		bridge.setBlock(world, i + 1, j + 10, k + 24, stone());
		bridge.setBlock(world, i + 1, j + 10, k + 25, stone());
		
		for(int fk = 4; fk <= 10; fk++) {bridge.setBlock(world, i + 1, j + 11, k + fk, stone());}

		bridge.setBlock(world, i + 1, j + 11, k + 16, stone());
		bridge.setBlock(world, i + 1, j + 11, k + 17, stone());
		bridge.setBlock(world, i + 1, j + 11, k + 18, stone());
		bridge.setBlock(world, i + 1, j + 11, k + 22, stone());
		bridge.setBlock(world, i + 1, j + 11, k + 23, stone());
		bridge.setBlock(world, i + 1, j + 11, k + 24, stone());
		bridge.setBlock(world, i + 1, j + 11, k + 25, stone());
		
		for(int fk = 4; fk <= 10; fk++) {bridge.setBlock(world, i + 1, j + 12, k + fk, stone());}

		bridge.setBlock(world, i + 1, j + 12, k + 16, stone());
		bridge.setBlock(world, i + 1, j + 12, k + 17, stone());
		bridge.setBlock(world, i + 1, j + 12, k + 18, stone());
		bridge.setBlock(world, i + 1, j + 12, k + 22, stone());
		bridge.setBlock(world, i + 1, j + 12, k + 23, stone());
		bridge.setBlock(world, i + 1, j + 12, k + 24, stone());
		bridge.setBlock(world, i + 1, j + 12, k + 25, stone());
		bridge.setBlock(world, i + 1, j + 13, k + 4, stone());
		bridge.setBlock(world, i + 1, j + 13, k + 5, stone());
		bridge.setBlock(world, i + 1, j + 13, k + 6, stone());
		bridge.setBlock(world, i + 1, j + 13, k + 7, Blocks.COBBLESTONE);
		bridge.setBlock(world, i + 1, j + 13, k + 8, stone());
		bridge.setBlock(world, i + 1, j + 13, k + 9, stone());
		bridge.setBlock(world, i + 1, j + 13, k + 10, stone());
		bridge.setBlock(world, i + 1, j + 13, k + 16, stone());
		bridge.setBlock(world, i + 1, j + 13, k + 17, stone());
		bridge.setBlock(world, i + 1, j + 13, k + 22, stone());
		bridge.setBlock(world, i + 1, j + 13, k + 23, stone());
		bridge.setBlock(world, i + 1, j + 13, k + 24, stone());
		bridge.setBlock(world, i + 1, j + 13, k + 25, stone());
		bridge.setBlock(world, i + 1, j + 14, k + 4, stone());
		bridge.setBlock(world, i + 1, j + 14, k + 5, stone());
		bridge.setBlock(world, i + 1, j + 14, k + 6, Blocks.COBBLESTONE);
		bridge.setBlock(world, i + 1, j + 14, k + 7, Blocks.COBBLESTONE);
		bridge.setBlock(world, i + 1, j + 14, k + 8, stone());
		bridge.setBlock(world, i + 1, j + 14, k + 9, stone());
		bridge.setBlock(world, i + 1, j + 14, k + 17, stone());
		bridge.setBlock(world, i + 1, j + 14, k + 22, stone());
		bridge.setBlock(world, i + 1, j + 14, k + 23, stone());
		bridge.setBlock(world, i + 1, j + 14, k + 24, stone());
		bridge.setBlock(world, i + 1, j + 14, k + 25, stone());
		bridge.setBlock(world, i + 1, j + 15, k + 4, stone());
		bridge.setBlock(world, i + 1, j + 15, k + 5, stone());
		bridge.setBlock(world, i + 1, j + 15, k + 6, Blocks.COBBLESTONE);
		bridge.setBlock(world, i + 1, j + 15, k + 7, JungleBlocks.ancientMossyBlock);
		bridge.setBlock(world, i + 1, j + 15, k + 8, JungleBlocks.ancientMossyBlock);
		bridge.setBlock(world, i + 1, j + 15, k + 9, stone());
		bridge.setBlock(world, i + 1, j + 15, k + 17, stone());
		bridge.setBlock(world, i + 1, j + 15, k + 21, stone());
		bridge.setBlock(world, i + 1, j + 15, k + 22, stone());
		bridge.setBlock(world, i + 1, j + 15, k + 23, stone());
		bridge.setBlock(world, i + 1, j + 15, k + 24, stone());
		bridge.setBlock(world, i + 1, j + 15, k + 25, stone());
		bridge.setBlock(world, i + 1, j + 16, k + 5, stone());
		bridge.setBlock(world, i + 1, j + 16, k + 6, JungleBlocks.ancientMossyBlock);
		bridge.setBlock(world, i + 1, j + 16, k + 7, JungleBlocks.ancientMossyBlock);
		bridge.setBlock(world, i + 1, j + 16, k + 8, JungleBlocks.ancientMossyBlock);
		bridge.setBlock(world, i + 1, j + 16, k + 9, stone());
		bridge.setBlock(world, i + 1, j + 16, k + 21, stone());
		bridge.setBlock(world, i + 1, j + 16, k + 22, JungleBlocks.ancientMossyBlock);
		bridge.setBlock(world, i + 1, j + 16, k + 23, JungleBlocks.ancientMossyBlock);
		bridge.setBlock(world, i + 1, j + 16, k + 24, JungleBlocks.ancientMossyBlock);
		bridge.setBlock(world, i + 1, j + 16, k + 25, stone());
		bridge.setBlock(world, i + 1, j + 17, k + 5, JungleBlocks.ancientMossyBlock);
		bridge.setBlock(world, i + 1, j + 17, k + 6, JungleBlocks.ancientMossyBlock);
		bridge.setBlock(world, i + 1, j + 17, k + 7, JungleBlocks.ancientMossyBlock);
		bridge.setBlock(world, i + 1, j + 17, k + 8, JungleBlocks.ancientMossyBlock);
		bridge.setBlock(world, i + 1, j + 17, k + 9, JungleBlocks.ancientMossyBlock);

		//fill.fillWithRotation(world, i, j, k, 1, 1, 17, 17, 10, 20, (Blocks.STONEBRICK, 1, 2), rota);
		for(int fk = 10; fk <= 20; fk++) {bridge.setBlock(world, i + 1, j + 17, k + fk, Blocks.STONEBRICK, 1, 2);}
		
		bridge.setBlock(world, i + 1, j + 17, k + 21, JungleBlocks.ancientMossyBlock);
		bridge.setBlock(world, i + 1, j + 17, k + 22, JungleBlocks.ancientMossyBlock);
		bridge.setBlock(world, i + 1, j + 17, k + 23, JungleBlocks.ancientMossyBlock);
		bridge.setBlock(world, i + 1, j + 17, k + 24, JungleBlocks.ancientMossyBlock);
		bridge.setBlock(world, i + 1, j + 17, k + 25, JungleBlocks.ancientMossyBlock);
		bridge.setBlock(world, i + 1, j + 18, k + 5, JungleBlocks.ancientMossyBlock);
		bridge.setBlock(world, i + 1, j + 18, k + 6, JungleBlocks.ancientMossyBlock);
		bridge.setBlock(world, i + 1, j + 18, k + 7, Blocks.COBBLESTONE);
		bridge.setBlock(world, i + 1, j + 18, k + 8, Blocks.COBBLESTONE);
		bridge.setBlock(world, i + 1, j + 18, k + 9, JungleBlocks.ancientMossyBlock);
		bridge.setBlock(world, i + 1, j + 18, k + 10, Blocks.COBBLESTONE_WALL, 1, 2);
		bridge.setBlock(world, i + 1, j + 18, k + 11, JungleBlocks.ancientMossyBlock);
		bridge.setBlock(world, i + 1, j + 18, k + 12, Blocks.COBBLESTONE_WALL, 1, 2);
		bridge.setBlock(world, i + 1, j + 18, k + 13, JungleBlocks.ancientMossyBlock);
		bridge.setBlock(world, i + 1, j + 18, k + 14, Blocks.COBBLESTONE_WALL, 1, 2);
		bridge.setBlock(world, i + 1, j + 18, k + 15, JungleBlocks.ancientMossyBlock);
		bridge.setBlock(world, i + 1, j + 18, k + 16, Blocks.COBBLESTONE_WALL, 1, 2);
		bridge.setBlock(world, i + 1, j + 18, k + 17, JungleBlocks.ancientMossyBlock);
		bridge.setBlock(world, i + 1, j + 18, k + 18, Blocks.COBBLESTONE_WALL, 1, 2);
		bridge.setBlock(world, i + 1, j + 18, k + 19, JungleBlocks.ancientMossyBlock);
		bridge.setBlock(world, i + 1, j + 18, k + 20, Blocks.COBBLESTONE_WALL, 1, 2);
		bridge.setBlock(world, i + 1, j + 18, k + 21, JungleBlocks.ancientMossyBlock);
		bridge.setBlock(world, i + 1, j + 18, k + 22, JungleBlocks.ancientMossyBlock);
		bridge.setBlock(world, i + 1, j + 18, k + 23, JungleBlocks.ancientMossyBlock);
		bridge.setBlock(world, i + 1, j + 18, k + 24, JungleBlocks.ancientMossyBlock);
		bridge.setBlock(world, i + 1, j + 18, k + 25, JungleBlocks.ancientMossyBlock);
		bridge.setBlock(world, i + 1, j + 19, k + 5, Blocks.COBBLESTONE_WALL, 1, 2);
		bridge.setBlock(world, i + 1, j + 19, k + 6, Blocks.STONEBRICK, 1, 2);
		bridge.setBlock(world, i + 1, j + 19, k + 8, Blocks.STONEBRICK, 1, 2);
		bridge.setBlock(world, i + 1, j + 19, k + 9, Blocks.COBBLESTONE_WALL, 1, 2);
		bridge.setBlock(world, i + 1, j + 19, k + 21, Blocks.COBBLESTONE_WALL, 1, 2);
		bridge.setBlock(world, i + 1, j + 19, k + 22, Blocks.STONEBRICK, 1, 2);
		bridge.setBlock(world, i + 1, j + 19, k + 23, Blocks.STONEBRICK, 1, 2);
		bridge.setBlock(world, i + 1, j + 19, k + 24, Blocks.STONEBRICK, 1, 2);
		bridge.setBlock(world, i + 1, j + 19, k + 25, Blocks.COBBLESTONE_WALL, 1, 2);
		bridge.setBlock(world, i + 1, j + 20, k + 5, Blocks.COBBLESTONE_WALL, 1, 2);
		bridge.setBlock(world, i + 1, j + 20, k + 6, Blocks.STONEBRICK, 1, 2);
		bridge.setBlock(world, i + 1, j + 20, k + 8, Blocks.STONEBRICK, 1, 2);
		bridge.setBlock(world, i + 1, j + 20, k + 9, Blocks.COBBLESTONE_WALL, 1, 2);
		bridge.setBlock(world, i + 1, j + 20, k + 21, Blocks.COBBLESTONE_WALL, 1, 2);
		bridge.setBlock(world, i + 1, j + 20, k + 22, Blocks.STONEBRICK, 1, 2);
		bridge.setBlock(world, i + 1, j + 20, k + 23, Blocks.STONEBRICK, 1, 2);
		bridge.setBlock(world, i + 1, j + 20, k + 24, Blocks.STONEBRICK, 1, 2);
		bridge.setBlock(world, i + 1, j + 20, k + 25, Blocks.COBBLESTONE_WALL, 1, 2);
		bridge.setBlock(world, i + 1, j + 21, k + 5, JungleBlocks.ancientMossyBlock);
		bridge.setBlock(world, i + 1, j + 21, k + 6, JungleBlocks.ancientMossyBlock);
		bridge.setBlock(world, i + 1, j + 21, k + 7, JungleBlocks.ancientMossyBlock);
		bridge.setBlock(world, i + 1, j + 21, k + 8, JungleBlocks.ancientMossyBlock);
		bridge.setBlock(world, i + 1, j + 21, k + 9, JungleBlocks.ancientMossyBlock);
		bridge.setBlock(world, i + 1, j + 21, k + 21, JungleBlocks.ancientMossyBlock);
		bridge.setBlock(world, i + 1, j + 21, k + 22, JungleBlocks.ancientMossyBlock);
		bridge.setBlock(world, i + 1, j + 21, k + 23, JungleBlocks.ancientMossyBlock);
		bridge.setBlock(world, i + 1, j + 21, k + 24, JungleBlocks.ancientMossyBlock);
		bridge.setBlock(world, i + 1, j + 21, k + 25, JungleBlocks.ancientMossyBlock);
		bridge.setBlock(world, i + 1, j + 22, k + 5, Blocks.COBBLESTONE_WALL, 1, 2);
		bridge.setBlock(world, i + 1, j + 22, k + 6, Blocks.STONEBRICK, 1, 2);
		bridge.setBlock(world, i + 1, j + 22, k + 7, Blocks.STONEBRICK, 1, 2);
		bridge.setBlock(world, i + 1, j + 22, k + 8, Blocks.STONEBRICK, 1, 2);
		bridge.setBlock(world, i + 1, j + 22, k + 9, Blocks.COBBLESTONE_WALL, 1, 2);
		bridge.setBlock(world, i + 1, j + 22, k + 21, Blocks.COBBLESTONE_WALL, 1, 2);
		bridge.setBlock(world, i + 1, j + 22, k + 22, Blocks.STONEBRICK, 1, 2);
		bridge.setBlock(world, i + 1, j + 22, k + 23, Blocks.STONEBRICK, 1, 2);
		bridge.setBlock(world, i + 1, j + 22, k + 24, Blocks.STONEBRICK, 1, 2);
		bridge.setBlock(world, i + 1, j + 22, k + 25, Blocks.COBBLESTONE_WALL, 1, 2);
		bridge.setBlock(world, i + 1, j + 23, k + 5, JungleBlocks.ancientMossyBlock);
		bridge.setBlock(world, i + 1, j + 23, k + 6, JungleBlocks.ancientMossyBlock);
		bridge.setBlock(world, i + 1, j + 23, k + 7, JungleBlocks.mossystairs);
		bridge.setBlock(world, i + 1, j + 23, k + 8, JungleBlocks.ancientMossyBlock);
		bridge.setBlock(world, i + 1, j + 23, k + 9, JungleBlocks.ancientMossyBlock);
		bridge.setBlock(world, i + 1, j + 23, k + 21, JungleBlocks.ancientMossyBlock);
		bridge.setBlock(world, i + 1, j + 23, k + 22, JungleBlocks.ancientMossyBlock);
		bridge.setBlock(world, i + 1, j + 23, k + 23, JungleBlocks.mossystairs);
		bridge.setBlock(world, i + 1, j + 23, k + 24, JungleBlocks.ancientMossyBlock);
		bridge.setBlock(world, i + 1, j + 23, k + 25, JungleBlocks.ancientMossyBlock);
		bridge.setBlock(world, i + 1, j + 24, k + 5, Blocks.COBBLESTONE_WALL, 1, 2);
		bridge.setBlock(world, i + 1, j + 24, k + 6, Blocks.STONEBRICK, 1, 2);
		bridge.setBlock(world, i + 1, j + 24, k + 8, Blocks.STONEBRICK, 1, 2);
		bridge.setBlock(world, i + 1, j + 24, k + 9, Blocks.COBBLESTONE_WALL, 1, 2);
		bridge.setBlock(world, i + 1, j + 24, k + 21, Blocks.COBBLESTONE_WALL, 1, 2);
		bridge.setBlock(world, i + 1, j + 24, k + 22, Blocks.STONEBRICK, 1, 2);
		bridge.setBlock(world, i + 1, j + 24, k + 24, Blocks.STONEBRICK, 1, 2);
		bridge.setBlock(world, i + 1, j + 24, k + 25, Blocks.COBBLESTONE_WALL, 1, 2);
		bridge.setBlock(world, i + 1, j + 25, k + 5, Blocks.COBBLESTONE_WALL, 1, 2);
		bridge.setBlock(world, i + 1, j + 25, k + 6, Blocks.STONEBRICK, 1, 2);
		bridge.setBlock(world, i + 1, j + 25, k + 8, Blocks.STONEBRICK, 1, 2);
		bridge.setBlock(world, i + 1, j + 25, k + 9, Blocks.COBBLESTONE_WALL, 1, 2);
		bridge.setBlock(world, i + 1, j + 25, k + 21, Blocks.COBBLESTONE_WALL, 1, 2);
		bridge.setBlock(world, i + 1, j + 25, k + 22, Blocks.STONEBRICK, 1, 2);
		bridge.setBlock(world, i + 1, j + 25, k + 24, Blocks.STONEBRICK, 1, 2);
		bridge.setBlock(world, i + 1, j + 25, k + 25, Blocks.COBBLESTONE_WALL, 1, 2);
		bridge.setBlock(world, i + 1, j + 26, k + 5, JungleBlocks.ancientMossyBlock);
		bridge.setBlock(world, i + 1, j + 26, k + 6, JungleBlocks.ancientMossyBlock);
		bridge.setBlock(world, i + 1, j + 26, k + 7, JungleBlocks.mossystairs, 4 , 2);
		bridge.setBlock(world, i + 1, j + 26, k + 8, JungleBlocks.ancientMossyBlock);
		bridge.setBlock(world, i + 1, j + 26, k + 9, JungleBlocks.ancientMossyBlock);
		bridge.setBlock(world, i + 1, j + 26, k + 21, JungleBlocks.ancientMossyBlock);
		bridge.setBlock(world, i + 1, j + 26, k + 22, JungleBlocks.ancientMossyBlock);
		bridge.setBlock(world, i + 1, j + 26, k + 23, JungleBlocks.mossystairs, 4 , 2);
		bridge.setBlock(world, i + 1, j + 26, k + 24, JungleBlocks.ancientMossyBlock);
		bridge.setBlock(world, i + 1, j + 26, k + 25, JungleBlocks.ancientMossyBlock);
		bridge.setBlock(world, i + 1, j + 27, k + 5, Blocks.COBBLESTONE_WALL, 1, 2);
		bridge.setBlock(world, i + 1, j + 27, k + 6, Blocks.STONEBRICK, 1, 2);
		bridge.setBlock(world, i + 1, j + 27, k + 7, Blocks.STONEBRICK, 1, 2);
		bridge.setBlock(world, i + 1, j + 27, k + 8, Blocks.STONEBRICK, 1, 2);
		bridge.setBlock(world, i + 1, j + 27, k + 9, Blocks.COBBLESTONE_WALL, 1, 2);
		bridge.setBlock(world, i + 1, j + 27, k + 21, Blocks.COBBLESTONE_WALL, 1, 2);
		bridge.setBlock(world, i + 1, j + 27, k + 22, Blocks.STONEBRICK, 1, 2);
		bridge.setBlock(world, i + 1, j + 27, k + 23, Blocks.STONEBRICK, 1, 2);
		bridge.setBlock(world, i + 1, j + 27, k + 24, Blocks.STONEBRICK);
		bridge.setBlock(world, i + 1, j + 27, k + 25, Blocks.COBBLESTONE_WALL, 1, 2);
		bridge.setBlock(world, i + 1, j + 28, k + 5, JungleBlocks.ancientMossyBlock);
		bridge.setBlock(world, i + 1, j + 28, k + 6, JungleBlocks.ancientMossyBlock);
		bridge.setBlock(world, i + 1, j + 28, k + 7, JungleBlocks.ancientMossyBlock);
		bridge.setBlock(world, i + 1, j + 28, k + 8, JungleBlocks.ancientMossyBlock);
		bridge.setBlock(world, i + 1, j + 28, k + 9, JungleBlocks.ancientMossyBlock);
		bridge.setBlock(world, i + 1, j + 28, k + 21, JungleBlocks.ancientMossyBlock);
		bridge.setBlock(world, i + 1, j + 28, k + 22, JungleBlocks.ancientMossyBlock);
		bridge.setBlock(world, i + 1, j + 28, k + 23, Blocks.COBBLESTONE);
		bridge.setBlock(world, i + 1, j + 28, k + 24, Blocks.COBBLESTONE);
		bridge.setBlock(world, i + 1, j + 28, k + 25, Blocks.COBBLESTONE);
		bridge.setBlock(world, i + 1, j + 29, k + 5, Blocks.STONEBRICK, 1, 2);
		bridge.setBlock(world, i + 1, j + 29, k + 6, this.blockRandom("mossSmoothStairs"));
		bridge.setBlock(world, i + 1, j + 29, k + 7, Blocks.STONEBRICK, 1, 2);
		bridge.setBlock(world, i + 1, j + 29, k + 8, this.blockRandom("mossSmoothStairs"));
		bridge.setBlock(world, i + 1, j + 29, k + 9, Blocks.STONEBRICK, 1, 2);
		bridge.setBlock(world, i + 1, j + 29, k + 21, Blocks.STONEBRICK, 1, 2);
		bridge.setBlock(world, i + 1, j + 29, k + 22, this.blockRandom("mossSmoothStairs"));
		bridge.setBlock(world, i + 1, j + 29, k + 23, Blocks.STONEBRICK);
		bridge.setBlock(world, i + 1, j + 29, k + 24, this.blockRandom("mossSmoothStairs"));
		bridge.setBlock(world, i + 1, j + 29, k + 25, Blocks.STONEBRICK);
		bridge.setBlock(world, i + 1, j + 30, k + 5, Blocks.COBBLESTONE);
		bridge.setBlock(world, i + 1, j + 30, k + 6, this.blockRandom(null), 4, 2);
		bridge.setBlock(world, i + 1, j + 30, k + 7, this.blockRandom(null), 4, 2);
		bridge.setBlock(world, i + 1, j + 30, k + 8, JungleBlocks.mossystairs, 4 , 2);
		bridge.setBlock(world, i + 1, j + 30, k + 9, JungleBlocks.ancientMossyBlock);
		bridge.setBlock(world, i + 1, j + 30, k + 21, JungleBlocks.ancientMossyBlock);
		bridge.setBlock(world, i + 1, j + 30, k + 22, this.blockRandom(null), 4, 2);
		bridge.setBlock(world, i + 1, j + 30, k + 23, this.blockRandom(null), 4, 2);
		bridge.setBlock(world, i + 1, j + 30, k + 24, this.blockRandom(null), 4, 2);
		bridge.setBlock(world, i + 1, j + 30, k + 25, Blocks.COBBLESTONE);
		bridge.setBlock(world, i + 1, j + 31, k + 5, Blocks.STONEBRICK);
		bridge.setBlock(world, i + 1, j + 31, k + 6, Blocks.COBBLESTONE_WALL, 1, 2);
		bridge.setBlock(world, i + 1, j + 31, k + 7, Blocks.STONEBRICK);
		bridge.setBlock(world, i + 1, j + 31, k + 8, Blocks.COBBLESTONE_WALL, 1, 2);
		bridge.setBlock(world, i + 1, j + 31, k + 9, Blocks.STONEBRICK);
		bridge.setBlock(world, i + 1, j + 31, k + 21, Blocks.STONEBRICK);
		bridge.setBlock(world, i + 1, j + 31, k + 22, Blocks.COBBLESTONE_WALL, 1, 2);
		bridge.setBlock(world, i + 1, j + 31, k + 23, Blocks.STONEBRICK);
		bridge.setBlock(world, i + 1, j + 31, k + 24, Blocks.COBBLESTONE_WALL, 1, 2);
		bridge.setBlock(world, i + 1, j + 31, k + 25, Blocks.STONEBRICK);
		bridge.setBlock(world, i + 1, j + 32, k + 5, Blocks.COBBLESTONE_WALL, 1, 2);
		bridge.setBlock(world, i + 1, j + 32, k + 9, Blocks.COBBLESTONE_WALL, 1, 2);
		bridge.setBlock(world, i + 1, j + 32, k + 10, this.blockRandom("mossCobbSlab"), 3, 2);
		bridge.setBlock(world, i + 1, j + 32, k + 11, this.blockRandom("mossCobbSlab"), 11, 2);
		bridge.setBlock(world, i + 1, j + 32, k + 19, this.blockRandom("mossCobbSlab"), 11, 2);
		bridge.setBlock(world, i + 1, j + 32, k + 20, this.blockRandom("mossCobbSlab"), 3, 2);
		bridge.setBlock(world, i + 1, j + 32, k + 21, Blocks.COBBLESTONE_WALL, 1, 2);
		bridge.setBlock(world, i + 1, j + 32, k + 25, Blocks.COBBLESTONE_WALL, 1, 2);
		bridge.setBlock(world, i + 1, j + 33, k + 12, this.blockRandom("mossCobbSlab"), 3, 2);
		bridge.setBlock(world, i + 1, j + 33, k + 13, this.blockRandom("mossCobbSlab"), 11, 2);
		bridge.setBlock(world, i + 1, j + 33, k + 17, this.blockRandom("mossCobbSlab"), 11, 2);
		bridge.setBlock(world, i + 1, j + 33, k + 18, this.blockRandom("mossCobbSlab"), 3, 2);
		bridge.setBlock(world, i + 1, j + 34, k + 14, this.blockRandom("mossCobbSlab"), 3, 2);
		bridge.setBlock(world, i + 1, j + 34, k + 15, Blocks.STONEBRICK, 1, 2);
		bridge.setBlock(world, i + 1, j + 34, k + 16, this.blockRandom("mossCobbSlab"), 3, 2);
		bridge.setBlock(world, i + 1, j + 35, k + 15, JungleBlocks.ancientMossyBlock);
		bridge.setBlock(world, i + 1, j + 36, k + 15, Blocks.COBBLESTONE_WALL, 1, 2);
		
		for(int fk = 4; fk <= 11; fk++) {bridge.setBlock(world, i + 2, j + 0, k + fk, stone());}
		for(int fk = 14; fk <= 23; fk++) {bridge.setBlock(world, i + 2, j + 0, k + fk, stone());}
		for(int fk = 4; fk <= 11; fk++) {bridge.setBlock(world, i + 2, j + 1, k + fk, stone());}
		for(int fk = 15; fk <= 23; fk++) {bridge.setBlock(world, i + 2, j + 1, k + fk, stone());}
		for(int fk = 4; fk <= 11; fk++) {bridge.setBlock(world, i + 2, j + 2, k + fk, stone());}
		for(int fk = 15; fk <= 23; fk++) {bridge.setBlock(world, i + 2, j + 2, k + fk, stone());}
		for(int fk = 4; fk <= 11; fk++) {bridge.setBlock(world, i + 2, j + 3, k + fk, stone());}
		for(int fk = 15; fk <= 23; fk++) {bridge.setBlock(world, i + 2, j + 3, k + fk, stone());}
		for(int fk = 4; fk <= 12; fk++) {bridge.setBlock(world, i + 2, j + 4, k + fk, stone());}
		for(int fk = 15; fk <= 24; fk++) {bridge.setBlock(world, i + 2, j + 4, k + fk, stone());}
		for(int fk = 4; fk <= 12; fk++) {bridge.setBlock(world, i + 2, j + 5, k + fk, stone());}
		for(int fk = 15; fk <= 24; fk++) {bridge.setBlock(world, i + 2, j + 5, k + fk, stone());}
		for(int fk = 4; fk <= 12; fk++) {bridge.setBlock(world, i + 2, j + 6, k + fk, stone());}
		for(int fk = 14; fk <= 24; fk++) {bridge.setBlock(world, i + 2, j + 6, k + fk, stone());}
		
		//here

		bridge.setBlock(world, i + 2, j + 7, k + 4, stone());
		bridge.setBlock(world, i + 2, j + 7, k + 5, stone());
		bridge.setBlock(world, i + 2, j + 7, k + 6, stone());
		bridge.setBlock(world, i + 2, j + 7, k + 7, stone());
		bridge.setBlock(world, i + 2, j + 7, k + 8, stone());
		bridge.setBlock(world, i + 2, j + 7, k + 9, stone());
		bridge.setBlock(world, i + 2, j + 7, k + 10, stone());
		bridge.setBlock(world, i + 2, j + 7, k + 11, stone());
		bridge.setBlock(world, i + 2, j + 7, k + 12, stone());
		bridge.setBlock(world, i + 2, j + 7, k + 14, stone());
		bridge.setBlock(world, i + 2, j + 7, k + 15, stone());
		bridge.setBlock(world, i + 2, j + 7, k + 16, stone());
		bridge.setBlock(world, i + 2, j + 7, k + 17, stone());
		bridge.setBlock(world, i + 2, j + 7, k + 18, stone());
		bridge.setBlock(world, i + 2, j + 7, k + 19, stone());
		bridge.setBlock(world, i + 2, j + 7, k + 20, stone());
		bridge.setBlock(world, i + 2, j + 7, k + 22, stone());
		bridge.setBlock(world, i + 2, j + 7, k + 23, stone());
		bridge.setBlock(world, i + 2, j + 7, k + 24, stone());
		bridge.setBlock(world, i + 2, j + 7, k + 25, stone());
		bridge.setBlock(world, i + 2, j + 8, k + 4, stone());
		bridge.setBlock(world, i + 2, j + 8, k + 5, stone());
		bridge.setBlock(world, i + 2, j + 8, k + 6, stone());
		bridge.setBlock(world, i + 2, j + 8, k + 7, stone());
		bridge.setBlock(world, i + 2, j + 8, k + 8, stone());
		bridge.setBlock(world, i + 2, j + 8, k + 9, stone());
		bridge.setBlock(world, i + 2, j + 8, k + 10, stone());
		bridge.setBlock(world, i + 2, j + 8, k + 11, stone());
		bridge.setBlock(world, i + 2, j + 8, k + 12, stone());
		bridge.setBlock(world, i + 2, j + 8, k + 14, stone());
		bridge.setBlock(world, i + 2, j + 8, k + 15, stone());
		bridge.setBlock(world, i + 2, j + 8, k + 16, stone());
		bridge.setBlock(world, i + 2, j + 8, k + 17, stone());
		bridge.setBlock(world, i + 2, j + 8, k + 18, stone());
		bridge.setBlock(world, i + 2, j + 8, k + 19, stone());
		bridge.setBlock(world, i + 2, j + 8, k + 20, stone());
		bridge.setBlock(world, i + 2, j + 8, k + 22, stone());
		bridge.setBlock(world, i + 2, j + 8, k + 23, stone());
		bridge.setBlock(world, i + 2, j + 8, k + 24, stone());
		bridge.setBlock(world, i + 2, j + 8, k + 25, stone());
		bridge.setBlock(world, i + 2, j + 9, k + 4, stone());
		bridge.setBlock(world, i + 2, j + 9, k + 5, stone());
		bridge.setBlock(world, i + 2, j + 9, k + 6, stone());
		bridge.setBlock(world, i + 2, j + 9, k + 7, stone());
		bridge.setBlock(world, i + 2, j + 9, k + 8, stone());
		bridge.setBlock(world, i + 2, j + 9, k + 9, stone());
		bridge.setBlock(world, i + 2, j + 9, k + 10, stone());
		bridge.setBlock(world, i + 2, j + 9, k + 11, stone());
		bridge.setBlock(world, i + 2, j + 9, k + 12, stone());
		bridge.setBlock(world, i + 2, j + 9, k + 14, stone());
		bridge.setBlock(world, i + 2, j + 9, k + 15, stone());
		bridge.setBlock(world, i + 2, j + 9, k + 16, stone());
		bridge.setBlock(world, i + 2, j + 9, k + 17, stone());
		bridge.setBlock(world, i + 2, j + 9, k + 18, stone());
		bridge.setBlock(world, i + 2, j + 9, k + 19, stone());
		bridge.setBlock(world, i + 2, j + 9, k + 20, stone());
		bridge.setBlock(world, i + 2, j + 9, k + 22, stone());
		bridge.setBlock(world, i + 2, j + 9, k + 23, stone());
		bridge.setBlock(world, i + 2, j + 9, k + 24, stone());
		bridge.setBlock(world, i + 2, j + 9, k + 25, stone());
		bridge.setBlock(world, i + 2, j + 10, k + 4, stone());
		bridge.setBlock(world, i + 2, j + 10, k + 5, stone());
		bridge.setBlock(world, i + 2, j + 10, k + 6, stone());
		bridge.setBlock(world, i + 2, j + 10, k + 7, stone());
		bridge.setBlock(world, i + 2, j + 10, k + 8, stone());
		bridge.setBlock(world, i + 2, j + 10, k + 9, stone());
		bridge.setBlock(world, i + 2, j + 10, k + 10, stone());
		bridge.setBlock(world, i + 2, j + 10, k + 11, stone());
		bridge.setBlock(world, i + 2, j + 10, k + 12, stone());
		bridge.setBlock(world, i + 2, j + 10, k + 14, stone());
		bridge.setBlock(world, i + 2, j + 10, k + 15, stone());
		bridge.setBlock(world, i + 2, j + 10, k + 16, stone());
		bridge.setBlock(world, i + 2, j + 10, k + 17, stone());
		bridge.setBlock(world, i + 2, j + 10, k + 18, stone());
		bridge.setBlock(world, i + 2, j + 10, k + 19, stone());
		bridge.setBlock(world, i + 2, j + 10, k + 21, stone());
		bridge.setBlock(world, i + 2, j + 10, k + 22, stone());
		bridge.setBlock(world, i + 2, j + 10, k + 23, stone());
		bridge.setBlock(world, i + 2, j + 10, k + 24, stone());
		bridge.setBlock(world, i + 2, j + 10, k + 25, stone());
		bridge.setBlock(world, i + 2, j + 11, k + 4, stone());
		bridge.setBlock(world, i + 2, j + 11, k + 5, stone());
		bridge.setBlock(world, i + 2, j + 11, k + 6, stone());
		bridge.setBlock(world, i + 2, j + 11, k + 7, stone());
		bridge.setBlock(world, i + 2, j + 11, k + 8, stone());
		bridge.setBlock(world, i + 2, j + 11, k + 9, stone());
		bridge.setBlock(world, i + 2, j + 11, k + 10, stone());
		bridge.setBlock(world, i + 2, j + 11, k + 11, stone());
		bridge.setBlock(world, i + 2, j + 11, k + 12, stone());
		bridge.setBlock(world, i + 2, j + 11, k + 15, stone());
		bridge.setBlock(world, i + 2, j + 11, k + 16, stone());
		bridge.setBlock(world, i + 2, j + 11, k + 17, stone());
		bridge.setBlock(world, i + 2, j + 11, k + 18, stone());
		bridge.setBlock(world, i + 2, j + 11, k + 19, stone());
		bridge.setBlock(world, i + 2, j + 11, k + 21, stone());
		bridge.setBlock(world, i + 2, j + 11, k + 22, stone());
		bridge.setBlock(world, i + 2, j + 11, k + 23, stone());
		bridge.setBlock(world, i + 2, j + 11, k + 24, stone());
		bridge.setBlock(world, i + 2, j + 11, k + 25, stone());
		bridge.setBlock(world, i + 2, j + 12, k + 4, stone());
		bridge.setBlock(world, i + 2, j + 12, k + 5, stone());
		bridge.setBlock(world, i + 2, j + 12, k + 6, JungleBlocks.ancientMossyBlock);
		bridge.setBlock(world, i + 2, j + 12, k + 7, stone());
		bridge.setBlock(world, i + 2, j + 12, k + 8, stone());
		bridge.setBlock(world, i + 2, j + 12, k + 9, stone());
		bridge.setBlock(world, i + 2, j + 12, k + 10, stone());
		bridge.setBlock(world, i + 2, j + 12, k + 11, stone());
		bridge.setBlock(world, i + 2, j + 12, k + 12, stone());
		bridge.setBlock(world, i + 2, j + 12, k + 15, stone());
		bridge.setBlock(world, i + 2, j + 12, k + 16, stone());
		bridge.setBlock(world, i + 2, j + 12, k + 17, stone());
		bridge.setBlock(world, i + 2, j + 12, k + 18, stone());
		bridge.setBlock(world, i + 2, j + 12, k + 19, stone());
		bridge.setBlock(world, i + 2, j + 12, k + 21, stone());
		bridge.setBlock(world, i + 2, j + 12, k + 22, stone());
		bridge.setBlock(world, i + 2, j + 12, k + 23, stone());
		bridge.setBlock(world, i + 2, j + 12, k + 24, stone());
		bridge.setBlock(world, i + 2, j + 12, k + 25, stone());
		bridge.setBlock(world, i + 2, j + 13, k + 5, stone());
		bridge.setBlock(world, i + 2, j + 13, k + 6, JungleBlocks.ancientMossyBlock);
		bridge.setBlock(world, i + 2, j + 13, k + 7, JungleBlocks.ancientMossyBlock);
		bridge.setBlock(world, i + 2, j + 13, k + 8, stone());
		bridge.setBlock(world, i + 2, j + 13, k + 9, stone());
		bridge.setBlock(world, i + 2, j + 13, k + 10, stone());
		bridge.setBlock(world, i + 2, j + 13, k + 11, stone());
		bridge.setBlock(world, i + 2, j + 13, k + 15, stone());
		bridge.setBlock(world, i + 2, j + 13, k + 16, stone());
		bridge.setBlock(world, i + 2, j + 13, k + 17, stone());
		bridge.setBlock(world, i + 2, j + 13, k + 18, stone());
		bridge.setBlock(world, i + 2, j + 13, k + 19, stone());
		bridge.setBlock(world, i + 2, j + 13, k + 21, stone());
		bridge.setBlock(world, i + 2, j + 13, k + 22, stone());
		bridge.setBlock(world, i + 2, j + 13, k + 23, JungleBlocks.ancientMossyBlock);
		bridge.setBlock(world, i + 2, j + 13, k + 24, stone());
		bridge.setBlock(world, i + 2, j + 13, k + 25, stone());
		bridge.setBlock(world, i + 2, j + 14, k + 5, stone());
		bridge.setBlock(world, i + 2, j + 14, k + 6, JungleBlocks.ancientMossyBlock);
		bridge.setBlock(world, i + 2, j + 14, k + 7, JungleBlocks.ancientMossyBlock);
		bridge.setBlock(world, i + 2, j + 14, k + 8, JungleBlocks.ancientMossyBlock);
		bridge.setBlock(world, i + 2, j + 14, k + 9, stone());
		bridge.setBlock(world, i + 2, j + 14, k + 10, stone());
		bridge.setBlock(world, i + 2, j + 14, k + 11, stone());
		bridge.setBlock(world, i + 2, j + 14, k + 16, stone());
		bridge.setBlock(world, i + 2, j + 14, k + 17, stone());
		bridge.setBlock(world, i + 2, j + 14, k + 18, stone());
		bridge.setBlock(world, i + 2, j + 14, k + 21, stone());
		bridge.setBlock(world, i + 2, j + 14, k + 22, stone());
		bridge.setBlock(world, i + 2, j + 14, k + 23, JungleBlocks.ancientMossyBlock);
		bridge.setBlock(world, i + 2, j + 14, k + 24, stone());
		bridge.setBlock(world, i + 2, j + 14, k + 25, stone());
		bridge.setBlock(world, i + 2, j + 15, k + 5, JungleBlocks.ancientMossyBlock);
		bridge.setBlock(world, i + 2, j + 15, k + 6, JungleBlocks.ancientMossyBlock);
		bridge.setBlock(world, i + 2, j + 15, k + 7, JungleBlocks.ancientMossyBlock);
		bridge.setBlock(world, i + 2, j + 15, k + 8, JungleBlocks.ancientMossyBlock);
		bridge.setBlock(world, i + 2, j + 15, k + 9, JungleBlocks.ancientMossyBlock);
		bridge.setBlock(world, i + 2, j + 15, k + 10, stone());
		bridge.setBlock(world, i + 2, j + 15, k + 16, stone());
		bridge.setBlock(world, i + 2, j + 15, k + 17, stone());
		bridge.setBlock(world, i + 2, j + 15, k + 18, stone());
		bridge.setBlock(world, i + 2, j + 15, k + 21, stone());
		bridge.setBlock(world, i + 2, j + 15, k + 22, stone());
		bridge.setBlock(world, i + 2, j + 15, k + 23, JungleBlocks.ancientMossyBlock);
		bridge.setBlock(world, i + 2, j + 15, k + 24, JungleBlocks.ancientMossyBlock);
		bridge.setBlock(world, i + 2, j + 15, k + 25, stone());
		bridge.setBlock(world, i + 2, j + 16, k + 5, JungleBlocks.ancientMossyBlock);
		bridge.setBlock(world, i + 2, j + 16, k + 6, JungleBlocks.ancientMossyBlock);
		bridge.setBlock(world, i + 2, j + 16, k + 7, JungleBlocks.ancientMossyBlock);
		bridge.setBlock(world, i + 2, j + 16, k + 8, JungleBlocks.ancientMossyBlock);
		bridge.setBlock(world, i + 2, j + 16, k + 9, JungleBlocks.ancientMossyBlock);
		bridge.setBlock(world, i + 2, j + 16, k + 10, stone());
		bridge.setBlock(world, i + 2, j + 16, k + 11, this.blockRandom(null), 4, 2);
		bridge.setBlock(world, i + 2, j + 16, k + 13, JungleBlocks.mossystairs, 4 , 2);
		bridge.setBlock(world, i + 2, j + 16, k + 15, JungleBlocks.mossystairs, 4 , 2);
		bridge.setBlock(world, i + 2, j + 16, k + 16, stone());
		bridge.setBlock(world, i + 2, j + 16, k + 17, stone());
		bridge.setBlock(world, i + 2, j + 16, k + 18, stone());
		bridge.setBlock(world, i + 2, j + 16, k + 19, JungleBlocks.mossystairs, 4 , 2);
		bridge.setBlock(world, i + 2, j + 16, k + 21, stone());
		bridge.setBlock(world, i + 2, j + 16, k + 22, JungleBlocks.ancientMossyBlock);
		bridge.setBlock(world, i + 2, j + 16, k + 23, JungleBlocks.ancientMossyBlock);
		bridge.setBlock(world, i + 2, j + 16, k + 24, JungleBlocks.ancientMossyBlock);
		bridge.setBlock(world, i + 2, j + 16, k + 25, JungleBlocks.ancientMossyBlock);
		bridge.setBlock(world, i + 2, j + 17, k + 5, JungleBlocks.ancientMossyBlock);
		bridge.setBlock(world, i + 2, j + 17, k + 6, JungleBlocks.ancientMossyBlock);
		bridge.setBlock(world, i + 2, j + 17, k + 7, JungleBlocks.ancientMossyBlock);
		bridge.setBlock(world, i + 2, j + 17, k + 8, JungleBlocks.ancientMossyBlock);
		bridge.setBlock(world, i + 2, j + 17, k + 9, JungleBlocks.ancientMossyBlock);
		bridge.setBlock(world, i + 2, j + 17, k + 10, JungleBlocks.ancientMossyBlock);
		bridge.setBlock(world, i + 2, j + 17, k + 11, JungleBlocks.ancientMossyBlock);
		bridge.setBlock(world, i + 2, j + 17, k + 12, JungleBlocks.ancientMossyBlock);
		bridge.setBlock(world, i + 2, j + 17, k + 13, JungleBlocks.ancientMossyBlock);
		bridge.setBlock(world, i + 2, j + 17, k + 14, JungleBlocks.ancientMossyBlock);
		bridge.setBlock(world, i + 2, j + 17, k + 15, JungleBlocks.ancientMossyBlock);
		bridge.setBlock(world, i + 2, j + 17, k + 16, JungleBlocks.ancientMossyBlock);
		bridge.setBlock(world, i + 2, j + 17, k + 17, JungleBlocks.ancientMossyBlock);
		bridge.setBlock(world, i + 2, j + 17, k + 18, JungleBlocks.ancientMossyBlock);
		bridge.setBlock(world, i + 2, j + 17, k + 19, JungleBlocks.ancientMossyBlock);
		bridge.setBlock(world, i + 2, j + 17, k + 20, JungleBlocks.ancientMossyBlock);
		bridge.setBlock(world, i + 2, j + 17, k + 21, JungleBlocks.ancientMossyBlock);
		bridge.setBlock(world, i + 2, j + 17, k + 22, JungleBlocks.ancientMossyBlock);
		bridge.setBlock(world, i + 2, j + 17, k + 23, JungleBlocks.ancientMossyBlock);
		bridge.setBlock(world, i + 2, j + 17, k + 24, JungleBlocks.ancientMossyBlock);
		bridge.setBlock(world, i + 2, j + 17, k + 25, JungleBlocks.ancientMossyBlock);
		bridge.setBlock(world, i + 2, j + 18, k + 5, JungleBlocks.ancientMossyBlock);
		bridge.setBlock(world, i + 2, j + 18, k + 9, JungleBlocks.ancientMossyBlock);
		
		for(int fillk = 21; fillk <= 25; fillk++) {bridge.setBlock(world, i + 2, j + 18, k + fillk, JungleBlocks.ancientMossyBlock);}
		
		bridge.setBlock(world, i + 2, j + 19, k + 5, Blocks.STONEBRICK, 1, 2);
		bridge.setBlock(world, i + 2, j + 19, k + 9, Blocks.STONEBRICK, 1, 2);
		bridge.setBlock(world, i + 2, j + 19, k + 21, Blocks.STONEBRICK, 1, 2);
		bridge.setBlock(world, i + 2, j + 19, k + 22, this.blockRandom(null), 1, 2);
		bridge.setBlock(world, i + 2, j + 19, k + 23, Blocks.STONEBRICK, 1, 2);
		bridge.setBlock(world, i + 2, j + 19, k + 24, Blocks.STONEBRICK, 1, 2);
		bridge.setBlock(world, i + 2, j + 19, k + 25, Blocks.STONEBRICK, 1, 2);
		bridge.setBlock(world, i + 2, j + 20, k + 5, Blocks.STONEBRICK, 1, 2);
		bridge.setBlock(world, i + 2, j + 20, k + 9, Blocks.STONEBRICK, 1, 2);
		bridge.setBlock(world, i + 2, j + 20, k + 21, Blocks.STONEBRICK, 1, 2);
		bridge.setBlock(world, i + 2, j + 20, k + 23, this.blockRandom(null), 2, 2);
		bridge.setBlock(world, i + 2, j + 20, k + 24, Blocks.STONEBRICK, 1, 2);
		bridge.setBlock(world, i + 2, j + 20, k + 25, Blocks.STONEBRICK, 1, 2);
		bridge.setBlock(world, i + 2, j + 21, k + 5, JungleBlocks.ancientMossyBlock);
		bridge.setBlock(world, i + 2, j + 21, k + 9, JungleBlocks.ancientMossyBlock);
		bridge.setBlock(world, i + 2, j + 21, k + 21, JungleBlocks.ancientMossyBlock);
		bridge.setBlock(world, i + 2, j + 21, k + 24, this.blockRandom(null), 2, 2);
		bridge.setBlock(world, i + 2, j + 21, k + 25, JungleBlocks.ancientMossyBlock);
		bridge.setBlock(world, i + 2, j + 22, k + 5, Blocks.STONEBRICK, 1, 2);
		bridge.setBlock(world, i + 2, j + 22, k + 6, JungleBlocks.ancientMossyBlock);
		bridge.setBlock(world, i + 2, j + 22, k + 7, JungleBlocks.ancientMossyBlock);
		bridge.setBlock(world, i + 2, j + 22, k + 8, JungleBlocks.ancientMossyBlock);
		bridge.setBlock(world, i + 2, j + 22, k + 9, Blocks.STONEBRICK, 1, 2);
		bridge.setBlock(world, i + 2, j + 22, k + 21, Blocks.STONEBRICK, 1, 2);
		bridge.setBlock(world, i + 2, j + 22, k + 25, Blocks.STONEBRICK, 1, 2);
		bridge.setBlock(world, i + 2, j + 23, k + 5, JungleBlocks.ancientMossyBlock);
		bridge.setBlock(world, i + 2, j + 23, k + 9, JungleBlocks.ancientMossyBlock);
		bridge.setBlock(world, i + 2, j + 23, k + 21, JungleBlocks.ancientMossyBlock);
		bridge.setBlock(world, i + 2, j + 23, k + 25, JungleBlocks.ancientMossyBlock);
		bridge.setBlock(world, i + 2, j + 24, k + 5, Blocks.STONEBRICK, 1, 2);
		bridge.setBlock(world, i + 2, j + 24, k + 9, Blocks.STONEBRICK, 1, 2);
		bridge.setBlock(world, i + 2, j + 24, k + 21, Blocks.STONEBRICK, 1, 2);
		bridge.setBlock(world, i + 2, j + 24, k + 25, Blocks.STONEBRICK, 1, 2);
		bridge.setBlock(world, i + 2, j + 25, k + 5, Blocks.STONEBRICK, 1, 2);
		bridge.setBlock(world, i + 2, j + 25, k + 9, Blocks.STONEBRICK, 1, 2);
		bridge.setBlock(world, i + 2, j + 25, k + 21, Blocks.STONEBRICK, 1, 2);
		bridge.setBlock(world, i + 2, j + 25, k + 25, Blocks.STONEBRICK, 1, 2);
		bridge.setBlock(world, i + 2, j + 26, k + 5, JungleBlocks.ancientMossyBlock);
		bridge.setBlock(world, i + 2, j + 26, k + 9, JungleBlocks.ancientMossyBlock);
		bridge.setBlock(world, i + 2, j + 26, k + 21, JungleBlocks.ancientMossyBlock);
		bridge.setBlock(world, i + 2, j + 26, k + 25, JungleBlocks.ancientMossyBlock);
		bridge.setBlock(world, i + 2, j + 27, k + 5, Blocks.STONEBRICK, 1, 2);
		bridge.setBlock(world, i + 2, j + 27, k + 9, Blocks.STONEBRICK, 1, 2);
		bridge.setBlock(world, i + 2, j + 27, k + 21, Blocks.STONEBRICK, 1, 2);
		bridge.setBlock(world, i + 2, j + 27, k + 25, Blocks.STONEBRICK, 1, 2);
		bridge.setBlock(world, i + 2, j + 28, k + 5, JungleBlocks.ancientMossyBlock);
		bridge.setBlock(world, i + 2, j + 28, k + 9, JungleBlocks.ancientMossyBlock);
		bridge.setBlock(world, i + 2, j + 28, k + 10, JungleBlocks.mossystairs, 4 , 2);
		bridge.setBlock(world, i + 2, j + 28, k + 12, JungleBlocks.mossystairs, 4 , 2);
		bridge.setBlock(world, i + 2, j + 28, k + 18, JungleBlocks.mossystairs, 4 , 2);
		bridge.setBlock(world, i + 2, j + 28, k + 20, JungleBlocks.mossystairs, 4 , 2);
		bridge.setBlock(world, i + 2, j + 28, k + 21, JungleBlocks.ancientMossyBlock);
		bridge.setBlock(world, i + 2, j + 28, k + 25, JungleBlocks.ancientMossyBlock);
		bridge.setBlock(world, i + 2, j + 29, k + 5, this.blockRandom("mossSmoothStairs"), 2, 2);
		bridge.setBlock(world, i + 2, j + 29, k + 6, JungleBlocks.ancientMossyBlock);
		bridge.setBlock(world, i + 2, j + 29, k + 7, JungleBlocks.ancientMossyBlock);
		bridge.setBlock(world, i + 2, j + 29, k + 8, JungleBlocks.ancientMossyBlock);
		
		for(int fillk = 9; fillk <= 21; fillk++) {bridge.setBlock(world, i + 2, j + 29, k + fillk, Blocks.STONEBRICK, 1, 2);}
		
		bridge.setBlock(world, i + 2, j + 29, k + 25, this.blockRandom("mossSmoothStairs"), 3, 2);
		bridge.setBlock(world, i + 2, j + 30, k + 5, this.blockRandom(null), 6, 2);
		bridge.setBlock(world, i + 2, j + 30, k + 6, JungleBlocks.ancientMossyBlock);
		bridge.setBlock(world, i + 2, j + 30, k + 7, JungleBlocks.ancientMossyBlock);
		bridge.setBlock(world, i + 2, j + 30, k + 8, JungleBlocks.ancientMossyBlock);
		bridge.setBlock(world, i + 2, j + 30, k + 9, JungleBlocks.ancientMossyBlock);
		bridge.setBlock(world, i + 2, j + 30, k + 21, JungleBlocks.ancientMossyBlock);
		bridge.setBlock(world, i + 2, j + 30, k + 22, JungleBlocks.ancientMossyBlock);
		bridge.setBlock(world, i + 2, j + 30, k + 23, JungleBlocks.ancientMossyBlock);
		bridge.setBlock(world, i + 2, j + 30, k + 24, JungleBlocks.ancientMossyBlock);
		bridge.setBlock(world, i + 2, j + 30, k + 25, this.blockRandom(null), 7, 2);
		bridge.setBlock(world, i + 2, j + 31, k + 5, Blocks.COBBLESTONE_WALL, 1, 2);
		bridge.setBlock(world, i + 2, j + 31, k + 6, JungleBlocks.ancientMossyBlock);
		bridge.setBlock(world, i + 2, j + 31, k + 7, Blocks.NETHERRACK);
		bridge.setBlock(world, i + 2, j + 31, k + 8, JungleBlocks.ancientMossyBlock);
		bridge.setBlock(world, i + 2, j + 31, k + 9, Blocks.STONEBRICK, 1, 2);
		bridge.setBlock(world, i + 2, j + 31, k + 21, Blocks.STONEBRICK);
		bridge.setBlock(world, i + 2, j + 31, k + 22, Blocks.COBBLESTONE);
		bridge.setBlock(world, i + 2, j + 31, k + 23, Blocks.NETHERRACK);
		bridge.setBlock(world, i + 2, j + 31, k + 24, Blocks.COBBLESTONE);
		bridge.setBlock(world, i + 2, j + 31, k + 25, Blocks.COBBLESTONE_WALL, 1, 2);
		bridge.setBlock(world, i + 2, j + 32, k + 7, Blocks.FIRE, 15, 2);
		bridge.setBlock(world, i + 2, j + 32, k + 10, this.blockRandom("mossCobbSlab"), 3, 2);
		bridge.setBlock(world, i + 2, j + 32, k + 11, this.blockRandom("mossCobbSlab"), 11, 2);
		bridge.setBlock(world, i + 2, j + 32, k + 19, this.blockRandom("mossCobbSlab"), 11, 2);
		bridge.setBlock(world, i + 2, j + 32, k + 20, this.blockRandom("mossCobbSlab"), 3, 2);
		bridge.setBlock(world, i + 2, j + 32, k + 23, Blocks.FIRE, 15, 2);
		bridge.setBlock(world, i + 2, j + 33, k + 12, this.blockRandom("mossCobbSlab"), 3, 2);
		bridge.setBlock(world, i + 2, j + 33, k + 13, this.blockRandom("mossCobbSlab"), 11, 2);
		bridge.setBlock(world, i + 2, j + 33, k + 15, this.blockRandom(null), 4, 2);
		bridge.setBlock(world, i + 2, j + 33, k + 17, this.blockRandom("mossCobbSlab"), 11, 2);
		bridge.setBlock(world, i + 2, j + 33, k + 18, this.blockRandom("mossCobbSlab"), 3, 2);
		bridge.setBlock(world, i + 2, j + 34, k + 14, this.blockRandom("mossCobbSlab"), 3, 2);
		bridge.setBlock(world, i + 2, j + 34, k + 15, Blocks.STONEBRICK, 1, 2);
		bridge.setBlock(world, i + 2, j + 34, k + 16, this.blockRandom("mossCobbSlab"), 3, 2);
		
		for(int fillk = 3; fillk <= 24; fillk++) {bridge.setBlock(world, i + 3, j + 0, k + fillk, stone());}
		
		for(int fillk = 3; fillk <= 24; fillk++) {bridge.setBlock(world, i + 3, j + 1, k + fillk, stone());}

		for(int fillk = 3; fillk <= 24; fillk++) {bridge.setBlock(world, i + 3, j + 2, k + fillk, stone());}

		for(int fillk = 3; fillk <= 24; fillk++) {bridge.setBlock(world, i + 3, j + 3, k + fillk, stone());}
		
		bridge.setBlock(world, i+3, j+2, k+10, Blocks.AIR, 2, 2);
		bridge.setBlock(world, i+3, j+3, k+10, Blocks.AIR, 2, 2);
		
		for(int fk = 3; fk <= 24; fk++) {bridge.setBlock(world, i + 3, j + 4, k + fk, stone());}
		
		bridge.setBlock(world, i + 3, j + 4, k + 23, Blocks.COBBLESTONE);

		bridge.setBlock(world, i + 3, j + 5, k + 3, stone());
		bridge.setBlock(world, i + 3, j + 5, k + 4, stone());
		bridge.setBlock(world, i + 3, j + 5, k + 5, stone());
		bridge.setBlock(world, i + 3, j + 5, k + 6, stone());
		bridge.setBlock(world, i + 3, j + 5, k + 7, JungleBlocks.ancientMossyBlock);
		bridge.setBlock(world, i + 3, j + 5, k + 8, JungleBlocks.ancientMossyBlock);
		bridge.setBlock(world, i + 3, j + 5, k + 9, JungleBlocks.ancientMossyBlock);
		bridge.setBlock(world, i + 3, j + 5, k + 10, JungleBlocks.ancientMossyBlock);
		bridge.setBlock(world, i + 3, j + 5, k + 11, JungleBlocks.ancientMossyBlock);
		bridge.setBlock(world, i + 3, j + 5, k + 12, JungleBlocks.ancientMossyBlock);
		bridge.setBlock(world, i + 3, j + 5, k + 13, JungleBlocks.ancientMossyBlock);
		bridge.setBlock(world, i + 3, j + 5, k + 14, JungleBlocks.ancientMossyBlock);
		bridge.setBlock(world, i + 3, j + 5, k + 15, JungleBlocks.mossyCarved);
		bridge.setBlock(world, i + 3, j + 5, k + 16, JungleBlocks.ancientMossyBlock);
		bridge.setBlock(world, i + 3, j + 5, k + 17, JungleBlocks.ancientMossyBlock);
		bridge.setBlock(world, i + 3, j + 5, k + 18, JungleBlocks.ancientMossyBlock);
		bridge.setBlock(world, i + 3, j + 5, k + 19, JungleBlocks.ancientMossyBlock);
		bridge.setBlock(world, i + 3, j + 5, k + 20, JungleBlocks.ancientMossyBlock);
		bridge.setBlock(world, i + 3, j + 5, k + 21, JungleBlocks.ancientMossyBlock);
		bridge.setBlock(world, i + 3, j + 5, k + 22, JungleBlocks.ancientMossyBlock);
		bridge.setBlock(world, i + 3, j + 5, k + 23, Blocks.COBBLESTONE);
		bridge.setBlock(world, i + 3, j + 5, k + 24, stone());
		bridge.setBlock(world, i + 3, j + 5, k + 25, stone());
		bridge.setBlock(world, i + 3, j + 6, k + 3, stone());
		bridge.setBlock(world, i + 3, j + 6, k + 4, stone());
		bridge.setBlock(world, i + 3, j + 6, k + 5, stone());
		bridge.setBlock(world, i + 3, j + 6, k + 6, stone());
		bridge.setBlock(world, i + 3, j + 6, k + 7, JungleBlocks.ancientMossyBlock);
		bridge.setBlock(world, i + 3, j + 6, k + 8, JungleBlocks.ancientMossyBlock);
		bridge.setBlock(world, i + 3, j + 6, k + 9, JungleBlocks.ancientMossyBlock);
		bridge.setBlock(world, i + 3, j + 6, k + 10, JungleBlocks.ancientMossyBlock);
		bridge.setBlock(world, i + 3, j + 6, k + 11, JungleBlocks.ancientMossyBlock);
		bridge.setBlock(world, i + 3, j + 6, k + 12, JungleBlocks.ancientMossyBlock);
		bridge.setBlock(world, i + 3, j + 6, k + 13, JungleBlocks.ancientMossyBlock);
		bridge.setBlock(world, i + 3, j + 6, k + 14, JungleBlocks.ancientMossyBlock);
		bridge.setBlock(world, i + 3, j + 6, k + 15, JungleBlocks.ancientMossyBlock);
		bridge.setBlock(world, i + 3, j + 6, k + 16, JungleBlocks.ancientMossyBlock);
		bridge.setBlock(world, i + 3, j + 6, k + 17, JungleBlocks.ancientMossyBlock);
		bridge.setBlock(world, i + 3, j + 6, k + 18, JungleBlocks.ancientMossyBlock);
		bridge.setBlock(world, i + 3, j + 6, k + 19, JungleBlocks.ancientMossyBlock);
		bridge.setBlock(world, i + 3, j + 6, k + 20, JungleBlocks.ancientMossyBlock);
		bridge.setBlock(world, i + 3, j + 6, k + 21, JungleBlocks.ancientMossyBlock);
		bridge.setBlock(world, i + 3, j + 6, k + 22, Blocks.COBBLESTONE);
		bridge.setBlock(world, i + 3, j + 6, k + 23, Blocks.COBBLESTONE);
		bridge.setBlock(world, i + 3, j + 6, k + 24, stone());
		bridge.setBlock(world, i + 3, j + 6, k + 25, stone());
		bridge.setBlock(world, i + 3, j + 7, k + 3, stone());
		bridge.setBlock(world, i + 3, j + 7, k + 4, stone());
		bridge.setBlock(world, i + 3, j + 7, k + 5, stone());
		bridge.setBlock(world, i + 3, j + 7, k + 6, stone());
		bridge.setBlock(world, i + 3, j + 7, k + 7, JungleBlocks.ancientMossyBlock);
		bridge.setBlock(world, i + 3, j + 7, k + 8, JungleBlocks.ancientMossyBlock);
		bridge.setBlock(world, i + 3, j + 7, k + 9, JungleBlocks.ancientMossyBlock);
		bridge.setBlock(world, i + 3, j + 7, k + 10, JungleBlocks.ancientMossyBlock);
		bridge.setBlock(world, i + 3, j + 7, k + 11, JungleBlocks.ancientMossyBlock);
		bridge.setBlock(world, i + 3, j + 7, k + 12, JungleBlocks.ancientMossyBlock);
		bridge.setBlock(world, i + 3, j + 7, k + 13, JungleBlocks.ancientMossyBlock);
		bridge.setBlock(world, i + 3, j + 7, k + 14, JungleBlocks.ancientMossyBlock);
		bridge.setBlock(world, i + 3, j + 7, k + 15, JungleBlocks.ancientMossyBlock);
		bridge.setBlock(world, i + 3, j + 7, k + 16, JungleBlocks.ancientMossyBlock);
		bridge.setBlock(world, i + 3, j + 7, k + 17, JungleBlocks.ancientMossyBlock);
		bridge.setBlock(world, i + 3, j + 7, k + 18, JungleBlocks.ancientMossyBlock);
		bridge.setBlock(world, i + 3, j + 7, k + 19, JungleBlocks.ancientMossyBlock);
		bridge.setBlock(world, i + 3, j + 7, k + 20, Blocks.COBBLESTONE);
		bridge.setBlock(world, i + 3, j + 7, k + 21, JungleBlocks.ancientMossyBlock);
		bridge.setBlock(world, i + 3, j + 7, k + 22, Blocks.COBBLESTONE);
		bridge.setBlock(world, i + 3, j + 7, k + 23, Blocks.COBBLESTONE);
		bridge.setBlock(world, i + 3, j + 7, k + 24, stone());
		bridge.setBlock(world, i + 3, j + 7, k + 25, stone());
		bridge.setBlock(world, i + 3, j + 8, k + 3, stone());
		bridge.setBlock(world, i + 3, j + 8, k + 4, stone());
		bridge.setBlock(world, i + 3, j + 8, k + 5, stone());
		bridge.setBlock(world, i + 3, j + 8, k + 6, stone());
		bridge.setBlock(world, i + 3, j + 8, k + 7, JungleBlocks.ancientMossyBlock);
		bridge.setBlock(world, i + 3, j + 8, k + 8, JungleBlocks.ancientMossyBlock);
		bridge.setBlock(world, i + 3, j + 8, k + 9, JungleBlocks.ancientMossyBlock);
		bridge.setBlock(world, i + 3, j + 8, k + 10, JungleBlocks.ancientMossyBlock);
		bridge.setBlock(world, i + 3, j + 8, k + 11, JungleBlocks.ancientMossyBlock);
		bridge.setBlock(world, i + 3, j + 8, k + 12, JungleBlocks.ancientMossyBlock);
		bridge.setBlock(world, i + 3, j + 8, k + 13, JungleBlocks.ancientMossyBlock);
		bridge.setBlock(world, i + 3, j + 8, k + 14, JungleBlocks.ancientMossyBlock);
		bridge.setBlock(world, i + 3, j + 8, k + 15, JungleBlocks.ancientMossyBlock);
		bridge.setBlock(world, i + 3, j + 8, k + 16, JungleBlocks.ancientMossyBlock);
		bridge.setBlock(world, i + 3, j + 8, k + 17, JungleBlocks.ancientMossyBlock);
		bridge.setBlock(world, i + 3, j + 8, k + 18, JungleBlocks.ancientMossyBlock);
		bridge.setBlock(world, i + 3, j + 8, k + 19, JungleBlocks.ancientMossyBlock);
		bridge.setBlock(world, i + 3, j + 8, k + 20, Blocks.COBBLESTONE);
		bridge.setBlock(world, i + 3, j + 8, k + 21, Blocks.COBBLESTONE);
		bridge.setBlock(world, i + 3, j + 8, k + 22, JungleBlocks.ancientMossyBlock);
		bridge.setBlock(world, i + 3, j + 8, k + 23, Blocks.COBBLESTONE);
		bridge.setBlock(world, i + 3, j + 8, k + 24, stone());
		bridge.setBlock(world, i + 3, j + 8, k + 25, stone());
		bridge.setBlock(world, i + 3, j + 9, k + 4, stone());
		bridge.setBlock(world, i + 3, j + 9, k + 5, stone());
		bridge.setBlock(world, i + 3, j + 9, k + 6, stone());
		bridge.setBlock(world, i + 3, j + 9, k + 7, JungleBlocks.ancientMossyBlock);
		bridge.setBlock(world, i + 3, j + 9, k + 8, JungleBlocks.ancientMossyBlock);
		bridge.setBlock(world, i + 3, j + 9, k + 9, JungleBlocks.ancientMossyBlock);
		bridge.setBlock(world, i + 3, j + 9, k + 10, JungleBlocks.ancientMossyBlock);
		bridge.setBlock(world, i + 3, j + 9, k + 11, JungleBlocks.ancientMossyBlock);
		bridge.setBlock(world, i + 3, j + 9, k + 12, JungleBlocks.ancientMossyBlock);
		bridge.setBlock(world, i + 3, j + 9, k + 13, JungleBlocks.ancientMossyBlock);
		bridge.setBlock(world, i + 3, j + 9, k + 14, JungleBlocks.ancientMossyBlock);
		bridge.setBlock(world, i + 3, j + 9, k + 15, JungleBlocks.ancientMossyBlock);
		bridge.setBlock(world, i + 3, j + 9, k + 16, JungleBlocks.ancientMossyBlock);
		bridge.setBlock(world, i + 3, j + 9, k + 17, JungleBlocks.ancientMossyBlock);
		bridge.setBlock(world, i + 3, j + 9, k + 18, JungleBlocks.ancientMossyBlock);
		bridge.setBlock(world, i + 3, j + 9, k + 19, JungleBlocks.ancientMossyBlock);
		bridge.setBlock(world, i + 3, j + 9, k + 20, JungleBlocks.ancientMossyBlock);
		bridge.setBlock(world, i + 3, j + 9, k + 21, Blocks.COBBLESTONE);
		bridge.setBlock(world, i + 3, j + 9, k + 22, JungleBlocks.ancientMossyBlock);
		bridge.setBlock(world, i + 3, j + 9, k + 23, JungleBlocks.ancientMossyBlock);
		bridge.setBlock(world, i + 3, j + 9, k + 24, stone());
		bridge.setBlock(world, i + 3, j + 9, k + 25, stone());
		bridge.setBlock(world, i + 3, j + 10, k + 4, stone());
		bridge.setBlock(world, i + 3, j + 10, k + 5, stone());
		bridge.setBlock(world, i + 3, j + 10, k + 6, stone());
		bridge.setBlock(world, i + 3, j + 10, k + 7, JungleBlocks.ancientMossyBlock);
		bridge.setBlock(world, i + 3, j + 10, k + 8, JungleBlocks.ancientMossyBlock);
		bridge.setBlock(world, i + 3, j + 10, k + 9, JungleBlocks.ancientMossyBlock);
		bridge.setBlock(world, i + 3, j + 10, k + 10, JungleBlocks.ancientMossyBlock);
		bridge.setBlock(world, i + 3, j + 10, k + 11, JungleBlocks.ancientMossyBlock);
		bridge.setBlock(world, i + 3, j + 10, k + 12, stone());
		bridge.setBlock(world, i + 3, j + 10, k + 13, stone());
		bridge.setBlock(world, i + 3, j + 10, k + 14, stone());
		bridge.setBlock(world, i + 3, j + 10, k + 15, stone());
		bridge.setBlock(world, i + 3, j + 10, k + 16, stone());
		bridge.setBlock(world, i + 3, j + 10, k + 17, stone());
		bridge.setBlock(world, i + 3, j + 10, k + 18, stone());
		bridge.setBlock(world, i + 3, j + 10, k + 19, stone());
		bridge.setBlock(world, i + 3, j + 10, k + 20, stone());
		bridge.setBlock(world, i + 3, j + 10, k + 21, JungleBlocks.ancientMossyBlock);
		bridge.setBlock(world, i + 3, j + 10, k + 22, JungleBlocks.ancientMossyBlock);
		bridge.setBlock(world, i + 3, j + 10, k + 23, JungleBlocks.ancientMossyBlock);
		bridge.setBlock(world, i + 3, j + 10, k + 24, stone());
		bridge.setBlock(world, i + 3, j + 10, k + 25, stone());
		bridge.setBlock(world, i + 3, j + 11, k + 4, stone());
		bridge.setBlock(world, i + 3, j + 11, k + 5, stone());
		bridge.setBlock(world, i + 3, j + 11, k + 6, stone());
		bridge.setBlock(world, i + 3, j + 11, k + 7, JungleBlocks.ancientMossyBlock);
		bridge.setBlock(world, i + 3, j + 11, k + 8, JungleBlocks.ancientMossyBlock);
		bridge.setBlock(world, i + 3, j + 11, k + 9, JungleBlocks.ancientMossyBlock);
		bridge.setBlock(world, i + 3, j + 11, k + 10, JungleBlocks.ancientMossyBlock);
		bridge.setBlock(world, i + 3, j + 11, k + 11, JungleBlocks.ancientMossyBlock);
		bridge.setBlock(world, i + 3, j + 11, k + 12, stone());
		bridge.setBlock(world, i + 3, j + 11, k + 13, stone());
		bridge.setBlock(world, i + 3, j + 11, k + 14, stone());
		bridge.setBlock(world, i + 3, j + 11, k + 15, stone());
		bridge.setBlock(world, i + 3, j + 11, k + 16, stone());
		bridge.setBlock(world, i + 3, j + 11, k + 17, stone());
		bridge.setBlock(world, i + 3, j + 11, k + 18, stone());
		bridge.setBlock(world, i + 3, j + 11, k + 19, stone());
		bridge.setBlock(world, i + 3, j + 11, k + 20, stone());
		bridge.setBlock(world, i + 3, j + 11, k + 21, stone());
		bridge.setBlock(world, i + 3, j + 11, k + 22, stone());
		bridge.setBlock(world, i + 3, j + 11, k + 23, JungleBlocks.ancientMossyBlock);
		bridge.setBlock(world, i + 3, j + 11, k + 24, stone());
		bridge.setBlock(world, i + 3, j + 11, k + 25, stone());
		bridge.setBlock(world, i + 3, j + 12, k + 5, stone());
		bridge.setBlock(world, i + 3, j + 12, k + 6, JungleBlocks.ancientMossyBlock);
		bridge.setBlock(world, i + 3, j + 12, k + 7, JungleBlocks.ancientMossyBlock);
		bridge.setBlock(world, i + 3, j + 12, k + 8, JungleBlocks.ancientMossyBlock);
		bridge.setBlock(world, i + 3, j + 12, k + 9, JungleBlocks.ancientMossyBlock);
		bridge.setBlock(world, i + 3, j + 12, k + 10, JungleBlocks.ancientMossyBlock);
		bridge.setBlock(world, i + 3, j + 12, k + 11, JungleBlocks.ancientMossyBlock);
		bridge.setBlock(world, i + 3, j + 12, k + 12, JungleBlocks.ancientMossyBlock);
		bridge.setBlock(world, i + 3, j + 12, k + 13, Blocks.COBBLESTONE);
		bridge.setBlock(world, i + 3, j + 12, k + 14, Blocks.COBBLESTONE);
		bridge.setBlock(world, i + 3, j + 12, k + 15, stone());
		bridge.setBlock(world, i + 3, j + 12, k + 16, stone());
		bridge.setBlock(world, i + 3, j + 12, k + 17, stone());
		bridge.setBlock(world, i + 3, j + 12, k + 18, stone());
		bridge.setBlock(world, i + 3, j + 12, k + 19, Blocks.COBBLESTONE);
		bridge.setBlock(world, i + 3, j + 12, k + 20, Blocks.COBBLESTONE);
		bridge.setBlock(world, i + 3, j + 12, k + 21, JungleBlocks.ancientMossyBlock);
		bridge.setBlock(world, i + 3, j + 12, k + 22, JungleBlocks.ancientMossyBlock);
		bridge.setBlock(world, i + 3, j + 12, k + 23, JungleBlocks.ancientMossyBlock);
		bridge.setBlock(world, i + 3, j + 12, k + 24, stone());
		bridge.setBlock(world, i + 3, j + 12, k + 25, stone());
		bridge.setBlock(world, i + 3, j + 13, k + 5, JungleBlocks.ancientMossyBlock);
		bridge.setBlock(world, i + 3, j + 13, k + 6, JungleBlocks.ancientMossyBlock);
		bridge.setBlock(world, i + 3, j + 13, k + 7, JungleBlocks.ancientMossyBlock);
		bridge.setBlock(world, i + 3, j + 13, k + 8, JungleBlocks.ancientMossyBlock);
		bridge.setBlock(world, i + 3, j + 13, k + 9, JungleBlocks.ancientMossyBlock);
		bridge.setBlock(world, i + 3, j + 13, k + 10, JungleBlocks.ancientMossyBlock);
		bridge.setBlock(world, i + 3, j + 13, k + 11, JungleBlocks.ancientMossyBlock);
		bridge.setBlock(world, i + 3, j + 13, k + 12, Blocks.COBBLESTONE);
		bridge.setBlock(world, i + 3, j + 13, k + 13, Blocks.COBBLESTONE);
		bridge.setBlock(world, i + 3, j + 13, k + 14, Blocks.COBBLESTONE);
		bridge.setBlock(world, i + 3, j + 13, k + 15, JungleBlocks.ancientMossyBlock);
		bridge.setBlock(world, i + 3, j + 13, k + 16, stone());
		bridge.setBlock(world, i + 3, j + 13, k + 17, Blocks.COBBLESTONE);
		bridge.setBlock(world, i + 3, j + 13, k + 18, Blocks.COBBLESTONE);
		bridge.setBlock(world, i + 3, j + 13, k + 19, Blocks.COBBLESTONE);
		bridge.setBlock(world, i + 3, j + 13, k + 20, JungleBlocks.ancientMossyBlock);
		bridge.setBlock(world, i + 3, j + 13, k + 21, JungleBlocks.ancientMossyBlock);
		bridge.setBlock(world, i + 3, j + 13, k + 22, JungleBlocks.ancientMossyBlock);
		bridge.setBlock(world, i + 3, j + 13, k + 23, JungleBlocks.ancientMossyBlock);
		bridge.setBlock(world, i + 3, j + 13, k + 24, stone());
		bridge.setBlock(world, i + 3, j + 13, k + 25, stone());
		bridge.setBlock(world, i + 3, j + 14, k + 5, JungleBlocks.ancientMossyBlock);
		bridge.setBlock(world, i + 3, j + 14, k + 6, JungleBlocks.ancientMossyBlock);
		bridge.setBlock(world, i + 3, j + 14, k + 7, JungleBlocks.ancientMossyBlock);
		bridge.setBlock(world, i + 3, j + 14, k + 8, JungleBlocks.ancientMossyBlock);
		bridge.setBlock(world, i + 3, j + 14, k + 9, JungleBlocks.ancientMossyBlock);
		bridge.setBlock(world, i + 3, j + 14, k + 10, JungleBlocks.ancientMossyBlock);
		bridge.setBlock(world, i + 3, j + 14, k + 11, JungleBlocks.ancientMossyBlock);
		bridge.setBlock(world, i + 3, j + 14, k + 12, Blocks.COBBLESTONE);
		bridge.setBlock(world, i + 3, j + 14, k + 13, JungleBlocks.ancientMossyBlock);
		bridge.setBlock(world, i + 3, j + 14, k + 14, JungleBlocks.ancientMossyBlock);
		bridge.setBlock(world, i + 3, j + 14, k + 15, JungleBlocks.ancientMossyBlock);
		bridge.setBlock(world, i + 3, j + 14, k + 16, JungleBlocks.ancientMossyBlock);
		bridge.setBlock(world, i + 3, j + 14, k + 17, JungleBlocks.ancientMossyBlock);
		bridge.setBlock(world, i + 3, j + 14, k + 18, JungleBlocks.ancientMossyBlock);
		bridge.setBlock(world, i + 3, j + 14, k + 19, JungleBlocks.ancientMossyBlock);
		bridge.setBlock(world, i + 3, j + 14, k + 20, JungleBlocks.ancientMossyBlock);
		bridge.setBlock(world, i + 3, j + 14, k + 21, JungleBlocks.ancientMossyBlock);
		bridge.setBlock(world, i + 3, j + 14, k + 22, JungleBlocks.ancientMossyBlock);
		bridge.setBlock(world, i + 3, j + 14, k + 23, JungleBlocks.ancientMossyBlock);
		bridge.setBlock(world, i + 3, j + 14, k + 24, JungleBlocks.ancientMossyBlock);
		bridge.setBlock(world, i + 3, j + 14, k + 25, stone());
		bridge.setBlock(world, i + 3, j + 15, k + 5, JungleBlocks.ancientMossyBlock);
		bridge.setBlock(world, i + 3, j + 15, k + 6, JungleBlocks.ancientMossyBlock);
		bridge.setBlock(world, i + 3, j + 15, k + 7, JungleBlocks.ancientMossyBlock);
		bridge.setBlock(world, i + 3, j + 15, k + 8, JungleBlocks.ancientMossyBlock);
		bridge.setBlock(world, i + 3, j + 15, k + 9, JungleBlocks.ancientMossyBlock);
		bridge.setBlock(world, i + 3, j + 15, k + 10, JungleBlocks.ancientMossyBlock);
		bridge.setBlock(world, i + 3, j + 15, k + 11, Blocks.COBBLESTONE);
		bridge.setBlock(world, i + 3, j + 15, k + 12, JungleBlocks.ancientMossyBlock);
		bridge.setBlock(world, i + 3, j + 15, k + 13, JungleBlocks.ancientMossyBlock);
		bridge.setBlock(world, i + 3, j + 15, k + 14, Blocks.COBBLESTONE);
		bridge.setBlock(world, i + 3, j + 15, k + 15, JungleBlocks.ancientMossyBlock);
		bridge.setBlock(world, i + 3, j + 15, k + 16, JungleBlocks.ancientMossyBlock);
		bridge.setBlock(world, i + 3, j + 15, k + 17, JungleBlocks.ancientMossyBlock);
		bridge.setBlock(world, i + 3, j + 15, k + 18, JungleBlocks.ancientMossyBlock);
		bridge.setBlock(world, i + 3, j + 15, k + 19, JungleBlocks.ancientMossyBlock);
		bridge.setBlock(world, i + 3, j + 15, k + 20, JungleBlocks.ancientMossyBlock);
		bridge.setBlock(world, i + 3, j + 15, k + 21, JungleBlocks.ancientMossyBlock);
		bridge.setBlock(world, i + 3, j + 15, k + 22, JungleBlocks.ancientMossyBlock);
		bridge.setBlock(world, i + 3, j + 15, k + 23, JungleBlocks.ancientMossyBlock);
		bridge.setBlock(world, i + 3, j + 15, k + 24, JungleBlocks.ancientMossyBlock);
		bridge.setBlock(world, i + 3, j + 15, k + 25, stone());
		bridge.setBlock(world, i + 3, j + 16, k + 5, JungleBlocks.ancientMossyBlock);
		bridge.setBlock(world, i + 3, j + 16, k + 6, JungleBlocks.ancientMossyBlock);
		bridge.setBlock(world, i + 3, j + 16, k + 7, JungleBlocks.ancientMossyBlock);
		bridge.setBlock(world, i + 3, j + 16, k + 8, JungleBlocks.ancientMossyBlock);
		bridge.setBlock(world, i + 3, j + 16, k + 9, JungleBlocks.ancientMossyBlock);
		bridge.setBlock(world, i + 3, j + 16, k + 10, JungleBlocks.ancientMossyBlock);
		bridge.setBlock(world, i + 3, j + 16, k + 11, Blocks.COBBLESTONE);
		bridge.setBlock(world, i + 3, j + 16, k + 12, JungleBlocks.ancientMossyBlock);
		bridge.setBlock(world, i + 3, j + 16, k + 13, JungleBlocks.ancientMossyBlock);
		bridge.setBlock(world, i + 3, j + 16, k + 14, JungleBlocks.ancientMossyBlock);
		bridge.setBlock(world, i + 3, j + 16, k + 15, Blocks.COBBLESTONE);
		bridge.setBlock(world, i + 3, j + 16, k + 16, JungleBlocks.ancientMossyBlock);
		bridge.setBlock(world, i + 3, j + 16, k + 17, JungleBlocks.ancientMossyBlock);
		bridge.setBlock(world, i + 3, j + 16, k + 18, Blocks.COBBLESTONE);
		bridge.setBlock(world, i + 3, j + 16, k + 19, JungleBlocks.ancientMossyBlock);
		bridge.setBlock(world, i + 3, j + 16, k + 20, JungleBlocks.ancientMossyBlock);
		bridge.setBlock(world, i + 3, j + 16, k + 21, JungleBlocks.ancientMossyBlock);
		bridge.setBlock(world, i + 3, j + 16, k + 22, JungleBlocks.ancientMossyBlock);
		bridge.setBlock(world, i + 3, j + 16, k + 23, JungleBlocks.ancientMossyBlock);
		bridge.setBlock(world, i + 3, j + 16, k + 24, JungleBlocks.ancientMossyBlock);
		bridge.setBlock(world, i + 3, j + 16, k + 25, JungleBlocks.ancientMossyBlock);
		bridge.setBlock(world, i + 3, j + 17, k + 5, JungleBlocks.ancientMossyBlock);
		bridge.setBlock(world, i + 3, j + 17, k + 6, JungleBlocks.ancientMossyBlock);
		bridge.setBlock(world, i + 3, j + 17, k + 7, JungleBlocks.mossyCarved);
		bridge.setBlock(world, i + 3, j + 17, k + 8, JungleBlocks.ancientMossyBlock);
		bridge.setBlock(world, i + 3, j + 17, k + 9, JungleBlocks.ancientMossyBlock);
		bridge.setBlock(world, i + 3, j + 17, k + 10, JungleBlocks.ancientMossyBlock);
		bridge.setBlock(world, i + 3, j + 17, k + 11, JungleBlocks.ancientMossyBlock);
		bridge.setBlock(world, i + 3, j + 17, k + 12, JungleBlocks.ancientMossyBlock);
		bridge.setBlock(world, i + 3, j + 17, k + 13, JungleBlocks.ancientMossyBlock);
		bridge.setBlock(world, i + 3, j + 17, k + 14, Blocks.COBBLESTONE);
		bridge.setBlock(world, i + 3, j + 17, k + 15, Blocks.COBBLESTONE);
		bridge.setBlock(world, i + 3, j + 17, k + 16, JungleBlocks.ancientMossyBlock);
		bridge.setBlock(world, i + 3, j + 17, k + 17, JungleBlocks.ancientMossyBlock);
		bridge.setBlock(world, i + 3, j + 17, k + 18, Blocks.COBBLESTONE);
		bridge.setBlock(world, i + 3, j + 17, k + 19, Blocks.COBBLESTONE);
		bridge.setBlock(world, i + 3, j + 17, k + 20, JungleBlocks.ancientMossyBlock);
		bridge.setBlock(world, i + 3, j + 17, k + 21, JungleBlocks.ancientMossyBlock);
		bridge.setBlock(world, i + 3, j + 17, k + 22, JungleBlocks.ancientMossyBlock);
		bridge.setBlock(world, i + 3, j + 17, k + 23, JungleBlocks.ancientMossyBlock);
		bridge.setBlock(world, i + 3, j + 17, k + 24, JungleBlocks.ancientMossyBlock);
		bridge.setBlock(world, i + 3, j + 17, k + 25, JungleBlocks.ancientMossyBlock);
		bridge.setBlock(world, i + 3, j + 18, k + 5, JungleBlocks.ancientMossyBlock);
		bridge.setBlock(world, i + 3, j + 18, k + 9, JungleBlocks.ancientMossyBlock);
		bridge.setBlock(world, i + 3, j + 18, k + 10, JungleBlocks.ancientMossyBlock);
		bridge.setBlock(world, i + 3, j + 18, k + 11, JungleBlocks.mossystairs);
		bridge.setBlock(world, i + 3, j + 18, k + 12, JungleBlocks.ancientMossyBlock);
		bridge.setBlock(world, i + 3, j + 18, k + 13, JungleBlocks.ancientMossyBlock);
		bridge.setBlock(world, i + 3, j + 18, k + 14, JungleBlocks.ancientMossyBlock);
		bridge.setBlock(world, i + 3, j + 18, k + 15, JungleBlocks.ancientMossyBlock);
		bridge.setBlock(world, i + 3, j + 18, k + 16, JungleBlocks.ancientMossyBlock);
		bridge.setBlock(world, i + 3, j + 18, k + 17, JungleBlocks.ancientMossyBlock);
		bridge.setBlock(world, i + 3, j + 18, k + 18, JungleBlocks.ancientMossyBlock);
		bridge.setBlock(world, i + 3, j + 18, k + 19, JungleBlocks.mossystairs);
		bridge.setBlock(world, i + 3, j + 18, k + 20, JungleBlocks.ancientMossyBlock);
		bridge.setBlock(world, i + 3, j + 18, k + 21, JungleBlocks.ancientMossyBlock);
		bridge.setBlock(world, i + 3, j + 18, k + 22, this.blockRandom(null), 1, 2);
		bridge.setBlock(world, i + 3, j + 18, k + 24, JungleBlocks.ancientMossyBlock);
		bridge.setBlock(world, i + 3, j + 18, k + 25, JungleBlocks.ancientMossyBlock);
		bridge.setBlock(world, i + 3, j + 19, k + 9, Blocks.STONEBRICK, 1, 2);
		bridge.setBlock(world, i + 3, j + 19, k + 10, Blocks.STONEBRICK, 1, 2);
		bridge.setBlock(world, i + 3, j + 19, k + 12, Blocks.STONEBRICK, 1, 2);
		bridge.setBlock(world, i + 3, j + 19, k + 13, Blocks.STONEBRICK, 1, 2);
		bridge.setBlock(world, i + 3, j + 19, k + 14, Blocks.STONEBRICK, 1, 2);
		bridge.setBlock(world, i + 3, j + 19, k + 15, Blocks.STONEBRICK, 1, 2);
		bridge.setBlock(world, i + 3, j + 19, k + 16, Blocks.STONEBRICK, 1, 2);
		bridge.setBlock(world, i + 3, j + 19, k + 17, Blocks.STONEBRICK, 1, 2);
		bridge.setBlock(world, i + 3, j + 19, k + 18, Blocks.STONEBRICK, 1, 2);
		bridge.setBlock(world, i + 3, j + 19, k + 20, Blocks.STONEBRICK, 1, 2);
		bridge.setBlock(world, i + 3, j + 19, k + 21, Blocks.STONEBRICK, 1, 2);
		bridge.setBlock(world, i + 3, j + 19, k + 24, Blocks.STONEBRICK, 1, 2);
		bridge.setBlock(world, i + 3, j + 19, k + 25, Blocks.STONEBRICK, 1, 2);
		bridge.setBlock(world, i + 3, j + 20, k + 9, Blocks.STONEBRICK, 1, 2);
		bridge.setBlock(world, i + 3, j + 20, k + 10, Blocks.STONEBRICK, 1, 2);
		bridge.setBlock(world, i + 3, j + 20, k + 12, Blocks.STONEBRICK, 1, 2);
		bridge.setBlock(world, i + 3, j + 20, k + 13, Blocks.STONEBRICK, 1, 2);
		bridge.setBlock(world, i + 3, j + 20, k + 14, Blocks.STONEBRICK, 1, 2);
		bridge.setBlock(world, i + 3, j + 20, k + 15, Blocks.STONEBRICK, 1, 2);
		bridge.setBlock(world, i + 3, j + 20, k + 16, Blocks.STONEBRICK, 1, 2);
		bridge.setBlock(world, i + 3, j + 20, k + 17, Blocks.STONEBRICK, 1, 2);
		bridge.setBlock(world, i + 3, j + 20, k + 18, Blocks.STONEBRICK, 1, 2);
		bridge.setBlock(world, i + 3, j + 20, k + 20, Blocks.STONEBRICK, 1, 2);
		bridge.setBlock(world, i + 3, j + 20, k + 21, Blocks.STONEBRICK, 1, 2);
		bridge.setBlock(world, i + 3, j + 20, k + 24, Blocks.STONEBRICK, 1, 2);
		bridge.setBlock(world, i + 3, j + 20, k + 25, Blocks.STONEBRICK, 1, 2);
		bridge.setBlock(world, i + 3, j + 21, k + 5, JungleBlocks.ancientMossyBlock);
		bridge.setBlock(world, i + 3, j + 21, k + 9, JungleBlocks.ancientMossyBlock);
		bridge.setBlock(world, i + 3, j + 21, k + 10, JungleBlocks.ancientMossyBlock);
		bridge.setBlock(world, i + 3, j + 21, k + 12, JungleBlocks.ancientMossyBlock);
		bridge.setBlock(world, i + 3, j + 21, k + 13, JungleBlocks.ancientMossyBlock);
		bridge.setBlock(world, i + 3, j + 21, k + 14, JungleBlocks.ancientMossyBlock);
		bridge.setBlock(world, i + 3, j + 21, k + 15, JungleBlocks.ancientMossyBlock);
		bridge.setBlock(world, i + 3, j + 21, k + 16, JungleBlocks.ancientMossyBlock);
		bridge.setBlock(world, i + 3, j + 21, k + 17, JungleBlocks.ancientMossyBlock);
		bridge.setBlock(world, i + 3, j + 21, k + 18, JungleBlocks.ancientMossyBlock);
		bridge.setBlock(world, i + 3, j + 21, k + 20, JungleBlocks.ancientMossyBlock);
		bridge.setBlock(world, i + 3, j + 21, k + 21, JungleBlocks.ancientMossyBlock);
		bridge.setBlock(world, i + 3, j + 21, k + 24, JungleBlocks.ancientMossyBlock);
		bridge.setBlock(world, i + 3, j + 21, k + 25, JungleBlocks.ancientMossyBlock);
		bridge.setBlock(world, i + 3, j + 22, k + 5, Blocks.STONEBRICK, 1, 2);
		bridge.setBlock(world, i + 3, j + 22, k + 6, JungleBlocks.ancientMossyBlock);
		bridge.setBlock(world, i + 3, j + 22, k + 7, JungleBlocks.mossyCarved);
		bridge.setBlock(world, i + 3, j + 22, k + 8, Blocks.STONEBRICK, 1, 2);
		bridge.setBlock(world, i + 3, j + 22, k + 9, Blocks.STONEBRICK, 1, 2);
		bridge.setBlock(world, i + 3, j + 22, k + 10, Blocks.STONEBRICK, 1, 2);
		bridge.setBlock(world, i + 3, j + 22, k + 12, Blocks.STONEBRICK, 1, 2);
		bridge.setBlock(world, i + 3, j + 22, k + 13, Blocks.STONEBRICK, 1, 2);
		bridge.setBlock(world, i + 3, j + 22, k + 14, Blocks.STONEBRICK, 1, 2);
		bridge.setBlock(world, i + 3, j + 22, k + 15, Blocks.STONEBRICK, 1, 2);
		bridge.setBlock(world, i + 3, j + 22, k + 16, Blocks.STONEBRICK, 1, 2);
		bridge.setBlock(world, i + 3, j + 22, k + 17, Blocks.STONEBRICK, 1, 2);
		bridge.setBlock(world, i + 3, j + 22, k + 18, Blocks.STONEBRICK, 1, 2);
		bridge.setBlock(world, i + 3, j + 22, k + 20, Blocks.STONEBRICK, 1, 2);
		bridge.setBlock(world, i + 3, j + 22, k + 21, Blocks.STONEBRICK, 1, 2);
		bridge.setBlock(world, i + 3, j + 22, k + 22, JungleBlocks.ancientMossyBlock);
		bridge.setBlock(world, i + 3, j + 22, k + 23, JungleBlocks.ancientMossyBlock);
		bridge.setBlock(world, i + 3, j + 22, k + 24, this.blockRandom(null));
		bridge.setBlock(world, i + 3, j + 22, k + 25, Blocks.STONEBRICK, 1, 2);
		bridge.setBlock(world, i + 3, j + 23, k + 5, JungleBlocks.mossystairs, 2, 2);
		bridge.setBlock(world, i + 3, j + 23, k + 9, JungleBlocks.ancientMossyBlock);
		bridge.setBlock(world, i + 3, j + 23, k + 10, JungleBlocks.ancientMossyBlock);
		bridge.setBlock(world, i + 3, j + 23, k + 11, JungleBlocks.mossystairs, 4 , 2);
		bridge.setBlock(world, i + 3, j + 23, k + 12, JungleBlocks.ancientMossyBlock);
		bridge.setBlock(world, i + 3, j + 23, k + 13, JungleBlocks.ancientMossyBlock);
		bridge.setBlock(world, i + 3, j + 23, k + 14, JungleBlocks.ancientMossyBlock);
		bridge.setBlock(world, i + 3, j + 23, k + 15, JungleBlocks.ancientMossyBlock);
		bridge.setBlock(world, i + 3, j + 23, k + 16, JungleBlocks.ancientMossyBlock);
		bridge.setBlock(world, i + 3, j + 23, k + 17, JungleBlocks.ancientMossyBlock);
		bridge.setBlock(world, i + 3, j + 23, k + 18, JungleBlocks.ancientMossyBlock);
		bridge.setBlock(world, i + 3, j + 23, k + 19, JungleBlocks.mossystairs, 4 , 2);
		bridge.setBlock(world, i + 3, j + 23, k + 20, JungleBlocks.ancientMossyBlock);
		bridge.setBlock(world, i + 3, j + 23, k + 21, JungleBlocks.ancientMossyBlock);
		bridge.setBlock(world, i + 3, j + 23, k + 25, JungleBlocks.mossystairs, 3, 2);
		bridge.setBlock(world, i + 3, j + 24, k + 9, Blocks.STONEBRICK, 1, 2);
		bridge.setBlock(world, i + 3, j + 24, k + 10, Blocks.STONEBRICK, 1, 2);
		bridge.setBlock(world, i + 3, j + 24, k + 11, Blocks.STONEBRICK, 1, 2);
		bridge.setBlock(world, i + 3, j + 24, k + 12, Blocks.STONEBRICK, 1, 2);
		bridge.setBlock(world, i + 3, j + 24, k + 13, Blocks.STONEBRICK, 1, 2);
		bridge.setBlock(world, i + 3, j + 24, k + 14, this.blockRandom("mossSmoothStairs"));
		bridge.setBlock(world, i + 3, j + 24, k + 15, this.blockRandom("mossSmoothStairs"));
		bridge.setBlock(world, i + 3, j + 24, k + 16, this.blockRandom("mossSmoothStairs"));
		bridge.setBlock(world, i + 3, j + 24, k + 17, Blocks.STONEBRICK, 1, 2);
		bridge.setBlock(world, i + 3, j + 24, k + 18, Blocks.STONEBRICK, 1, 2);
		bridge.setBlock(world, i + 3, j + 24, k + 19, Blocks.STONEBRICK, 1, 2);
		bridge.setBlock(world, i + 3, j + 24, k + 20, Blocks.STONEBRICK, 1, 2);
		bridge.setBlock(world, i + 3, j + 24, k + 21, Blocks.STONEBRICK, 1, 2);
		bridge.setBlock(world, i + 3, j + 25, k + 9, Blocks.STONEBRICK, 1, 2);
		bridge.setBlock(world, i + 3, j + 25, k + 10, Blocks.STONEBRICK, 1, 2);
		bridge.setBlock(world, i + 3, j + 25, k + 11, this.blockRandom("mossSmoothStairs"));
		bridge.setBlock(world, i + 3, j + 25, k + 12, Blocks.STONEBRICK, 1, 2);
		bridge.setBlock(world, i + 3, j + 25, k + 18, Blocks.STONEBRICK, 1, 2);
		bridge.setBlock(world, i + 3, j + 25, k + 19, this.blockRandom("mossSmoothStairs"));
		bridge.setBlock(world, i + 3, j + 25, k + 20, Blocks.STONEBRICK, 1, 2);
		bridge.setBlock(world, i + 3, j + 25, k + 21, Blocks.STONEBRICK, 1, 2);
		bridge.setBlock(world, i + 3, j + 26, k + 5, JungleBlocks.mossystairs, 6, 2);
		bridge.setBlock(world, i + 3, j + 26, k + 9, JungleBlocks.ancientMossyBlock);
		bridge.setBlock(world, i + 3, j + 26, k + 10, JungleBlocks.ancientMossyBlock);

		generate2(world, rand, i, j, k);
		return true;
	}

	public boolean generate2(World world, Random rand, int i, int j, int k) {
		bridge.setBlock(world, i + 3, j + 26, k + 12, JungleBlocks.ancientMossyBlock);
		bridge.setBlock(world, i + 3, j + 26, k + 18, JungleBlocks.ancientMossyBlock);
		bridge.setBlock(world, i + 3, j + 26, k + 20, JungleBlocks.ancientMossyBlock);
		bridge.setBlock(world, i + 3, j + 26, k + 21, JungleBlocks.ancientMossyBlock);
		bridge.setBlock(world, i + 3, j + 26, k + 25, JungleBlocks.mossystairs, 7, 2);
		bridge.setBlock(world, i + 3, j + 27, k + 5, Blocks.STONEBRICK, 1, 2);
		bridge.setBlock(world, i + 3, j + 27, k + 9, Blocks.STONEBRICK, 1, 2);
		bridge.setBlock(world, i + 3, j + 27, k + 10, Blocks.STONEBRICK, 1, 2);
		bridge.setBlock(world, i + 3, j + 27, k + 12, Blocks.STONEBRICK, 1, 2);
		bridge.setBlock(world, i + 3, j + 27, k + 18, Blocks.STONEBRICK, 1, 2);
		bridge.setBlock(world, i + 3, j + 27, k + 20, Blocks.STONEBRICK, 1, 2);
		bridge.setBlock(world, i + 3, j + 27, k + 21, Blocks.STONEBRICK, 1, 2);
		bridge.setBlock(world, i + 3, j + 27, k + 25, Blocks.STONEBRICK, 1, 2);
		bridge.setBlock(world, i + 3, j + 28, k + 5, JungleBlocks.ancientMossyBlock);
		bridge.setBlock(world, i + 3, j + 28, k + 9, JungleBlocks.ancientMossyBlock);
		bridge.setBlock(world, i + 3, j + 28, k + 10, JungleBlocks.ancientMossyBlock);
		bridge.setBlock(world, i + 3, j + 28, k + 11, JungleBlocks.mossystairs, 4 , 2);
		bridge.setBlock(world, i + 3, j + 28, k + 12, JungleBlocks.ancientMossyBlock);
		bridge.setBlock(world, i + 3, j + 28, k + 13, JungleBlocks.mossystairs, 4 , 2);
		bridge.setBlock(world, i + 3, j + 28, k + 17, this.blockRandom(null), 4, 2);
		bridge.setBlock(world, i + 3, j + 28, k + 18, JungleBlocks.ancientMossyBlock);
		bridge.setBlock(world, i + 3, j + 28, k + 19, JungleBlocks.mossystairs, 4 , 2);
		bridge.setBlock(world, i + 3, j + 28, k + 20, JungleBlocks.ancientMossyBlock);
		bridge.setBlock(world, i + 3, j + 28, k + 21, JungleBlocks.ancientMossyBlock);
		bridge.setBlock(world, i + 3, j + 28, k + 25, JungleBlocks.ancientMossyBlock);
		bridge.setBlock(world, i + 3, j + 29, k + 5, Blocks.STONEBRICK, 1, 2);
		bridge.setBlock(world, i + 3, j + 29, k + 6, JungleBlocks.ancientMossyBlock);
		bridge.setBlock(world, i + 3, j + 29, k + 7, JungleBlocks.ancientMossyBlock);
		bridge.setBlock(world, i + 3, j + 29, k + 8, JungleBlocks.ancientMossyBlock);
		bridge.setBlock(world, i + 3, j + 29, k + 9, Blocks.STONEBRICK, 1, 2);
		bridge.setBlock(world, i + 3, j + 29, k + 10, Blocks.STONEBRICK, 1, 2);
		bridge.setBlock(world, i + 3, j + 29, k + 11, Blocks.STONEBRICK, 1, 2);
		bridge.setBlock(world, i + 3, j + 29, k + 12, Blocks.STONEBRICK, 1, 2);
		bridge.setBlock(world, i + 3, j + 29, k + 13, Blocks.STONEBRICK, 1, 2);
		bridge.setBlock(world, i + 3, j + 29, k + 14, Blocks.STONEBRICK, 1, 2);
		bridge.setBlock(world, i + 3, j + 29, k + 15, Blocks.STONEBRICK);
		bridge.setBlock(world, i + 3, j + 29, k + 16, Blocks.STONEBRICK);
		bridge.setBlock(world, i + 3, j + 29, k + 17, Blocks.STONEBRICK);
		bridge.setBlock(world, i + 3, j + 29, k + 18, Blocks.STONEBRICK, 1, 2);
		bridge.setBlock(world, i + 3, j + 29, k + 19, Blocks.STONEBRICK, 1, 2);
		bridge.setBlock(world, i + 3, j + 29, k + 20, Blocks.STONEBRICK, 1, 2);
		bridge.setBlock(world, i + 3, j + 29, k + 21, Blocks.STONEBRICK, 1, 2);
		bridge.setBlock(world, i + 3, j + 29, k + 25, Blocks.STONEBRICK);
		bridge.setBlock(world, i + 3, j + 30, k + 5, this.blockRandom(null), 6, 2);
		bridge.setBlock(world, i + 3, j + 30, k + 6, JungleBlocks.ancientMossyBlock);
		bridge.setBlock(world, i + 3, j + 30, k + 7, JungleBlocks.ancientMossyBlock);
		bridge.setBlock(world, i + 3, j + 30, k + 8, JungleBlocks.ancientMossyBlock);
		bridge.setBlock(world, i + 3, j + 30, k + 9, JungleBlocks.ancientMossyBlock);
		bridge.setBlock(world, i + 3, j + 30, k + 10, JungleBlocks.ancientMossyBlock);
		bridge.setBlock(world, i + 3, j + 30, k + 11, JungleBlocks.ancientMossyBlock);
		bridge.setBlock(world, i + 3, j + 30, k + 12, JungleBlocks.ancientMossyBlock);
		bridge.setBlock(world, i + 3, j + 30, k + 13, JungleBlocks.ancientMossyBlock);
		bridge.setBlock(world, i + 3, j + 30, k + 14, JungleBlocks.mossystairs, 2, 2);
		bridge.setBlock(world, i + 3, j + 30, k + 15, Blocks.COBBLESTONE);
		bridge.setBlock(world, i + 3, j + 30, k + 16, this.blockRandom(null), 3, 2);
		bridge.setBlock(world, i + 3, j + 30, k + 17, JungleBlocks.ancientMossyBlock);
		bridge.setBlock(world, i + 3, j + 30, k + 18, JungleBlocks.ancientMossyBlock);
		bridge.setBlock(world, i + 3, j + 30, k + 19, JungleBlocks.ancientMossyBlock);
		bridge.setBlock(world, i + 3, j + 30, k + 20, JungleBlocks.ancientMossyBlock);
		bridge.setBlock(world, i + 3, j + 30, k + 21, JungleBlocks.ancientMossyBlock);
		bridge.setBlock(world, i + 3, j + 30, k + 22, JungleBlocks.ancientMossyBlock);
		bridge.setBlock(world, i + 3, j + 30, k + 23, JungleBlocks.ancientMossyBlock);
		bridge.setBlock(world, i + 3, j + 30, k + 24, JungleBlocks.ancientMossyBlock);
		bridge.setBlock(world, i + 3, j + 30, k + 25, this.blockRandom(null), 7, 2);
		bridge.setBlock(world, i + 3, j + 31, k + 5, Blocks.STONEBRICK);
		bridge.setBlock(world, i + 3, j + 31, k + 6, Blocks.NETHERRACK);
		bridge.setBlock(world, i + 3, j + 31, k + 7, JungleBlocks.ancientMossyBlock);
		bridge.setBlock(world, i + 3, j + 31, k + 8, Blocks.NETHERRACK);
		bridge.setBlock(world, i + 3, j + 31, k + 9, Blocks.STONEBRICK, 1, 2);
		bridge.setBlock(world, i + 3, j + 31, k + 10, Blocks.STONEBRICK, 1, 2);
		bridge.setBlock(world, i + 3, j + 31, k + 11, Blocks.STONEBRICK, 1, 2);
		bridge.setBlock(world, i + 3, j + 31, k + 12, Blocks.STONEBRICK, 1, 2);
		bridge.setBlock(world, i + 3, j + 31, k + 15, Blocks.STONEBRICK, 1, 2);
		bridge.setBlock(world, i + 3, j + 31, k + 18, Blocks.STONEBRICK, 1, 2);
		bridge.setBlock(world, i + 3, j + 31, k + 19, Blocks.STONEBRICK, 1, 2);
		bridge.setBlock(world, i + 3, j + 31, k + 20, Blocks.STONEBRICK, 1, 2);
		bridge.setBlock(world, i + 3, j + 31, k + 21, Blocks.STONEBRICK, 1, 2);
		bridge.setBlock(world, i + 3, j + 31, k + 22, Blocks.NETHERRACK);
		bridge.setBlock(world, i + 3, j + 31, k + 23, Blocks.COBBLESTONE);
		bridge.setBlock(world, i + 3, j + 31, k + 24, Blocks.NETHERRACK);
		bridge.setBlock(world, i + 3, j + 31, k + 25, Blocks.STONEBRICK);
		bridge.setBlock(world, i + 3, j + 32, k + 6, Blocks.FIRE, 15, 2);
		bridge.setBlock(world, i + 3, j + 32, k + 8, Blocks.FIRE, 15, 2);
		bridge.setBlock(world, i + 3, j + 32, k + 10, this.blockRandom("mossCobbSlab"), 3, 2);
		bridge.setBlock(world, i + 3, j + 32, k + 11, JungleBlocks.ancientMossyBlock);
		bridge.setBlock(world, i + 3, j + 32, k + 12, Blocks.STONEBRICK, 1, 2);
		bridge.setBlock(world, i + 3, j + 32, k + 13, Blocks.STONEBRICK, 1, 2);
		bridge.setBlock(world, i + 3, j + 32, k + 14, this.blockRandom("mossSmoothStairs"), 6, 2);
		bridge.setBlock(world, i + 3, j + 32, k + 15, Blocks.STONEBRICK, 1, 2);
		bridge.setBlock(world, i + 3, j + 32, k + 16, this.blockRandom("mossSmoothStairs"), 7, 2);
		bridge.setBlock(world, i + 3, j + 32, k + 17, Blocks.STONEBRICK, 1, 2);
		bridge.setBlock(world, i + 3, j + 32, k + 18, Blocks.STONEBRICK, 1, 2);
		bridge.setBlock(world, i + 3, j + 32, k + 19, Blocks.STONEBRICK, 1, 2);
		bridge.setBlock(world, i + 3, j + 32, k + 20, this.blockRandom("mossCobbSlab"), 3, 2);
		bridge.setBlock(world, i + 3, j + 32, k + 22, Blocks.FIRE, 15, 2);
		bridge.setBlock(world, i + 3, j + 32, k + 24, Blocks.FIRE, 15, 2);
		bridge.setBlock(world, i + 3, j + 33, k + 12, this.blockRandom("mossCobbSlab"), 3, 2);
		bridge.setBlock(world, i + 3, j + 33, k + 13, JungleBlocks.ancientMossyBlock);
		bridge.setBlock(world, i + 3, j + 33, k + 14, JungleBlocks.ancientMossyBlock);
		bridge.setBlock(world, i + 3, j + 33, k + 15, JungleBlocks.ancientMossyBlock);
		bridge.setBlock(world, i + 3, j + 33, k + 16, Blocks.COBBLESTONE);
		bridge.setBlock(world, i + 3, j + 33, k + 17, JungleBlocks.ancientMossyBlock);
		bridge.setBlock(world, i + 3, j + 33, k + 18, this.blockRandom("mossCobbSlab"), 3, 2);
		bridge.setBlock(world, i + 3, j + 34, k + 14, this.blockRandom("mossCobbSlab"), 3, 2);
		bridge.setBlock(world, i + 3, j + 34, k + 15, Blocks.STONEBRICK, 1, 2);
		bridge.setBlock(world, i + 3, j + 34, k + 16, this.blockRandom("mossCobbSlab"), 3, 2);
		
		for (int fill = 3; fill < 26; ++fill)
		{
			bridge.setBlock(world, i + 4, j + 0, k + fill, stone());
			bridge.setBlock(world, i + 4, j + 1, k + fill, stone());
			bridge.setBlock(world, i + 4, j + 2, k + fill, stone());
			bridge.setBlock(world, i + 4, j + 3, k + fill, stone());}
		
		bridge.setBlock(world, i + 4, j + 4, k + 3, stone());
		bridge.setBlock(world, i + 4, j + 4, k + 4, stone());
		bridge.setBlock(world, i + 4, j + 4, k + 5, stone());
		bridge.setBlock(world, i + 4, j + 4, k + 6, stone());
		bridge.setBlock(world, i + 4, j + 4, k + 7, stone());
		bridge.setBlock(world, i + 4, j + 4, k + 8, stone());
		bridge.setBlock(world, i + 4, j + 4, k + 9, stone());
		bridge.setBlock(world, i + 4, j + 4, k + 10, stone());
		bridge.setBlock(world, i + 4, j + 4, k + 11, stone());
		bridge.setBlock(world, i + 4, j + 4, k + 12, stone());
		bridge.setBlock(world, i + 4, j + 4, k + 13, stone());
		bridge.setBlock(world, i + 4, j + 4, k + 14, stone());
		bridge.setBlock(world, i + 4, j + 4, k + 15, stone());
		bridge.setBlock(world, i + 4, j + 4, k + 16, stone());
		bridge.setBlock(world, i + 4, j + 4, k + 17, stone());
		bridge.setBlock(world, i + 4, j + 4, k + 18, stone());
		bridge.setBlock(world, i + 4, j + 4, k + 19, stone());
		bridge.setBlock(world, i + 4, j + 4, k + 20, stone());
		bridge.setBlock(world, i + 4, j + 4, k + 21, stone());
		bridge.setBlock(world, i + 4, j + 4, k + 22, stone());
		bridge.setBlock(world, i + 4, j + 4, k + 23, Blocks.COBBLESTONE);
		bridge.setBlock(world, i + 4, j + 4, k + 24, stone());
		bridge.setBlock(world, i + 4, j + 4, k + 25, stone());
		bridge.setBlock(world, i + 4, j + 5, k + 3, stone());
		bridge.setBlock(world, i + 4, j + 5, k + 4, stone());
		bridge.setBlock(world, i + 4, j + 5, k + 5, stone());
		bridge.setBlock(world, i + 4, j + 5, k + 6, stone());
		bridge.setBlock(world, i + 4, j + 5, k + 7, JungleBlocks.ancientMossyBlock);
		bridge.setBlock(world, i + 4, j + 5, k + 8, JungleBlocks.ancientMossyBlock);
		bridge.setBlock(world, i + 4, j + 5, k + 9, JungleBlocks.ancientMossyBlock);
		bridge.setBlock(world, i + 4, j + 5, k + 10, JungleBlocks.ancientMossyBlock);
		bridge.setBlock(world, i + 4, j + 5, k + 11, JungleBlocks.ancientMossyBlock);
		bridge.setBlock(world, i + 4, j + 5, k + 12, JungleBlocks.ancientMossyBlock);
		bridge.setBlock(world, i + 4, j + 5, k + 13, JungleBlocks.ancientMossyBlock);
		bridge.setBlock(world, i + 4, j + 5, k + 14, JungleBlocks.ancientMossyBlock);
		bridge.setBlock(world, i + 4, j + 5, k + 15, JungleBlocks.ancientMossyBlock);
		bridge.setBlock(world, i + 4, j + 5, k + 16, JungleBlocks.ancientMossyBlock);
		bridge.setBlock(world, i + 4, j + 5, k + 17, JungleBlocks.ancientMossyBlock);
		bridge.setBlock(world, i + 4, j + 5, k + 18, JungleBlocks.ancientMossyBlock);
		bridge.setBlock(world, i + 4, j + 5, k + 19, JungleBlocks.ancientMossyBlock);
		bridge.setBlock(world, i + 4, j + 5, k + 20, JungleBlocks.ancientMossyBlock);
		bridge.setBlock(world, i + 4, j + 5, k + 21, JungleBlocks.ancientMossyBlock);
		bridge.setBlock(world, i + 4, j + 5, k + 22, JungleBlocks.ancientMossyBlock);
		bridge.setBlock(world, i + 4, j + 5, k + 23, Blocks.COBBLESTONE);
		bridge.setBlock(world, i + 4, j + 5, k + 24, stone());
		bridge.setBlock(world, i + 4, j + 5, k + 25, stone());
		bridge.setBlock(world, i + 4, j + 6, k + 3, stone());
		bridge.setBlock(world, i + 4, j + 6, k + 4, stone());
		bridge.setBlock(world, i + 4, j + 6, k + 5, stone());
		bridge.setBlock(world, i + 4, j + 6, k + 6, stone());
		bridge.setBlock(world, i + 4, j + 6, k + 7, JungleBlocks.ancientMossyBlock);
		bridge.setBlock(world, i + 4, j + 6, k + 8, JungleBlocks.ancientMossyBlock);
		bridge.setBlock(world, i + 4, j + 6, k + 9, this.blockRandom(null), 3, 2);
		bridge.setBlock(world, i + 4, j + 6, k + 11, JungleBlocks.ancientMossyBlock);
		
		fill.fillWithRotation(world, i, j, k, 4, 4, 6, 6, 12, 18, JungleBlocks.infusedObsidianBlock, rota);
		
		bridge.setBlock(world, i + 4, j + 6, k + 19, JungleBlocks.ancientMossyBlock);
		bridge.setBlock(world, i + 4, j + 6, k + 21, JungleBlocks.mossystairs, 2, 2);
		bridge.setBlock(world, i + 4, j + 6, k + 22, JungleBlocks.ancientMossyBlock);
		bridge.setBlock(world, i + 4, j + 6, k + 23, Blocks.COBBLESTONE);
		bridge.setBlock(world, i + 4, j + 6, k + 24, stone());
		bridge.setBlock(world, i + 4, j + 6, k + 25, stone());
		bridge.setBlock(world, i + 4, j + 7, k + 3, stone());
		bridge.setBlock(world, i + 4, j + 7, k + 4, stone());
		bridge.setBlock(world, i + 4, j + 7, k + 5, stone());
		bridge.setBlock(world, i + 4, j + 7, k + 6, stone());
		bridge.setBlock(world, i + 4, j + 7, k + 7, JungleBlocks.ancientMossyBlock);
		bridge.setBlock(world, i + 4, j + 7, k + 8, Blocks.STONEBRICK, 1, 2);
		bridge.setBlock(world, i + 4, j + 7, k + 11, Blocks.STONEBRICK, 1, 2);
		bridge.setBlock(world, i + 4, j + 7, k + 12, JungleBlocks.infusedObsidianBlock);
		bridge.setBlock(world, i + 4, j + 7, k + 13, JungleBlocks.infusedObsidianBlock);
		bridge.setBlock(world, i + 4, j + 7, k + 14, JungleBlocks.lostWorldPortal);
		bridge.setBlock(world, i + 4, j + 7, k + 15, JungleBlocks.lostWorldPortal);
		bridge.setBlock(world, i + 4, j + 7, k + 16, JungleBlocks.lostWorldPortal);
		bridge.setBlock(world, i + 4, j + 7, k + 17, JungleBlocks.infusedObsidianBlock);
		bridge.setBlock(world, i + 4, j + 7, k + 18, JungleBlocks.infusedObsidianBlock);
		bridge.setBlock(world, i + 4, j + 7, k + 19, Blocks.STONEBRICK, 1, 2);
		bridge.setBlock(world, i + 4, j + 7, k + 22, Blocks.STONEBRICK, 1, 2);
		bridge.setBlock(world, i + 4, j + 7, k + 23, JungleBlocks.ancientMossyBlock);
		bridge.setBlock(world, i + 4, j + 7, k + 24, stone());
		bridge.setBlock(world, i + 4, j + 7, k + 25, stone());
		bridge.setBlock(world, i + 4, j + 8, k + 3, stone());
		bridge.setBlock(world, i + 4, j + 8, k + 4, stone());
		bridge.setBlock(world, i + 4, j + 8, k + 5, stone());
		bridge.setBlock(world, i + 4, j + 8, k + 6, stone());
		bridge.setBlock(world, i + 4, j + 8, k + 7, JungleBlocks.ancientMossyBlock);
		bridge.setBlock(world, i + 4, j + 8, k + 8, Blocks.STONEBRICK, 1, 2);
		bridge.setBlock(world, i + 4, j + 8, k + 11, Blocks.STONEBRICK, 1, 2);
		bridge.setBlock(world, i + 4, j + 8, k + 12, JungleBlocks.infusedObsidianBlock);
		bridge.setBlock(world, i + 4, j + 8, k + 13, JungleBlocks.infusedObsidianBlock);
		bridge.setBlock(world, i + 4, j + 8, k + 14, JungleBlocks.lostWorldPortal);
		bridge.setBlock(world, i + 4, j + 8, k + 15, JungleBlocks.lostWorldPortal);
		bridge.setBlock(world, i + 4, j + 8, k + 16, JungleBlocks.lostWorldPortal);
		bridge.setBlock(world, i + 4, j + 8, k + 17, JungleBlocks.infusedObsidianBlock);
		bridge.setBlock(world, i + 4, j + 8, k + 18, JungleBlocks.infusedObsidianBlock);
		bridge.setBlock(world, i + 4, j + 8, k + 19, Blocks.STONEBRICK, 1, 2);
		bridge.setBlock(world, i + 4, j + 8, k + 22, Blocks.STONEBRICK);
		bridge.setBlock(world, i + 4, j + 8, k + 23, JungleBlocks.ancientMossyBlock);
		bridge.setBlock(world, i + 4, j + 8, k + 24, stone());
		bridge.setBlock(world, i + 4, j + 8, k + 25, stone());
		bridge.setBlock(world, i + 4, j + 9, k + 3, stone());
		bridge.setBlock(world, i + 4, j + 9, k + 4, stone());
		bridge.setBlock(world, i + 4, j + 9, k + 5, stone());
		bridge.setBlock(world, i + 4, j + 9, k + 6, stone());
		bridge.setBlock(world, i + 4, j + 9, k + 7, JungleBlocks.ancientMossyBlock);
		bridge.setBlock(world, i + 4, j + 9, k + 8, JungleBlocks.mossyCarved);
		bridge.setBlock(world, i + 4, j + 9, k + 11, JungleBlocks.ancientMossyBlock);
		bridge.setBlock(world, i + 4, j + 9, k + 12, JungleBlocks.infusedObsidianBlock);
		bridge.setBlock(world, i + 4, j + 9, k + 13, JungleBlocks.infusedObsidianBlock);
		bridge.setBlock(world, i + 4, j + 9, k + 14, JungleBlocks.lostWorldPortal);
		bridge.setBlock(world, i + 4, j + 9, k + 15, JungleBlocks.lostWorldPortal);
		bridge.setBlock(world, i + 4, j + 9, k + 16, JungleBlocks.lostWorldPortal);
		bridge.setBlock(world, i + 4, j + 9, k + 17, JungleBlocks.infusedObsidianBlock);
		bridge.setBlock(world, i + 4, j + 9, k + 18, JungleBlocks.infusedObsidianBlock);
		bridge.setBlock(world, i + 4, j + 9, k + 19, JungleBlocks.ancientMossyBlock);
		bridge.setBlock(world, i + 4, j + 9, k + 22, JungleBlocks.mossyCarved);
		bridge.setBlock(world, i + 4, j + 9, k + 23, JungleBlocks.ancientMossyBlock);
		bridge.setBlock(world, i + 4, j + 9, k + 24, stone());
		bridge.setBlock(world, i + 4, j + 9, k + 25, stone());
		bridge.setBlock(world, i + 4, j + 10, k + 3, stone());
		bridge.setBlock(world, i + 4, j + 10, k + 4, stone());
		bridge.setBlock(world, i + 4, j + 10, k + 5, stone());
		bridge.setBlock(world, i + 4, j + 10, k + 6, stone());
		bridge.setBlock(world, i + 4, j + 10, k + 7, JungleBlocks.ancientMossyBlock);
		bridge.setBlock(world, i + 4, j + 10, k + 8, Blocks.STONEBRICK, 1, 2);
		bridge.setBlock(world, i + 4, j + 10, k + 11, Blocks.STONEBRICK, 1, 2);
		bridge.setBlock(world, i + 4, j + 10, k + 12, JungleBlocks.infusedObsidianBlock);
		bridge.setBlock(world, i + 4, j + 10, k + 13, JungleBlocks.infusedObsidianBlock);
		bridge.setBlock(world, i + 4, j + 10, k + 14, JungleBlocks.lostWorldPortal);
		bridge.setBlock(world, i + 4, j + 10, k + 15, JungleBlocks.lostWorldPortal);
		bridge.setBlock(world, i + 4, j + 10, k + 16, JungleBlocks.lostWorldPortal);
		bridge.setBlock(world, i + 4, j + 10, k + 17, JungleBlocks.infusedObsidianBlock);
		bridge.setBlock(world, i + 4, j + 10, k + 18, JungleBlocks.infusedObsidianBlock);
		bridge.setBlock(world, i + 4, j + 10, k + 19, Blocks.STONEBRICK, 1, 2);
		bridge.setBlock(world, i + 4, j + 10, k + 22, Blocks.STONEBRICK, 1, 2);
		bridge.setBlock(world, i + 4, j + 10, k + 23, JungleBlocks.ancientMossyBlock);
		bridge.setBlock(world, i + 4, j + 10, k + 24, stone());
		bridge.setBlock(world, i + 4, j + 10, k + 25, stone());
		bridge.setBlock(world, i + 4, j + 11, k + 4, stone());
		bridge.setBlock(world, i + 4, j + 11, k + 5, stone());
		bridge.setBlock(world, i + 4, j + 11, k + 6, stone());
		bridge.setBlock(world, i + 4, j + 11, k + 7, JungleBlocks.ancientMossyBlock);
		bridge.setBlock(world, i + 4, j + 11, k + 8, JungleBlocks.ancientMossyBlock);
		bridge.setBlock(world, i + 4, j + 11, k + 9, JungleBlocks.mossystairs, 7, 2);
		bridge.setBlock(world, i + 4, j + 11, k + 11, JungleBlocks.ancientMossyBlock);
		bridge.setBlock(world, i + 4, j + 11, k + 12, JungleBlocks.infusedObsidianBlock);
		bridge.setBlock(world, i + 4, j + 11, k + 13, JungleBlocks.infusedObsidianBlock);
		bridge.setBlock(world, i + 4, j + 11, k + 14, JungleBlocks.infusedObsidianBlock);
		bridge.setBlock(world, i + 4, j + 11, k + 15, JungleBlocks.infusedObsidianBlock);
		bridge.setBlock(world, i + 4, j + 11, k + 16, JungleBlocks.infusedObsidianBlock);
		bridge.setBlock(world, i + 4, j + 11, k + 17, JungleBlocks.infusedObsidianBlock);
		bridge.setBlock(world, i + 4, j + 11, k + 18, JungleBlocks.infusedObsidianBlock);
		bridge.setBlock(world, i + 4, j + 11, k + 19, JungleBlocks.ancientMossyBlock);
		bridge.setBlock(world, i + 4, j + 11, k + 21, this.blockRandom(null), 6, 2);
		bridge.setBlock(world, i + 4, j + 11, k + 22, JungleBlocks.ancientMossyBlock);
		bridge.setBlock(world, i + 4, j + 11, k + 23, JungleBlocks.ancientMossyBlock);
		bridge.setBlock(world, i + 4, j + 11, k + 24, stone());
		bridge.setBlock(world, i + 4, j + 11, k + 25, stone());
		bridge.setBlock(world, i + 4, j + 12, k + 4, stone());
		bridge.setBlock(world, i + 4, j + 12, k + 5, stone());
		bridge.setBlock(world, i + 4, j + 12, k + 6, JungleBlocks.ancientMossyBlock);
		bridge.setBlock(world, i + 4, j + 12, k + 7, JungleBlocks.ancientMossyBlock);
		//corner nw is i3, j12 k7.
		// i6 j13 k11
		//blocked
		for(int fillj = 0; fillj <= 3; fillj++) {
			bridge.setBlock(world, i+6, j+13+fillj, k+11, JungleBlocks.ancientMossyBlock);
		}
		
		bridge.setBlock(world, i + 4, j + 12, k + 8, JungleBlocks.mossyCarved);
		bridge.setBlock(world, i + 4, j + 12, k + 9, Blocks.STONEBRICK, 1, 2);
		bridge.setBlock(world, i + 4, j + 12, k + 10, Blocks.STONEBRICK, 1, 2);
		bridge.setBlock(world, i + 4, j + 12, k + 11, Blocks.STONEBRICK, 1, 2);
		bridge.setBlock(world, i + 4, j + 12, k + 12, JungleBlocks.ancientMossyBlock);
		bridge.setBlock(world, i + 4, j + 12, k + 13, Blocks.STONEBRICK, 1, 2);
		bridge.setBlock(world, i + 4, j + 12, k + 14, Blocks.STONEBRICK, 1, 2);
		bridge.setBlock(world, i + 4, j + 12, k + 15, Blocks.STONEBRICK, 1, 2);
		bridge.setBlock(world, i + 4, j + 12, k + 16, JungleBlocks.ancientMossyBlock);
		bridge.setBlock(world, i + 4, j + 12, k + 17, Blocks.STONEBRICK, 1, 2);
		bridge.setBlock(world, i + 4, j + 12, k + 18, Blocks.STONEBRICK, 1, 2);
		bridge.setBlock(world, i + 4, j + 12, k + 19, Blocks.STONEBRICK, 1, 2);
		bridge.setBlock(world, i + 4, j + 12, k + 20, JungleBlocks.ancientMossyBlock);
		bridge.setBlock(world, i + 4, j + 12, k + 21, Blocks.STONEBRICK, 1, 2);
		bridge.setBlock(world, i + 4, j + 12, k + 22, Blocks.STONEBRICK, 1, 2);
		bridge.setBlock(world, i + 4, j + 12, k + 23, JungleBlocks.ancientMossyBlock);
		bridge.setBlock(world, i + 4, j + 12, k + 24, stone());
		bridge.setBlock(world, i + 4, j + 12, k + 25, stone());
		bridge.setBlock(world, i + 4, j + 13, k + 4, stone());
